File: Data used in paper/Case study 4/ML_20240715_2_QHS_0-QHS1059B_NdBa0p7K0p3CuBO5_powder_DC-14p5mg_MvT_50oe_20240718 (1).dat
[Header]
; MPMS3 Data File (default extension .dat)
; Copyright (c) 2007, Quantum Design, Inc. All rights reserved.
TITLE,
FILEOPENTIME,3930468371.14175,07/18/2024,12:45 pm
BYAPP,MPMS3 w/ AC,1.0,1.1
INFO,MPMS3 Measurement Release 1.1.16 Build 419, MultiVu Release 2.3.4.15,APPNAME
INFO,Linear Motor Servo Controller,MOTOR_MODULE_NAME
INFO,3101-100 F0,MOTOR_HW_VERSION
INFO,MMC1118,MOTOR_SERIAL_NUMBER
INFO,01.04.28,MOTOR_SOFTWARE_VERSION
INFO,Quantum Design Squid Module,SQUID_MODULE_NAME
INFO,3101-501 B0,SQUID_HW_VERSION
INFO,SQM313,SQUID_SERIAL_NUMBER
INFO,01.03.04,SQUID_SOFTWARE_VERSION
INFO,Quantum Design VSM Oven,OVEN_MODULE_NAME
INFO,3101-201 A3,OVEN_HW_VERSION
INFO,OVB345,OVEN_SERIAL_NUMBER
INFO,01.07.07,OVEN_SOFTWARE_VERSION
INFO,SQUID AC,AC_MODULE_NAME
INFO,3101-401 G0,AC_HW_VERSION
INFO,SAC210,AC_SERIAL_NUMBER
INFO,SQUID AC 00.95.07,AC_SOFTWARE_VERSION
INFO,TCI318,COIL_SERIAL_NUMBER
INFO,0,MOMENT_UNITS
INFO,ML_Barksdale_20240705_1_MRG128B_q(cs)=7_q(cu)=0.1_no_peroxide_ony_H20_20.0mg_ZFC_FC_MvT_10000oe,SAMPLE_MATERIAL
INFO,,SAMPLE_COMMENT
INFO,14.5,SAMPLE_MASS
INFO,,SAMPLE_VOLUME
INFO,,SAMPLE_MOLECULAR_WEIGHT
INFO,,SAMPLE_SIZE
INFO,,SAMPLE_SHAPE
INFO,Straw,SAMPLE_HOLDER
INFO,Standard,SAMPLE_HOLDER_DETAIL
INFO,68.54,SAMPLE_OFFSET
DATATYPE,COMMENT,1
DATATYPE,TIME,2
STARTUPAXIS,X,2
STARTUPAXIS,Y1,5
FIELDGROUP, VSM,2,3,4,5,6,8,9,10,11,14,15
FIELDGROUP, DC, 2,3,4,14,56,57,58,59,60,61,62,63,64,65,66,67,68,69
FIELDGROUP, AC, 2,3,4,11,16,17,18,19,20,21,22,23,24,25,26,27,28,29,30
STARTUPGROUP, All
[Data]
Comment,Time Stamp (sec),Temperature (K),Magnetic Field (Oe),Moment (emu),M. Std. Err. (emu),Transport Action,Averaging Time (sec),Frequency (Hz),Peak Amplitude (mm),Center Position (mm),Lockin Signal' (V),Lockin Signal (V),Range,M. Quad. Signal (emu),AC Moment (emu),AC M. Std Err. (emu),AC Phase (deg),AC Phase Std. Err. (deg),AC Susceptibility (emu/Oe),AC Suscept. Std Err. (emu/Oe),AC X' (emu/Oe),AC X' Std Err. (emu/Oe),AC X'' (emu/Oe),AC X'' Std Err. (emu/Oe),AC Drive (Oe),AC Frequency (Hz),AC Averaging Time (sec),AC Cycles,AC Range,AC Measure Type,AC Signal' (V),AC Signal'' (V),AC Trim Coil Ratio,AC Trim Coil Phase,Min. Temperature (K),Max. Temperature (K),Min. Field (Oe),Max. Field (Oe),Mass (grams),Motor Lag (deg),Pressure (Torr),Measure Count,Measurement Number,SQUID Status (code),Motor Status (code),Measure Status (code),Motor Current (amps),Motor Temp. (C),Temp. Status (code),Field Status (code),Chamber Status (code),Chamber Temp (K),Redirection State,Evercool Status,Average Temp (K),Rotation Angle (deg),Rotator state,DC Moment Fixed Ctr (emu),DC Moment Err Fixed Ctr (emu),DC Moment Free Ctr (emu),DC Moment Err Free Ctr (emu),DC Fixed Fit,DC Free Fit,DC Calculated Center (mm),DC Calculated Center Err (mm),DC Scan Length (mm),DC Scan Time (s),DC Number of Points,DC Squid Drift,DC Min V (V),DC Max V (V),DC Scans per Measure,Map 01,Map 02,Map 03,Map 04,Map 05,Map 06,Map 07,Map 08,Map 09,Map 10,Map 11,Map 12,Map 13,Map 14,Map 15,Map 16
,3930469927.51134,1.79935491085052,49.9937515258789,,,3,,,,26.9466075897217,,,,,,,,,,,,,,,,,,,,,,,,,1.79935491085052,1.79935491085052,49.9937515258789,49.9937515258789,,,2.73728823661804,,0,,,,,,1,1,1,1.79935491085052,0,0,0,,,,,,,,,,,,,,,,,,,,,,,,,,,,,,,,,
,3930469961.96702,1.92167580127716,49.9937515258789,,,6,,,,26.9466075897217,,,1,,,,,,,,,,,,,,,,,,,,,,1.85663259029388,1.98306107521057,49.9937515258789,49.9937515258789,,,2.83423638343811,,1,0,0,0,0.013885498046875,28.8367557525635,6,1,1,1.98671901226044,0,2084574272,1.91552032232285,,,0.000935957957287439,4.66819297648506E-5,0.000935957954040447,4.66819294331155E-5,0.994961678981781,0.994962453842163,26.9462852478027,INF,30,4,200,-0.000505177653394639,-4.0651068687439,0.349881172180176,1,,,,,,,,,,,,,,,,
,3930469981.77094,2.19714558124542,49.9937515258789,,,6,,,,26.9466075897217,,,1,,,,,,,,,,,,,,,,,,,,,,2.1277437210083,2.26069498062134,49.9937515258789,49.9937515258789,,,3.02039337158203,,1,0,0,0,0.013885498046875,28.3479976654053,6,1,1,2.26654744148254,0,2084574336,2.1919691324234,,,0.000927626719313369,4.6266300451112E-5,0.000927626717566075,4.62663002465119E-5,0.995413362979889,0.995413959026337,26.9463386535645,INF,30,4,200,-1.21683260658756E-5,-4.03388214111328,0.333834320306778,1,,,,,,,,,,,,,,,,
,3930470010.00918,2.5904815196991,49.9937515258789,,,6,,,,26.9516608379761,,,1,,,,,,,,,,,,,,,,,,,,,,2.52366924285889,2.65412664413452,49.9937515258789,49.9937515258789,,,3.25292658805847,,1,0,0,0,0.013885498046875,28.3479976654053,6,1,1,2.65729379653931,0,2084574624,2.58581449985504,,,0.000925743412940792,4.61724207479367E-5,0.000925744530593594,4.6172424122078E-5,0.995185017585754,0.995426654815674,26.9459667205811,5.19095039367676,30,4,200,0.000205581513000652,-4.02775812149048,0.328324168920517,1,,,,,,,,,,,,,,,,
,3930470029.84364,2.8734757900238,49.9937515258789,,,6,,,,26.9516608379761,,,1,,,,,,,,,,,,,,,,,,,,,,2.80486273765564,2.94222784042358,49.9937515258789,49.9937515258789,,,3.41079711914063,,1,0,0,0,0.013885498046875,27.8592376708984,6,1,1,2.94538950920105,0,2084574400,2.87083075046539,,,0.000927019180772945,4.62360619507399E-5,0.000927020242609514,4.62360608985688E-5,0.995166897773743,0.995414972305298,26.9458808898926,5.41724784852704E-6,30,4,200,0.000269851443590596,-4.03401947021484,0.328125804662704,1,,,,,,,,,,,,,,,,
,3930470049.51488,3.16432893276215,49.9937515258789,,,6,,,,26.9516608379761,,,1,,,,,,,,,,,,,,,,,,,,,,3.09495162963867,3.23370623588562,49.9937515258789,49.9937515258789,,,3.5545928478241,,1,0,0,0,0.013885498046875,28.3479976654053,6,1,1,3.23370623588562,0,2084574688,3.15870003700256,,,0.000929846647222174,4.6377067053979E-5,0.000929847835193903,4.63770707609031E-5,0.995157837867737,0.995411872863769,26.9458084106445,INF,30,4,200,0.00037644401891157,-4.04550647735596,0.330857127904892,1,,,,,,,,,,,,,,,,
,3930470069.13277,3.44554007053375,49.9937515258789,,,6,,,,26.9516608379761,,,1,,,,,,,,,,,,,,,,,,,,,,3.38166928291321,3.50193786621094,49.9937515258789,49.9937515258789,,,3.68120765686035,,1,0,0,0,0.013885498046875,26.881721496582,6,1,1,3.5094108581543,0,2084574336,3.43911190032959,,,0.000933758785777018,4.65721978021954E-5,0.000933760048285623,4.65722012118284E-5,0.995155453681946,0.995427072048187,26.945613861084,0,30,4,200,0.000481050636153668,-4.06006336212158,0.335574984550476,1,,,,,,,,,,,,,,,,
,3930470088.79904,3.71983695030212,49.9937515258789,,,6,,,,26.9516608379761,,,1,,,,,,,,,,,,,,,,,,,,,,3.65071368217468,3.78637146949768,49.9937515258789,49.9937515258789,,,3.79627108573914,,1,0,0,0,0.013885498046875,28.3479976654053,6,1,1,3.78896021842957,0,2084574400,3.71573846340179,,,0.000938006916528683,4.67841077280956E-5,0.000938008210349054,4.67841085202306E-5,0.995101392269134,0.99538791179657,26.9454193115234,INF,30,4,200,0.000452796841273084,-4.07518815994263,0.340391844511032,1,,,,,,,,,,,,,,,,
,3930470108.39376,3.99703454971313,49.9937515258789,,,6,,,,26.9516608379761,,,1,,,,,,,,,,,,,,,,,,,,,,3.92922401428223,4.05774450302124,49.9937515258789,49.9937515258789,,,3.90411376953125,,1,0,0,0,0.013885498046875,27.8592376708984,6,1,1,4.06484508514404,0,2084574240,3.99052350521088,,,0.000942693174983474,4.70178425872413E-5,0.000942694499853809,4.70178417928908E-5,0.995072662830353,0.995370328426361,26.9452838897705,,30,4,200,0.000492523249704391,-4.09180212020874,0.345874577760696,1,,,,,,,,,,,,,,,,
,3930470128.18964,4.2835373878479,49.9937515258789,,,6,,,,26.9516608379761,,,1,,,,,,,,,,,,,,,,,,,,,,4.21329164505005,4.35378313064575,49.9937515258789,49.9937515258789,,,4.00685024261475,,1,0,0,0,0.013885498046875,27.8592376708984,6,1,1,4.35378313064575,0,2084574464,4.27755837440491,,,0.000947750096027454,4.72700550630527E-5,0.000947751564558934,4.72700567604045E-5,0.995052576065063,0.995368599891663,26.9450817108154,48031168,30,4,200,0.000489691272377968,-4.10992002487183,0.351533204317093,1,,,,,,,,,,,,,,,,
,3930470147.78287,4.57580900192261,49.9937515258789,,,6,,,,26.9516608379761,,,1,,,,,,,,,,,,,,,,,,,,,,4.50755643844604,4.64379453659058,49.9937515258789,49.9937515258789,,,4.10689115524292,,1,0,0,0,0.013885498046875,27.8592376708984,6,1,1,4.64911460876465,0,2084574528,4.57363343238831,,,0.000953070461460969,4.75354230094138E-5,0.000953072125078264,4.75354317497632E-5,0.99503219127655,0.995357155799866,26.9449787139893,0,30,4,200,0.000500919530168176,-4.12897300720215,0.358025193214417,1,,,,,,,,,,,,,,,,
,3930470167.37615,4.87429714202881,49.9937515258789,,,6,,,,26.9516608379761,,,1,,,,,,,,,,,,,,,,,,,,,,4.80233001708984,4.94001388549805,49.9937515258789,49.9937515258789,,,4.20030546188354,,1,0,0,0,0.013885498046875,27.3704795837402,6,1,1,4.94626426696777,0,2084574368,4.86789588928223,,,0.000958657742022665,4.78140954234789E-5,0.000958659411392038,4.78140994639042E-5,0.995009124279022,0.995352923870087,26.9447765350342,5.29646587371826,30,4,200,0.000513495062477887,-4.14862203598022,0.3647800385952,1,,,,,,,,,,,,,,,,
,3930470187.09332,5.17103815078735,49.9937515258789,,,6,,,,26.9516608379761,,,1,,,,,,,,,,,,,,,,,,,,,,5.09889936447144,5.23563575744629,49.9937515258789,49.9937515258789,,,4.28823518753052,,1,0,0,0,0.013885498046875,28.3479976654053,6,1,1,5.24317693710327,0,2084574368,5.16510357856751,,,0.000964210861455456,4.80910619009631E-5,0.000964212653267696,4.80910661699245E-5,0.994999051094055,0.995366334915161,26.9445476531982,0,30,4,200,0.000541382993105799,-4.16754007339478,0.371646225452423,1,,,,,,,,,,,,,,,,
,3930470206.76861,5.46286988258362,49.9937515258789,,,6,,,,26.9516608379761,,,1,,,,,,,,,,,,,,,,,,,,,,5.39104270935059,5.53149652481079,49.9937515258789,49.9937515258789,,,4.36834716796875,,1,0,0,0,0.013885498046875,28.3479976654053,6,1,1,5.53469705581665,0,2084574400,5.45829510688782,,,0.000969757859107673,4.83677339180399E-5,0.000969759751754854,4.836773922155E-5,0.994979441165924,0.995360851287842,26.9444046020508,INF,30,4,200,0.000534430670086294,-4.18692779541016,0.378197520971298,1,,,,,,,,,,,,,,,,
,3930470226.59876,5.74884533882141,49.9937515258789,,,6,,,,26.9516608379761,,,1,,,,,,,,,,,,,,,,,,,,,,5.67794370651245,5.80878019332886,49.9937515258789,49.9937515258789,,,4.44130277633667,,1,0,0,0,0.013885498046875,28.3479976654053,6,1,1,5.81974697113037,0,2084574592,5.73891019821167,,,0.000975263820918286,4.86423544340162E-5,0.000975265783693382,4.86423590573799E-5,0.994977295398712,0.995374798774719,26.9442558288574,5.29685544967651,30,4,200,0.000471520907012746,-4.20584344863892,0.384505838155746,1,,,,,,,,,,,,,,,,
,3930470246.249,6.04894614219666,49.9937515258789,,,6,,,,26.9516608379761,,,1,,,,,,,,,,,,,,,,,,,,,,5.975998878479,6.11495018005371,49.9937515258789,49.9937515258789,,,4.51314830780029,,1,0,0,0,0.013885498046875,28.3479976654053,6,1,1,6.12189340591431,0,2084574464,6.04432888031006,,,0.00097985296966917,4.88712307018657E-5,0.00097985498596828,4.8871230830089E-5,0.994964420795441,0.99539053440094,26.9439964294434,,30,4,200,0.000555619655642658,-4.22163772583008,0.390430450439453,1,,,,,,,,,,,,,,,,
,3930470265.88563,6.35332274436951,49.9937515258789,,,6,,,,26.9516608379761,,,1,,,,,,,,,,,,,,,,,,,,,,6.27662324905395,6.42483139038086,49.9937515258789,49.9937515258789,,,4.58242559432983,,1,0,0,0,0.013885498046875,28.3479976654053,6,1,1,6.43002223968506,0,2084574720,6.34991273880005,,,0.000984421690974516,4.90991256896673E-5,0.000984423852065391,4.90991314866342E-5,0.994948923587799,0.995378434658051,26.9439544677734,0,30,4,200,0.00051165244076401,-4.23687791824341,0.396364629268646,1,,,,,,,,,,,,,,,,
,3930470285.57128,6.65839052200317,49.9937515258789,,,6,,,,26.9516608379761,,,1,,,,,,,,,,,,,,,,,,,,,,6.58113193511963,6.72842645645142,49.9937515258789,49.9937515258789,,,4.650954246521,,1,0,0,0,0.013885498046875,27.8592376708984,6,1,1,6.73564910888672,0,2084574400,6.65420842170715,,,0.000988605954933334,4.93078120510764E-5,0.000988608196355399,4.93078195737817E-5,0.994942009449005,0.995378971099854,26.9438858032227,3.38971149176359E-5,30,4,200,0.000499125104397535,-4.25082635879517,0.401789039373398,1,,,,,,,,,,,,,,,,
,3930470305.31882,6.97299957275391,49.9937515258789,,,6,,,,26.9516608379761,,,1,,,,,,,,,,,,,,,,,,,,,,6.8985481262207,7.04745101928711,49.9937515258789,49.9937515258789,,,4.7154598236084,,1,0,0,0,0.013885498046875,28.3479976654053,6,1,1,7.04745101928711,0,2084574592,6.96731672286987,,,0.000992038577358185,4.94790296961393E-5,0.000992040854600235,4.94790330414489E-5,0.994949638843536,0.995411932468414,26.9436798095703,5.19073009490967,30,4,200,0.000572874210774899,-4.25994920730591,0.408550292253494,1,,,,,,,,,,,,,,,,
,3930470324.98105,7.28032875061035,49.9937515258789,,,6,,,,26.9516608379761,,,1,,,,,,,,,,,,,,,,,,,,,,7.20387649536133,7.35187005996704,49.9937515258789,49.9937515258789,,,4.77739095687866,,1,0,0,0,0.013885498046875,27.8592376708984,6,1,1,7.35678100585938,0,2084574592,7.27659869194031,,,0.000994557380256921,4.96046452475344E-5,0.000994559787984644,4.96046533893397E-5,0.994946181774139,0.995414435863495,26.9436283111572,0,30,4,200,0.000473344349302351,-4.26631546020508,0.413990557193756,1,,,,,,,,,,,,,,,,
,3930470344.73986,7.59744334220886,49.9937515258789,,,6,,,,26.9516608379761,,,1,,,,,,,,,,,,,,,,,,,,,,7.52134609222412,7.66953659057617,49.9937515258789,49.9937515258789,,,4.83435440063477,,1,0,0,0,0.013885498046875,28.3479976654053,6,1,1,7.6735405921936,0,2084574400,7.59301052093506,,,0.000996104164749081,4.96817891636769E-5,0.000996106546223674,4.96817950930495E-5,0.994953215122223,0.995425403118134,26.9436016082764,INF,30,4,200,0.000487550103571266,-4.26950454711914,0.418651849031448,1,,,,,,,,,,,,,,,,
,3930470364.65095,7.91022562980652,49.9937515258789,,,6,,,,26.9516608379761,,,1,,,,,,,,,,,,,,,,,,,,,,7.83568000793457,7.98101329803467,49.9937515258789,49.9937515258789,,,4.89212894439697,,1,0,0,0,0.013885498046875,27.8592376708984,6,1,1,7.98477125167847,0,2084574432,7.90667839050293,,,0.000996549877780857,4.9704026121485E-5,0.000996552263649216,4.97040308483521E-5,0.994947195053101,0.995424747467041,26.9435539245605,0,30,4,200,0.000409645261242986,-4.26881122589111,0.421354860067368,1,,,,,,,,,,,,,,,,
,3930470384.34236,8.22368431091309,49.9937515258789,,,6,,,,26.9516608379761,,,1,,,,,,,,,,,,,,,,,,,,,,8.14970111846924,8.29766750335693,49.9937515258789,49.9937515258789,,,4.94588184356689,,1,0,0,0,0.013885498046875,29.3255138397217,6,1,1,8.29766750335693,0,2084574432,8.21928586959839,,,0.000995974453145799,4.96753199831958E-5,0.000995976867932589,4.96753277693178E-5,0.994948089122772,0.995418906211853,26.9436092376709,5.29698514938354,30,4,200,0.000406642531743273,-4.26479578018188,0.422944277524948,1,,,,,,,,,,,,,,,,
,3930470403.99408,8.53646039962769,49.9937515258789,,,6,,,,26.9516608379761,,,1,,,,,,,,,,,,,,,,,,,,,,8.45922374725342,8.60151958465576,49.9937515258789,49.9937515258789,,,4.99757289886475,,1,0,0,0,0.013885498046875,28.3479976654053,6,1,1,8.61369705200195,0,2084574560,8.53209762573242,,,0.000994374775714303,4.95955376229541E-5,0.000994377174632037,4.95955467033112E-5,0.994946420192718,0.995408713817596,26.9436779022217,9.07328825405784E-8,30,4,200,0.000377383956220001,-4.25714063644409,0.424128860235214,1,,,,,,,,,,,,,,,,
,3930470423.80739,8.85453128814697,49.9937515258789,,,6,,,,26.9516608379761,,,1,,,,,,,,,,,,,,,,,,,,,,8.77775096893311,8.92411231994629,49.9937515258789,49.9937515258789,,,5.04547309875488,,1,0,0,0,0.013885498046875,27.8592376708984,6,1,1,8.93131160736084,0,2084574368,8.84883413314819,,,0.000991860881020329,4.94701639324624E-5,0.000991863194929555,4.94701695802913E-5,0.994930386543274,0.995388746261597,26.943696975708,0,30,4,200,0.000329157919622958,-4.24558591842651,0.424245417118073,1,,,,,,,,,,,,,,,,
,3930470443.59793,9.16896295547485,49.9937515258789,,,6,,,,26.9516608379761,,,1,,,,,,,,,,,,,,,,,,,,,,9.09178447723389,9.24220466613769,49.9937515258789,49.9937515258789,,,5.09424686431885,,1,0,0,0,0.013885498046875,28.3479976654053,6,1,1,9.24614143371582,0,2084574496,9.16417407989502,,,0.000988567756265174,4.93059175605968E-5,0.000988570090814834,4.93059245866213E-5,0.99492084980011,0.995378315448761,26.9436950683594,0,30,4,200,0.000271841417998075,-4.23207187652588,0.423010945320129,1,,,,,,,,,,,,,,,,
,3930470463.8741,9.49406147003174,49.9937515258789,,,6,,,,26.9516608379761,,,1,,,,,,,,,,,,,,,,,,,,,,9.41892814636231,9.56919479370117,49.9937515258789,49.9937515258789,,,5.1403284072876,,1,0,0,0,0.013885498046875,27.8592376708984,6,1,1,9.56919479370117,0,2084574368,9.49291839599609,,,0.000984441483196944,4.91001145232605E-5,0.000984443870168856,4.91001241777795E-5,0.994915544986725,0.995374500751495,26.9436798095703,INF,30,4,200,0.000213582723517902,-4.21584129333496,0.420213490724564,1,,,,,,,,,,,,,,,,
,3930470483.62706,9.80863904953003,49.9937515258789,,,6,,,,26.9516608379761,,,1,,,,,,,,,,,,,,,,,,,,,,9.72893047332764,9.87915802001953,49.9937515258789,49.9937515258789,,,5.18332529067993,,1,0,0,0,0.013885498046875,28.3479976654053,6,1,1,9.88834762573242,0,2084574624,9.8031099319458,,,0.000979788433230504,4.88680412237102E-5,0.000979790607068858,4.88680452408623E-5,0.994914412498474,0.99535346031189,26.9438457489014,2.98637388596035E-7,30,4,200,0.000190531718544662,-4.19799470901489,0.416724592447281,1,,,,,,,,,,,,,,,,
,3930470503.42282,10.1276049613953,49.9937515258789,,,6,,,,26.9516608379761,,,1,,,,,,,,,,,,,,,,,,,,,,10.0509376525879,10.1830749511719,49.9937515258789,49.9937515258789,,,5.22484350204468,,1,0,0,0,0.013885498046875,27.8592376708984,6,1,1,10.2042722702026,0,2084574592,10.1156028111776,,,0.000974549207968412,4.86067166010401E-5,0.000974551413461403,4.86067244406736E-5,0.994924426078796,0.995356917381287,26.9439086914062,0,30,4,200,0.000156379741383716,-4.17774295806885,0.412257879972458,1,,,,,,,,,,,,,,,,
,3930470523.13676,10.4388737678528,49.9937515258789,,,6,,,,26.9516608379761,,,1,,,,,,,,,,,,,,,,,,,,,,10.3579177856445,10.5157060623169,49.9937515258789,49.9937515258789,,,5.26430511474609,,1,0,0,0,0.013885498046875,27.8592376708984,6,1,1,10.519829750061,0,2084574688,10.4392097473145,,,0.000968842413866515,4.83220928263602E-5,0.000968844547592794,4.8322102003016E-5,0.994927406311035,0.995341002941132,26.9440746307373,INF,30,4,200,0.000139989671879448,-4.15611886978149,0.407123953104019,1,,,,,,,,,,,,,,,,
,3930470542.86119,10.7615985870361,49.9937515258789,,,6,,,,26.9516608379761,,,1,,,,,,,,,,,,,,,,,,,,,,10.6824474334717,10.8202390670776,49.9937515258789,49.9937515258789,,,5.30264711380005,,1,0,0,0,0.013885498046875,28.3479976654053,6,1,1,10.8401117324829,0,2084574624,10.7496625052558,,,0.000962688851102614,4.80151746754214E-5,0.00096269089744822,4.80151824185843E-5,0.994920611381531,0.995323300361633,26.9441661834717,INF,30,4,200,0.000117790899821557,-4.1334400177002,0.401413530111313,1,,,,,,,,,,,,,,,,
,3930470562.87719,11.0846900939941,49.9937515258789,,,6,,,,26.9516608379761,,,1,,,,,,,,,,,,,,,,,,,,,,11.0025949478149,11.1557340621948,49.9937515258789,49.9937515258789,,,5.33957958221436,,1,0,0,0,0.013885498046875,28.3479976654053,6,1,1,11.1667852401733,0,2084574304,11.0783062934875,,,0.000955994370418131,4.76812798898491E-5,0.000955996272504287,4.7681285186949E-5,0.994912564754486,0.99529629945755,26.9443321228027,INF,30,4,200,0.000161602190928534,-4.10860395431519,0.394857436418533,1,,,,,,,,,,,,,,,,
,3930470582.81836,11.4083404541016,49.9937515258789,,,6,,,,26.9516608379761,,,1,,,,,,,,,,,,,,,,,,,,,,11.3298921585083,11.475305557251,49.9937515258789,49.9937515258789,,,5.37595653533936,,1,0,0,0,0.013885498046875,28.3479976654053,6,1,1,11.4867887496948,0,2084574368,11.4010617256165,,,0.000949035478244856,4.73341901816762E-5,0.000949037349640898,4.73341970538236E-5,0.994932353496552,0.995306611061096,26.9444332122803,INF,30,4,200,4.27755076088943E-5,-4.08253002166748,0.388732761144638,1,,,,,,,,,,,,,,,,
,3930470602.5507,11.7256536483765,49.9937515258789,,,6,,,,26.9516608379761,,,1,,,,,,,,,,,,,,,,,,,,,,11.6499090194702,11.7943210601807,49.9937515258789,49.9937515258789,,,5.40974473953247,,1,0,0,0,0.013885498046875,28.3479976654053,6,1,1,11.8013982772827,0,2084574432,11.721179485321,,,0.000941946831912667,4.69806348801204E-5,0.000941948533632098,4.69806382852077E-5,0.994935750961304,0.995290577411652,26.9446182250977,3.32179860857705E-24,30,4,200,6.1938349972479E-5,-4.05690431594849,0.380888283252716,1,,,,,,,,,,,,,,,,
,3930470622.28854,12.045590877533,49.9937515258789,,,6,,,,26.9516608379761,,,1,,,,,,,,,,,,,,,,,,,,,,11.9696216583252,12.1167602539062,49.9937515258789,49.9937515258789,,,5.44246912002563,,1,0,0,0,0.013885498046875,28.3479976654053,6,1,1,12.123854637146,0,2084574464,12.0433295249939,,,0.000934414845461033,4.66049642699348E-5,0.000934416468018097,4.66049682953748E-5,0.994940161705017,0.995277464389801,26.9447917938232,5.19083738327026,30,4,200,4.79290174553171E-5,-4.02862787246704,0.374116003513336,1,,,,,,,,,,,,,,,,
,3930470642.02318,12.3643751144409,49.9937515258789,,,6,,,,26.9516608379761,,,1,,,,,,,,,,,,,,,,,,,,,,12.2884683609009,12.43394947052,49.9937515258789,49.9937515258789,,,5.47345733642578,,1,0,0,0,0.013885498046875,28.3479976654053,6,1,1,12.440281867981,0,2084574432,12.3600406646729,,,0.000926715033211877,4.62209447484193E-5,0.000926716594642182,4.62209497009643E-5,0.994935870170593,0.995257616043091,26.9449443817139,0,30,4,200,-7.28587792764301E-6,-4.00081300735474,0.365693420171738,1,,,,,,,,,,,,,,,,
,3930470670.28472,12.8234553337097,49.9937515258789,,,6,,,,26.9566707663665,,,1,,,,,,,,,,,,,,,,,,,,,,12.7457418441772,12.9011688232422,49.9937515258789,49.9937515258789,,,5.5124773979187,,1,0,0,0,0.013885498046875,28.3479976654053,6,1,1,12.9011688232422,0,2084574592,12.8231852531433,,,0.00091555933802201,4.56646797877089E-5,0.000915563630854958,4.56646816032066E-5,0.994359791278839,0.99525511264801,26.945140838623,7.81081962486496E-6,30,4,200,-5.28825985384174E-5,-3.96137070655823,0.353110641241074,1,,,,,,,,,,,,,,,,
,3930470689.90975,13.1402397155762,49.9937515258789,,,6,,,,26.9566707663665,,,1,,,,,,,,,,,,,,,,,,,,,,13.0639200210571,13.2165594100952,49.9937515258789,49.9937515258789,,,5.54316091537476,,1,0,0,0,0.013885498046875,28.3479976654053,6,1,1,13.2165594100952,0,2084574432,13.1377336502075,,,0.000907403581349319,4.52578940589793E-5,0.000907407764257548,4.52579030163419E-5,0.994399070739746,0.995251595973969,26.9454402923584,0,30,4,200,-4.73315776616801E-5,-3.93261337280273,0.343302577733994,1,,,,,,,,,,,,,,,,
,3930470709.63698,13.4620389938354,49.9937515258789,,,6,,,,26.9566707663665,,,1,,,,,,,,,,,,,,,,,,,,,,13.3830127716064,13.5342569351196,49.9937515258789,49.9937515258789,,,5.57206678390503,,1,0,0,0,0.013885498046875,28.3479976654053,6,1,1,13.5410652160645,0,2084574432,13.4586079597473,,,0.000899183451275036,4.48478850036459E-5,0.000899187219676139,4.48478823416906E-5,0.994419097900391,0.995241165161133,26.9456462860107,INF,30,4,200,-5.39253087481484E-5,-3.90368890762329,0.333631992340088,1,,,,,,,,,,,,,,,,
,3930470729.45816,13.7845435142517,49.9937515258789,,,6,,,,26.9566707663665,,,1,,,,,,,,,,,,,,,,,,,,,,13.7068433761597,13.8585710525513,49.9937515258789,49.9937515258789,,,5.59883499145508,,1,0,0,0,0.013885498046875,27.8592376708984,6,1,1,13.8622436523437,0,2084574432,13.7836610794067,,,0.000890859083434176,4.44326941292696E-5,0.000890862701775514,4.44326949372E-5,0.994448482990265,0.995232105255127,26.9459190368652,INF,30,4,200,-5.72928656765725E-5,-3.87444567680359,0.323594808578491,1,,,,,,,,,,,,,,,,
,3930470749.00257,14.0997080802917,49.9937515258789,,,6,,,,26.9566707663665,,,1,,,,,,,,,,,,,,,,,,,,,,14.0268592834473,14.180136680603,49.9937515258789,49.9937515258789,,,5.62440633773804,,1,0,0,0,0.013885498046875,27.8592376708984,6,1,1,14.180136680603,0,2084574496,14.1013085365295,,,0.000882602388731904,4.40208882673823E-5,0.000882605894642715,4.40208907863382E-5,0.994481325149536,0.995243310928345,26.9460906982422,INF,30,4,200,-5.97132093389519E-5,-3.845858335495,0.31341814994812,1,,,,,,,,,,,,,,,,
,3930470768.7803,14.4210348129272,49.9937515258789,,,6,,,,26.9566707663665,,,1,,,,,,,,,,,,,,,,,,,,,,14.3414831161499,14.4933795928955,49.9937515258789,49.9937515258789,,,5.6506667137146,,1,0,0,0,0.013885498046875,28.3479976654053,6,1,1,14.5005865097046,0,2084574432,14.4170722961426,,,0.000874247525068788,4.36041519257016E-5,0.000874250843846757,4.36041535243129E-5,0.994490027427673,0.99522078037262,26.9463024139404,0,30,4,200,-0.000247208634391427,-3.81814026832581,0.302187651395798,1,,,,,,,,,,,,,,,,
,3930470788.30876,14.7375416755676,49.9937515258789,,,6,,,,26.9566707663665,,,1,,,,,,,,,,,,,,,,,,,,,,14.6568336486816,14.8123235702515,49.9937515258789,49.9937515258789,,,5.67468643188477,,1,0,0,0,0.013885498046875,28.3479976654053,6,1,1,14.8182497024536,0,2084573664,14.7383670806885,,,0.000865919345410322,4.31887730343217E-5,0.000865922312168717,4.31887743299639E-5,0.994563639163971,0.995229065418243,26.9468173980713,0,30,4,200,6.66202540742233E-5,-3.79563736915588,0.28531488776207,1,,,,,,,,,,,,,,,,
,3930470807.83718,15.0633449554443,49.9937515258789,,,6,,,,26.9566707663665,,,1,,,,,,,,,,,,,,,,,,,,,,14.9851474761963,15.1415424346924,49.9937515258789,49.9937515258789,,,5.69795417785645,,1,0,0,0,0.013885498046875,28.3479976654053,6,1,1,15.1415424346924,0,2084574528,15.0572113990784,,,0.00085748904796781,4.27682895646704E-5,0.000857491938750996,4.27682879047987E-5,0.994574010372162,0.995243787765503,26.9467964172363,INF,30,4,200,-3.6567867937265E-5,-3.75941109657288,0.281354010105133,1,,,,,,,,,,,,,,,,
,3930470827.45076,15.4389772415161,49.9937515258789,,,6,,,,26.9566707663665,,,1,,,,,,,,,,,,,,,,,,,,,,15.3555660247803,15.5162763595581,49.9937515258789,49.9937515258789,,,5.71341514587402,,1,0,0,0,0.013885498046875,28.3479976654053,2,1,1,15.522388458252,0,2084574336,15.4409395217895,,,0.00084738201579088,4.22642167953644E-5,0.000847384760350568,4.22642167180124E-5,0.994465351104736,0.995085656642914,26.9470443725586,0,30,4,200,-0.000174609958776273,-3.72248220443726,0.27179229259491,1,,,,,,,,,,,,,,,,
,3930470847.06963,15.7661929130554,49.9937515258789,,,6,,,,26.9566707663665,,,1,,,,,,,,,,,,,,,,,,,,,,15.6847801208496,15.8311948776245,49.9937515258789,49.9937515258789,,,5.72199630737305,,1,0,0,0,0.013885498046875,27.8592376708984,2,1,1,15.8476057052612,0,2084574624,15.7639476776123,,,0.00083915562838581,4.18538831622783E-5,0.000839158358372789,4.18538844775683E-5,0.994598686695099,0.995232343673706,26.9470729827881,3.46163545827949E-7,30,4,200,-0.000126530867419206,-3.69408345222473,0.260612010955811,1,,,,,,,,,,,,,,,,
,3930470866.77508,16.092625617981,49.9937515258789,,,6,,,,26.9566707663665,,,1,,,,,,,,,,,,,,,,,,,,,,16.0138149261475,16.1608142852783,49.9937515258789,49.9937515258789,,,5.73430013656616,,1,0,0,0,0.013885498046875,30.3030319213867,2,1,1,16.1714363098145,0,2084574592,16.088395690918,,,0.000830613250552072,4.14278316820212E-5,0.000830615948110206,4.14278343317509E-5,0.994605958461762,0.995232582092285,26.9471302032471,0,30,4,200,-0.000178143178345636,-3.66539978981018,0.249150559306145,1,,,,,,,,,,,,,,,,
,3930470886.43458,16.4096202850342,49.9937515258789,,,6,,,,26.9566707663665,,,1,,,,,,,,,,,,,,,,,,,,,,16.3328418731689,16.4829750061035,49.9937515258789,49.9937515258789,,,5.74702072143555,,1,0,0,0,0.013885498046875,28.8367557525635,2,1,1,16.4863986968994,0,2084574560,16.4071544647217,,,0.000822465608509841,4.10214490150922E-5,0.000822468121845984,4.10214471548011E-5,0.994616985321045,0.995227754116058,26.9472560882568,0,30,4,200,-0.000146433434565552,-3.63789963722229,0.23816291987896,1,,,,,,,,,,,,,,,,
,3930470906.00439,16.7317934036255,49.9937515258789,,,6,,,,26.9566707663665,,,1,,,,,,,,,,,,,,,,,,,,,,16.6526508331299,16.8079299926758,49.9937515258789,49.9937515258789,,,5.76039838790894,,1,0,0,0,0.013885498046875,27.8592376708984,2,1,1,16.8129196166992,0,2084574464,16.7308944702148,,,0.00081405281384836,4.06018572151516E-5,0.000814055310526853,4.06018567428401E-5,0.994612276554108,0.995217680931091,26.9472885131836,,30,4,200,-0.000157213275087997,-3.60991954803467,0.226420789957046,1,,,,,,,,,,,,,,,,
,3930470925.68006,17.054594039917,49.9937515258789,,,6,,,,26.9566707663665,,,1,,,,,,,,,,,,,,,,,,,,,,16.9733066558838,17.131649017334,49.9937515258789,49.9937515258789,,,5.77543592453003,,1,0,0,0,0.013885498046875,28.3479976654053,2,1,1,17.1358814239502,0,2084574336,17.0555702209473,,,0.000805877580767703,4.0194093285822E-5,0.00080587995658287,4.01940932933484E-5,0.994639813899994,0.995221316814423,26.9474906921387,0,30,4,200,-0.000150402018334717,-3.58212161064148,0.215704694390297,1,,,,,,,,,,,,,,,,
,3930470945.43939,17.3796081542969,49.9937515258789,,,6,,,,26.9566707663665,,,1,,,,,,,,,,,,,,,,,,,,,,17.3004989624023,17.451789855957,49.9937515258789,49.9937515258789,,,5.7881007194519,,1,0,0,0,0.013885498046875,29.3255138397217,2,1,1,17.4587173461914,0,2084574368,17.3756536483765,,,0.000797850797353977,3.97937422610266E-5,0.000797853054613175,3.97937398047057E-5,0.994667232036591,0.995240092277527,26.9475803375244,,30,4,200,-0.000145580881508067,-3.55504965782166,0.204597473144531,1,,,,,,,,,,,,,,,,
,3930470965.0934,17.7031650543213,49.9937515258789,,,6,,,,26.9566707663665,,,1,,,,,,,,,,,,,,,,,,,,,,17.6248188018799,17.7781810760498,49.9937515258789,49.9937515258789,,,5.80295610427856,,1,0,0,0,0.013885498046875,27.8592376708984,2,1,1,17.7815113067627,0,2084574432,17.7001823425293,,,0.000789877728930877,3.9396075234253E-5,0.000789879921572504,3.93960756121932E-5,0.994664013385773,0.995210409164429,26.9477767944336,INF,30,4,200,-0.000136548609589227,-3.52858066558838,0.193806320428848,1,,,,,,,,,,,,,,,,
,3930470984.71936,18.0240440368652,49.9937515258789,,,6,,,,26.9566707663665,,,1,,,,,,,,,,,,,,,,,,,,,,17.9457912445068,18.1022968292236,49.9937515258789,49.9937515258789,,,5.81697034835815,,1,0,0,0,0.013885498046875,28.3479976654053,2,1,1,18.1022968292236,0,2084574560,18.0238759994507,,,0.000781983561762455,3.90023517655559E-5,0.000781985606320433,3.90023502264555E-5,0.994692206382751,0.995218336582184,26.9479598999023,3.83376172976568E-5,30,4,200,-0.00015189396799542,-3.50196385383606,0.183016017079353,1,,,,,,,,,,,,,,,,
,3930471004.31727,18.345118522644,49.9937515258789,,,6,,,,26.9566707663665,,,1,,,,,,,,,,,,,,,,,,,,,,18.2653293609619,18.4180889129639,49.9937515258789,49.9937515258789,,,5.83193826675415,,1,0,0,0,0.013885498046875,28.3479976654053,2,1,1,18.4249076843262,0,2084574432,18.343692779541,,,0.000774240106021094,3.86161433909315E-5,0.000774242082018692,3.8616143222259E-5,0.994690537452698,0.995196104049683,26.9481220245361,INF,30,4,200,-0.000132156652398407,-3.47623491287231,0.172322750091553,1,,,,,,,,,,,,,,,,
,3930471023.88701,18.6681222915649,49.9937515258789,,,6,,,,26.9566707663665,,,1,,,,,,,,,,,,,,,,,,,,,,18.5885715484619,18.7407455444336,49.9937515258789,49.9937515258789,,,5.84553909301758,,1,0,0,0,0.013885498046875,28.3479976654053,2,1,1,18.747673034668,0,2084574368,18.6656681060791,,,0.000766573302282923,3.82337286129181E-5,0.000766575224765548,3.82337315576392E-5,0.994715869426727,0.995197832584381,26.9483337402344,INF,30,4,200,-0.000127588311443105,-3.45055341720581,0.161733791232109,1,,,,,,,,,,,,,,,,
,3930471043.55029,18.9936103820801,49.9937515258789,,,6,,,,26.9566707663665,,,1,,,,,,,,,,,,,,,,,,,,,,18.9189548492432,19.068265914917,49.9937515258789,49.9937515258789,,,5.85978841781616,,1,0,0,0,0.013885498046875,27.8592376708984,2,1,1,19.068265914917,0,2084574592,18.9922817230225,,,0.000759022592588977,3.78571261277347E-5,0.000759024388673837,3.78571275550016E-5,0.994744658470154,0.995208203792572,26.9485111236572,INF,30,4,200,-0.000106268664239906,-3.42503142356873,0.151639640331268,1,,,,,,,,,,,,,,,,
,3930471063.12242,19.3127565383911,49.9937515258789,,,6,,,,26.9566707663665,,,1,,,,,,,,,,,,,,,,,,,,,,19.2343864440918,19.384407043457,49.9937515258789,49.9937515258789,,,5.87283897399902,,1,0,0,0,0.013885498046875,27.8592376708984,2,1,1,19.3911266326904,0,2084574368,19.3119312286377,,,0.000751592799462013,3.74865515307563E-5,0.000751594434730653,3.74865510139363E-5,0.994755506515503,0.995191037654877,26.9487590789795,INF,30,4,200,-0.000120358468848281,-3.40034437179565,0.14132285118103,1,,,,,,,,,,,,,,,,
,3930471082.76429,19.6358213424683,49.9937515258789,,,6,,,,26.9566707663665,,,1,,,,,,,,,,,,,,,,,,,,,,19.557502746582,19.7060947418213,49.9937515258789,49.9937515258789,,,5.88633060455322,,1,0,0,0,0.013885498046875,28.3479976654053,2,1,1,19.7141399383545,0,2084574400,19.6340230941772,,,0.000744236238226821,3.71196399426537E-5,0.000744237777440104,3.71196400118957E-5,0.994777798652649,0.995189726352692,26.9489841461182,7.00712917023338E-6,30,4,200,-0.0001248262997251,-3.3758819103241,0.131097882986069,1,,,,,,,,,,,,,,,,
,3930471102.43283,19.9558324813843,49.9937515258789,,,6,,,,26.9566707663665,,,1,,,,,,,,,,,,,,,,,,,,,,19.8742370605469,20.0303764343262,49.9937515258789,49.9937515258789,,,5.89905452728271,,1,0,0,0,0.013885498046875,27.8592376708984,2,1,1,20.0374279022217,0,2084574624,19.9533945083618,,,0.000737040953310911,3.67607548477594E-5,0.000737042320581747,3.67607512662305E-5,0.994801044464111,0.995191216468811,26.9491996765137,0,30,4,200,-0.000101236255432013,-3.35201334953308,0.121071696281433,1,,,,,,,,,,,,,,,,
,3930471122.17689,20.2832183837891,49.9937515258789,,,6,,,,26.9566707663665,,,1,,,,,,,,,,,,,,,,,,,,,,20.2035140991211,20.3543338775635,49.9937515258789,49.9937515258789,,,5.91360664367676,,1,0,0,0,0.013885498046875,28.3479976654053,2,1,1,20.362922668457,0,2084574656,20.2770874023438,,,0.000729863057271725,3.64027486894288E-5,0.000729864361623441,3.6402747135337E-5,0.994816184043884,0.99518209695816,26.9494380950928,5.29694604873657,30,4,200,-0.000112023029942065,-3.32806301116943,0.111251011490822,1,,,,,,,,,,,,,,,,
,3930471141.86724,20.6046648025513,49.9937515258789,,,6,,,,26.9566707663665,,,1,,,,,,,,,,,,,,,,,,,,,,20.5241069793701,20.681022644043,49.9937515258789,49.9937515258789,,,5.92611503601074,,1,0,0,0,0.013885498046875,28.3479976654053,2,1,1,20.6852226257324,0,2084574560,20.6007875442505,,,0.000722832780357717,3.60521023191483E-5,0.000722833981475093,3.60521007696303E-5,0.994821906089783,0.99516224861145,26.9496898651123,0,30,4,200,-0.000212553990422748,-3.30459380149841,0.10142333060503,1,,,,,,,,,,,,,,,,
,3930471161.62405,20.931324005127,49.9937515258789,,,6,,,,26.9566707663665,,,1,,,,,,,,,,,,,,,,,,,,,,20.8509464263916,21.0043926239014,49.9937515258789,49.9937515258789,,,5.94032335281372,,1,0,0,0,0.013885498046875,28.8367557525635,2,1,1,21.0117015838623,0,2084574400,20.9257246017456,,,0.000715865483135137,3.5704608209447E-5,0.000715866662987836,3.57046100534973E-5,0.994856953620911,0.995177328586578,26.949914932251,0,30,4,200,-8.00382767920382E-5,-3.28165817260742,0.0912225171923637,1,,,,,,,,,,,,,,,,
,3930471181.32476,21.2551097869873,49.9937515258789,,,6,,,,26.9566707663665,,,1,,,,,,,,,,,,,,,,,,,,,,21.1797504425049,21.32373046875,49.9937515258789,49.9937515258789,,,5.95313405990601,,1,0,0,0,0.013885498046875,26.881721496582,2,1,1,21.3304691314697,0,2084574560,21.2515323638916,,,0.00070912906067638,3.53685967843508E-5,0.000709130014755895,3.53685946189901E-5,0.994893372058868,0.995176672935486,26.9503288269043,,30,4,200,-7.90013655205257E-5,-3.25919818878174,0.0820812955498695,1,,,,,,,,,,,,,,,,
,3930471201.01932,21.5731830596924,49.9937515258789,,,6,,,,26.9566707663665,,,1,,,,,,,,,,,,,,,,,,,,,,21.4932880401611,21.6311435699463,49.9937515258789,49.9937515258789,,,5.96518468856812,,1,0,0,0,0.013885498046875,28.3479976654053,2,1,1,21.6530780792236,0,2084574560,21.5648759206136,,,0.000702552375868385,3.5040592799949E-5,0.000702553299289099,3.50405930943473E-5,0.99490225315094,0.995165169239044,26.9505596160889,5.19139289855957,30,4,200,-0.000102429992693942,-3.23729968070984,0.0730390325188637,1,,,,,,,,,,,,,,,,
,3930471220.693,21.8968257904053,49.9937515258789,,,6,,,,26.9566707663665,,,1,,,,,,,,,,,,,,,,,,,,,,21.8181457519531,21.97047996521,49.9937515258789,49.9937515258789,,,5.97701692581177,,1,0,0,0,0.013885498046875,28.3479976654053,2,1,1,21.9755058288574,0,2084574624,21.8934883117676,,,0.000696037352011371,3.47156306480983E-5,0.00069603814997929,3.47156300153815E-5,0.994928896427155,0.995164036750793,26.9509010314941,0,30,4,200,-9.39375458983704E-5,-3.21538853645325,0.0641650557518005,1,,,,,,,,,,,,,,,,
,3930471240.33311,22.2213954925537,49.9937515258789,,,6,,,,26.9566707663665,,,1,,,,,,,,,,,,,,,,,,,,,,22.1430110931396,22.2900161743164,49.9937515258789,49.9937515258789,,,5.98835754394531,,1,0,0,0,0.013885498046875,27.8592376708984,2,1,1,22.2997798919678,0,2084574656,22.2181913375854,,,0.000689686533703072,3.43988682986024E-5,0.000689687278265324,3.43988702459597E-5,0.99494993686676,0.995156764984131,26.9512634277344,6.14591999692493E-6,30,4,200,-0.000115990325866733,-3.19413709640503,0.0557024776935577,1,,,,,,,,,,,,,,,,
,3930471260.14265,22.5425329208374,49.9937515258789,,,6,,,,26.9566707663665,,,1,,,,,,,,,,,,,,,,,,,,,,22.4615249633789,22.6168785095215,49.9937515258789,49.9937515258789,,,6.00184392929077,,1,0,0,0,0.013885498046875,27.8592376708984,2,1,1,22.6235408782959,0,2084574464,22.5387281417847,,,0.000683423363539068,3.40865062193072E-5,0.00068342397816837,3.40865063610384E-5,0.99496728181839,0.995148360729218,26.9516124725342,0,30,4,200,-8.9643377577886E-5,-3.1731538772583,0.0469242297112942,1,,,,,,,,,,,,,,,,
,3930471279.89267,22.8647832870483,49.9937515258789,,,6,,,,26.9566707663665,,,1,,,,,,,,,,,,,,,,,,,,,,22.7846088409424,22.9366264343262,49.9937515258789,49.9937515258789,,,6.01234292984009,,1,0,0,0,0.013885498046875,27.8592376708984,2,1,1,22.9449577331543,0,2084574464,22.8653354644775,,,0.000677255169296203,3.3778835064986E-5,0.000677255696822111,3.37788344252838E-5,0.994985222816467,0.995146930217743,26.9518947601318,0,30,4,200,-0.000100390614534263,-3.15243124961853,0.038714375346899,1,,,,,,,,,,,,,,,,
,3930471300.03143,23.1971950531006,49.9937515258789,,,6,,,,26.9566707663665,,,1,,,,,,,,,,,,,,,,,,,,,,23.1204833984375,23.265941619873,49.9937515258789,49.9937515258789,,,6.02384090423584,,1,0,0,0,0.013885498046875,27.8592376708984,2,1,1,23.2739067077637,0,2084574656,23.1932273864746,,,0.000671085054522169,3.34710961860177E-5,0.000671085529966057,3.34710963075282E-5,0.994992971420288,0.99513578414917,26.9521827697754,0,30,4,200,-6.85729755787179E-5,-3.13201928138733,0.0300016216933727,1,,,,,,,,,,,,,,,,
,3930471319.79535,23.5173892974854,49.9937515258789,,,6,,,,26.9566707663665,,,1,,,,,,,,,,,,,,,,,,,,,,23.4409484863281,23.586597442627,49.9937515258789,49.9937515258789,,,6.03464460372925,,1,0,0,0,0.013885498046875,28.8367557525635,2,1,1,23.5938301086426,0,2084574496,23.5119667053223,,,0.000665149650632578,3.31750552601185E-5,0.000665150043013894,3.31750535978323E-5,0.995029747486115,0.995160222053528,26.952392578125,0,30,4,200,-1.34494821395492E-5,-3.11167478561401,0.0220302399247885,1,,,,,,,,,,,,,,,,
,3930471339.90184,23.8386030197144,49.9937515258789,,,6,,,,26.9566707663665,,,1,,,,,,,,,,,,,,,,,,,,,,23.7515144348145,23.9219913482666,49.9937515258789,49.9937515258789,,,6.04513788223267,,1,0,0,0,0.013885498046875,27.8592376708984,2,1,1,23.9256916046143,0,2084574432,23.833576965332,,,0.000659517905694179,3.28941765512557E-5,0.000659518204944254,3.2894174869071E-5,0.994999289512634,0.99510133266449,26.9528713226318,0,30,4,200,0.000648714310955256,-3.08137345314026,0.0271884258836508,1,,,,,,,,,,,,,,,,
,3930471359.75474,24.1766033172607,49.9937515258789,,,6,,,,26.9566707663665,,,1,,,,,,,,,,,,,,,,,,,,,,24.0959491729736,24.2354164123535,49.9937515258789,49.9937515258789,,,6.05609703063965,,1,0,0,0,0.013885498046875,28.3479976654053,2,1,1,24.2572574615479,0,2084574656,24.1659414503309,,,0.00065343930062043,3.2590969646127E-5,0.000653439591003828,3.25909699218903E-5,0.995108366012573,0.995198309421539,26.9531402587891,0,30,4,200,0.000292002194328234,-3.04763460159302,0.0302121341228485,1,,,,,,,,,,,,,,,,
,3930471379.50207,24.5035238265991,49.9937515258789,,,6,,,,26.9566707663665,,,1,,,,,,,,,,,,,,,,,,,,,,24.4150485992432,24.5881156921387,49.9937515258789,49.9937515258789,,,6.06687593460083,,1,0,0,0,0.013885498046875,28.3479976654053,2,1,1,24.5919990539551,0,2084574720,24.5002626419067,,,0.000647830924301437,3.23112688180738E-5,0.00064783113498905,3.23112681801605E-5,0.995026469230652,0.995096325874329,26.9535312652588,0,30,4,200,-8.80795705597848E-5,-3.02683162689209,0.0257803481072187,1,,,,,,,,,,,,,,,,
,3930471399.20697,24.8310089111328,49.9937515258789,,,6,,,,26.9566707663665,,,1,,,,,,,,,,,,,,,,,,,,,,24.7564716339111,24.8969802856445,49.9937515258789,49.9937515258789,,,6.07718324661255,,1,0,0,0,0.013885498046875,28.3479976654053,2,1,1,24.9055461883545,0,2084574592,24.8253164291382,,,0.000642302863409578,3.20355351551727E-5,0.000642303022376389,3.20355347946736E-5,0.995081722736359,0.995134592056274,26.953950881958,2.41378493228694E-5,30,4,200,-5.95708797845873E-6,-3.00773048400879,0.0184006970375776,1,,,,,,,,,,,,,,,,
,3930471418.98576,25.1521921157837,49.9937515258789,,,6,,,,26.9566707663665,,,1,,,,,,,,,,,,,,,,,,,,,,25.0735206604004,25.2245712280273,49.9937515258789,49.9937515258789,,,6.08882522583008,,1,0,0,0,0.013885498046875,27.8592376708984,2,1,1,25.230863571167,0,2084574464,25.1482622146606,,,0.000636914669604453,3.17668006282236E-5,0.000636914779529652,3.17668006855922E-5,0.99506014585495,0.995094835758209,26.9544620513916,INF,30,4,200,-8.53190722409636E-5,-2.98983073234558,0.0109938066452742,1,,,,,,,,,,,,,,,,
,3930471438.72162,25.4727058410645,49.9937515258789,,,6,,,,26.9566707663665,,,1,,,,,,,,,,,,,,,,,,,,,,25.395435333252,25.549976348877,49.9937515258789,49.9937515258789,,,6.09906053543091,,1,0,0,0,0.013885498046875,28.3479976654053,2,1,1,25.549976348877,0,2084574688,25.471471786499,,,0.000631645857873703,3.15040127724828E-5,0.000631645910977054,3.15040119090016E-5,0.995104789733887,0.995127618312836,26.9548854827881,INF,30,4,200,-6.2886560044717E-5,-2.97232413291931,0.00341971730813384,1,,,,,,,,,,,,,,,,
,3930471458.84296,25.8040828704834,49.9937515258789,,,6,,,,26.9566707663665,,,1,,,,,,,,,,,,,,,,,,,,,,25.7213497161865,25.8803787231445,49.9937515258789,49.9937515258789,,,6.1100754737854,,1,0,0,0,0.013885498046875,27.8592376708984,2,1,1,25.8868160247803,0,2084574336,25.8009944915771,,,0.000626436583096094,3.12441850797469E-5,0.000626436614244295,3.12441844539248E-5,0.99516099691391,0.995175421237946,26.9552593231201,8.47777698709251E-7,30,4,200,-8.3314924268052E-5,-2.95513606071472,-0.00393360015004873,1,,,,,,,,,,,,,,,,
,3930471478.47448,26.1234540939331,49.9937515258789,,,6,,,,26.9566707663665,,,1,,,,,,,,,,,,,,,,,,,,,,26.0434265136719,26.2034816741943,49.9937515258789,49.9937515258789,,,6.1195592880249,,1,0,0,0,0.013885498046875,27.8592376708984,2,1,1,26.2034816741943,0,2084574528,26.1232920752631,,,0.000621428475195374,3.09944067923713E-5,0.000621428482827653,3.09944063207592E-5,0.995078086853027,0.995083689689636,26.9557838439941,3.32179860857705E-24,30,4,200,-7.2092647315003E-5,-2.93833518028259,-0.0107882609590888,1,,,,,,,,,,,,,,,,
,3930471498.09306,26.4478950500488,49.9937515258789,,,6,,,,26.9566707663665,,,1,,,,,,,,,,,,,,,,,,,,,,26.3687171936035,26.5200614929199,49.9937515258789,49.9937515258789,,,6.13032007217407,,1,0,0,0,0.013885498046875,28.8367557525635,2,1,1,26.5270729064941,0,2084574496,26.4469148635864,,,0.000616587624026953,3.07529682601543E-5,0.000616587625110016,3.07529681261309E-5,0.995059669017792,0.995060920715332,26.9562530517578,5.1919412612915,30,4,200,-5.17729058628902E-5,-2.92264175415039,-0.0181928928941488,1,,,,,,,,,,,,,,,,
,3930471517.80863,26.7735729217529,49.9937515258789,,,6,,,,26.9566707663665,,,1,,,,,,,,,,,,,,,,,,,,,,26.6983451843262,26.8332595825195,49.9937515258789,49.9937515258789,,,6.13939237594605,,1,0,0,0,0.013885498046875,28.3479976654053,2,1,1,26.8488006591797,0,2084574592,26.7674545288086,,,0.000611838155475082,3.05160736768359E-5,0.000611838155183676,3.05160736586493E-5,0.995097100734711,0.995097160339356,26.9566116333008,0,30,4,200,-6.22509396634996E-5,-2.90718126296997,-0.0248308274894953,1,,,,,,,,,,,,,,,,
,3930471537.43645,27.0934600830078,49.9937515258789,,,6,,,,26.9566707663665,,,1,,,,,,,,,,,,,,,,,,,,,,27.0108165740967,27.169116973877,49.9937515258789,49.9937515258789,,,6.1496262550354,,1,0,0,0,0.013885498046875,27.8592376708984,2,1,1,27.1761035919189,0,2084574528,27.0895853042603,,,0.000607176010646183,3.02835444598774E-5,0.00060717601775213,3.02835445974902E-5,0.995108604431152,0.995110034942627,26.9571228027344,1.93211099031032E-6,30,4,200,-7.06546779838391E-5,-2.89177513122559,-0.0315153636038303,1,,,,,,,,,,,,,,,,
,3930471556.99638,27.4160146713257,49.9937515258789,,,6,,,,26.9566707663665,,,1,,,,,,,,,,,,,,,,,,,,,,27.3400020599365,27.4846935272217,49.9937515258789,49.9937515258789,,,6.15924263000488,,1,0,0,0,0.013885498046875,27.3704795837402,2,1,1,27.4920272827148,0,2084574528,27.4102079391479,,,0.000602681698045971,3.00593957092024E-5,0.000602681720705116,3.00593957643101E-5,0.995076715946198,0.99508398771286,26.9576816558838,3.32179860857705E-24,30,4,200,-4.26900187449064E-5,-2.87732815742493,-0.0383507870137692,1,,,,,,,,,,,,,,,,
,3930471576.6692,27.7361726760864,49.9937515258789,,,6,,,,26.9566707663665,,,1,,,,,,,,,,,,,,,,,,,,,,27.6575889587402,27.8079013824463,49.9937515258789,49.9937515258789,,,6.1680908203125,,1,0,0,0,0.013885498046875,28.3479976654053,2,1,1,27.8147563934326,0,2084574400,27.7321413040161,,,0.000598261845480691,2.98389546228104E-5,0.000598261906209921,2.9838955404313E-5,0.995070219039917,0.995085477828979,26.958137512207,3.32179860857705E-24,30,4,200,-4.08326195611153E-5,-2.86302995681763,-0.0448388792574406,1,,,,,,,,,,,,,,,,
,3930471596.52998,28.0660352706909,49.9937515258789,,,6,,,,26.9566707663665,,,1,,,,,,,,,,,,,,,,,,,,,,27.9826545715332,28.1207675933838,49.9937515258789,49.9937515258789,,,6.17729377746582,,1,0,0,0,0.013885498046875,27.8592376708984,2,1,1,28.1494159698486,0,2084574496,28.0517353481717,,,0.000593946604317839,2.96237297855099E-5,0.000593946679176853,2.96237295460002E-5,0.99505490064621,0.995082080364227,26.9586296081543,INF,30,4,200,-4.18665222241543E-5,-2.84924364089966,-0.0514223761856556,1,,,,,,,,,,,,,,,,
,3930471616.19652,28.390323638916,49.9937515258789,,,6,,,,26.9566707663665,,,1,,,,,,,,,,,,,,,,,,,,,,28.3134498596191,28.4593849182129,49.9937515258789,49.9937515258789,,,6.18557357788086,,1,0,0,0,0.013885498046875,28.3479976654053,2,1,1,28.4671974182129,0,2084574496,28.3851314544678,,,0.000589774496197552,2.94156442907274E-5,0.000589774652222501,2.94156457084483E-5,0.995036065578461,0.995079874992371,26.9591579437256,2.31259235761172E-7,30,4,200,-1.04693890534691E-5,-2.83606219291687,-0.0578300058841705,1,,,,,,,,,,,,,,,,
,3930471635.86031,28.7093000411987,49.9937515258789,,,6,,,,26.9566707663665,,,1,,,,,,,,,,,,,,,,,,,,,,28.6255111694336,28.7853202819824,49.9937515258789,49.9937515258789,,,6.19509506225586,,1,0,0,0,0.013885498046875,28.8367557525635,2,1,1,28.7930889129639,0,2084574720,28.7071578979492,,,0.000585677106280076,2.92112744026448E-5,0.00058567733946066,2.92112764441162E-5,0.995018541812897,0.995084881782532,26.9597339630127,3.32179860857705E-24,30,4,200,-4.5494507503463E-5,-2.82248163223267,-0.0637087747454643,1,,,,,,,,,,,,,,,,
,3930471655.60584,29.0370635986328,49.9937515258789,,,6,,,,26.9566707663665,,,1,,,,,,,,,,,,,,,,,,,,,,28.9557399749756,29.1082725524902,49.9937515258789,49.9937515258789,,,6.20338153839111,,1,0,0,0,0.013885498046875,28.3479976654053,2,1,1,29.11838722229,0,2084574496,29.0307849884033,,,0.000581679316314379,2.9011890516658E-5,0.000581679599548616,2.90118919246816E-5,0.994983315467834,0.995071470737457,26.9602108001709,0,30,4,200,-2.35965635511093E-5,-2.80973649024963,-0.0697463452816009,1,,,,,,,,,,,,,,,,
,3930471683.99693,29.5049247741699,49.9937515258789,,,6,,,,26.96168992776,,,1,,,,,,,,,,,,,,,,,,,,,,29.4237041473389,29.5783996582031,49.9937515258789,49.9937515258789,,,6.21598958969116,,1,0,0,0,0.013885498046875,28.3479976654053,2,1,1,29.586145401001,0,2084574496,29.5018442153931,,,0.00057621757846887,2.87394685860632E-5,0.000576217594291109,2.87394686537319E-5,0.995049118995667,0.995054185390472,26.9608421325684,1.33141526248437E-7,30,4,200,-1.53310065797996E-5,-2.79214239120483,-0.0780278369784355,1,,,,,,,,,,,,,,,,
,3930471703.67651,29.8461818695068,49.9937515258789,,,6,,,,26.96168992776,,,1,,,,,,,,,,,,,,,,,,,,,,29.7770195007324,29.9123363494873,49.9937515258789,49.9937515258789,,,6.22304677963257,,1,0,0,0,0.013885498046875,27.3704795837402,6,1,1,29.9153442382812,0,2084574720,29.8495077133179,,,0.000572136775142195,2.85359442388595E-5,0.000572136776236676,2.85359442396081E-5,0.995057582855225,0.995057940483093,26.9614582061768,0,30,4,200,4.60215887869708E-5,-2.77852129936218,-0.0842152163386345,1,,,,,,,,,,,,,,,,
,3930471723.36461,29.9815349578857,49.9937515258789,,,6,,,,26.96168992776,,,1,,,,,,,,,,,,,,,,,,,,,,29.9719753265381,29.9903316497803,49.9937515258789,49.9937515258789,,,6.22652101516724,,1,0,0,0,0.013885498046875,27.8592376708984,5,1,1,29.9910945892334,0,2084574464,29.9825901031494,,,0.00057118062964649,2.84882435989945E-5,0.0005711806300626,2.84882436120025E-5,0.995118081569672,0.995118141174316,26.9616012573242,0,30,4,200,0.000193962419871241,-2.77421307563782,-0.0865149945020676,1,,,,,,,,,,,,,,,,
,3930471743.54225,29.9983673095703,49.9937515258789,,,6,,,,26.96168992776,,,1,,,,,,,,,,,,,,,,,,,,,,29.9972953796387,29.9993152618408,49.9937515258789,49.9937515258789,,,6.22972011566162,,1,0,0,0,0.013885498046875,27.8592376708984,5,1,1,29.999439239502,0,2084574592,29.9984086990356,,,0.000571233893055052,2.8490903664656E-5,0.00057123389307459,2.84909036546338E-5,0.995128333568573,0.995128393173218,26.9615840911865,0,30,4,200,0.000190359380212612,-2.77395915985107,-0.0858602300286293,1,,,,,,,,,,,,,,,,
,3930471763.17157,30.0005311965942,49.9937515258789,,,6,,,,26.96168992776,,,1,,,,,,,,,,,,,,,,,,,,,,29.999927520752,30.0006771087646,49.9937515258789,49.9937515258789,,,6.23205518722534,,1,0,0,0,0.013885498046875,27.8592376708984,5,1,1,30.0005912780762,0,2084574496,30.0003242492676,,,0.000571347862477185,2.84965790248418E-5,0.000571347862574753,2.84965790263519E-5,0.995126962661743,0.995126962661743,26.9617481231689,7.20117725450109E-7,30,4,200,0.000205943491891958,-2.77466869354248,-0.0860276073217392,1,,,,,,,,,,,,,,,,
,3930471772.98121,30.0004959106445,49.9937515258789,,,6,,,,26.96168992776,,,1,,,,,,,,,,,,,,,,,,,,,,29.9998722076416,30.000602722168,49.9937515258789,49.9937515258789,,,6.23329448699951,,1,0,0,0,0.013885498046875,27.8592376708984,1,1,1,30.0004005432129,0,2084574816,30.0002662658691,,,0.000571413874708184,2.84998718266431E-5,0.000571413874792222,2.84998718299685E-5,0.995135724544525,0.99513578414917,26.9616603851318,0,30,4,200,0.000202042021555826,-2.77463674545288,-0.0858289822936058,1,,,,,,,,,,,,,,,,