File: Data used in paper/Case study 4/ML_20240717_7_QHS_0-QHS1063G_SmBa0p9K0p1CuBO5_DC-8p1mg_MvT_50oe_20240731 (1).dat
[Header]
; MPMS3 Data File (default extension .dat)
; Copyright (c) 2007, Quantum Design, Inc. All rights reserved.
TITLE,
FILEOPENTIME,3931579834.68187,07/31/2024,9:30 am
BYAPP,MPMS3 w/ AC,1.0,1.1
INFO,MPMS3 Measurement Release 1.1.16 Build 419, MultiVu Release 2.3.4.15,APPNAME
INFO,Linear Motor Servo Controller,MOTOR_MODULE_NAME
INFO,3101-100 F0,MOTOR_HW_VERSION
INFO,MMC1118,MOTOR_SERIAL_NUMBER
INFO,01.04.28,MOTOR_SOFTWARE_VERSION
INFO,Quantum Design Squid Module,SQUID_MODULE_NAME
INFO,3101-501 B0,SQUID_HW_VERSION
INFO,SQM313,SQUID_SERIAL_NUMBER
INFO,01.03.04,SQUID_SOFTWARE_VERSION
INFO,Quantum Design VSM Oven,OVEN_MODULE_NAME
INFO,3101-201 A3,OVEN_HW_VERSION
INFO,OVB345,OVEN_SERIAL_NUMBER
INFO,01.07.07,OVEN_SOFTWARE_VERSION
INFO,SQUID AC,AC_MODULE_NAME
INFO,3101-401 G0,AC_HW_VERSION
INFO,SAC210,AC_SERIAL_NUMBER
INFO,SQUID AC 00.95.07,AC_SOFTWARE_VERSION
INFO,TCI318,COIL_SERIAL_NUMBER
INFO,0,MOMENT_UNITS
INFO,ML_20240717_7_QHS_0-QHS1063G_SmBa0p9K0p1CuBO5_DC-8p1mg_MvT_50oe_20240731,SAMPLE_MATERIAL
INFO,,SAMPLE_COMMENT
INFO,8.1,SAMPLE_MASS
INFO,,SAMPLE_VOLUME
INFO,,SAMPLE_MOLECULAR_WEIGHT
INFO,,SAMPLE_SIZE
INFO,,SAMPLE_SHAPE
INFO,Straw,SAMPLE_HOLDER
INFO,Standard,SAMPLE_HOLDER_DETAIL
INFO,66.21,SAMPLE_OFFSET
DATATYPE,COMMENT,1
DATATYPE,TIME,2
STARTUPAXIS,X,2
STARTUPAXIS,Y1,5
FIELDGROUP, VSM,2,3,4,5,6,8,9,10,11,14,15
FIELDGROUP, DC, 2,3,4,14,56,57,58,59,60,61,62,63,64,65,66,67,68,69
FIELDGROUP, AC, 2,3,4,11,16,17,18,19,20,21,22,23,24,25,26,27,28,29,30
STARTUPGROUP, All
[Data]
Comment,Time Stamp (sec),Temperature (K),Magnetic Field (Oe),Moment (emu),M. Std. Err. (emu),Transport Action,Averaging Time (sec),Frequency (Hz),Peak Amplitude (mm),Center Position (mm),Lockin Signal' (V),Lockin Signal (V),Range,M. Quad. Signal (emu),AC Moment (emu),AC M. Std Err. (emu),AC Phase (deg),AC Phase Std. Err. (deg),AC Susceptibility (emu/Oe),AC Suscept. Std Err. (emu/Oe),AC X' (emu/Oe),AC X' Std Err. (emu/Oe),AC X'' (emu/Oe),AC X'' Std Err. (emu/Oe),AC Drive (Oe),AC Frequency (Hz),AC Averaging Time (sec),AC Cycles,AC Range,AC Measure Type,AC Signal' (V),AC Signal'' (V),AC Trim Coil Ratio,AC Trim Coil Phase,Min. Temperature (K),Max. Temperature (K),Min. Field (Oe),Max. Field (Oe),Mass (grams),Motor Lag (deg),Pressure (Torr),Measure Count,Measurement Number,SQUID Status (code),Motor Status (code),Measure Status (code),Motor Current (amps),Motor Temp. (C),Temp. Status (code),Field Status (code),Chamber Status (code),Chamber Temp (K),Redirection State,Evercool Status,Average Temp (K),Rotation Angle (deg),Rotator state,DC Moment Fixed Ctr (emu),DC Moment Err Fixed Ctr (emu),DC Moment Free Ctr (emu),DC Moment Err Free Ctr (emu),DC Fixed Fit,DC Free Fit,DC Calculated Center (mm),DC Calculated Center Err (mm),DC Scan Length (mm),DC Scan Time (s),DC Number of Points,DC Squid Drift,DC Min V (V),DC Max V (V),DC Scans per Measure,Map 01,Map 02,Map 03,Map 04,Map 05,Map 06,Map 07,Map 08,Map 09,Map 10,Map 11,Map 12,Map 13,Map 14,Map 15,Map 16
,3931581365.1482,1.7993141412735,49.9325294494629,,,3,,,,23.948938369751,,,,,,,,,,,,,,,,,,,,,,,,,1.7993141412735,1.7993141412735,49.9325294494629,49.9325294494629,,,2.70980930328369,,0,,,,,,5,1,1,1.7993141412735,0,0,0,,,,,,,,,,,,,,,,,,,,,,,,,,,,,,,,,
,3931581410.51076,1.91800493001938,49.9325294494629,,,6,,,,23.948938369751,,,1,,,,,,,,,,,,,,,,,,,,,,1.85137343406677,1.97785305976868,49.9325294494629,49.9325294494629,,,2.79901766777039,,1,0,0,0,0.0145721435546875,28.3479976654053,6,1,1,1.98463642597198,0,2084574656,1.91207679510117,,,2.77985332312587E-5,1.37649899851819E-6,2.77985327685432E-5,1.37649897293161E-6,0.980332732200623,0.980332851409912,23.9487018585205,0.187446758151054,30,4,200,-0.00019495768356137,0.139156863093376,0.271860986948013,1,,,,,,,,,,,,,,,,
,3931581438.81674,2.31356155872345,49.9325294494629,,,6,,,,23.9540057786846,,,1,,,,,,,,,,,,,,,,,,,,,,2.24537301063538,2.37712001800537,49.9325294494629,49.9325294494629,,,3.05838894844055,,1,0,0,0,0.0145721435546875,28.3479976654053,6,1,1,2.38175010681152,0,2084574528,2.30799188613892,,,2.44015237850229E-5,1.20826338903329E-6,2.44015509094864E-5,1.20826303227502E-6,0.981448829174042,0.98152482509613,23.9476318359375,0,30,4,200,-0.000142159362439997,0.14899505674839,0.26517978310585,1,,,,,,,,,,,,,,,,
,3931581458.91287,2.59388852119446,49.9325294494629,,,6,,,,23.9540057786846,,,1,,,,,,,,,,,,,,,,,,,,,,2.52573657035828,2.65553164482117,49.9325294494629,49.9325294494629,,,3.22814106941223,,1,0,0,0,0.0145721435546875,28.3479976654053,6,1,1,2.66204047203064,0,2084574560,2.59009068012238,,,2.23020229595401E-5,1.10431335792753E-6,2.230206343822E-5,1.10431312899017E-6,0.981031239032745,0.981138110160828,23.9463634490967,0,30,4,200,-0.000138441231683828,0.155219778418541,0.261439770460129,1,,,,,,,,,,,,,,,,
,3931581478.59435,2.87590169906616,49.9325294494629,,,6,,,,23.9540057786846,,,1,,,,,,,,,,,,,,,,,,,,,,2.80384469032288,2.9377977848053,49.9325294494629,49.9325294494629,,,3.38136315345764,,1,0,0,0,0.0145721435546875,26.881721496582,6,1,1,2.94795870780945,0,2084574560,2.8699816942215,,,2.0425557252733E-5,1.01139638537753E-6,2.04256247511517E-5,1.01139618792223E-6,0.981102287769318,0.981288313865662,23.9439544677734,0,30,4,200,-0.000104452432424296,0.160749077796936,0.258018553256989,1,,,,,,,,,,,,,,,,
,3931581499.10324,3.17817616462708,49.9325294494629,,,6,,,,23.9540057786846,,,1,,,,,,,,,,,,,,,,,,,,,,3.10462093353271,3.24477124214172,49.9325294494629,49.9325294494629,,,3.53207111358643,,1,0,0,0,0.0145721435546875,28.3479976654053,6,1,1,3.25173139572144,0,2084574656,3.17221419811249,,,1.86767945037472E-5,9.2479713638992E-7,1.86768748789224E-5,9.24796700789156E-7,0.981519937515259,0.981780052185059,23.9422645568848,5.60788919301558E-7,30,4,200,-8.6076746811159E-5,0.166043445467949,0.254911333322525,1,,,,,,,,,,,,,,,,
,3931581519.32906,3.46961975097656,49.9325294494629,,,6,,,,23.9540057786846,,,1,,,,,,,,,,,,,,,,,,,,,,3.40348410606384,3.52374625205994,49.9325294494629,49.9325294494629,,,3.66373348236084,,1,0,0,0,0.0145721435546875,28.3479976654053,6,1,1,3.53575539588928,0,2084574560,3.46721427440643,,,1.71790301239521E-5,8.50628682750485E-7,1.71791915435743E-5,8.50628417954241E-7,0.981850564479828,0.982393383979797,23.9372615814209,7.50804247218184E-7,30,4,200,-1.24053185572848E-5,0.170724391937256,0.252284854650497,1,,,,,,,,,,,,,,,,
,3931581539.10067,3.74724769592285,49.9325294494629,,,6,,,,23.9540057786846,,,1,,,,,,,,,,,,,,,,,,,,,,3.67663598060608,3.81232237815857,49.9325294494629,49.9325294494629,,,3.78078031539917,,1,0,0,0,0.0145721435546875,28.3479976654053,6,1,1,3.81785941123962,0,2084573184,3.74257333278656,,,1.59714450139847E-5,7.90813449905071E-7,1.59716015576421E-5,7.90813355770511E-7,0.983397603034973,0.984006106853485,23.9370861053467,0,30,4,200,4.96123211632948E-5,0.173202335834503,0.249001830816269,1,,,,,,,,,,,,,,,,
,3931581558.78529,4.03037488460541,49.9325294494629,,,6,,,,23.9540057786846,,,1,,,,,,,,,,,,,,,,,,,,,,3.96053194999695,4.07808971405029,49.9325294494629,49.9325294494629,,,3.88812494277954,,1,0,0,0,0.0145721435546875,28.3479976654053,6,1,1,4.10021781921387,0,2084573184,4.01574079195658,,,1.48719672335735E-5,7.36396548891221E-7,1.48722106685406E-5,7.36396529758815E-7,0.981613397598267,0.982527494430542,23.9322509765625,0,30,4,200,6.97732457410893E-6,0.17780114710331,0.248482435941696,1,,,,,,,,,,,,,,,,
,3931581578.67252,4.31874918937683,49.9325294494629,,,6,,,,23.9540057786846,,,1,,,,,,,,,,,,,,,,,,,,,,4.24845504760742,4.38651084899902,49.9325294494629,49.9325294494629,,,3.99084663391113,,1,0,0,0,0.0145721435546875,27.8592376708984,6,1,1,4.38904333114624,0,2084574656,4.31304230690002,,,1.38721833331885E-5,6.86889871160817E-7,1.38724138887819E-5,6.86889828454481E-7,0.981742203235626,0.982679665088654,23.9320583343506,0,30,4,200,-3.19685677823145E-5,0.181466042995453,0.247356578707695,1,,,,,,,,,,,,,,,,
,3931581598.5411,4.61436653137207,49.9325294494629,,,6,,,,23.9540057786846,,,1,,,,,,,,,,,,,,,,,,,,,,4.53994369506836,4.68296957015991,49.9325294494629,49.9325294494629,,,4.09132242202759,,1,0,0,0,0.0145721435546875,28.3479976654053,6,1,1,4.68878936767578,0,2084574912,4.61125531196594,,,1.29504221862037E-5,6.41248447900094E-7,1.29507592128549E-5,6.41248227728027E-7,0.981740474700928,0.983246147632599,23.9264183044434,0,30,4,200,-4.5651486288989E-5,0.184422746300697,0.245933338999748,1,,,,,,,,,,,,,,,,
,3931581618.19459,4.91277408599854,49.9325294494629,,,6,,,,23.9540057786846,,,1,,,,,,,,,,,,,,,,,,,,,,4.8404688835144,4.97588491439819,49.9325294494629,49.9325294494629,,,4.18428182601929,,1,0,0,0,0.0145721435546875,27.8592376708984,6,1,1,4.98507928848267,0,2084574720,4.90597267150879,,,1.21305621265323E-5,6.00654063845664E-7,1.21309305978173E-5,6.00653856802845E-7,0.981582343578339,0.983332931995392,23.9242305755615,0,30,4,200,-1.06782290458796E-5,0.18727596104145,0.244735792279243,1,,,,,,,,,,,,,,,,
,3931581637.91178,5.21122097969055,49.9325294494629,,,6,,,,23.9540057786846,,,1,,,,,,,,,,,,,,,,,,,,,,5.13796091079712,5.27484178543091,49.9325294494629,49.9325294494629,,,4.2712926864624,,1,0,0,0,0.0145721435546875,26.881721496582,6,1,1,5.28448104858398,0,2084574720,5.20338373184204,,,1.13821308453162E-5,5.63600957676463E-7,1.13825474443552E-5,5.63600565252448E-7,0.981018662452698,0.983096718788147,23.9211864471436,,30,4,200,-1.17794634206803E-5,0.190059542655945,0.243975833058357,1,,,,,,,,,,,,,,,,
,3931581657.77269,5.51235485076904,49.9325294494629,,,6,,,,23.9540057786846,,,1,,,,,,,,,,,,,,,,,,,,,,5.44157600402832,5.57513189315796,49.9325294494629,49.9325294494629,,,4.35256576538086,,1,0,0,0,0.0145721435546875,28.3479976654053,6,1,1,5.58313369750977,0,2084574432,5.5048234462738,,,1.06979889016583E-5,5.29722230817204E-7,1.06984937033608E-5,5.29722605925059E-7,0.981273949146271,0.983945786952972,23.9173812866211,0,30,4,200,-5.32804915565066E-6,0.192606508731842,0.243386819958687,1,,,,,,,,,,,,,,,,
,3931581677.43999,5.79698729515076,49.9325294494629,,,6,,,,23.9540057786846,,,1,,,,,,,,,,,,,,,,,,,,,,5.73201990127563,5.85886859893799,49.9325294494629,49.9325294494629,,,4.42480802536011,,1,0,0,0,0.0145721435546875,28.8367557525635,6,1,1,5.86195468902588,0,2084574656,5.79487829208374,,,1.01171364078191E-5,5.00959588537362E-7,1.0117676929834E-5,5.00960035678617E-7,0.981385946273804,0.98446136713028,23.9150657653809,0,30,4,200,-3.10509994960739E-6,0.194885492324829,0.242750331759453,1,,,,,,,,,,,,,,,,
,3931581697.25112,6.09026861190796,49.9325294494629,,,6,,,,23.9540057786846,,,1,,,,,,,,,,,,,,,,,,,,,,6.01342010498047,6.16128969192505,49.9325294494629,49.9325294494629,,,4.49534225463867,,1,0,0,0,0.0145721435546875,27.8592376708984,6,1,1,6.16711711883545,0,2084574496,6.08663682937622,,,9.5646453121641E-6,4.73616970638459E-7,9.5653124057688E-6,4.73617787685742E-7,0.979823887348175,0.983535349369049,23.9096927642822,1.21306202345295E-5,30,4,200,-7.29041494196281E-6,0.196862399578094,0.24220335483551,1,,,,,,,,,,,,,,,,
,3931581717.07483,6.40185737609863,49.9325294494629,,,6,,,,23.9540057786846,,,1,,,,,,,,,,,,,,,,,,,,,,6.32351875305176,6.46388149261475,49.9325294494629,49.9325294494629,,,4.5653772354126,,1,0,0,0,0.0145721435546875,28.3479976654053,6,1,1,6.48019599914551,0,2084574624,6.39399542808533,,,9.0335247951944E-6,4.47318599194162E-7,9.0343030510853E-6,4.47319529015707E-7,0.979675590991974,0.984347581863403,23.9047508239746,0,30,4,200,9.41595953918295E-6,0.1989955753088,0.241783037781715,1,,,,,,,,,,,,,,,,
,3931581736.76771,6.7127742767334,49.9325294494629,,,6,,,,23.9540057786846,,,1,,,,,,,,,,,,,,,,,,,,,,6.63736009597778,6.77854585647583,49.9325294494629,49.9325294494629,,,4.63181447982788,,1,0,0,0,0.0145721435546875,27.8592376708984,6,1,1,6.78818845748901,0,2084574528,6.70622544288635,,,8.54326194413349E-6,4.23050337631802E-7,8.54414288802187E-6,4.23050734144489E-7,0.978739559650421,0.984260499477386,23.8997039794922,0,30,4,200,5.17779917572625E-5,0.20122417807579,0.24187009036541,1,,,,,,,,,,,,,,,,
,3931581756.45633,7.01935601234436,49.9325294494629,,,6,,,,23.9540057786846,,,1,,,,,,,,,,,,,,,,,,,,,,6.94141483306885,7.0896897315979,49.9325294494629,49.9325294494629,,,4.69443702697754,,1,0,0,0,0.0145721435546875,28.3479976654053,6,1,1,7.09729719161987,0,2084574560,7.01491475105286,,,8.0963443954805E-6,4.00925211986598E-7,8.09723052381745E-6,4.00926004376642E-7,0.978058755397797,0.983673095703125,23.8983173370361,0.0458485521376133,30,4,200,0.000154001885675825,0.204633891582489,0.243802532553673,1,,,,,,,,,,,,,,,,
,3931581776.27493,7.33468985557556,49.9325294494629,,,6,,,,23.9540057786846,,,1,,,,,,,,,,,,,,,,,,,,,,7.25914335250855,7.40122079849243,49.9325294494629,49.9325294494629,,,4.75766897201538,,1,0,0,0,0.0145721435546875,27.8592376708984,6,1,1,7.41023635864258,0,2084574592,7.32819361686707,,,7.66795719997318E-6,3.79719265011587E-7,7.66905126990746E-6,3.79720575622228E-7,0.977182626724243,0.984434008598328,23.8906173706055,,30,4,200,8.81219093571417E-5,0.20868507027626,0.245466992259026,1,,,,,,,,,,,,,,,,
,3931581795.98647,7.64383888244629,49.9325294494629,,,6,,,,23.9540057786846,,,1,,,,,,,,,,,,,,,,,,,,,,7.56809711456299,7.71958065032959,49.9325294494629,49.9325294494629,,,4.81500005722046,,1,0,0,0,0.0145721435546875,27.8592376708984,6,1,1,7.71958065032959,0,2084574560,7.64225091934204,,,7.276726621512E-6,3.60352333021058E-7,7.2779885551816E-6,3.60354237143674E-7,0.976365625858307,0.985084533691406,23.8843631744385,1.24208063425613E-5,30,4,200,0.000114503316581249,0.212628573179245,0.247591942548752,1,,,,,,,,,,,,,,,,
,3931581815.60272,7.95466089248657,49.9325294494629,,,6,,,,23.9540057786846,,,1,,,,,,,,,,,,,,,,,,,,,,7.88169145584106,8.02729034423828,49.9325294494629,49.9325294494629,,,4.86996698379517,,1,0,0,0,0.0145721435546875,27.8592376708984,6,1,1,8.03366279602051,0,2084574624,7.95354928970337,,,6.91590151783303E-6,3.42489446589572E-7,6.91723099697313E-6,3.4249141801283E-7,0.975677132606506,0.98520702123642,23.8806667327881,0,30,4,200,9.94104048004374E-5,0.216140955686569,0.249256432056427,1,,,,,,,,,,,,,,,,
,3931581835.27123,8.26960563659668,49.9325294494629,,,6,,,,23.9540057786846,,,1,,,,,,,,,,,,,,,,,,,,,,8.19222354888916,8.34329986572266,49.9325294494629,49.9325294494629,,,4.92266607284546,,1,0,0,0,0.0145721435546875,28.3479976654053,6,1,1,8.3469877243042,0,2084574464,8.26568279266357,,,6.57767271201617E-6,3.25751777715755E-7,6.57917347768955E-6,3.25753312488632E-7,0.974196493625641,0.985195457935333,23.8737316131592,0,30,4,200,0.00011776384053519,0.219421625137329,0.251338243484497,1,,,,,,,,,,,,,,,,
,3931581855.43879,8.59264326095581,49.9325294494629,,,6,,,,23.9540057786846,,,1,,,,,,,,,,,,,,,,,,,,,,8.51366901397705,8.65859699249268,49.9325294494629,49.9325294494629,,,4.97566604614258,,1,0,0,0,0.0145721435546875,27.8592376708984,6,1,1,8.67161750793457,0,2084574560,8.5847882270813,,,6.24034345275634E-6,3.09055608043475E-7,6.24202428885389E-6,3.09058455031429E-7,0.973011314868927,0.985562860965729,23.8673763275146,0,30,4,200,0.000130244370666333,0.22347617149353,0.253656566143036,1,,,,,,,,,,,,,,,,
,3931581875.21155,8.90497827529907,49.9325294494629,,,6,,,,23.9540057786846,,,1,,,,,,,,,,,,,,,,,,,,,,8.83053112030029,8.97591972351074,49.9325294494629,49.9325294494629,,,5.02409744262695,,1,0,0,0,0.0145721435546875,27.8592376708984,6,1,1,8.97942543029785,0,2084574464,8.90393533706665,,,5.93855504120035E-6,2.94116882225854E-7,5.9403286355676E-6,2.9411979963384E-7,0.972082436084747,0.985777258872986,23.8627681732178,0,30,4,200,9.12099567358382E-5,0.227000057697296,0.255535989999771,1,,,,,,,,,,,,,,,,
,3931581894.94806,9.22134304046631,49.9325294494629,,,6,,,,23.9540057786846,,,1,,,,,,,,,,,,,,,,,,,,,,9.14322090148926,9.29511547088623,49.9325294494629,49.9325294494629,,,5.07051563262939,,1,0,0,0,0.0145721435546875,27.8592376708984,6,1,1,9.29946517944336,0,2084574560,9.21958990097046,,,5.64720341932986E-6,2.79697142680206E-7,5.6491027109928E-6,2.79700114001534E-7,0.970836818218231,0.985873937606812,23.8570919036865,5.58019473828608E-6,30,4,200,7.96156673459336E-5,0.229965507984161,0.256970345973969,1,,,,,,,,,,,,,,,,
,3931581914.97535,9.54156112670898,49.9325294494629,,,6,,,,23.9540057786846,,,1,,,,,,,,,,,,,,,,,,,,,,9.45848083496094,9.61503601074219,49.9325294494629,49.9325294494629,,,5.1166524887085,,1,0,0,0,0.0145721435546875,28.3479976654053,6,1,1,9.62464141845703,0,2084574560,9.53863344192505,,,5.36421073523101E-6,2.65696727299443E-7,5.36624259857673E-6,2.65700286989676E-7,0.968876361846924,0.984556615352631,23.851375579834,0,30,4,200,6.15081080468371E-5,0.23257577419281,0.258290231227875,1,,,,,,,,,,,,,,,,
,3931581935.03711,9.86517381668091,49.9325294494629,,,6,,,,23.9540057786846,,,1,,,,,,,,,,,,,,,,,,,,,,9.78646945953369,9.93746852874756,49.9325294494629,49.9325294494629,,,5.15844058990479,,1,0,0,0,0.0145721435546875,28.3479976654053,6,1,1,9.94387817382813,0,2084574496,9.85958938598633,,,5.09827377119617E-6,2.52543522887331E-7,5.10065122734228E-6,2.52547899492926E-7,0.966552972793579,0.985116124153137,23.8402462005615,,30,4,200,5.36447550985031E-5,0.235139712691307,0.259455353021622,1,,,,,,,,,,,,,,,,
,3931581954.73886,10.1815395355225,49.9325294494629,,,6,,,,23.9540057786846,,,1,,,,,,,,,,,,,,,,,,,,,,10.1048402786255,10.2488288879395,49.9325294494629,49.9325294494629,,,5.19976139068604,,1,0,0,0,0.0145721435546875,28.3479976654053,6,1,1,10.2582387924194,0,2084574528,10.1760348320007,,,4.84420909552972E-6,2.39966771563037E-7,4.84663665491919E-6,2.39971193768132E-7,0.96551650762558,0.985011696815491,23.8360691070557,8.45371914692805E-7,30,4,200,6.37668345007114E-5,0.237500578165054,0.260808676481247,1,,,,,,,,,,,,,,,,
,3931581974.64615,10.5051169395447,49.9325294494629,,,6,,,,23.9540057786846,,,1,,,,,,,,,,,,,,,,,,,,,,10.4267950057983,10.5724830627441,49.9325294494629,49.9325294494629,,,5.23817777633667,,1,0,0,0,0.0145721435546875,28.3479976654053,6,1,1,10.583438873291,0,2084574528,10.4976294517517,,,4.61432976784163E-6,2.28589200389123E-7,4.6169264294331E-6,2.28593883246265E-7,0.964282751083374,0.98613178730011,23.8290386199951,1,30,4,200,6.03495172981638E-5,0.239829748868942,0.261984586715698,1,,,,,,,,,,,,,,,,
,3931581995.08095,10.8292946815491,49.9325294494629,,,6,,,,23.9540057786846,,,1,,,,,,,,,,,,,,,,,,,,,,10.7488050460815,10.9049301147461,49.9325294494629,49.9325294494629,,,5.27713537216186,,1,0,0,0,0.0145721435546875,27.8592376708984,6,1,1,10.9097843170166,0,2084574496,10.8268566131592,,,4.38179625091773E-6,2.17097172376612E-7,4.38479983206831E-6,2.17102876814696E-7,0.960912764072418,0.985472679138184,23.816219329834,6.90484455390106E-7,30,4,200,6.21585422777571E-5,0.242043659090996,0.263175636529922,1,,,,,,,,,,,,,,,,
,3931582014.90202,11.1523246765137,49.9325294494629,,,6,,,,23.9540057786846,,,1,,,,,,,,,,,,,,,,,,,,,,11.0741271972656,11.2245712280273,49.9325294494629,49.9325294494629,,,5.31462478637695,,1,0,0,0,0.0145721435546875,27.8592376708984,6,1,1,11.2305221557617,0,2084574496,11.147353553772,,,4.1744352589504E-6,2.06827875221272E-7,4.17737394296755E-6,2.06833327639999E-7,0.960361540317535,0.9852454662323,23.8142833709717,0,30,4,200,5.57525090698618E-5,0.244089484214783,0.264131218194962,1,,,,,,,,,,,,,,,,
,3931582034.64635,11.4732022285461,49.9325294494629,,,6,,,,23.9540057786846,,,1,,,,,,,,,,,,,,,,,,,,,,11.3928709030151,11.5378656387329,49.9325294494629,49.9325294494629,,,5.34910488128662,,1,0,0,0,0.0145721435546875,28.3479976654053,6,1,1,11.5535335540771,0,2084574528,11.4659505844116,,,3.97433116510752E-6,1.96947972024799E-7,3.97785317114717E-6,1.96954818883229E-7,0.95616865158081,0.985135614871979,23.7974109649658,0.0656125396490097,30,4,200,4.57649366580881E-5,0.245981842279434,0.26496359705925,1,,,,,,,,,,,,,,,,
,3931582054.5485,11.7918491363525,49.9325294494629,,,6,,,,23.9540057786846,,,1,,,,,,,,,,,,,,,,,,,,,,11.7114658355713,11.8578205108643,49.9325294494629,49.9325294494629,,,5.3804759979248,,1,0,0,0,0.0145721435546875,28.3479976654053,6,1,1,11.8722324371338,0,2084574432,11.7848798751831,,,3.78985927878219E-6,1.87811557515302E-7,3.7932997891089E-6,1.87817636213663E-7,0.955557107925415,0.984933078289032,23.7952251434326,0.187574252486229,30,4,200,4.33320165029727E-5,0.247697502374649,0.265803515911102,1,,,,,,,,,,,,,,,,
,3931582083.10087,12.2540221214294,49.9325294494629,,,6,,,,23.9590112263352,,,1,,,,,,,,,,,,,,,,,,,,,,12.1749124526978,12.3331317901611,49.9325294494629,49.9325294494629,,,5.42752027511597,,1,0,0,0,0.0145721435546875,28.8367557525635,6,1,1,12.3331317901611,0,2084574624,12.2491875648499,,,3.53778876803403E-6,1.75357252419314E-7,3.54178823604129E-6,1.75364711636143E-7,0.95100724697113,0.984883844852447,23.7821044921875,0,30,4,200,3.48692265106365E-5,0.24976122379303,0.266732394695282,1,,,,,,,,,,,,,,,,
,3931582102.80105,12.5728883743286,49.9325294494629,,,6,,,,23.9590112263352,,,1,,,,,,,,,,,,,,,,,,,,,,12.4940061569214,12.644287109375,49.9325294494629,49.9325294494629,,,5.45888710021973,,1,0,0,0,0.0145721435546875,28.3479976654053,6,1,1,12.6517705917358,0,2084574464,12.5689091682434,,,3.37502212954485E-6,1.67315540929681E-7,3.3794057773979E-6,1.67323974616385E-7,0.947919428348541,0.985139191150665,23.769495010376,0,30,4,200,3.05555768136401E-5,0.251185685396194,0.267313182353973,1,,,,,,,,,,,,,,,,
,3931582122.79631,12.898241519928,49.9325294494629,,,6,,,,23.9590112263352,,,1,,,,,,,,,,,,,,,,,,,,,,12.8212013244629,12.969952583313,49.9325294494629,49.9325294494629,,,5.48868894577026,,1,0,0,0,0.0145721435546875,27.8592376708984,6,1,1,12.9752817153931,0,2084574624,12.8957785606384,,,3.21764521311708E-6,1.59477347466992E-7,3.22080981185605E-6,1.59482363190026E-7,0.952476918697357,0.981085062026978,23.7935523986816,0,30,4,200,8.65711353981169E-6,0.252414554357529,0.267756342887878,1,,,,,,,,,,,,,,,,
,3931582143.12833,13.2277207374573,49.9325294494629,,,6,,,,23.9590112263352,,,1,,,,,,,,,,,,,,,,,,,,,,13.1483430862427,13.3004007339478,49.9325294494629,49.9325294494629,,,5.51737642288208,,1,0,0,0,0.0145721435546875,27.8592376708984,6,1,1,13.3070983886719,0,2084574656,13.2228636741638,,,3.08501865073714E-6,1.52974508827893E-7,3.08973163612504E-6,1.52983429778846E-7,0.943620979785919,0.984277904033661,23.7534809112549,0,30,4,200,3.29436625179369E-5,0.253488957881927,0.268218845129013,1,,,,,,,,,,,,,,,,
,3931582162.81028,13.54692029953,49.9325294494629,,,6,,,,23.9590112263352,,,1,,,,,,,,,,,,,,,,,,,,,,13.4623336791992,13.61598777771,49.9325294494629,49.9325294494629,,,5.54549694061279,,1,0,0,0,0.0145721435546875,28.3479976654053,6,1,1,13.6315069198608,0,2084574496,13.5428936004639,,,2.96418529732276E-6,1.47013669447367E-7,2.96935968605005E-6,1.47023445389964E-7,0.940025568008423,0.984247326850891,23.739278793335,4.8722972869873,30,4,200,2.14877636608435E-5,0.254451870918274,0.268475234508514,1,,,,,,,,,,,,,,,,
,3931582182.61057,13.866081237793,49.9325294494629,,,6,,,,23.9590112263352,,,1,,,,,,,,,,,,,,,,,,,,,,13.7874374389648,13.9374675750732,49.9325294494629,49.9325294494629,,,5.57199716567993,,1,0,0,0,0.0145721435546875,27.8592376708984,6,1,1,13.9447250366211,0,2084574432,13.8650750160217,,,2.8470618284393E-6,1.41216533429464E-7,2.8522447705894E-6,1.41225765913069E-7,0.938658118247986,0.983781397342682,23.7343311309814,0,30,4,200,7.54975280869985E-6,0.255251973867416,0.268884539604187,1,,,,,,,,,,,,,,,,
,3931582202.29494,14.1868119239807,49.9325294494629,,,6,,,,23.9590112263352,,,1,,,,,,,,,,,,,,,,,,,,,,14.1070508956909,14.2601451873779,49.9325294494629,49.9325294494629,,,5.59702253341675,,1,0,0,0,0.0145721435546875,28.3479976654053,6,1,1,14.2665729522705,0,2084574464,14.1846528053284,,,2.73874154108451E-6,1.35864107561803E-7,2.7441446745464E-6,1.35874776706106E-7,0.936268985271454,0.983114957809448,23.7256565093994,2.71736695367508E-7,30,4,200,1.15499269668362E-5,0.25593027472496,0.269067406654358,1,,,,,,,,,,,,,,,,
,3931582222.31237,14.5137901306152,49.9325294494629,,,6,,,,23.9590112263352,,,1,,,,,,,,,,,,,,,,,,,,,,14.432825088501,14.5876302719116,49.9325294494629,49.9325294494629,,,5.62247276306152,,1,0,0,0,0.0145721435546875,27.8592376708984,6,1,1,14.5947551727295,0,2084574496,14.5096821784973,,,2.62632611159527E-6,1.30310203220158E-7,2.6320774427455E-6,1.30321708946301E-7,0.933586716651917,0.985097885131836,23.71337890625,0,30,4,200,3.52875281350862E-6,0.256630897521973,0.26920160651207,1,,,,,,,,,,,,,,,,
,3931582242.31358,14.8407692909241,49.9325294494629,,,6,,,,23.9590112263352,,,1,,,,,,,,,,,,,,,,,,,,,,14.7630634307861,14.9115209579468,49.9325294494629,49.9325294494629,,,5.6479926109314,,1,0,0,0,0.0145721435546875,27.8592376708984,6,1,1,14.918475151062,0,2084574560,14.8358497619629,,,2.5274045979398E-6,1.25442188261582E-7,2.53361008153527E-6,1.2545428531999E-7,0.928953647613525,0.98132848739624,23.6986446380615,4.80160815641284E-6,30,4,200,1.32691752696701E-6,0.257172882556915,0.269228398799896,1,,,,,,,,,,,,,,,,
,3931582262.1888,15.1695580482483,49.9325294494629,,,6,,,,23.9590112263352,,,1,,,,,,,,,,,,,,,,,,,,,,15.0876636505127,15.2538642883301,49.9325294494629,49.9325294494629,,,5.6717700958252,,1,0,0,0,0.0145721435546875,27.8592376708984,6,1,1,15.2585077285767,0,2084574432,15.1654368400574,,,2.3829307303697E-6,1.18689909664064E-7,2.38551611826297E-6,1.18694741050778E-7,0.89022558927536,0.90006959438324,23.7868385314941,0.000204394280444831,30,4,200,0.000316833436954767,0.257637500762939,0.273628145456314,1,,,,,,,,,,,,,,,,
,3931582281.98338,15.5543036460876,49.9325294494629,,,6,,,,23.9590112263352,,,1,,,,,,,,,,,,,,,,,,,,,,15.4770927429199,15.6181030273438,49.9325294494629,49.9325294494629,,,5.6809573173523,,1,0,0,0,0.0145721435546875,27.8592376708984,2,1,1,15.6315145492554,0,2084574464,15.5456062316895,,,2.24127119662508E-6,1.11262504153283E-7,2.24553955813211E-6,1.11270577147252E-7,0.926240861415863,0.957650184631348,23.7314624786377,,30,4,200,-3.34846663463395E-5,0.259120672941208,0.270143747329712,1,,,,,,,,,,,,,,,,
,3931582301.70792,15.8665375709534,49.9325294494629,,,6,,,,23.9590112263352,,,1,,,,,,,,,,,,,,,,,,,,,,15.7898845672607,15.9403839111328,49.9325294494629,49.9325294494629,,,5.68924522399902,,1,0,0,0,0.0145721435546875,27.3704795837402,2,1,1,15.943190574646,0,2084574368,15.8729236602783,,,2.25328648114899E-6,1.11898104207163E-7,2.25831774394233E-6,1.11907934888183E-7,0.921669721603394,0.956782519817352,23.7110157012939,0,30,4,200,-4.10673092119396E-5,0.258225977420807,0.269503831863403,1,,,,,,,,,,,,,,,,
,3931582321.39521,16.2023954391479,49.9325294494629,,,6,,,,23.9590112263352,,,1,,,,,,,,,,,,,,,,,,,,,,16.1189956665039,16.275260925293,49.9325294494629,49.9325294494629,,,5.70255661010742,,1,0,0,0,0.0145721435546875,27.8592376708984,2,1,1,16.285795211792,0,2084574464,16.1922550201416,,,2.16114964835057E-6,1.07331281960532E-7,2.16679058352672E-6,1.07341981848742E-7,0.92065155506134,0.963929295539856,23.6903820037842,0.187977656722069,30,4,200,-0.000116626353701577,0.257752925157547,0.269073307514191,1,,,,,,,,,,,,,,,,
,3931582341.54958,16.5283136367798,49.9325294494629,,,6,,,,23.9590112263352,,,1,,,,,,,,,,,,,,,,,,,,,,16.4476623535156,16.584285736084,49.9325294494629,49.9325294494629,,,5.7129168510437,,1,0,0,0,0.0145721435546875,27.8592376708984,2,1,1,16.6089649200439,0,2084574560,16.5133344862196,,,2.08980370405793E-6,1.03816894342505E-7,2.0969284358432E-6,1.0383161963838E-7,0.917233347892761,0.981277823448181,23.6530647277832,0,30,4,200,-5.2005208999617E-5,0.257946491241455,0.268083989620209,1,,,,,,,,,,,,,,,,
,3931582361.32183,16.8595724105835,49.9325294494629,,,6,,,,23.9590112263352,,,1,,,,,,,,,,,,,,,,,,,,,,16.7810573577881,16.9310684204102,49.9325294494629,49.9325294494629,,,5.72874784469604,,1,0,0,0,0.0145721435546875,27.8592376708984,2,1,1,16.9380874633789,0,2084574496,16.8549980163574,,,2.01445309104547E-6,1.00100205490986E-7,2.02184731384812E-6,1.00115629500673E-7,0.914107441902161,0.980372846126556,23.6415576934814,,30,4,200,-3.63516955985688E-5,0.257201880216598,0.267138361930847,1,,,,,,,,,,,,,,,,
,3931582381.18203,17.1819849014282,49.9325294494629,,,6,,,,23.9590112263352,,,1,,,,,,,,,,,,,,,,,,,,,,17.1023178100586,17.2549343109131,49.9325294494629,49.9325294494629,,,5.74369716644287,,1,0,0,0,0.0145721435546875,27.3704795837402,2,1,1,17.2616519927979,0,2084574464,17.1772872924805,,,1.94348145441963E-6,9.65838694268991E-8,1.95093686978846E-6,9.65992041401129E-8,0.912884891033173,0.983329117298126,23.6345462799072,0,30,4,200,-3.97252333641518E-5,0.256868064403534,0.266345947980881,1,,,,,,,,,,,,,,,,
,3931582400.89305,17.50084400177,49.9325294494629,,,6,,,,23.9590112263352,,,1,,,,,,,,,,,,,,,,,,,,,,17.4228477478027,17.5726490020752,49.9325294494629,49.9325294494629,,,5.7574257850647,,1,0,0,0,0.0145721435546875,27.8592376708984,2,1,1,17.5827026367187,0,2084574496,17.4976676940918,,,1.87551588911899E-6,9.32515200008469E-8,1.8835994911951E-6,9.32680419643145E-8,0.907517790794373,0.981496036052704,23.6152420043945,0,30,4,200,-3.57507014996372E-5,0.256397038698196,0.265571117401123,1,,,,,,,,,,,,,,,,
,3931582420.65307,17.8297328948975,49.9325294494629,,,6,,,,23.9590112263352,,,1,,,,,,,,,,,,,,,,,,,,,,17.7509632110596,17.9029331207275,49.9325294494629,49.9325294494629,,,5.77017831802368,,1,0,0,0,0.0138092041015625,27.8592376708984,2,1,1,17.9085025787354,0,2084574432,17.8224769592285,,,1.81202850867552E-6,9.01443945362021E-8,1.82079056192327E-6,9.016229480756E-8,0.901809096336365,0.979081988334656,23.5946941375732,3.15509311121787E-7,30,4,200,-4.56062043667771E-5,0.255773693323135,0.264813929796219,1,,,,,,,,,,,,,,,,
,3931582440.45428,18.1508846282959,49.9325294494629,,,6,,,,23.9590112263352,,,1,,,,,,,,,,,,,,,,,,,,,,18.0662994384766,18.2249946594238,49.9325294494629,49.9325294494629,,,5.78601694107056,,1,0,0,0,0.0145721435546875,27.8592376708984,2,1,1,18.2354698181152,0,2084574464,18.1484846115112,,,1.75031910423743E-6,8.70878934718511E-8,1.75903829547117E-6,8.71049171662785E-8,0.900268137454987,0.978814661502838,23.5891170501709,0,30,4,200,-5.07844197272789E-5,0.255141317844391,0.26386570930481,1,,,,,,,,,,,,,,,,
,3931582460.26422,18.4795732498169,49.9325294494629,,,6,,,,23.9590112263352,,,1,,,,,,,,,,,,,,,,,,,,,,18.4030208587646,18.5318622589111,49.9325294494629,49.9325294494629,,,5.80001640319824,,1,0,0,0,0.0145721435546875,27.8592376708984,2,1,1,18.5561256408691,0,2084574464,18.4654407501221,,,1.6849160738544E-6,8.38358540477936E-8,1.6932542282736E-6,8.38527086546738E-8,0.900020003318787,0.976017296314239,23.5904102325439,0,30,4,200,-5.92952856095508E-5,0.25363764166832,0.262921839952469,1,,,,,,,,,,,,,,,,
,3931582479.93555,18.8008480072021,49.9325294494629,,,6,,,,23.9590112263352,,,1,,,,,,,,,,,,,,,,,,,,,,18.7218265533447,18.867359161377,49.9325294494629,49.9325294494629,,,5.81418800354004,,1,0,0,0,0.0145721435546875,27.8592376708984,2,1,1,18.8798694610596,0,2084574496,18.7958837509155,,,1.63121933375748E-6,8.12411908603029E-8,1.64093451076842E-6,8.12612377987758E-8,0.891026020050049,0.976262271404266,23.5551300048828,3.36343691742513E-5,30,4,200,-4.37883791164495E-5,0.253083497285843,0.261104375123978,1,,,,,,,,,,,,,,,,
,3931582500.15819,19.1348037719727,49.9325294494629,,,6,,,,23.9590112263352,,,1,,,,,,,,,,,,,,,,,,,,,,19.0569400787354,19.1894226074219,49.9325294494629,49.9325294494629,,,5.82887935638428,,1,0,0,0,0.0145721435546875,28.3479976654053,2,1,1,19.21266746521,0,2084574496,19.1208843655056,,,1.57835337945282E-6,7.85857211852498E-8,1.58726052012811E-6,7.86037052614134E-8,0.893660187721252,0.976017534732819,23.5660018920898,7.06461719346407E-7,30,4,200,-4.72801075375173E-5,0.252278327941895,0.260024338960648,1,,,,,,,,,,,,,,,,
,3931582519.95982,19.4570837020874,49.9325294494629,,,6,,,,23.9590112263352,,,1,,,,,,,,,,,,,,,,,,,,,,19.3810729980469,19.5258960723877,49.9325294494629,49.9325294494629,,,5.8400182723999,,1,0,0,0,0.0145721435546875,27.8592376708984,2,1,1,19.5330944061279,0,2084574336,19.4518915176392,,,1.52268248215438E-6,7.58663153144508E-8,1.5324018855048E-6,7.5886746880326E-8,0.887420296669006,0.976167559623718,23.5410289764404,0,30,4,200,-2.36184860114008E-5,0.25166580080986,0.259198993444443,1,,,,,,,,,,,,,,,,
,3931582539.79983,19.7795362472534,49.9325294494629,,,6,,,,23.9590112263352,,,1,,,,,,,,,,,,,,,,,,,,,,19.7031631469727,19.8525810241699,49.9325294494629,49.9325294494629,,,5.85469245910644,,1,0,0,0,0.0145721435546875,27.8592376708984,2,1,1,19.8559093475342,0,2084574496,19.776676940918,,,1.47450409886159E-6,7.35122832177239E-8,1.48483228969677E-6,7.35338602570419E-8,0.882017433643341,0.97461861371994,23.5215072631836,0,30,4,200,-4.06165672757197E-5,0.251107066869736,0.258505821228027,1,,,,,,,,,,,,,,,,
,3931582559.60156,20.1103267669678,49.9325294494629,,,6,,,,23.9590112263352,,,1,,,,,,,,,,,,,,,,,,,,,,20.0284423828125,20.1855449676514,49.9325294494629,49.9325294494629,,,5.86851358413696,,1,0,0,0,0.0145721435546875,27.8592376708984,2,1,1,20.192211151123,0,2084574560,20.1050539016724,,,1.42245016064118E-6,7.09017277077056E-8,1.43200636783182E-6,7.09218569730929E-8,0.883842885494232,0.972424030303955,23.530689239502,4.85084438323975,30,4,200,-0.000103741738712415,0.249450251460075,0.256899356842041,1,,,,,,,,,,,,,,,,
,3931582579.60446,20.4361896514893,49.9325294494629,,,6,,,,23.9590112263352,,,1,,,,,,,,,,,,,,,,,,,,,,20.3559532165527,20.5072822570801,49.9325294494629,49.9325294494629,,,5.88257789611816,,1,0,0,0,0.0145721435546875,27.8592376708984,2,1,1,20.5164260864258,0,2084574432,20.4324947357178,,,1.37202098390237E-6,6.84681867469447E-8,1.38286392792494E-6,6.84908365827706E-8,0.87430340051651,0.970961093902588,23.4948749542236,0,30,4,200,-3.85833809559699E-5,0.249086380004883,0.255936145782471,1,,,,,,,,,,,,,,,,
,3931582599.44236,20.7616128921509,49.9325294494629,,,6,,,,23.9590112263352,,,1,,,,,,,,,,,,,,,,,,,,,,20.6846199035645,20.834358215332,49.9325294494629,49.9325294494629,,,5.89599657058716,,1,0,0,0,0.0145721435546875,28.3479976654053,2,1,1,20.8386058807373,0,2084574560,20.7577783584595,,,1.32631318651858E-6,6.622325869608E-8,1.33766807257682E-6,6.62473907125364E-8,0.870116412639618,0.973684787750244,23.4762229919434,0,30,4,200,-3.77271571778692E-5,0.248373791575432,0.255041599273682,1,,,,,,,,,,,,,,,,
,3931582619.15582,21.0835227966309,49.9325294494629,,,6,,,,23.9590112263352,,,1,,,,,,,,,,,,,,,,,,,,,,21.0022602081299,21.1569938659668,49.9325294494629,49.9325294494629,,,5.90905475616455,,1,0,0,0,0.0145721435546875,27.8592376708984,2,1,1,21.1647853851318,0,2084574656,21.0796216964722,,,1.28884772236971E-6,6.43960634506174E-8,1.30068986782837E-6,6.44210566636922E-8,0.865104734897614,0.970885753631592,23.4591751098633,0,30,4,200,-3.94636190321762E-5,0.247735619544983,0.254233688116074,1,,,,,,,,,,,,,,,,
,3931582638.85965,21.4108352661133,49.9325294494629,,,6,,,,23.9590112263352,,,1,,,,,,,,,,,,,,,,,,,,,,21.3299388885498,21.4727897644043,49.9325294494629,49.9325294494629,,,5.92137336730957,,1,0,0,0,0.0145721435546875,27.8592376708984,2,1,1,21.4917316436768,0,2084574528,21.4022975921631,,,1.24990368941736E-6,6.24646779339116E-8,1.26163042286096E-6,6.24896917664361E-8,0.863434910774231,0.969183146953583,23.4542217254639,0,30,4,200,-3.82408943551127E-5,0.247214585542679,0.253467738628387,1,,,,,,,,,,,,,,,,
,3931582658.79155,21.7379379272461,49.9325294494629,,,6,,,,23.9590112263352,,,1,,,,,,,,,,,,,,,,,,,,,,21.649284362793,21.8138370513916,49.9325294494629,49.9325294494629,,,5.93448400497437,,1,0,0,0,0.0145721435546875,28.3479976654053,2,1,1,21.8265914916992,0,2084574528,21.72825756073,,,1.21044995158217E-6,6.05263478791501E-8,1.22249815350138E-6,6.05512398349568E-8,0.859525859355927,0.969281554222107,23.4390506744385,4.84138917922974,30,4,200,-3.18028614856303E-5,0.246535629034042,0.252653121948242,1,,,,,,,,,,,,,,,,
,3931582678.68661,22.0581722259521,49.9325294494629,,,6,,,,23.9590112263352,,,1,,,,,,,,,,,,,,,,,,,,,,21.9810047149658,22.1353397369385,49.9325294494629,49.9325294494629,,,5.94629335403442,,1,0,0,0,0.0145721435546875,28.3479976654053,2,1,1,22.1353397369385,0,2084574432,22.0587396621704,,,1.18114520830999E-6,5.90896310778811E-8,1.19347051611218E-6,5.91153148769487E-8,0.856188654899597,0.968294739723206,23.4263648986816,0,30,4,200,-3.98580377805047E-5,0.246055141091347,0.251952350139618,1,,,,,,,,,,,,,,,,
,3931582698.55344,22.3848743438721,49.9325294494629,,,6,,,,23.9590112263352,,,1,,,,,,,,,,,,,,,,,,,,,,22.3068904876709,22.4529228210449,49.9325294494629,49.9325294494629,,,5.95816802978516,,1,0,0,0,0.0145721435546875,27.8592376708984,2,1,1,22.4628582000732,0,2084574432,22.379566192627,,,1.13945264562089E-6,5.70637873918398E-8,1.15266589871626E-6,5.70911493466347E-8,0.849208474159241,0.969998300075531,23.3989334106445,2.23468596232124E-5,30,4,200,-2.64791124209296E-5,0.245539143681526,0.251247406005859,1,,,,,,,,,,,,,,,,
,3931582718.42509,22.7076778411865,49.9325294494629,,,6,,,,23.9590112263352,,,1,,,,,,,,,,,,,,,,,,,,,,22.626443862915,22.7666702270508,49.9325294494629,49.9325294494629,,,5.96895980834961,,1,0,0,0,0.0145721435546875,27.8592376708984,2,1,1,22.788911819458,0,2084574464,22.6947428385417,,,1.11053462454329E-6,5.56535182833421E-8,1.12404690550894E-6,5.56823120568216E-8,0.844854772090912,0.965210318565369,23.3846092224121,0,30,4,200,-4.08095183956902E-5,0.244947656989098,0.250585734844208,1,,,,,,,,,,,,,,,,
,3931582738.30243,23.0329246520996,49.9325294494629,,,6,,,,23.9590112263352,,,1,,,,,,,,,,,,,,,,,,,,,,22.9576206207275,23.1021347045898,49.9325294494629,49.9325294494629,,,5.97926807403564,,1,0,0,0,0.0145721435546875,27.8592376708984,2,1,1,23.1082286834717,0,2084574496,23.0286855697632,,,1.08077977952561E-6,5.60952347315757E-8,1.08304417537349E-6,5.60996492639413E-8,0.69972550868988,0.7059046626091,23.7192897796631,0,30,4,200,0.0004936020122841,0.244618147611618,0.253654092550278,1,,,,,,,,,,,,,,,,
,3931582758.22584,23.3533048629761,49.9325294494629,,,6,,,,23.9590112263352,,,1,,,,,,,,,,,,,,,,,,,,,,23.2651920318604,23.4303531646729,49.9325294494629,49.9325294494629,,,5.99062252044678,,1,0,0,0,0.0138092041015625,27.8592376708984,2,1,1,23.4414176940918,0,2084574560,23.3497064590454,,,1.05547447095882E-6,5.30007501090405E-8,1.07050855871699E-6,5.3032794419461E-8,0.832701206207275,0.963817417621613,23.3382549285889,0,30,4,200,0.00073781528044492,0.257819324731827,0.267524987459183,1,,,,,,,,,,,,,,,,
,3931582777.82121,23.6849098205566,49.9325294494629,,,6,,,,23.9590112263352,,,1,,,,,,,,,,,,,,,,,,,,,,23.606819152832,23.759428024292,49.9325294494629,49.9325294494629,,,6.001380443573,,1,0,0,0,0.0145721435546875,27.8592376708984,2,1,1,23.7630004882813,0,2084574560,23.6852554321289,,,1.04392215528082E-6,5.29664737345898E-8,1.06339826111163E-6,5.30093245781907E-8,0.78109747171402,0.883131802082062,23.246675491333,0,30,4,200,0.00019029229588341,0.268900394439697,0.275018632411957,1,,,,,,,,,,,,,,,,
,3931582797.4694,24.0038537979126,49.9325294494629,,,6,,,,23.9590112263352,,,1,,,,,,,,,,,,,,,,,,,,,,23.9266242980957,24.0810832977295,49.9325294494629,49.9325294494629,,,6.01195478439331,,1,0,0,0,0.0145721435546875,27.8592376708984,2,1,1,24.0810832977295,0,2084574624,24.002760887146,,,1.00461901273635E-6,5.03198412840972E-8,1.01609416885691E-6,5.0343665264784E-8,0.848117530345917,0.960393667221069,23.40256690979,0,30,4,200,-9.69285028986633E-5,0.270093739032745,0.275688648223877,1,,,,,,,,,,,,,,,,
,3931582817.21745,24.3390636444092,49.9325294494629,,,6,,,,23.9590112263352,,,1,,,,,,,,,,,,,,,,,,,,,,24.2661972045898,24.4056568145752,49.9325294494629,49.9325294494629,,,6.02405452728271,,1,0,0,0,0.0145721435546875,27.8592376708984,2,1,1,24.4119300842285,0,2084574528,24.3344387054443,,,9.82880657594231E-7,4.93420298480331E-8,9.96672616973146E-7,4.9371645079983E-8,0.834288060665131,0.96572732925415,23.3431453704834,4.83147430419922,30,4,200,3.41560444212519E-5,0.269852131605148,0.274905025959015,1,,,,,,,,,,,,,,,,
,3931582836.93364,24.6571865081787,49.9325294494629,,,6,,,,23.9590112263352,,,1,,,,,,,,,,,,,,,,,,,,,,24.5719051361084,24.7355442047119,49.9325294494629,49.9325294494629,,,6.03452301025391,,1,0,0,0,0.0145721435546875,27.3704795837402,2,1,1,24.742467880249,0,2084574560,24.6541902542114,,,9.5813133155841E-7,4.81582173338368E-8,9.72538754033436E-7,4.81892576829476E-8,0.827294528484344,0.958549559116364,23.3231582641602,0,30,4,200,-6.315278733382E-5,0.269446730613709,0.274579107761383,1,,,,,,,,,,,,,,,,
,3931582856.73157,24.9825448989868,49.9325294494629,,,6,,,,23.9590112263352,,,1,,,,,,,,,,,,,,,,,,,,,,24.9050273895264,25.0491943359375,49.9325294494629,49.9325294494629,,,6.04548454284668,,1,0,0,0,0.0145721435546875,28.3479976654053,2,1,1,25.0600624084473,0,2084574560,24.9767040252686,,,9.41511632031548E-7,4.74705557707124E-8,9.58743081525375E-7,4.7507472628138E-8,0.810646831989288,0.957650721073151,23.2575569152832,0,30,4,200,7.98383334768005E-5,0.270154178142548,0.27523347735405,1,,,,,,,,,,,,,,,,
,3931582876.70648,25.312105178833,49.9325294494629,,,6,,,,23.9590112263352,,,1,,,,,,,,,,,,,,,,,,,,,,25.2310447692871,25.370361328125,49.9325294494629,49.9325294494629,,,6.05687379837036,,1,0,0,0,0.0145721435546875,27.8592376708984,2,1,1,25.3931655883789,0,2084574592,25.2955718570285,,,9.27917359609885E-7,4.66761362074165E-8,9.425799846217E-7,4.67074436150772E-8,0.822950601577759,0.957204639911652,23.3066120147705,0,30,4,200,-4.77333269373048E-5,0.269879996776581,0.274715691804886,1,,,,,,,,,,,,,,,,
,3931582896.67641,25.635856628418,49.9325294494629,,,6,,,,23.9590112263352,,,1,,,,,,,,,,,,,,,,,,,,,,25.5564937591553,25.7086811065674,49.9325294494629,49.9325294494629,,,6.06693077087402,,1,0,0,0,0.0138092041015625,27.8592376708984,2,1,1,25.7152194976807,0,2084574496,25.6347043991089,,,9.03420617074168E-7,4.55134438869483E-8,9.19312252165913E-7,4.55475684832889E-8,0.814786672592163,0.96090042591095,23.2709465026855,6.69920655127498E-6,30,4,200,-4.38563329225872E-5,0.269142866134644,0.273882269859314,1,,,,,,,,,,,,,,,,
,3931582916.6153,25.9645042419434,49.9325294494629,,,6,,,,23.9590112263352,,,1,,,,,,,,,,,,,,,,,,,,,,25.8912448883057,26.0325412750244,49.9325294494629,49.9325294494629,,,6.07716846466065,,1,0,0,0,0.0145721435546875,27.8592376708984,2,1,1,26.0446872711182,0,2084574432,25.9615716934204,,,8.88069220400076E-7,4.47478530598274E-8,9.03907774802499E-7,4.47819372718951E-8,0.813878655433655,0.962292015552521,23.2676563262939,,30,4,200,-4.51800879091024E-5,0.268390983343124,0.273060530424118,1,,,,,,,,,,,,,,,,
,3931582936.87554,26.2990865707397,49.9325294494629,,,6,,,,23.9590112263352,,,1,,,,,,,,,,,,,,,,,,,,,,26.2186527252197,26.3711547851562,49.9325294494629,49.9325294494629,,,6.08774852752686,,1,0,0,0,0.0145721435546875,27.8592376708984,2,1,1,26.3795204162598,0,2084574496,26.2956367492676,,,8.60178924131082E-7,4.33389079996916E-8,8.75192966359299E-7,4.33709174930368E-8,0.814313352108002,0.955787479877472,23.2750568389893,0.0103145446628332,30,4,200,-3.73521834262647E-5,0.267499655485153,0.272081136703491,1,,,,,,,,,,,,,,,,
,3931582956.59578,26.6192264556885,49.9325294494629,,,6,,,,23.9590112263352,,,1,,,,,,,,,,,,,,,,,,,,,,26.5369110107422,26.6944847106934,49.9325294494629,49.9325294494629,,,6.0958080291748,,1,0,0,0,0.0145721435546875,27.8592376708984,2,1,1,26.7015419006348,0,2084574496,26.616286277771,,,8.45097533854934E-7,4.26478995128194E-8,8.61289568998874E-7,4.26827403810075E-8,0.806107759475708,0.955358386039734,23.2424411773682,0,30,4,200,-4.448919207789E-5,0.266716092824936,0.271056771278381,1,,,,,,,,,,,,,,,,
,3931582976.45265,26.9476680755615,49.9325294494629,,,6,,,,23.9590112263352,,,1,,,,,,,,,,,,,,,,,,,,,,26.8630619049072,27.021900177002,49.9325294494629,49.9325294494629,,,6.10655498504639,,1,0,0,0,0.0145721435546875,28.3479976654053,2,1,1,27.0322742462158,0,2084574528,26.9440826416016,,,8.20132773029122E-7,4.13990190259785E-8,8.36054171028068E-7,4.14330821251572E-8,0.804798185825348,0.954864680767059,23.2384300231934,4.82062530517578,30,4,200,-5.81123313168064E-5,0.265728324651718,0.270114630460739,1,,,,,,,,,,,,,,,,
,3931582996.77128,27.2805461883545,49.9325294494629,,,6,,,,23.9590112263352,,,1,,,,,,,,,,,,,,,,,,,,,,27.1936473846436,27.3557548522949,49.9325294494629,49.9325294494629,,,6.11686134338379,,1,0,0,0,0.0145721435546875,27.8592376708984,2,1,1,27.3674449920654,0,2084574560,27.278183555603,,,8.02606657113719E-7,4.0587200918591E-8,8.1976073898641E-7,4.06243205799437E-8,0.796149909496307,0.955572843551636,23.2032260894775,0,30,4,200,-5.27301090187393E-5,0.264808386564255,0.269124299287796,1,,,,,,,,,,,,,,,,
,3931583016.98254,27.612380027771,49.9325294494629,,,6,,,,23.9590112263352,,,1,,,,,,,,,,,,,,,,,,,,,,27.5314998626709,27.682559967041,49.9325294494629,49.9325294494629,,,6.12586212158203,,1,0,0,0,0.0138092041015625,27.8592376708984,2,1,1,27.6932601928711,0,2084574624,27.6069753646851,,,7.84208101860265E-7,3.96556638397579E-8,8.00690058119213E-7,3.96909210147729E-8,0.796284675598145,0.94939649105072,23.2091598510742,0,30,4,200,-4.46138765255455E-5,0.263861626386642,0.268250942230225,1,,,,,,,,,,,,,,,,
,3931583037.43772,27.9502859115601,49.9325294494629,,,6,,,,23.9590112263352,,,1,,,,,,,,,,,,,,,,,,,,,,27.8705234527588,28.0152893066406,49.9325294494629,49.9325294494629,,,6.13476467132568,,1,0,0,0,0.0145721435546875,26.881721496582,2,1,1,28.0335578918457,0,2084574400,27.9414937973022,,,7.62462813586395E-7,3.86031815099669E-8,7.79401965546331E-7,3.86396130530291E-8,0.790622115135193,0.947412133216858,23.1888084411621,0,30,4,200,-4.99961424793582E-5,0.263082385063171,0.267116725444794,1,,,,,,,,,,,,,,,,
,3931583057.38834,28.2746953964233,49.9325294494629,,,6,,,,23.9590112263352,,,1,,,,,,,,,,,,,,,,,,,,,,28.1946620941162,28.3429145812988,49.9325294494629,49.9325294494629,,,6.14480447769165,,1,0,0,0,0.0138092041015625,27.8592376708984,2,1,1,28.3547286987305,0,2084574688,28.2692035675049,,,7.45578445415501E-7,3.77600657395744E-8,7.6216169580998E-7,3.77957313514532E-8,0.789206266403198,0.942230761051178,23.1901836395264,3.25022083416116E-5,30,4,200,-5.07340591866523E-5,0.262131363153458,0.266125649213791,1,,,,,,,,,,,,,,,,
,3931583077.19037,28.5987977981567,49.9325294494629,,,6,,,,23.9590112263352,,,1,,,,,,,,,,,,,,,,,,,,,,28.5202255249023,28.6569976806641,49.9325294494629,49.9325294494629,,,6.15337371826172,,1,0,0,0,0.0138092041015625,28.3479976654053,2,1,1,28.6773700714111,0,2084574656,28.5880576239692,,,7.28684763745209E-7,3.69362249645307E-8,7.4579147265182E-7,3.69735472420993E-8,0.785349071025848,0.947306156158447,23.1680870056152,INF,30,4,200,-5.49176984350197E-5,0.261225044727325,0.265172153711319,1,,,,,,,,,,,,,,,,
,3931583105.9424,29.0705986022949,49.9325294494629,,,6,,,,23.9640735101564,,,1,,,,,,,,,,,,,,,,,,,,,,28.9872741699219,29.1506099700928,49.9325294494629,49.9325294494629,,,6.16476106643677,,1,0,0,0,0.0138092041015625,26.881721496582,2,1,1,29.153923034668,0,2084574496,29.0677263259888,,,7.09690472014318E-7,3.63090353256959E-8,7.30892159816765E-7,3.6356169342052E-8,0.747755646705627,0.902955949306488,23.0675029754639,5.16217803955078,30,4,200,-8.0930236435961E-5,0.259654134511948,0.263789027929306,1,,,,,,,,,,,,,,,,
,3931583125.96247,29.4041051864624,49.9325294494629,,,6,,,,23.9640735101564,,,1,,,,,,,,,,,,,,,,,,,,,,29.3257389068604,29.4742565155029,49.9325294494629,49.9325294494629,,,6.17346048355103,,1,0,0,0,0.0145721435546875,27.8592376708984,2,1,1,29.4824714660645,0,2084574432,29.3972947862413,,,6.74147999242723E-7,3.43486773355408E-8,6.93529713027055E-7,3.43908142824312E-8,0.76362282037735,0.942959070205688,23.0915870666504,0,30,4,200,-4.28546918556094E-5,0.258740365505218,0.262470602989197,1,,,,,,,,,,,,,,,,
,3931583145.5414,29.7420997619629,49.9325294494629,,,6,,,,23.9640735101564,,,1,,,,,,,,,,,,,,,,,,,,,,29.6468276977539,29.8308887481689,49.9325294494629,49.9325294494629,,,6.18179559707642,,1,0,0,0,0.0145721435546875,27.8592376708984,6,1,1,29.8373718261719,0,2084574432,29.7437994003296,,,6.49961189641643E-7,3.32409279090459E-8,6.7089346961865E-7,3.32865542332079E-8,0.749126791954041,0.9340940117836,23.0442008972168,0,30,4,200,1.49235820572358E-5,0.257874637842178,0.261344015598297,1,,,,,,,,,,,,,,,,
,3931583165.18113,29.961555480957,49.9325294494629,,,6,,,,23.9640735101564,,,1,,,,,,,,,,,,,,,,,,,,,,29.9421157836914,29.9809951782227,49.9325294494629,49.9325294494629,,,6.18662405014038,,1,0,0,0,0.0145721435546875,27.8592376708984,5,1,1,29.9809951782227,0,2084574528,29.9646507263184,,,6.28971035563504E-7,3.34336607841275E-8,6.67860575055322E-7,3.3520716796473E-8,0.635894656181335,0.835491359233856,22.7072563171387,0,30,4,200,7.19211602699943E-5,0.257500886917114,0.261514455080032,1,,,,,,,,,,,,,,,,
,3931583184.98966,29.9965305328369,49.9325294494629,,,6,,,,23.9640735101564,,,1,,,,,,,,,,,,,,,,,,,,,,29.994649887085,29.998348236084,49.9325294494629,49.9325294494629,,,6.18995237350464,,1,0,0,0,0.0138092041015625,28.3479976654053,5,1,1,29.9984111785889,0,2084573728,29.9963966369629,,,9.80170042735697E-7,6.11657435160153E-8,9.80194608994178E-7,6.116588730539E-8,0.391230016946793,0.391253501176834,23.9895496368408,0,30,4,200,-0.000949249777477235,0.252590864896774,0.261553019285202,1,,,,,,,,,,,,,,,,
,3931583204.80986,30.0001783370972,49.9325294494629,,,6,,,,23.9640735101564,,,1,,,,,,,,,,,,,,,,,,,,,,29.9995098114014,30.0002861022949,49.9325294494629,49.9325294494629,,,6.19184064865112,,1,0,0,0,0.0146484375,28.3479976654053,5,1,1,30.0004615783691,0,2084574272,29.9998735427856,,,6.41055710741118E-7,3.27789941302907E-8,6.61644035742487E-7,3.28240664451631E-8,0.749865114688873,0.935754716396332,23.0464630126953,,30,4,200,4.87488723592833E-5,0.257713705301285,0.261288166046143,1,,,,,,,,,,,,,,,,
,3931583224.81092,30.0004787445068,49.9325294494629,,,6,,,,23.9640735101564,,,1,,,,,,,,,,,,,,,,,,,,,,29.9999294281006,30.000545501709,49.9325294494629,49.9325294494629,,,6.19466924667358,,1,0,0,0,0.0138092041015625,27.8592376708984,1,1,1,30.0004119873047,0,2084574432,30.0002422332764,,,6.41338131978471E-7,3.27226912734057E-8,6.60128772086931E-7,3.27636343035648E-8,0.758112668991089,0.929126799106598,23.0856761932373,0,30,4,200,-1.62211097176623E-6,0.258238822221756,0.26155748963356,1,,,,,,,,,,,,,,,,