File: Data used in paper/Case study 4/ML_Namond_20240605_4_QHS_0-QHS1007D_Sm0p8Ca0p2BaCuBO5_DC-11p5mg_powder_MvT_50oe_20240607 (1).dat
[Header]
; MPMS3 Data File (default extension .dat)
; Copyright (c) 2007, Quantum Design, Inc. All rights reserved.
TITLE,
FILEOPENTIME,3926934265.55116,06/07/2024,3:04 pm
BYAPP,MPMS3 w/ AC,1.0,1.1
INFO,MPMS3 Measurement Release 1.1.16 Build 419, MultiVu Release 2.3.4.15,APPNAME
INFO,Linear Motor Servo Controller,MOTOR_MODULE_NAME
INFO,3101-100 F0,MOTOR_HW_VERSION
INFO,MMC1118,MOTOR_SERIAL_NUMBER
INFO,01.04.28,MOTOR_SOFTWARE_VERSION
INFO,Quantum Design Squid Module,SQUID_MODULE_NAME
INFO,3101-501 B0,SQUID_HW_VERSION
INFO,SQM313,SQUID_SERIAL_NUMBER
INFO,01.03.04,SQUID_SOFTWARE_VERSION
INFO,Quantum Design VSM Oven,OVEN_MODULE_NAME
INFO,3101-201 A3,OVEN_HW_VERSION
INFO,OVB345,OVEN_SERIAL_NUMBER
INFO,01.07.07,OVEN_SOFTWARE_VERSION
INFO,SQUID AC,AC_MODULE_NAME
INFO,3101-401 G0,AC_HW_VERSION
INFO,SAC210,AC_SERIAL_NUMBER
INFO,SQUID AC 00.95.07,AC_SOFTWARE_VERSION
INFO,TCI318,COIL_SERIAL_NUMBER
INFO,0,MOMENT_UNITS
INFO,ML_Namond_20240605_4_QHS_0-QHS1007D_Sm0p8Ca0p2BaCuBO5_DC-11p5mg_powder_MvT_50oe_20240607,SAMPLE_MATERIAL
INFO,,SAMPLE_COMMENT
INFO,,SAMPLE_MASS
INFO,,SAMPLE_VOLUME
INFO,,SAMPLE_MOLECULAR_WEIGHT
INFO,,SAMPLE_SIZE
INFO,,SAMPLE_SHAPE
INFO,Straw,SAMPLE_HOLDER
INFO,Standard,SAMPLE_HOLDER_DETAIL
INFO,65.49,SAMPLE_OFFSET
DATATYPE,COMMENT,1
DATATYPE,TIME,2
STARTUPAXIS,X,2
STARTUPAXIS,Y1,5
FIELDGROUP, VSM,2,3,4,5,6,8,9,10,11,14,15
FIELDGROUP, DC, 2,3,4,14,56,57,58,59,60,61,62,63,64,65,66,67,68,69
FIELDGROUP, AC, 2,3,4,11,16,17,18,19,20,21,22,23,24,25,26,27,28,29,30
STARTUPGROUP, All
[Data]
Comment,Time Stamp (sec),Temperature (K),Magnetic Field (Oe),Moment (emu),M. Std. Err. (emu),Transport Action,Averaging Time (sec),Frequency (Hz),Peak Amplitude (mm),Center Position (mm),Lockin Signal' (V),Lockin Signal (V),Range,M. Quad. Signal (emu),AC Moment (emu),AC M. Std Err. (emu),AC Phase (deg),AC Phase Std. Err. (deg),AC Susceptibility (emu/Oe),AC Suscept. Std Err. (emu/Oe),AC X' (emu/Oe),AC X' Std Err. (emu/Oe),AC X'' (emu/Oe),AC X'' Std Err. (emu/Oe),AC Drive (Oe),AC Frequency (Hz),AC Averaging Time (sec),AC Cycles,AC Range,AC Measure Type,AC Signal' (V),AC Signal'' (V),AC Trim Coil Ratio,AC Trim Coil Phase,Min. Temperature (K),Max. Temperature (K),Min. Field (Oe),Max. Field (Oe),Mass (grams),Motor Lag (deg),Pressure (Torr),Measure Count,Measurement Number,SQUID Status (code),Motor Status (code),Measure Status (code),Motor Current (amps),Motor Temp. (C),Temp. Status (code),Field Status (code),Chamber Status (code),Chamber Temp (K),Redirection State,Evercool Status,Average Temp (K),Rotation Angle (deg),Rotator state,DC Moment Fixed Ctr (emu),DC Moment Err Fixed Ctr (emu),DC Moment Free Ctr (emu),DC Moment Err Free Ctr (emu),DC Fixed Fit,DC Free Fit,DC Calculated Center (mm),DC Calculated Center Err (mm),DC Scan Length (mm),DC Scan Time (s),DC Number of Points,DC Squid Drift,DC Min V (V),DC Max V (V),DC Scans per Measure,Map 01,Map 02,Map 03,Map 04,Map 05,Map 06,Map 07,Map 08,Map 09,Map 10,Map 11,Map 12,Map 13,Map 14,Map 15,Map 16
,3926935798.34794,1.79598486423492,49.8468170166016,,,3,,,,26.0534400939941,,,,,,,,,,,,,,,,,,,,,,,,,1.79598486423492,1.79598486423492,49.8468170166016,49.8468170166016,,,2.40280508995056,,0,,,,,,5,1,1,1.79598486423492,0,0,0,,,,,,,,,,,,,,,,,,,,,,,,,,,,,,,,,
,3926935867.76131,2.07690823078156,49.8468170166016,,,6,,,,26.0534400939941,,,1,,,,,,,,,,,,,,,,,,,,,,2.00674962997437,2.13429355621338,49.8468170166016,49.8468170166016,,,2.57468438148499,,1,0,0,0,0,29.8142719268799,6,1,1,2.14815545082092,0,4232058240,2.06752231385973,,,6.95247377113726E-6,3.46826551555339E-7,6.9524734848974E-6,3.46826532649974E-7,0.98009729385376,0.980098009109497,26.0528202056885,0.042893473058939,30,4,200,-9.67044325079769E-5,-0.542169988155365,-0.508860290050507,1,,,,,,,,,,,,,,,,
,3926935908.56953,2.6489874124527,49.8468170166016,,,6,,,,26.0585144989227,,,1,,,,,,,,,,,,,,,,,,,,,,2.5745747089386,2.71856737136841,49.8468170166016,49.8468170166016,,,2.88328623771667,,1,0,0,0,0.000152587890625,29.8142719268799,6,1,1,2.7234001159668,0,4232058048,2.64410881996155,,,6.63237998200897E-6,3.30858296356903E-7,6.63241439629602E-6,3.30857986941263E-7,0.980145931243896,0.980456709861755,26.0717945098877,4.13919588027056E-6,30,4,200,-4.86196076963097E-5,-0.54374486207962,-0.512172400951385,1,,,,,,,,,,,,,,,,
,3926935940.38357,3.10992932319641,49.8468170166016,,,6,,,,26.0585144989227,,,1,,,,,,,,,,,,,,,,,,,,,,3.03350853919983,3.18041467666626,49.8468170166016,49.8468170166016,,,3.09599447250366,,1,0,0,0,0.0171661376953125,29.3255138397217,6,1,1,3.18635010719299,0,4232058048,3.10685975551605,,,6.47889203332272E-6,3.23206231424222E-7,6.4789620817117E-6,3.23206238394767E-7,0.979425013065338,0.979956090450287,26.0761394500732,5.10648012161255,30,4,200,-2.3052243705024E-5,-0.544930994510651,-0.513910233974457,1,,,,,,,,,,,,,,,,
,3926935971.57292,3.55675220489502,49.8468170166016,,,6,,,,26.0585144989227,,,1,,,,,,,,,,,,,,,,,,,,,,3.48442268371582,3.60776519775391,49.8468170166016,49.8468170166016,,,3.27439260482788,,1,0,0,0,0.019378662109375,29.3255138397217,6,1,1,3.63052082061768,0,4232058048,3.54292753007677,,,6.38537038821679E-6,3.18530058757369E-7,6.38544498544545E-6,3.18530229046559E-7,0.981140732765198,0.981741189956665,26.0764331817627,,30,4,200,-3.04276582028251E-5,-0.545220077037811,-0.514928817749023,1,,,,,,,,,,,,,,,,
,3926936002.88958,4.00461959838867,49.8468170166016,,,6,,,,26.0585144989227,,,1,,,,,,,,,,,,,,,,,,,,,,3.9310474395752,4.07819175720215,49.8468170166016,49.8468170166016,,,3.43023109436035,,1,0,0,0,0.0138092041015625,28.8367557525635,6,1,1,4.07819175720215,0,4232058080,4.00124480724335,,,6.31786574856274E-6,3.15159552008757E-7,6.31799638959694E-6,3.15159737727367E-7,0.981649935245514,0.982779085636139,26.082555770874,0,30,4,200,-1.48546396303573E-5,-0.545684099197388,-0.515785276889801,1,,,,,,,,,,,,,,,,
,3926936034.62988,4.47104549407959,49.8468170166016,,,6,,,,26.0585144989227,,,1,,,,,,,,,,,,,,,,,,,,,,4.39377689361572,4.53402662277222,49.8468170166016,49.8468170166016,,,3.57429814338684,,1,0,0,0,0,29.3255138397217,6,1,1,4.54831409454346,0,4232058144,4.46233744621277,,,6.30490116536311E-6,3.14516414058849E-7,6.30509038961509E-6,3.14516874506243E-7,0.981037139892578,0.982607066631317,26.0871772766113,,30,4,200,-1.04672699308139E-5,-0.546067237854004,-0.516114473342895,1,,,,,,,,,,,,,,,,
,3926936066.22566,4.94467687606812,49.8468170166016,,,6,,,,26.0585144989227,,,1,,,,,,,,,,,,,,,,,,,,,,4.86587858200073,5.01366376876831,49.8468170166016,49.8468170166016,,,3.70896291732788,,1,0,0,0,0,28.8367557525635,6,1,1,5.0234751701355,0,4232058368,4.93934826850891,,,6.31623941468557E-6,3.15077916916303E-7,6.31642947215538E-6,3.1507819642656E-7,0.981750786304474,0.98342752456665,26.0875053405762,0.18875689804554,30,4,200,1.87034493137617E-5,-0.546004414558411,-0.51621550321579,1,,,,,,,,,,,,,,,,
,3926936097.37968,5.41657757759094,49.8468170166016,,,6,,,,26.0585144989227,,,1,,,,,,,,,,,,,,,,,,,,,,5.34141683578491,5.48562335968018,49.8468170166016,49.8468170166016,,,3.82871127128601,,1,0,0,0,0.0002288818359375,27.3704795837402,6,1,1,5.49173831939697,0,4232058112,5.41167035102844,,,6.33832568965343E-6,3.1619100585664E-7,6.33855649746153E-6,3.1619152050259E-7,0.979867994785309,0.981676518917084,26.0901546478271,0,30,4,200,1.29093987197848E-5,-0.545651853084564,-0.515623390674591,1,,,,,,,,,,,,,,,,
,3926936128.68074,5.8710458278656,49.8468170166016,,,6,,,,26.0585144989227,,,1,,,,,,,,,,,,,,,,,,,,,,5.79420280456543,5.94193172454834,49.8468170166016,49.8468170166016,,,3.92938661575317,,1,0,0,0,0.0165557861328125,29.3255138397217,6,1,1,5.94788885116577,0,4232058048,5.86429486274719,,,6.41422771783813E-6,3.19961210870621E-7,6.41440939550071E-6,3.19961531416863E-7,0.982556939125061,0.984200298786163,26.0865497589111,2.65305345692468E-7,30,4,200,-7.27015412849141E-6,-0.546059846878052,-0.51570600271225,1,,,,,,,,,,,,,,,,
,3926936160.30591,6.36268615722656,49.8468170166016,,,6,,,,26.0585144989227,,,1,,,,,,,,,,,,,,,,,,,,,,6.28549194335938,6.43652486801148,49.8468170166016,49.8468170166016,,,4.03041410446167,,1,0,0,0,0.0220489501953125,28.8367557525635,6,1,1,6.4459981918335,0,4232058080,6.35817141532898,,,6.39465419023319E-6,3.18982760200813E-7,6.39483737177875E-6,3.18983212516529E-7,0.982937216758728,0.984614968299866,26.0865116119385,3.33282566070557,30,4,200,1.80440165422624E-5,-0.545577108860016,0.577972233295441,1,,,,,,,,,,,,,,,,
,3926936191.98965,6.86315298080444,49.8468170166016,,,6,,,,26.0585144989227,,,1,,,,,,,,,,,,,,,,,,,,,,6.78244733810425,6.93412685394287,49.8468170166016,49.8468170166016,,,4.1255030632019,,1,0,0,0,0.0002288818359375,29.3255138397217,6,1,1,6.94385862350464,0,4232058112,6.85421299934387,,,6.36073812436525E-6,3.1728821996153E-7,6.36095232046601E-6,3.17288631471958E-7,0.983440041542053,0.985526144504547,26.089038848877,5.29796838760376,30,4,200,0.000154009932884946,-0.54406863451004,-0.513082921504974,1,,,,,,,,,,,,,,,,
,3926936223.46688,7.35847735404968,49.8468170166016,,,6,,,,26.0585144989227,,,1,,,,,,,,,,,,,,,,,,,,,,7.27683115005493,7.42818927764893,49.8468170166016,49.8468170166016,,,4.21235132217407,,1,0,0,0,0.000152587890625,28.8367557525635,6,1,1,7.44012355804443,0,4232058240,7.35243072509766,,,6.32652749857521E-6,3.15601144443676E-7,6.32696050089983E-6,3.15602186964503E-7,0.980070471763611,0.983661234378815,26.1018085479736,0,30,4,200,9.16849821805954E-5,-0.5399209856987,-0.509534657001495,1,,,,,,,,,,,,,,,,
,3926936254.90728,7.85580921173096,49.8468170166016,,,6,,,,26.0585144989227,,,1,,,,,,,,,,,,,,,,,,,,,,7.77437496185303,7.9288592338562,49.8468170166016,49.8468170166016,,,4.29480695724487,,1,0,0,0,0.0215911865234375,28.8367557525635,6,1,1,7.93724346160889,0,4232058176,7.84745573997498,,,6.31051880592924E-6,3.14801303545008E-7,6.31103081670908E-6,3.14802527837569E-7,0.980259597301483,0.984662294387817,26.1056518554687,3.16792551302569E-7,30,4,200,0.000135615409817547,-0.536074757575989,-0.505312323570251,1,,,,,,,,,,,,,,,,
,3926936286.62412,8.36133146286011,49.8468170166016,,,6,,,,26.0585144989227,,,1,,,,,,,,,,,,,,,,,,,,,,8.27591514587402,8.44381237030029,49.8468170166016,49.8468170166016,,,4.37084007263184,,1,0,0,0,0.0147247314453125,27.3704795837402,6,1,1,8.44674777984619,0,4232058080,8.35949802398682,,,6.29049556523448E-6,3.13806567372252E-7,6.29109690398793E-6,3.13808004122226E-7,0.979615092277527,0.984716653823853,26.1096801757813,,30,4,200,0.000128944142488763,-0.532180726528168,-0.501696825027466,1,,,,,,,,,,,,,,,,
,3926936318.07719,8.86164855957031,49.8468170166016,,,6,,,,26.0585144989227,,,1,,,,,,,,,,,,,,,,,,,,,,8.78172016143799,8.93765544891357,49.8468170166016,49.8468170166016,,,4.44170951843262,,1,0,0,0,0.0218963623046875,29.3255138397217,6,1,1,8.94157695770264,0,4232058048,8.85753564834595,,,6.2916525745524E-6,3.13879724378543E-7,6.29246316799432E-6,3.13882071213789E-7,0.977330207824707,0.983528435230255,26.1175899505615,,30,4,200,0.000123501580674201,-0.527510941028595,-0.497074693441391,1,,,,,,,,,,,,,,,,
,3926936349.93554,9.37170219421387,49.8468170166016,,,6,,,,26.0585144989227,,,1,,,,,,,,,,,,,,,,,,,,,,9.28898525238037,9.44733715057373,49.8468170166016,49.8468170166016,,,4.5055775642395,,1,0,0,0,0,28.8367557525635,6,1,1,9.45441913604736,0,4232058048,9.3661735534668,,,6.29262617692376E-6,3.13918379910743E-7,6.29334686426756E-6,3.1392016859526E-7,0.978768110275269,0.984728515148163,26.1144638061523,0,30,4,200,7.96062013250776E-5,-0.524179935455322,-0.493968665599823,1,,,,,,,,,,,,,,,,
,3926936381.41725,9.87205171585083,49.8468170166016,,,6,,,,26.0585144989227,,,1,,,,,,,,,,,,,,,,,,,,,,9.78982448577881,9.94907665252686,49.8468170166016,49.8468170166016,,,4.56868600845337,,1,0,0,0,0.000152587890625,29.3255138397217,6,1,1,9.95427894592285,0,4232058080,9.87008438110351,,,6.30748508161426E-6,3.14677458026351E-7,6.30848828266701E-6,3.14679836385056E-7,0.976265013217926,0.983859419822693,26.1245212554932,0,30,4,200,9.54787246882915E-5,-0.521268367767334,-0.490724146366119,1,,,,,,,,,,,,,,,,
,3926936412.83962,10.3798727989197,49.8468170166016,,,6,,,,26.0585144989227,,,1,,,,,,,,,,,,,,,,,,,,,,10.2986688613892,10.4526691436768,49.8468170166016,49.8468170166016,,,4.62500381469727,,1,0,0,0,0.000152587890625,28.8367557525635,6,1,1,10.4610767364502,0,4232058112,10.3766494750977,,,6.33066073291032E-6,3.15852372175369E-7,6.33201532781068E-6,3.15855677977836E-7,0.973886609077454,0.983412861824036,26.1350326538086,3.54432086169254E-5,30,4,200,9.29025627556257E-5,-0.518340170383453,-0.487814515829086,1,,,,,,,,,,,,,,,,
,3926936444.63302,10.894679069519,49.8468170166016,,,6,,,,26.0585144989227,,,1,,,,,,,,,,,,,,,,,,,,,,10.8120498657227,10.9472093582153,49.8468170166016,49.8468170166016,,,4.67686605453491,,1,0,0,0,0,29.3255138397217,6,1,1,10.9773082733154,0,4232058080,10.8772446314494,,,6.37623724226861E-6,3.18130101656865E-7,6.37776696637113E-6,3.18134234774433E-7,0.97343635559082,0.984123468399048,26.1392860412598,,30,4,200,6.36982658761553E-5,-0.515709161758423,-0.485121697187424,1,,,,,,,,,,,,,,,,
,3926936476.38902,11.4054002761841,49.8468170166016,,,6,,,,26.0585144989227,,,1,,,,,,,,,,,,,,,,,,,,,,11.3252153396606,11.4609756469727,49.8468170166016,49.8468170166016,,,4.72894668579102,,1,0,0,0,0.02105712890625,28.8367557525635,6,1,1,11.4855852127075,0,4232058144,11.3932396570841,,,6.4055524666703E-6,3.19592108506593E-7,6.40714336860597E-6,3.1959614559561E-7,0.973497748374939,0.984795153141022,26.1408748626709,,30,4,200,6.65283878333867E-5,-0.513372957706451,-0.482662379741669,1,,,,,,,,,,,,,,,,
,3926936508.07039,11.9127779006958,49.8468170166016,,,6,,,,26.0585144989227,,,1,,,,,,,,,,,,,,,,,,,,,,11.8296537399292,11.9759902954102,49.8468170166016,49.8468170166016,,,4.77599573135376,,1,0,0,0,0.0217437744140625,29.3255138397217,6,1,1,11.9999027252197,0,4232058208,11.9040849473741,,,6.45547589085663E-6,3.22086296892795E-7,6.45723301497254E-6,3.22090500027598E-7,0.973120033740997,0.985697448253632,26.1448459625244,0.188808724284172,30,4,200,4.90504316985607E-5,-0.511717677116394,-0.480811297893524,1,,,,,,,,,,,,,,,,
,3926936548.77816,12.575156211853,49.8468170166016,,,6,,,,26.0635404610146,,,1,,,,,,,,,,,,,,,,,,,,,,12.4944152832031,12.6418790817261,49.8468170166016,49.8468170166016,,,4.83289861679077,,1,0,0,0,0.0185394287109375,28.8367557525635,6,1,1,12.6593227386475,0,4232058208,12.5670362048679,,,6.52630794559285E-6,3.25643512885306E-7,6.52836303646467E-6,3.25648116889385E-7,0.970592021942139,0.98375940322876,26.1566066741943,5.11435317993164,30,4,200,6.04661618126556E-5,-0.509461760520935,-0.478333801031113,1,,,,,,,,,,,,,,,,
,3926936580.14472,13.0870385169983,49.8468170166016,,,6,,,,26.0635404610146,,,1,,,,,,,,,,,,,,,,,,,,,,13.0066747665405,13.1605396270752,49.8468170166016,49.8468170166016,,,4.8741946220398,,1,0,0,0,0.0002288818359375,28.8367557525635,6,1,1,13.1674022674561,0,4232058144,13.0802813529968,,,6.57641985018995E-6,3.28149448471839E-7,6.57860092651123E-6,3.28154151522604E-7,0.970017433166504,0.983727395534515,26.1590824127197,0,30,4,200,5.26534313394222E-5,-0.508107125759125,-0.476806163787842,1,,,,,,,,,,,,,,,,
,3926936611.54214,13.5935950279236,49.8468170166016,,,6,,,,26.0635404610146,,,1,,,,,,,,,,,,,,,,,,,,,,13.5079765319824,13.6755933761597,49.8468170166016,49.8468170166016,,,4.91324520111084,,1,0,0,0,0.015869140625,28.8367557525635,6,1,1,13.6792135238647,0,4232058144,13.5921556472778,,,6.64103487293393E-6,3.31362908413211E-7,6.64321636392491E-6,3.31367243356152E-7,0.971125662326813,0.985739767551422,26.1587829589844,0,30,4,200,1.83370266313432E-5,-0.507204055786133,-0.475805789232254,1,,,,,,,,,,,,,,,,
,3926936642.87749,14.1064047813416,49.8468170166016,,,6,,,,26.0635404610146,,,1,,,,,,,,,,,,,,,,,,,,,,14.0302886962891,14.1794557571411,49.8468170166016,49.8468170166016,,,4.94974994659424,,1,0,0,0,0.0170135498046875,29.3255138397217,6,1,1,14.182520866394,0,4232058112,14.1029155731201,,,6.70127121955636E-6,3.34411573976108E-7,6.70408289493956E-6,3.34417624996772E-7,0.966959118843079,0.982986152172089,26.1710338592529,0.0303072817623615,30,4,200,4.87026773043908E-5,-0.507035851478577,-0.475092500448227,1,,,,,,,,,,,,,,,,
,3926936674.55565,14.6219897270203,49.8468170166016,,,6,,,,26.0635404610146,,,1,,,,,,,,,,,,,,,,,,,,,,14.5368719100952,14.7041673660278,49.8468170166016,49.8468170166016,,,4.98512601852417,,1,0,0,0,0.000152587890625,28.8367557525635,6,1,1,14.7104988098145,0,4232058080,14.6166405677795,,,6.76898964818256E-6,3.37777421867686E-7,6.77152226441438E-6,3.37782613492573E-7,0.968189716339111,0.982826113700867,26.1650428771973,,30,4,200,2.46825384238036E-5,-0.506358325481415,-0.474269598722458,1,,,,,,,,,,,,,,,,
,3926936706.38401,15.1483268737793,49.8468170166016,,,6,,,,26.0635404610146,,,1,,,,,,,,,,,,,,,,,,,,,,15.0581645965576,15.2082433700562,49.8468170166016,49.8468170166016,,,5.91171932220459,,1,0,0,0,0.0193023681640625,28.8367557525635,6,1,1,15.238489151001,0,4232058176,15.128002166748,,,6.85462035158161E-6,3.43439346192764E-7,6.86813721705363E-6,3.43468594502644E-7,0.904735386371613,0.926973700523377,26.2970294952393,0,30,4,200,0.000683112477418035,-0.50596559047699,-0.46980407834053,1,,,,,,,,,,,,,,,,
,3926936737.85523,15.7218332290649,49.8468170166016,,,6,,,,26.0635404610146,,,1,,,,,,,,,,,,,,,,,,,,,,15.6441497802734,15.7898015975952,49.8468170166016,49.8468170166016,,,5.93875360488892,,1,0,0,0,0.0002288818359375,29.8142719268799,2,1,1,15.7995166778564,0,4232058304,15.7177802085876,,,6.93245292276022E-6,3.45952257432011E-7,6.93572390921961E-6,3.45959523064662E-7,0.966602861881256,0.985353469848633,26.1773834228516,0,30,4,200,-2.1856882085558E-5,-0.505396783351898,-0.47231912612915,1,,,,,,,,,,,,,,,,
,3926936769.23077,16.2370233535767,49.8468170166016,,,6,,,,26.0635404610146,,,1,,,,,,,,,,,,,,,,,,,,,,16.1562175750732,16.3086032867432,49.8468170166016,49.8468170166016,,,5.95770263671875,,1,0,0,0,0.0138092041015625,28.8367557525635,2,1,1,16.3178291320801,0,4232058176,16.231902885437,,,7.02032093302582E-6,3.50347631725602E-7,7.02384298584961E-6,3.50355102911708E-7,0.965732157230377,0.985355317592621,26.1810359954834,,30,4,200,-2.08005149033852E-5,-0.506790995597839,-0.473480701446533,1,,,,,,,,,,,,,,,,
,3926936800.67299,16.7522296905518,49.8468170166016,,,6,,,,26.0635404610146,,,1,,,,,,,,,,,,,,,,,,,,,,16.6684703826904,16.8221015930176,49.8468170166016,49.8468170166016,,,5.95079708099365,,1,0,0,0,0.019073486328125,29.3255138397217,2,1,1,16.8359889984131,0,4232058240,16.7460027694702,,,7.09535772422414E-6,3.54092697890448E-7,7.09897555901064E-6,3.54100733238664E-7,0.96569687128067,0.985743582248688,26.1818561553955,0,30,4,200,-1.93769737961702E-5,-0.507892906665802,-0.47415366768837,1,,,,,,,,,,,,,,,,
,3926936832.19445,17.2653532028198,49.8468170166016,,,6,,,,26.0635404610146,,,1,,,,,,,,,,,,,,,,,,,,,,17.1841831207275,17.3361396789551,49.8468170166016,49.8468170166016,,,5.9823260307312,,1,0,0,0,0.021820068359375,28.8367557525635,2,1,1,17.3492431640625,0,4232057920,17.2616821289063,,,7.19612738454162E-6,3.59137555177722E-7,7.2000801310274E-6,3.59146156366957E-7,0.964416742324829,0.985283613204956,26.1864356994629,5.11726856231689,30,4,200,-2.94702203973429E-5,-0.508999347686768,-0.474647969007492,1,,,,,,,,,,,,,,,,
,3926936863.65716,17.7886219024658,49.8468170166016,,,6,,,,26.0635404610146,,,1,,,,,,,,,,,,,,,,,,,,,,17.7040462493896,17.8664569854736,49.8468170166016,49.8468170166016,,,5.99090957641602,,1,0,0,0,0.0002288818359375,28.8367557525635,2,1,1,17.873197555542,0,4232057824,17.786208152771,,,7.26901791244989E-6,3.62743249926798E-7,7.27254278350256E-6,3.62751123660518E-7,0.966998934745789,0.987214684486389,26.178882598877,0,30,4,200,4.47998627350898E-6,-0.510128736495972,-0.475807547569275,1,,,,,,,,,,,,,,,,
,3926936895.19891,18.3010101318359,49.8468170166016,,,6,,,,26.0635404610146,,,1,,,,,,,,,,,,,,,,,,,,,,18.2175579071045,18.3781890869141,49.8468170166016,49.8468170166016,,,6.03665781021118,,1,0,0,0,0.000152587890625,29.3255138397217,2,1,1,18.3844623565674,0,4232058080,18.298464012146,,,7.34382466439534E-6,3.66507117896839E-7,7.34795105569482E-6,3.66516017849488E-7,0.964549124240875,0.986485362052918,26.1878108978271,3.77765513803752E-6,30,4,200,-4.36872396676335E-5,-0.511113882064819,-0.476095736026764,1,,,,,,,,,,,,,,,,
,3926936926.86546,18.8296394348145,49.8468170166016,,,6,,,,26.0635404610146,,,1,,,,,,,,,,,,,,,,,,,,,,18.7489643096924,18.8987102508545,49.8468170166016,49.8468170166016,,,6.04732227325439,,1,0,0,0,0.0002288818359375,28.8367557525635,2,1,1,18.9103145599365,0,4232057920,18.8208766937256,,,7.42235138491403E-6,3.70425965391616E-7,7.4266328726728E-6,3.70434852695141E-7,0.964563071727753,0.987703859806061,26.1895446777344,0.188859164714813,30,4,200,-1.4249378182285E-5,-0.512782871723175,-0.477225542068481,1,,,,,,,,,,,,,,,,
,3926936958.76446,19.3467597961426,49.8468170166016,,,6,,,,26.0635404610146,,,1,,,,,,,,,,,,,,,,,,,,,,19.2662773132324,19.4049739837646,49.8468170166016,49.8468170166016,,,6.07351446151733,,1,0,0,0,0.0225830078125,28.8367557525635,2,1,1,19.4272422790527,0,4232058304,19.3340051439073,,,7.4930229668855E-6,3.73957709027019E-7,7.49739656647475E-6,3.73967111726558E-7,0.964207887649536,0.987149655818939,26.1902198791504,,30,4,200,-2.96539728878997E-5,-0.513564884662628,-0.477930694818497,1,,,,,,,,,,,,,,,,
,3926936990.05834,19.8593425750732,49.8468170166016,,,6,,,,26.0635404610146,,,1,,,,,,,,,,,,,,,,,,,,,,19.7777366638184,19.9365997314453,49.8468170166016,49.8468170166016,,,6.09400129318237,,1,0,0,0,0.000152587890625,28.8367557525635,2,1,1,19.9409484863281,0,4232058432,19.8552244186401,,,7.57690172821357E-6,3.78147833559327E-7,7.58133934496064E-6,3.78157218419386E-7,0.963912189006805,0.986517250537872,26.1904888153076,0.188860505819321,30,4,200,-4.40381263615564E-5,-0.515352547168732,-0.479266136884689,1,,,,,,,,,,,,,,,,
,3926937021.44612,20.3757362365723,49.8468170166016,,,6,,,,26.0635404610146,,,1,,,,,,,,,,,,,,,,,,,,,,20.2887325286865,20.4401969909668,49.8468170166016,49.8468170166016,,,6.11223745346069,,1,0,0,0,0.021209716796875,28.8367557525635,2,1,1,20.462739944458,0,4232058176,20.366633521186,,,7.63199492521626E-6,3.80922723962319E-7,7.63674001762929E-6,3.80932381028354E-7,0.962122440338135,0.984401047229767,26.1944046020508,5.11804676055908,30,4,200,-5.80974483455066E-5,-0.516950130462646,-0.480514407157898,1,,,,,,,,,,,,,,,,
,3926937053.13451,20.8937749862671,49.8468170166016,,,6,,,,26.0635404610146,,,1,,,,,,,,,,,,,,,,,,,,,,20.8093299865723,20.9665794372559,49.8468170166016,49.8468170166016,,,6.13896751403809,,1,0,0,0,0.0141143798828125,28.8367557525635,2,1,1,20.9814987182617,0,4232058048,20.8898508071899,,,7.69054256426402E-6,3.83832854673436E-7,7.69536501858804E-6,3.83843761405982E-7,0.962953865528107,0.986716866493225,26.1946239471436,,30,4,200,1.94481799553614E-6,-0.518450379371643,-0.482042968273163,1,,,,,,,,,,,,,,,,
,3926937084.55726,21.4083623886108,49.8468170166016,,,6,,,,26.0635404610146,,,1,,,,,,,,,,,,,,,,,,,,,,21.3262882232666,21.4824523925781,49.8468170166016,49.8468170166016,,,6.17182540893555,,1,0,0,0,0.0002288818359375,29.3255138397217,2,1,1,21.4904365539551,0,4232058016,21.406071472168,,,7.72923663640885E-6,3.8575129868932E-7,7.73402971573053E-6,3.85761779286879E-7,0.963863730430603,0.988993108272552,26.1939792633057,0.0325950905680656,30,4,200,-2.2721162167727E-5,-0.519732892513275,-0.483222424983978,1,,,,,,,,,,,,,,,,
,3926937116.20838,21.9307374954224,49.8468170166016,,,6,,,,26.0635404610146,,,1,,,,,,,,,,,,,,,,,,,,,,21.8475971221924,21.986442565918,49.8468170166016,49.8468170166016,,,6.19626951217651,,1,0,0,0,0.01556396484375,29.3255138397217,2,1,1,22.0138778686523,0,4232058080,21.9148591359456,,,7.77778578639457E-6,3.88203181663054E-7,7.78274839568023E-6,3.88212719038503E-7,0.961857736110687,0.984857022762299,26.1962738037109,0.00255169346928597,30,4,200,-5.89853189012501E-5,-0.521013081073761,-0.483911633491516,1,,,,,,,,,,,,,,,,
,3926937148.09958,22.4466104507446,49.8468170166016,,,6,,,,26.0635404610146,,,1,,,,,,,,,,,,,,,,,,,,,,22.3624019622803,22.5218639373779,49.8468170166016,49.8468170166016,,,6.21485757827759,,1,0,0,0,0.0203704833984375,29.3255138397217,2,1,1,22.530818939209,0,4232058112,22.4439105987549,,,7.82029099042929E-6,3.903088476194E-7,7.82516303621329E-6,3.90318643925711E-7,0.962936520576477,0.986612975597382,26.1945667266846,0,30,4,200,-2.75154161499813E-5,-0.521917521953583,-0.484865069389343,1,,,,,,,,,,,,,,,,
,3926937179.49207,22.9672193527222,49.8468170166016,,,6,,,,26.0635404610146,,,1,,,,,,,,,,,,,,,,,,,,,,22.881799697876,23.0455913543701,49.8468170166016,49.8468170166016,,,6.23632001876831,,1,0,0,0,0.0226593017578125,28.8367557525635,2,1,1,23.0526390075684,0,4232058144,22.961163520813,,,7.85167100397905E-6,3.91857886830396E-7,7.85625916295644E-6,3.91867215507358E-7,0.964131712913513,0.987092912197113,26.1904258728027,0.188855513930321,30,4,200,-5.78651743126102E-5,-0.523015975952148,-0.485685914754868,1,,,,,,,,,,,,,,,,
,3926937211.09417,23.4702301025391,49.8468170166016,,,6,,,,26.0635404610146,,,1,,,,,,,,,,,,,,,,,,,,,,23.385368347168,23.5430850982666,49.8468170166016,49.8468170166016,,,6.24305534362793,,1,0,0,0,0.0002288818359375,28.8367557525635,2,1,1,23.5550918579102,0,4232057920,23.4614612579346,,,7.8736552582319E-6,3.92998259268887E-7,7.87891234831213E-6,3.93009075395592E-7,0.961194753646851,0.984930753707886,26.1991004943848,0,30,4,200,0.000676144147291779,-0.514464676380157,-0.473102807998657,1,,,,,,,,,,,,,,,,
,3926937242.64375,24.0124139785767,49.8468170166016,,,6,,,,26.0635404610146,,,1,,,,,,,,,,,,,,,,,,,,,,23.9287109375,24.0862522125244,49.8468170166016,49.8468170166016,,,6.23348426818848,,1,0,0,0,0.0197601318359375,28.8367557525635,2,1,1,24.0961170196533,0,4232058080,24.0064872741699,,,7.89136515451645E-6,3.93876998946697E-7,7.8969000803713E-6,3.93889691104246E-7,0.961533725261688,0.988045990467071,26.202091217041,0,30,4,200,8.62886590766721E-5,-0.497884064912796,-0.460229754447937,1,,,,,,,,,,,,,,,,
,3926937274.58357,24.5316820144653,49.8468170166016,,,6,,,,26.0635404610146,,,1,,,,,,,,,,,,,,,,,,,,,,24.4523315429687,24.6076240539551,49.8468170166016,49.8468170166016,,,6.2689847946167,,1,0,0,0,0.016632080078125,28.8367557525635,2,1,1,24.6110324859619,0,4232058144,24.5279684066772,,,7.91412752287981E-6,3.95035553056545E-7,7.92008078401389E-6,3.95048229187578E-7,0.960086345672607,0.9875648021698,26.2072277069092,0,30,4,200,9.99112035060534E-6,-0.497736662626266,-0.460255175828934,1,,,,,,,,,,,,,,,,
,3926937306.17018,25.0448961257935,49.8468170166016,,,6,,,,26.0635404610146,,,1,,,,,,,,,,,,,,,,,,,,,,24.9595623016357,25.1207332611084,49.8468170166016,49.8468170166016,,,6.29077863693237,,1,0,0,0,0.014801025390625,27.3704795837402,2,1,1,25.1302299499512,0,4232058112,25.0428382873535,,,7.93430507864118E-6,3.96032682173916E-7,7.93998640866834E-6,3.96045392273712E-7,0.96073192358017,0.986742556095123,26.2036685943604,0,30,4,200,-4.77125358884223E-5,-0.498930484056473,-0.460985749959946,1,,,,,,,,,,,,,,,,
,3926937337.38594,25.5607175827026,49.8468170166016,,,6,,,,26.0635404610146,,,1,,,,,,,,,,,,,,,,,,,,,,25.4779529571533,25.6312789916992,49.8468170166016,49.8468170166016,,,6.31566572189331,,1,0,0,0,0.000152587890625,28.8367557525635,2,1,1,25.643482208252,0,4232058048,25.5537059783936,,,7.94033923019206E-6,3.96328508552013E-7,7.94590840030547E-6,3.96342685871062E-7,0.961076736450195,0.98638266324997,26.201753616333,,30,4,200,-4.74400876555592E-5,-0.500282883644104,-0.462476700544357,1,,,,,,,,,,,,,,,,
,3926937368.72783,26.07972240448,49.8468170166016,,,6,,,,26.0635404610146,,,1,,,,,,,,,,,,,,,,,,,,,,25.9954490661621,26.157657623291,49.8468170166016,49.8468170166016,,,6.32958936691284,,1,0,0,0,0.000152587890625,28.8367557525635,2,1,1,26.1639957427979,0,4232058240,26.0702959060669,,,7.95305155462258E-6,3.96985579071676E-7,7.9591464022327E-6,3.96997687398563E-7,0.959646224975586,0.987405478954315,26.2088642120361,,30,4,200,-2.93259854515782E-5,-0.501195311546326,-0.463622272014618,1,,,,,,,,,,,,,,,,
,3926937400.58293,26.5989980697632,49.8468170166016,,,6,,,,26.0635404610146,,,1,,,,,,,,,,,,,,,,,,,,,,26.5187969207764,26.6640625,49.8468170166016,49.8468170166016,,,6.34534502029419,,1,0,0,0,0.000152587890625,28.3479976654053,2,1,1,26.67919921875,0,4232058080,26.5906108856201,,,7.96292954046316E-6,3.97479804840367E-7,7.96910191464641E-6,3.97493575054216E-7,0.959567844867706,0.98752224445343,26.209342956543,5.11950635910034,30,4,200,-4.10719112551305E-5,-0.502704679965973,-0.464964210987091,1,,,,,,,,,,,,,,,,
,3926937431.97495,27.1134414672852,49.8468170166016,,,6,,,,26.0635404610146,,,1,,,,,,,,,,,,,,,,,,,,,,27.0294742584229,27.1697406768799,49.8468170166016,49.8468170166016,,,6.36326742172241,,1,0,0,0,0.000152587890625,29.3255138397217,2,1,1,27.1974086761475,0,4232058176,27.0993726518419,,,7.97834302723432E-6,3.98260149421951E-7,7.98471981975478E-6,3.98274549803116E-7,0.958899199962616,0.987150251865387,26.2115097045898,0.0331488475203514,30,4,200,-3.53388968505897E-5,-0.504214286804199,-0.466294199228287,1,,,,,,,,,,,,,,,,
,3926937463.39615,27.6322412490845,49.8468170166016,,,6,,,,26.0635404610146,,,1,,,,,,,,,,,,,,,,,,,,,,27.5532321929932,27.688081741333,49.8468170166016,49.8468170166016,,,6.37941932678223,,1,0,0,0,0.000152587890625,28.8367557525635,2,1,1,27.7112503051758,0,4232058208,27.6210214826796,,,7.97727328218689E-6,3.98209828813878E-7,7.98370672533167E-6,3.98223802421705E-7,0.958703398704529,0.987164974212647,26.2123184204102,0.0331333912909031,30,4,200,-3.46237065969035E-5,-0.505557894706726,-0.467585325241089,1,,,,,,,,,,,,,,,,
,3926937494.9566,28.1397171020508,49.8468170166016,,,6,,,,26.0635404610146,,,1,,,,,,,,,,,,,,,,,,,,,,28.0572814941406,28.2221527099609,49.8468170166016,49.8468170166016,,,6.41334342956543,,1,0,0,0,0.001373291015625,28.8367557525635,2,1,1,28.2284679412842,0,4232058112,28.1400188446045,,,7.97517686107333E-6,3.98097906852047E-7,7.98156777608521E-6,3.9811140320116E-7,0.959147751331329,0.988336682319641,26.2119464874268,0,30,4,200,3.18597158184275E-5,-0.506419241428375,-0.468547105789185,1,,,,,,,,,,,,,,,,
,3926937535.60525,28.8192930221558,49.8468170166016,,,6,,,,26.0685878107795,,,1,,,,,,,,,,,,,,,,,,,,,,28.7389793395996,28.8779144287109,49.8468170166016,49.8468170166016,,,6.43794536590576,,1,0,0,0,0.0193023681640625,29.3255138397217,2,1,1,28.8996067047119,0,4232058240,28.8053256140815,,,7.98763441485249E-6,3.98705343425771E-7,7.99352405553528E-6,3.98719105079118E-7,0.960041403770447,0.986113548278809,26.2106285095215,0,30,4,200,-3.33256757585332E-5,-0.508697271347046,-0.470632284879684,1,,,,,,,,,,,,,,,,
,3926937566.8611,29.3281240463257,49.8468170166016,,,6,,,,26.0685878107795,,,1,,,,,,,,,,,,,,,,,,,,,,29.2456665039063,29.3916721343994,49.8468170166016,49.8468170166016,,,6.43973588943481,,1,0,0,0,0.000152587890625,29.3255138397217,2,1,1,29.4105815887451,0,4232058240,29.315701590644,,,7.99479574233691E-6,3.9909026116736E-7,8.00137127470462E-6,3.99105925120862E-7,0.958365261554718,0.986993908882141,26.2185497283936,0,30,4,200,-2.75299407803686E-5,-0.509822010993958,-0.47185406088829,1,,,,,,,,,,,,,,,,
,3926937598.51703,29.8495016098022,49.8468170166016,,,6,,,,26.0685878107795,,,1,,,,,,,,,,,,,,,,,,,,,,29.7665271759033,29.9219913482666,49.8468170166016,49.8468170166016,,,6.46085643768311,,1,0,0,0,0,28.8367557525635,2,1,1,29.9324760437012,0,4232058176,29.8458578109741,,,7.99282080478373E-6,3.98984192791296E-7,7.99936634658984E-6,3.99000449054575E-7,0.958813309669495,0.988080441951752,26.2180442810059,0,30,4,200,-4.35507281508762E-5,-0.511173367500305,-0.473058998584747,1,,,,,,,,,,,,,,,,
,3926937629.66866,30.3622102737427,49.8468170166016,,,6,,,,26.0685878107795,,,1,,,,,,,,,,,,,,,,,,,,,,30.2802867889404,30.4204788208008,49.8468170166016,49.8468170166016,,,6.47359609603882,,1,0,0,0,0.018310546875,28.8367557525635,2,1,1,30.4441337585449,0,4232058080,30.3507855733236,,,8.00048281918305E-6,3.99397520765658E-7,8.00747389341616E-6,3.99412619679212E-7,0.956980228424072,0.986542403697967,26.2234992980957,5.29390048980713,30,4,200,-2.16009684663732E-5,-0.512150168418884,-0.47421658039093,1,,,,,,,,,,,,,,,,
,3926937661.13317,30.8800973892212,49.8468170166016,,,6,,,,26.0685878107795,,,1,,,,,,,,,,,,,,,,,,,,,,30.8030700683594,30.9501609802246,49.8468170166016,49.8468170166016,,,6.49643516540527,,1,0,0,0,0.02197265625,28.8367557525635,2,1,1,30.957124710083,0,4232058176,30.8763050079346,,,7.99147485429316E-6,3.98920952261503E-7,7.99806047558284E-6,3.98935766704014E-7,0.958572268486023,0.987978875637054,26.218864440918,,30,4,200,-8.83400662132772E-6,-0.513411819934845,-0.475573927164078,1,,,,,,,,,,,,,,,,
,3926937692.73359,31.3993453979492,49.8468170166016,,,6,,,,26.0685878107795,,,1,,,,,,,,,,,,,,,,,,,,,,31.3181991577148,31.4557971954346,49.8468170166016,49.8468170166016,,,6.50615739822388,,1,0,0,0,0,29.3255138397217,2,1,1,31.4804916381836,0,4232058176,31.3864943186442,,,7.99549032969402E-6,3.99143465122974E-7,8.00244443451458E-6,3.99158152889811E-7,0.957262873649597,0.98723429441452,26.2231826782227,0,30,4,200,-6.09453090874013E-5,-0.514711022377014,-0.476558685302734,1,,,,,,,,,,,,,,,,
,3926937724.19854,31.918004989624,49.8468170166016,,,6,,,,26.0685878107795,,,1,,,,,,,,,,,,,,,,,,,,,,31.8322715759277,31.9762554168701,49.8468170166016,49.8468170166016,,,6.51674127578735,,1,0,0,0,0,28.8367557525635,2,1,1,32.0037384033203,0,4232058112,31.9028659396701,,,8.00339034066215E-6,3.99554095571485E-7,8.0105356203906E-6,3.9956934349536E-7,0.956322193145752,0.985818684101105,26.2252502441406,1.01912200989318E-6,30,4,200,-2.95011959678959E-5,-0.515664339065552,-0.477642208337784,1,,,,,,,,,,,,,,,,
,3926937755.90875,32.4421043395996,49.8468170166016,,,6,,,,26.0685878107795,,,1,,,,,,,,,,,,,,,,,,,,,,32.3589324951172,32.5088272094727,49.8468170166016,49.8468170166016,,,6.51922416687012,,1,0,0,0,0,29.3255138397217,2,1,1,32.525276184082,0,4232058080,32.4303211636014,,,7.9993649961089E-6,3.99368568161696E-7,8.00693023132127E-6,3.99385379913843E-7,0.955451548099518,0.986578106880188,26.2295742034912,0,30,4,200,-3.30505281453952E-5,-0.516773879528046,-0.478725641965866,1,,,,,,,,,,,,,,,,
,3926937787.23438,32.9576625823975,49.8468170166016,,,6,,,,26.0685878107795,,,1,,,,,,,,,,,,,,,,,,,,,,32.8726272583008,33.0320358276367,49.8468170166016,49.8468170166016,,,6.51877737045288,,1,0,0,0,0,28.8367557525635,2,1,1,33.0426979064941,0,4232058272,32.9508777618408,,,8.00671949332196E-6,3.9965130665127E-7,8.01285068844409E-6,3.99668330591198E-7,0.96046656370163,0.989120125770569,26.2126522064209,0,30,4,200,-3.29801987390965E-5,-0.517853260040283,-0.479734808206558,1,,,,,,,,,,,,,,,,
,3926937818.80429,33.4780769348145,49.8468170166016,,,6,,,,26.0685878107795,,,1,,,,,,,,,,,,,,,,,,,,,,33.3976287841797,33.5457191467285,49.8468170166016,49.8468170166016,,,6.53647661209106,,1,0,0,0,0,29.8142719268799,2,1,1,33.5615539550781,0,4232058208,33.4711856842041,,,8.00897663978799E-6,3.99843189533483E-7,8.01650548024946E-6,3.9986241304343E-7,0.955747723579407,0.986692011356354,26.2285289764404,2.72789875452872E-5,30,4,200,-1.7593727534404E-5,-0.518588185310364,-0.480594873428345,1,,,,,,,,,,,,,,,,
,3926937850.09535,33.9901828765869,49.8468170166016,,,6,,,,26.0685878107795,,,1,,,,,,,,,,,,,,,,,,,,,,33.908992767334,34.0617942810059,49.8468170166016,49.8468170166016,,,6.53503894805908,,1,0,0,0,0,29.3255138397217,2,1,1,34.0713729858398,0,4232058112,33.9859272003174,,,8.02239863627991E-6,4.00530764062759E-7,8.03022703238641E-6,4.00550640976892E-7,0.954769313335419,0.985983669757843,26.2316093444824,0.188935130834579,30,4,200,-1.78182708623353E-5,-0.51980584859848,-0.481673926115036,1,,,,,,,,,,,,,,,,
,3926937881.44877,34.5055198669434,49.8468170166016,,,6,,,,26.0685878107795,,,1,,,,,,,,,,,,,,,,,,,,,,34.4217147827148,34.578670501709,49.8468170166016,49.8468170166016,,,6.53935432434082,,1,0,0,0,0,28.8367557525635,2,1,1,34.5893249511719,0,4232058080,34.5023494720459,,,8.02053813889326E-6,4.00452023982717E-7,8.02867617882516E-6,4.00473128983655E-7,0.953997492790222,0.986014902591705,26.2347297668457,,30,4,200,-3.0093457098701E-5,-0.520943105220795,-0.482903629541397,1,,,,,,,,,,,,,,,,
,3926937912.87908,35.0239181518555,49.8468170166016,,,6,,,,26.0685878107795,,,1,,,,,,,,,,,,,,,,,,,,,,34.9408378601074,35.0946731567383,49.8468170166016,49.8468170166016,,,6.55108022689819,,1,0,0,0,0.013885498046875,28.8367557525635,2,1,1,35.1069984436035,0,4232058144,35.0209953308105,,,8.02029969676193E-6,4.00463977572478E-7,8.02886725208989E-6,4.00487571802053E-7,0.952717244625092,0.985146105289459,26.2388114929199,0,30,4,200,-1.31288579723332E-5,-0.521731019020081,-0.483708441257477,1,,,,,,,,,,,,,,,,
,3926937953.37082,35.6959667205811,49.8468170166016,,,6,,,,26.0737017288825,,,1,,,,,,,,,,,,,,,,,,,,,,35.6149215698242,35.7590713500977,49.8468170166016,49.8468170166016,,,6.57051038742065,,1,0,0,0,0,28.8367557525635,2,1,1,35.7770118713379,0,4232589312,35.6855934990777,,,8.41618244768037E-6,4.22835955117286E-7,8.42509538620571E-6,4.22854819260448E-7,0.879622101783752,0.888239145278931,25.9013805389404,2.9180211640778E-5,30,4,200,-0.000604223634582013,-0.522301137447357,-0.47118079662323,1,,,,,,,,,,,,,,,,
,3926937984.75747,36.2138557434082,49.8468170166016,,,6,,,,26.0737017288825,,,1,,,,,,,,,,,,,,,,,,,,,,36.132511138916,36.2902984619141,49.8468170166016,49.8468170166016,,,6.58230352401733,,1,0,0,0,0,29.3255138397217,2,1,1,36.2952003479004,0,4232056832,36.2118297576904,,,8.02187951822477E-6,4.00540120820723E-7,8.03052107098233E-6,4.0056183338166E-7,0.952867388725281,0.986620306968689,26.2450370788574,0.0332823060452938,30,4,200,-0.000225232419325039,-0.521551728248596,-0.482443183660507,1,,,,,,,,,,,,,,,,
,3926938016.62554,36.7390289306641,49.8468170166016,,,6,,,,26.0737017288825,,,1,,,,,,,,,,,,,,,,,,,,,,36.6565971374512,36.7987594604492,49.8468170166016,49.8468170166016,,,6.60949230194092,,1,0,0,0,0.013885498046875,28.8367557525635,2,1,1,36.821460723877,0,4232058496,36.7270355224609,,,8.01236706073773E-6,4.00045589705583E-7,8.02066150777615E-6,4.00065188018081E-7,0.953918695449829,0.987575352191925,26.2418937683105,0,30,4,200,2.11219376069494E-5,-0.525431036949158,-0.487427324056625,1,,,,,,,,,,,,,,,,
,3926938048.11046,37.2565498352051,49.8468170166016,,,6,,,,26.0737017288825,,,1,,,,,,,,,,,,,,,,,,,,,,37.1755485534668,37.3326110839844,49.8468170166016,49.8468170166016,,,6.61512756347656,,1,0,0,0,0,28.8367557525635,2,1,1,37.3375511169434,0,4232058336,37.25305519104,,,8.01969440960204E-6,4.00410374123013E-7,8.02796032081858E-6,4.00431304029672E-7,0.95397162437439,0.987152993679047,26.2412433624268,0,30,4,200,2.04129059966363E-6,-0.525229096412659,-0.487194538116455,1,,,,,,,,,,,,,,,,
,3926938079.83657,37.7865009307861,49.8468170166016,,,6,,,,26.0737017288825,,,1,,,,,,,,,,,,,,,,,,,,,,37.6994552612305,37.8620262145996,49.8468170166016,49.8468170166016,,,6.62627935409546,,1,0,0,0,0,28.8367557525635,2,1,1,37.8735466003418,0,4232058112,37.7814956665039,,,8.02471393298529E-6,4.00656785151437E-7,8.03267237157377E-6,4.00676136318068E-7,0.95419842004776,0.985369145870209,26.2382507324219,1.1230144991714E-5,30,4,200,5.85851284995442E-6,-0.525310337543488,-0.487253665924072,1,,,,,,,,,,,,,,,,
,3926938111.43453,38.2964897155762,49.8468170166016,,,6,,,,26.0737017288825,,,1,,,,,,,,,,,,,,,,,,,,,,38.2139358520508,38.3710899353027,49.8468170166016,49.8468170166016,,,6.66853618621826,,1,0,0,0,0,29.3255138397217,2,1,1,38.3790435791016,0,4232058400,38.2930892944336,,,8.07210199886649E-6,4.03062503664721E-7,8.0809638349283E-6,4.03083170077577E-7,0.952102243900299,0.985686182975769,26.2470512390137,0,30,4,200,-5.87012073083315E-5,-0.526445150375366,-0.487962484359741,1,,,,,,,,,,,,,,,,
,3926938142.69313,38.8197345733643,49.8468170166016,,,6,,,,26.0737017288825,,,1,,,,,,,,,,,,,,,,,,,,,,38.7437057495117,38.8957633972168,49.8468170166016,49.8468170166016,,,6.69813585281372,,1,0,0,0,0.0186920166015625,28.8367557525635,2,1,1,38.8957633972168,0,4232058144,38.820491027832,,,8.03998724676942E-6,4.01452979814823E-7,8.04867774891894E-6,4.01474112324443E-7,0.952406227588654,0.985428154468536,26.2455005645752,8.67983018792984E-8,30,4,200,-4.5853612391511E-5,-0.527561664581299,-0.489451438188553,1,,,,,,,,,,,,,,,,
,3926938172.90273,39.311731338501,49.8468170166016,,,6,,,,26.0737017288825,,,1,,,,,,,,,,,,,,,,,,,,,,39.2369651794434,39.382698059082,49.8468170166016,49.8468170166016,,,6.70022344589233,,1,0,0,0,0,29.3255138397217,2,1,1,39.3913459777832,0,4232058144,39.3087505764431,,,8.04500802298881E-6,4.0167786456984E-7,8.05337344049901E-6,4.01698278874552E-7,0.953781843185425,0.987293362617493,26.2421817779541,1.000636984827E-5,30,4,200,-1.48008448377368E-5,-0.528534591197968,-0.490310728549957,1,,,,,,,,,,,,,,,,
,3926938203.02027,39.8151760101318,49.8468170166016,,,6,,,,26.0737017288825,,,1,,,,,,,,,,,,,,,,,,,,,,39.7317123413086,39.8932571411133,49.8468170166016,49.8468170166016,,,6.69597911834717,,1,0,0,0,0,28.8367557525635,2,1,1,39.8986396789551,0,4232058176,39.8106586456299,,,8.04639807675818E-6,4.01804243108278E-7,8.0557673367465E-6,4.01826626839252E-7,0.950804531574249,0.985610246658325,26.2520732879639,0.188978925347328,30,4,200,-7.9817655205261E-6,-0.528985857963562,-0.490794658660889,1,,,,,,,,,,,,,,,,
,3926938234.46056,40.3266773223877,49.8468170166016,,,6,,,,26.0737017288825,,,1,,,,,,,,,,,,,,,,,,,,,,40.245361328125,40.4004516601562,49.8468170166016,49.8468170166016,,,6.71561479568481,,1,0,0,0,0,28.8367557525635,2,1,1,40.4079933166504,0,4232058144,40.3237060546875,,,8.02902656595302E-6,4.00918949771369E-7,8.03807795651735E-6,4.00940504419807E-7,0.951722383499145,0.986304819583893,26.249174118042,,30,4,200,-2.67277191596804E-5,-0.52873706817627,-0.490640640258789,1,,,,,,,,,,,,,,,,
,3926938265.50173,40.8424892425537,49.8468170166016,,,6,,,,26.0737017288825,,,1,,,,,,,,,,,,,,,,,,,,,,40.7594108581543,40.9105415344238,49.8468170166016,49.8468170166016,,,6.70828628540039,,1,0,0,0,0,29.3255138397217,2,1,1,40.9255676269531,0,4232058304,40.8352882385254,,,8.0648817263498E-6,4.02710195803485E-7,8.07398511141084E-6,4.02733332971891E-7,0.951680064201355,0.985994100570679,26.2489852905273,6.40305328369141,30,4,200,-1.9666522348416E-6,-0.529502809047699,-0.491122096776962,1,,,,,,,,,,,,,,,,
,3926938306.41697,41.5183277130127,49.8468170166016,,,6,,,,26.0787588281298,,,1,,,,,,,,,,,,,,,,,,,,,,41.4338531494141,41.5832252502441,49.8468170166016,49.8468170166016,,,6.70223999023437,,1,0,0,0,0,29.3255138397217,2,1,1,41.6028022766113,0,4232058144,41.5148822784424,,,8.03108820171716E-6,4.01005869569052E-7,8.03999222187208E-6,4.01028419595781E-7,0.952558815479279,0.987773180007935,26.252513885498,0,30,4,200,6.68225675326539E-6,-0.529535412788391,-0.491469293832779,1,,,,,,,,,,,,,,,,
,3926938337.86241,42.0392303466797,49.8468170166016,,,6,,,,26.0787588281298,,,1,,,,,,,,,,,,,,,,,,,,,,41.9601516723633,42.1101913452148,49.8468170166016,49.8468170166016,,,6.69876098632813,,1,0,0,0,0,28.8367557525635,2,1,1,42.1183090209961,0,4232058176,42.0343063354492,,,8.03905342443268E-6,4.01489653448411E-7,8.04949930451294E-6,4.0151585517997E-7,0.948240041732788,0.985300123691559,26.2668952941895,5.29067420959473,30,4,200,-2.94764540740289E-5,-0.530327379703522,-0.492094099521637,1,,,,,,,,,,,,,,,,
,3926938369.2174,42.5538768768311,49.8468170166016,,,6,,,,26.0787588281298,,,1,,,,,,,,,,,,,,,,,,,,,,42.4722557067871,42.6249961853027,49.8468170166016,49.8468170166016,,,6.71771812438965,,1,0,0,0,0,29.3255138397217,2,1,1,42.635498046875,0,4232058272,42.5488838195801,,,8.03535044136707E-6,4.012514627498E-7,8.04456504538574E-6,4.0127527337208E-7,0.950865864753723,0.984394669532776,26.2554550170898,0,30,4,200,-4.06141807616223E-5,-0.530981600284576,-0.492902517318726,1,,,,,,,,,,,,,,,,
,3926938400.66227,43.0737571716309,49.8468170166016,,,6,,,,26.0787588281298,,,1,,,,,,,,,,,,,,,,,,,,,,42.9897346496582,43.1516799926758,49.8468170166016,49.8468170166016,,,6.72658586502075,,1,0,0,0,0,28.8367557525635,2,1,1,43.1577796936035,0,4232058240,43.0698844909668,,,7.99937602426873E-6,3.99487945268194E-7,8.00950299608135E-6,3.99513463561424E-7,0.949221730232239,0.986615061759949,26.2644748687744,3.87090985896066E-5,30,4,200,-4.8648657866579E-6,-0.531459271907806,-0.493477344512939,1,,,,,,,,,,,,,,,,
,3926938432.22464,43.5931739807129,49.8468170166016,,,6,,,,26.0787588281298,,,1,,,,,,,,,,,,,,,,,,,,,,43.5086402893066,43.6554908752441,49.8468170166016,49.8468170166016,,,6.73367118835449,,1,0,0,0,0,30.7917900085449,2,1,1,43.6777076721191,0,4232058144,43.5809911092122,,,7.99216874251433E-6,3.99104643031802E-7,8.00180310418547E-6,3.99129440889093E-7,0.950384557247162,0.986603200435638,26.2598896026611,,30,4,200,9.99197982309852E-6,-0.531626164913177,-0.493878692388535,1,,,,,,,,,,,,,,,,
,3926938463.60136,44.1084156036377,49.8468170166016,,,6,,,,26.0787588281298,,,1,,,,,,,,,,,,,,,,,,,,,,44.021915435791,44.1797752380371,49.8468170166016,49.8468170166016,,,6.74938058853149,,1,0,0,0,0,29.3255138397217,2,1,1,44.1949157714844,0,4232058144,44.1012180328369,,,7.98848951722221E-6,3.98932699852404E-7,7.99831092644727E-6,3.98957435737464E-7,0.949797034263611,0.98621141910553,26.2618217468262,5.29132175445557,30,4,200,-1.68656279129209E-5,-0.531714081764221,-0.493857115507126,1,,,,,,,,,,,,,,,,
,3926938494.8836,44.6357421875,49.8468170166016,,,6,,,,26.0787588281298,,,1,,,,,,,,,,,,,,,,,,,,,,44.5562286376953,44.711971282959,49.8468170166016,49.8468170166016,,,6.7657413482666,,1,0,0,0,0,29.8142719268799,2,1,1,44.7152557373047,0,4232058272,44.6346611022949,,,7.97224149582404E-6,3.98139190711489E-7,7.98235955867334E-6,3.98164452101443E-7,0.948907494544983,0.985716462135315,26.2647895812988,,30,4,200,-6.03926400799537E-6,-0.532019555568695,-0.49415248632431,1,,,,,,,,,,,,,,,,
,3926938526.24288,45.1483173370361,49.8468170166016,,,6,,,,26.0787588281298,,,1,,,,,,,,,,,,,,,,,,,,,,45.0662612915039,45.2231330871582,49.8468170166016,49.8468170166016,,,6.75655317306519,,1,0,0,0,0,28.8367557525635,2,1,1,45.2303733825684,0,4232058208,45.1458381652832,,,7.95485899850281E-6,3.97299633300092E-7,7.96558412677092E-6,3.97326239735615E-7,0.947534739971161,0.986013174057007,26.2704849243164,0,30,4,200,6.00265821049106E-6,-0.532310366630554,-0.494523257017136,1,,,,,,,,,,,,,,,,
,3926938557.69633,45.6667938232422,49.8468170166016,,,6,,,,26.0787588281298,,,1,,,,,,,,,,,,,,,,,,,,,,45.5833587646484,45.7266883850098,49.8468170166016,49.8468170166016,,,6.75963878631592,,1,0,0,0,0.013885498046875,29.8142719268799,2,1,1,45.7502288818359,0,4232058208,45.6554005940755,,,7.96078636111383E-6,3.97571362109504E-7,7.97102763083578E-6,3.97596970447406E-7,0.948707222938538,0.986145675182343,26.265962600708,,30,4,200,-7.52135792936315E-6,-0.532503128051758,-0.494670063257217,1,,,,,,,,,,,,,,,,
,3926938598.29608,46.3395900726318,49.8468170166016,,,6,,,,26.0838966147406,,,1,,,,,,,,,,,,,,,,,,,,,,46.2494697570801,46.4138374328613,49.8468170166016,49.8468170166016,,,6.76153373718262,,1,0,0,0,0,29.3255138397217,2,1,1,46.4297103881836,0,4232058080,46.3304176330566,,,7.96399133302505E-6,3.97718618137461E-7,7.9739607171578E-6,3.97741567272927E-7,0.949327707290649,0.98642361164093,26.2689456939697,0,30,4,200,-1.56921341840643E-5,-0.532741367816925,-0.49499586224556,1,,,,,,,,,,,,,,,,
,3926938630.04494,46.8623237609863,49.8468170166016,,,6,,,,26.0838966147406,,,1,,,,,,,,,,,,,,,,,,,,,,46.7774467468262,46.9364280700684,49.8468170166016,49.8468170166016,,,6.7827410697937,,1,0,0,0,0,28.8367557525635,2,1,1,46.9472007751465,0,4232057856,46.8546772003174,,,7.95972095404313E-6,3.97526318298211E-7,7.97021334639015E-6,3.97551841653005E-7,0.948308229446411,0.986985743045807,26.2735500335693,0,30,4,200,-1.48439030454028E-5,-0.5326908826828,-0.495011538267136,1,,,,,,,,,,,,,,,,
,3926938660.89242,47.3710594177246,49.8468170166016,,,6,,,,26.0838966147406,,,1,,,,,,,,,,,,,,,,,,,,,,47.2847557067871,47.4501419067383,49.8468170166016,49.8468170166016,,,6.7783260345459,,1,0,0,0,0,29.3255138397217,2,1,1,47.4573631286621,0,4232058336,47.3681282043457,,,7.96198888717634E-6,3.97624539277063E-7,7.97217798517327E-6,3.97648795202164E-7,0.94904088973999,0.987178206443787,26.270866394043,0,30,4,200,-3.55610536644235E-5,-0.533169984817505,-0.495371848344803,1,,,,,,,,,,,,,,,,
,3926938692.07784,47.8860912322998,49.8468170166016,,,6,,,,26.0838966147406,,,1,,,,,,,,,,,,,,,,,,,,,,47.8037528991699,47.961742401123,49.8468170166016,49.8468170166016,,,6.77501344680786,,1,0,0,0,0.013885498046875,28.8367557525635,2,1,1,47.9684295654297,0,4232058208,47.884753036499,,,7.97670744376304E-6,3.98638480515217E-7,7.99186209993223E-6,3.9867536369842E-7,0.936820030212402,0.980288684368134,26.3118667602539,0.189129441976547,30,4,200,7.50160324969329E-5,-0.533249020576477,-0.495234221220016,1,,,,,,,,,,,,,,,,
,3926938723.45356,48.4045372009277,49.8468170166016,,,6,,,,26.0838966147406,,,1,,,,,,,,,,,,,,,,,,,,,,48.3227958679199,48.4693298339844,49.8468170166016,49.8468170166016,,,6.78316020965576,,1,0,0,0,0,29.3255138397217,2,1,1,48.4862785339355,0,4232058304,48.3942426045736,,,7.93808753041626E-6,3.96391876659604E-7,7.9475286919556E-6,3.96414491677713E-7,0.951005637645721,0.988162040710449,26.2641086578369,0,30,4,200,4.73200452688616E-6,-0.533585548400879,-0.496018379926682,1,,,,,,,,,,,,,,,,
,3926938754.83422,48.9241180419922,49.8468170166016,,,6,,,,26.0838966147406,,,1,,,,,,,,,,,,,,,,,,,,,,48.8426094055176,48.9828987121582,49.8468170166016,49.8468170166016,,,6.78822946548462,,1,0,0,0,0.013885498046875,28.8367557525635,2,1,1,49.0056266784668,0,4232058144,48.9123463100857,,,7.94643505593464E-6,3.96863633956728E-7,7.95697445613592E-6,3.96889511733602E-7,0.948265075683594,0.987365543842316,26.2741260528564,3.90246714232489E-5,30,4,200,-2.74094054475427E-5,-0.533599436283112,-0.495890080928802,1,,,,,,,,,,,,,,,,
,3926938786.13147,49.4521808624268,49.8468170166016,,,6,,,,26.0838966147406,,,1,,,,,,,,,,,,,,,,,,,,,,49.3630447387695,49.5369567871094,49.8468170166016,49.8468170166016,,,6.79445362091064,,1,0,0,0,0,28.8367557525635,6,1,1,49.541316986084,0,4232058112,49.4471942901611,,,7.95454228104364E-6,3.97379633432516E-7,7.96613351060075E-6,3.97407315429912E-7,0.943128526210785,0.978399813175201,26.2834281921387,1.13553660412435E-5,30,4,200,5.99274098931346E-5,-0.534513831138611,-0.496221899986267,1,,,,,,,,,,,,,,,,
,3926938817.18004,49.8737239837646,49.8468170166016,,,6,,,,26.0838966147406,,,1,,,,,,,,,,,,,,,,,,,,,,49.8391342163086,49.9039154052734,49.8468170166016,49.8468170166016,,,6.80790853500366,,1,0,0,0,0,28.8367557525635,5,1,1,49.9083137512207,0,4232058336,49.8735248565674,,,7.95219156441516E-6,3.97306391571072E-7,7.96454362975672E-6,3.97335906413166E-7,0.941214203834534,0.977505028247833,26.2900009155273,0,30,4,200,6.12947769695893E-5,-0.533007264137268,-0.494855403900146,1,,,,,,,,,,,,,,,,
,3926938848.74641,49.9786338806152,49.8468170166016,,,6,,,,26.0838966147406,,,1,,,,,,,,,,,,,,,,,,,,,,49.9729347229004,49.9829139709473,49.8468170166016,49.8468170166016,,,6.80671453475952,,1,0,0,0,0,29.3255138397217,5,1,1,49.9848442077637,0,4232058144,49.9780951605903,,,7.95236966582636E-6,3.973257271691E-7,7.96489810045664E-6,3.97354614601358E-7,0.940765261650086,0.977376759052277,26.2915172576904,0,30,4,200,9.50843877944862E-6,-0.532567858695984,0.598779082298279,1,,,,,,,,,,,,,,,,
,3926938869.34459,49.993522644043,49.8468170166016,,,6,,,,26.0838966147406,,,1,,,,,,,,,,,,,,,,,,,,,,49.9917640686035,49.9943199157715,49.8468170166016,49.8468170166016,,,6.81743717193603,,1,0,0,0,0.0188446044921875,28.8367557525635,1,1,1,49.9952812194824,0,4232058112,49.992992401123,,,7.94263008819343E-6,3.96811706632038E-7,7.95493313293169E-6,3.96841569647906E-7,0.941941797733307,0.979232609272003,26.2894897460938,5.12732791900635,30,4,200,1.89229413081193E-5,-0.532437920570374,-0.494560658931732,1,,,,,,,,,,,,,,,,