File: Data used in paper/Case study 4/ML_Namond_20240606_3_QHS_0-QHS1007C_Sm0p8Sr0p2BaCuBO5_DC-17p7mg_powderXtalmix_MvT_50oe_20240607 (1).dat
[Header]
; MPMS3 Data File (default extension .dat)
; Copyright (c) 2007, Quantum Design, Inc. All rights reserved.
TITLE,
FILEOPENTIME,3926918416.23584,06/07/2024,10:40 am
BYAPP,MPMS3 w/ AC,1.0,1.1
INFO,MPMS3 Measurement Release 1.1.16 Build 419, MultiVu Release 2.3.4.15,APPNAME
INFO,Linear Motor Servo Controller,MOTOR_MODULE_NAME
INFO,3101-100 F0,MOTOR_HW_VERSION
INFO,MMC1118,MOTOR_SERIAL_NUMBER
INFO,01.04.28,MOTOR_SOFTWARE_VERSION
INFO,Quantum Design Squid Module,SQUID_MODULE_NAME
INFO,3101-501 B0,SQUID_HW_VERSION
INFO,SQM313,SQUID_SERIAL_NUMBER
INFO,01.03.04,SQUID_SOFTWARE_VERSION
INFO,Quantum Design VSM Oven,OVEN_MODULE_NAME
INFO,3101-201 A3,OVEN_HW_VERSION
INFO,OVB345,OVEN_SERIAL_NUMBER
INFO,01.07.07,OVEN_SOFTWARE_VERSION
INFO,SQUID AC,AC_MODULE_NAME
INFO,3101-401 G0,AC_HW_VERSION
INFO,SAC210,AC_SERIAL_NUMBER
INFO,SQUID AC 00.95.07,AC_SOFTWARE_VERSION
INFO,TCI318,COIL_SERIAL_NUMBER
INFO,0,MOMENT_UNITS
INFO,ML_Namond_20240606_3_QHS_0-QHS1007C_Sm0p8Sr0p2BaCuBO5_DC-17p7mg_powderXtalmix_MvT_50oe_20240607,SAMPLE_MATERIAL
INFO,,SAMPLE_COMMENT
INFO,,SAMPLE_MASS
INFO,,SAMPLE_VOLUME
INFO,,SAMPLE_MOLECULAR_WEIGHT
INFO,,SAMPLE_SIZE
INFO,,SAMPLE_SHAPE
INFO,Straw,SAMPLE_HOLDER
INFO,Standard,SAMPLE_HOLDER_DETAIL
INFO,65.6,SAMPLE_OFFSET
DATATYPE,COMMENT,1
DATATYPE,TIME,2
STARTUPAXIS,X,2
STARTUPAXIS,Y1,5
FIELDGROUP, VSM,2,3,4,5,6,8,9,10,11,14,15
FIELDGROUP, DC, 2,3,4,14,56,57,58,59,60,61,62,63,64,65,66,67,68,69
FIELDGROUP, AC, 2,3,4,11,16,17,18,19,20,21,22,23,24,25,26,27,28,29,30
STARTUPGROUP, All
[Data]
Comment,Time Stamp (sec),Temperature (K),Magnetic Field (Oe),Moment (emu),M. Std. Err. (emu),Transport Action,Averaging Time (sec),Frequency (Hz),Peak Amplitude (mm),Center Position (mm),Lockin Signal' (V),Lockin Signal (V),Range,M. Quad. Signal (emu),AC Moment (emu),AC M. Std Err. (emu),AC Phase (deg),AC Phase Std. Err. (deg),AC Susceptibility (emu/Oe),AC Suscept. Std Err. (emu/Oe),AC X' (emu/Oe),AC X' Std Err. (emu/Oe),AC X'' (emu/Oe),AC X'' Std Err. (emu/Oe),AC Drive (Oe),AC Frequency (Hz),AC Averaging Time (sec),AC Cycles,AC Range,AC Measure Type,AC Signal' (V),AC Signal'' (V),AC Trim Coil Ratio,AC Trim Coil Phase,Min. Temperature (K),Max. Temperature (K),Min. Field (Oe),Max. Field (Oe),Mass (grams),Motor Lag (deg),Pressure (Torr),Measure Count,Measurement Number,SQUID Status (code),Motor Status (code),Measure Status (code),Motor Current (amps),Motor Temp. (C),Temp. Status (code),Field Status (code),Chamber Status (code),Chamber Temp (K),Redirection State,Evercool Status,Average Temp (K),Rotation Angle (deg),Rotator state,DC Moment Fixed Ctr (emu),DC Moment Err Fixed Ctr (emu),DC Moment Free Ctr (emu),DC Moment Err Free Ctr (emu),DC Fixed Fit,DC Free Fit,DC Calculated Center (mm),DC Calculated Center Err (mm),DC Scan Length (mm),DC Scan Time (s),DC Number of Points,DC Squid Drift,DC Min V (V),DC Max V (V),DC Scans per Measure,Map 01,Map 02,Map 03,Map 04,Map 05,Map 06,Map 07,Map 08,Map 09,Map 10,Map 11,Map 12,Map 13,Map 14,Map 15,Map 16
,3926920323.3816,1.79873335361481,49.7855949401855,,,3,,,,25.721549987793,,,,,,,,,,,,,,,,,,,,,,,,,1.79873335361481,1.79873335361481,49.7855949401855,49.7855949401855,,,2.44683957099915,,0,,,,,,5,1,1,1.79873335361481,0,0,0,,,,,,,,,,,,,,,,,,,,,,,,,,,,,,,,,
,3926920369.3555,1.93052184581757,49.7855949401855,,,6,,,,25.7265615645196,,,1,,,,,,,,,,,,,,,,,,,,,,1.8573956489563,1.99366223812103,49.7855949401855,49.7855949401855,,,2.53113913536072,,1,0,0,0,0,29.3255138397217,6,1,1,2.00142931938171,0,4232058112,1.9234645485878,,,7.46482586512081E-6,3.72370383180076E-7,7.46482577449206E-6,3.72370371566874E-7,0.982260048389435,0.982261121273041,25.7258224487305,0,30,4,200,-7.83224677434191E-5,0.196203753352165,0.231816023588181,1,,,,,,,,,,,,,,,,
,3926920390.42149,2.22353208065033,49.7855949401855,,,6,,,,25.7265615645196,,,1,,,,,,,,,,,,,,,,,,,,,,2.15266394615173,2.2745144367218,49.7855949401855,49.7855949401855,,,2.70657825469971,,1,0,0,0,0,28.8367557525635,6,1,1,2.29440021514893,0,4232058336,2.21084462271796,,,7.04950816009017E-6,3.51635634516696E-7,7.04954984890995E-6,3.51635581622316E-7,0.985274255275726,0.985691905021667,25.7133655548096,5.29662609100342,30,4,200,-3.17389967676718E-5,0.197029009461403,0.230453714728355,1,,,,,,,,,,,,,,,,
,3926920411.4504,2.51730370521545,49.7855949401855,,,6,,,,25.7265615645196,,,1,,,,,,,,,,,,,,,,,,,,,,2.44564533233643,2.58680009841919,49.7855949401855,49.7855949401855,,,2.86737203598022,,1,0,0,0,0,29.8142719268799,6,1,1,2.59084725379944,0,4232057984,2.51631639003754,,,6.72880030439483E-6,3.35646264400267E-7,6.72903613232328E-6,3.35646675862371E-7,0.983783304691315,0.98602306842804,25.6954078674316,5.29715585708618,30,4,200,-2.20960209844634E-5,0.197490528225899,0.229353472590446,1,,,,,,,,,,,,,,,,
,3926920432.6505,2.81935393810272,49.7855949401855,,,6,,,,25.7265615645196,,,1,,,,,,,,,,,,,,,,,,,,,,2.74568819999695,2.88570713996887,49.7855949401855,49.7855949401855,,,3.01660966873169,,1,0,0,0,0,29.3255138397217,6,1,1,2.89536309242249,0,4232057920,2.81483607292175,,,6.47829037438282E-6,3.23154912472665E-7,6.47868252910227E-6,3.23155637869646E-7,0.982935130596161,0.986783981323242,25.6856460571289,0,30,4,200,-1.88065278052818E-5,0.197931915521622,0.22852411866188,1,,,,,,,,,,,,,,,,
,3926920453.8886,3.13107562065124,49.7855949401855,,,6,,,,25.7265615645196,,,1,,,,,,,,,,,,,,,,,,,,,,3.05525279045105,3.18951630592346,49.7855949401855,49.7855949401855,,,3.15676379203796,,1,0,0,0,0,29.3255138397217,6,1,1,3.20689845085144,0,4232058400,3.11963235007392,,,6.28477332235673E-6,3.13514993039704E-7,6.28533976720257E-6,3.13515759331296E-7,0.980596244335175,0.985815703868866,25.6764011383057,0,30,4,200,-1.08406193248811E-5,0.198320403695106,0.227997019886971,1,,,,,,,,,,,,,,,,
,3926920475.00034,3.4438636302948,49.7855949401855,,,6,,,,25.7265615645196,,,1,,,,,,,,,,,,,,,,,,,,,,3.36548852920532,3.51410126686096,49.7855949401855,49.7855949401855,,,3.28460264205933,,1,0,0,0,0,29.3255138397217,6,1,1,3.52223873138428,0,4232057952,3.43759844303131,,,6.1467739459516E-6,3.06635685407431E-7,6.14729277660276E-6,3.06636404142953E-7,0.979802012443543,0.984382927417755,25.6780166625977,0,30,4,200,2.79281939583598E-5,0.198917761445045,0.228248298168182,1,,,,,,,,,,,,,,,,
,3926920496.54591,3.74809861183167,49.7855949401855,,,6,,,,25.7265615645196,,,1,,,,,,,,,,,,,,,,,,,,,,3.67036652565002,3.8206205368042,49.7855949401855,49.7855949401855,,,3.39942693710327,,1,0,0,0,0,28.8367557525635,6,1,1,3.82583069801331,0,4232058336,3.74437594413757,,,6.04664900789301E-6,3.01642042404677E-7,6.04740508523533E-6,3.01643428118802E-7,0.979623019695282,0.986793398857117,25.6677513122559,5.29650020599365,30,4,200,1.92326024262002E-5,0.199820220470428,0.228400230407715,1,,,,,,,,,,,,,,,,
,3926920517.66135,4.05317890644073,49.7855949401855,,,6,,,,25.7265615645196,,,1,,,,,,,,,,,,,,,,,,,,,,3.9796736240387,4.12409496307373,49.7855949401855,49.7855949401855,,,3.50429153442383,,1,0,0,0,0,28.3479976654053,6,1,1,4.12668418884277,0,4232058176,4.04851107597351,,,5.97925101165382E-6,2.98291659568494E-7,5.98015477007174E-6,2.98293265478473E-7,0.977757692337036,0.985741198062897,25.6618461608887,5.0657525062561,30,4,200,7.93598519521765E-6,0.200527638196945,0.228779718279839,1,,,,,,,,,,,,,,,,
,3926920538.64137,4.36076211929321,49.7855949401855,,,6,,,,25.7265615645196,,,1,,,,,,,,,,,,,,,,,,,,,,4.2878098487854,4.41354179382324,49.7855949401855,49.7855949401855,,,3.60124516487122,,1,0,0,0,0.0002288818359375,28.8367557525635,6,1,1,4.43371438980103,0,4232057984,4.34686231613159,,,5.90121310830586E-6,2.9441806816165E-7,5.9019217216237E-6,2.94419022847246E-7,0.974965751171112,0.980171382427216,25.6685924530029,0,30,4,200,-5.93261538597289E-5,0.200800120830536,0.228918015956879,1,,,,,,,,,,,,,,,,
,3926920559.36761,4.66875958442688,49.7855949401855,,,6,,,,25.7265615645196,,,1,,,,,,,,,,,,,,,,,,,,,,4.59013795852661,4.73541355133057,49.7855949401855,49.7855949401855,,,3.69165062904358,,1,0,0,0,0,27.8592376708984,6,1,1,4.74738121032715,0,4232057824,4.66270155376858,,,5.90366029932104E-6,2.94525422107811E-7,5.90477114517845E-6,2.94527484308558E-7,0.977047026157379,0.987167239189148,25.654411315918,0,30,4,200,0.000110834676888771,0.202060893177986,0.230342596769333,1,,,,,,,,,,,,,,,,
,3926920580.20849,4.98497009277344,49.7855949401855,,,6,,,,25.7265615645196,,,1,,,,,,,,,,,,,,,,,,,,,,4.91172552108765,5.05821466445923,49.7855949401855,49.7855949401855,,,3.77971243858337,,1,0,0,0,0.015869140625,29.3255138397217,6,1,1,5.05821466445923,0,4232058208,4.98054456710815,,,5.89819497862022E-6,2.94253928469528E-7,5.89927250738084E-6,2.94255935690695E-7,0.976863384246826,0.986445367336273,25.6554718017578,5.2957272529602,30,4,200,1.40738711706945E-5,0.203293442726135,0.231314912438393,1,,,,,,,,,,,,,,,,
,3926920601.48547,5.30595541000366,49.7855949401855,,,6,,,,25.7265615645196,,,1,,,,,,,,,,,,,,,,,,,,,,5.22655534744263,5.37855052947998,49.7855949401855,49.7855949401855,,,3.86306810379028,,1,0,0,0,0,29.8142719268799,6,1,1,5.3853554725647,0,4232058144,5.29788551330566,,,5.89977250455808E-6,2.94368375888299E-7,5.90155440267827E-6,2.94371929460852E-7,0.97211754322052,0.985932648181915,25.6353359222412,0,30,4,200,2.32109996431973E-5,0.204196482896805,0.232217848300934,1,,,,,,,,,,,,,,,,
,3926920622.39228,5.62105941772461,49.7855949401855,,,6,,,,25.7265615645196,,,1,,,,,,,,,,,,,,,,,,,,,,5.54493379592895,5.69718503952026,49.7855949401855,49.7855949401855,,,3.939772605896,,1,0,0,0,0.0147247314453125,29.3255138397217,6,1,1,5.69718503952026,0,4232058176,5.61996746063232,,,5.94698387610682E-6,2.966883186728E-7,5.94801585025796E-6,2.96689791700582E-7,0.976823925971985,0.985852360725403,25.6569671630859,5.29614353179932,30,4,200,4.61105337308254E-5,0.204482555389404,0.232697188854218,1,,,,,,,,,,,,,,,,
,3926920643.65903,5.93653845787048,49.7855949401855,,,6,,,,25.7265615645196,,,1,,,,,,,,,,,,,,,,,,,,,,5.8661150932312,5.99476671218872,49.7855949401855,49.7855949401855,,,4.00575065612793,,1,0,0,0,0,28.8367557525635,6,1,1,6.00696182250977,0,4232058048,5.92908711433411,,,6.01962986546814E-6,3.00306476489297E-7,6.02071968418316E-6,3.00308356796474E-7,0.977704167366028,0.98784750699997,25.6557121276855,0,30,4,200,1.12134621303994E-5,0.204896286129951,0.233453005552292,1,,,,,,,,,,,,,,,,
,3926920664.73276,6.25056958198547,49.7855949401855,,,6,,,,25.7265615645196,,,1,,,,,,,,,,,,,,,,,,,,,,6.17223787307739,6.32890129089356,49.7855949401855,49.7855949401855,,,4.07081460952759,,1,0,0,0,0,28.3479976654053,6,1,1,6.32890129089356,0,4232058080,6.2445454120636,,,5.96170872985024E-6,2.97422430224056E-7,5.96285437996123E-6,2.97423613840697E-7,0.976889193058014,0.987434267997742,25.6530284881592,0,30,4,200,5.44820140930824E-5,0.205772802233696,0.233937814831734,1,,,,,,,,,,,,,,,,
,3926920685.65839,6.58134031295776,49.7855949401855,,,6,,,,25.7265615645196,,,1,,,,,,,,,,,,,,,,,,,,,,6.5011134147644,6.65143442153931,49.7855949401855,49.7855949401855,,,4.13654375076294,,1,0,0,0,0,29.3255138397217,6,1,1,6.66156721115112,0,4232057888,6.57694053649902,,,5.89010197765816E-6,2.93860464948687E-7,5.89138527690212E-6,2.93862424152265E-7,0.975412666797638,0.98649674654007,25.6486530303955,0,30,4,200,5.39255670446437E-5,0.206646248698235,0.234876602888107,1,,,,,,,,,,,,,,,,
,3926920706.78052,6.91338658332825,49.7855949401855,,,6,,,,25.7265615645196,,,1,,,,,,,,,,,,,,,,,,,,,,6.83066654205322,6.98644876480103,49.7855949401855,49.7855949401855,,,4.19862937927246,,1,0,0,0,0,28.3479976654053,6,1,1,6.99610662460327,0,4232058144,6.90533356666565,,,5.80519672548538E-6,2.89625219809571E-7,5.80637359911468E-6,2.89627089379648E-7,0.975317776203155,0.985273480415344,25.6514663696289,0,30,4,200,0.000140846357680857,0.208833485841751,0.237002179026604,1,,,,,,,,,,,,,,,,
,3926920728.13817,7.2492139339447,49.7855949401855,,,6,,,,25.7265615645196,,,1,,,,,,,,,,,,,,,,,,,,,,7.16975784301758,7.32205867767334,49.7855949401855,49.7855949401855,,,4.25961542129517,,1,0,0,0,0.015716552734375,29.3255138397217,6,1,1,7.32867002487183,0,4232058272,7.24330916404724,,,5.73051635736529E-6,2.85916932865023E-7,5.73223852827491E-6,2.85919480117029E-7,0.972934603691101,0.987766921520233,25.6350364685059,0,30,4,200,0.000102218393294606,0.212541192770004,0.240363210439682,1,,,,,,,,,,,,,,,,
,3926920749.07719,7.58030486106873,49.7855949401855,,,6,,,,25.7265615645196,,,1,,,,,,,,,,,,,,,,,,,,,,7.50257968902588,7.64137077331543,49.7855949401855,49.7855949401855,,,4.31427145004272,,1,0,0,0,0,28.8367557525635,6,1,1,7.6611590385437,0,4232058080,7.5701617134942,,,5.66351199055355E-6,2.82580062964567E-7,5.66522926462805E-6,2.82582736092863E-7,0.972127258777618,0.986224949359894,25.6346664428711,5.29520320892334,30,4,200,0.000177408859599382,0.215708404779434,0.243640586733818,1,,,,,,,,,,,,,,,,
,3926920769.93281,7.90880990028381,49.7855949401855,,,6,,,,25.7265615645196,,,1,,,,,,,,,,,,,,,,,,,,,,7.82892036437988,7.96420192718506,49.7855949401855,49.7855949401855,,,4.36774682998657,,1,0,0,0,0,28.8367557525635,6,1,1,7.98869943618774,0,4232057952,7.89572334289551,,,5.5872159472493E-6,2.78784811054907E-7,5.5891056050666E-6,2.78788078319566E-7,0.9706791639328,0.985605895519257,25.6296806335449,0,30,4,200,0.000151871587149799,0.219782665371895,0.247023791074753,1,,,,,,,,,,,,,,,,
,3926920790.84724,8.2451753616333,49.7855949401855,,,6,,,,25.7265615645196,,,1,,,,,,,,,,,,,,,,,,,,,,8.16098308563232,8.31441974639893,49.7855949401855,49.7855949401855,,,4.41800594329834,,1,0,0,0,0.013885498046875,28.8367557525635,6,1,1,8.32592391967773,0,4232058112,8.23694753646851,,,5.51958610991115E-6,2.75414012270268E-7,5.52159349446384E-6,2.75417381489732E-7,0.97022557258606,0.986430823802948,25.6260623931885,0,30,4,200,0.000155759524204768,0.223032504320145,0.24986258149147,1,,,,,,,,,,,,,,,,
,3926920811.93693,8.57993221282959,49.7855949401855,,,6,,,,25.7265615645196,,,1,,,,,,,,,,,,,,,,,,,,,,8.50020122528076,8.65246200561523,49.7855949401855,49.7855949401855,,,4.46786832809448,,1,0,0,0,0,28.8367557525635,6,1,1,8.65966320037842,0,4232058176,8.57512168884277,,,5.47743921767571E-6,2.73354971740676E-7,5.48024571008294E-6,2.7335972021706E-7,0.965243697166443,0.985202491283417,25.6072425842285,5.29431629180908,30,4,200,0.000180222617927939,0.226598545908928,0.253644317388535,1,,,,,,,,,,,,,,,,
,3926920833.33046,8.92277336120605,49.7855949401855,,,6,,,,25.7265615645196,,,1,,,,,,,,,,,,,,,,,,,,,,8.8354663848877,8.9913854598999,49.7855949401855,49.7855949401855,,,4.51543426513672,,1,0,0,0,0,29.3255138397217,6,1,1,9.00909614562988,0,4232058272,8.91300506591797,,,5.41071974658632E-6,2.70033411506969E-7,5.41364972355302E-6,2.70037809608468E-7,0.964387595653534,0.985205948352814,25.6036643981934,5.29405641555786,30,4,200,0.000157896807650104,0.230699777603149,0.256999492645264,1,,,,,,,,,,,,,,,,
,3926920854.63456,9.25926494598389,49.7855949401855,,,6,,,,25.7265615645196,,,1,,,,,,,,,,,,,,,,,,,,,,9.1805419921875,9.33798789978027,49.7855949401855,49.7855949401855,,,4.55916786193848,,1,0,0,0,0,28.8367557525635,6,1,1,9.34872436523437,0,4232058016,9.25760297775269,,,5.35543299035389E-6,2.67273841521419E-7,5.35841800006635E-6,2.67278861745454E-7,0.964429438114166,0.986246228218079,25.6021385192871,5.29387331008911,30,4,200,0.000108504464151338,0.233910083770752,0.259558916091919,1,,,,,,,,,,,,,,,,
,3926920875.89363,9.60039567947388,49.7855949401855,,,6,,,,25.7265615645196,,,1,,,,,,,,,,,,,,,,,,,,,,9.52213001251221,9.67512798309326,49.7855949401855,49.7855949401855,,,4.6023006439209,,1,0,0,0,0,28.8367557525635,6,1,1,9.67866134643555,0,4232058048,9.59461193084717,,,5.30139529039564E-6,2.64594954351307E-7,5.30467936059457E-6,2.64601051109281E-7,0.962571501731873,0.985530197620392,25.5956363677979,0,30,4,200,0.000118736970762257,0.237133696675301,0.26265686750412,1,,,,,,,,,,,,,,,,
,3926920897.19074,9.94389200210571,49.7855949401855,,,6,,,,25.7265615645196,,,1,,,,,,,,,,,,,,,,,,,,,,9.8638277053833,10.0239562988281,49.7855949401855,49.7855949401855,,,4.64076280593872,,1,0,0,0,0,29.8142719268799,6,1,1,10.0239562988281,0,4232058016,9.93888750076294,,,5.24808549035627E-6,2.61939995316248E-7,5.25143442217558E-6,2.61946306438381E-7,0.961988747119904,0.985227644443512,25.5936698913574,0,30,4,200,0.000121399534691591,0.239587754011154,0.264966189861298,1,,,,,,,,,,,,,,,,
,3926920918.11659,10.2813882827759,49.7855949401855,,,6,,,,25.7265615645196,,,1,,,,,,,,,,,,,,,,,,,,,,10.1970071792603,10.3412208557129,49.7855949401855,49.7855949401855,,,4.67798614501953,,1,0,0,0,0,28.8367557525635,6,1,1,10.3657693862915,0,4232057984,10.265234735277,,,5.18979742174092E-6,2.59043471023019E-7,5.19344765820288E-6,2.59050632083611E-7,0.960717916488647,0.986095249652863,25.587158203125,5.2926082611084,30,4,200,0.000110735607449897,0.242312371730804,0.267383635044098,1,,,,,,,,,,,,,,,,
,3926920938.97975,10.6161208152771,49.7855949401855,,,6,,,,25.7265615645196,,,1,,,,,,,,,,,,,,,,,,,,,,10.5363626480103,10.6890811920166,49.7855949401855,49.7855949401855,,,4.71612930297852,,1,0,0,0,0,28.8367557525635,6,1,1,10.6958789825439,0,4232058016,10.6110772132874,,,5.14920759789531E-6,2.57025189120783E-7,5.15285082674068E-6,2.57032175713876E-7,0.959968745708466,0.984393656253815,25.5866355895996,0,30,4,200,0.000100521639978979,0.244559988379478,0.269707202911377,1,,,,,,,,,,,,,,,,
,3926920959.8869,10.951735496521,49.7855949401855,,,6,,,,25.7265615645196,,,1,,,,,,,,,,,,,,,,,,,,,,10.8716268539429,11.0121450424194,49.7855949401855,49.7855949401855,,,4.75143384933472,,1,0,0,0,0,28.8367557525635,6,1,1,11.0318441390991,0,4232058304,10.9391159481472,,,5.1064912018036E-6,2.54906254030353E-7,5.11048240281397E-6,2.54914608270396E-7,0.958686649799347,0.985467314720154,25.5798320770264,0,30,4,200,0.000197989458683878,0.247390046715736,0.272698044776917,1,,,,,,,,,,,,,,,,
,3926920981.06117,11.2984781265259,49.7855949401855,,,6,,,,25.7265615645196,,,1,,,,,,,,,,,,,,,,,,,,,,11.215968132019,11.3619699478149,49.7855949401855,49.7855949401855,,,4.78681898117065,,1,0,0,0,0,28.8367557525635,6,1,1,11.3809881210327,0,4232058080,11.2880450248718,,,5.06470494819488E-6,2.52829869010852E-7,5.06878787876722E-6,2.52837713191812E-7,0.957786917686462,0.984706163406372,25.5772190093994,5.29268789291382,30,4,200,8.14040540717542E-5,0.25050014257431,0.275083810091019,1,,,,,,,,,,,,,,,,
,3926921011.11194,11.778064250946,49.7855949401855,,,6,,,,25.7316547995914,,,1,,,,,,,,,,,,,,,,,,,,,,11.6955690383911,11.848560333252,49.7855949401855,49.7855949401855,,,4.83139848709106,,1,0,0,0,0,28.8367557525635,6,1,1,11.860559463501,0,4232058048,11.7709505081177,,,4.98935390792351E-6,2.49108045902719E-7,4.99405887607052E-6,2.49118661963677E-7,0.954172611236572,0.982609570026398,25.5706691741943,0,30,4,200,-7.56728195483447E-6,0.253311157226562,0.27716401219368,1,,,,,,,,,,,,,,,,
,3926921032.63835,12.1272406578064,49.7855949401855,,,6,,,,25.7316547995914,,,1,,,,,,,,,,,,,,,,,,,,,,12.0465431213379,12.2079381942749,49.7855949401855,49.7855949401855,,,4.86296367645264,,1,0,0,0,0.01556396484375,28.8367557525635,6,1,1,12.2079381942749,0,4232058272,12.1247518539429,,,4.97368717073802E-6,2.4831055942682E-7,4.97816269371544E-6,2.4831994866191E-7,0.955535471439362,0.984007120132446,25.5741882324219,0,30,4,200,9.27652872633189E-5,0.254068404436111,0.278186559677124,1,,,,,,,,,,,,,,,,
,3926921053.61972,12.4658136367798,49.7855949401855,,,6,,,,25.7316547995914,,,1,,,,,,,,,,,,,,,,,,,,,,12.3830127716064,12.5372285842896,49.7855949401855,49.7855949401855,,,4.89211654663086,,1,0,0,0,0,29.3255138397217,6,1,1,12.5486145019531,0,4232058112,12.4613079071045,,,4.9278618230469E-6,2.46080724672271E-7,4.93337630739776E-6,2.4609281726861E-7,0.950530648231506,0.982347428798676,25.5561561584473,0,30,4,200,9.91928900475614E-5,0.255871295928955,0.279708623886108,1,,,,,,,,,,,,,,,,
,3926921074.72769,12.8127427101135,49.7855949401855,,,6,,,,25.7316547995914,,,1,,,,,,,,,,,,,,,,,,,,,,12.7327299118042,12.8854541778564,49.7855949401855,49.7855949401855,,,4.92108058929443,,1,0,0,0,0,28.8367557525635,6,1,1,12.8927555084229,0,4232058304,12.8058775901794,,,4.90873257928542E-6,2.45101121978741E-7,4.91386867067604E-6,2.45112811785686E-7,0.952575087547302,0.984016597270966,25.5621490478516,0,30,4,200,5.64222646062262E-5,0.257387638092041,0.28102058172226,1,,,,,,,,,,,,,,,,
,3926921096.11344,13.1560168266296,49.7855949401855,,,6,,,,25.7316547995914,,,1,,,,,,,,,,,,,,,,,,,,,,13.0757923126221,13.2126693725586,49.7855949401855,49.7855949401855,,,4.94905042648315,,1,0,0,0,0,30.3030319213867,6,1,1,13.24001121521,0,4232058304,13.1458249621921,,,4.87753508701814E-6,2.43571716805285E-7,4.88317796529714E-6,2.43584188812271E-7,0.95018345117569,0.983427286148071,25.5532417297363,5.29089021682739,30,4,200,6.38558194623329E-5,0.258859038352966,0.282320588827133,1,,,,,,,,,,,,,,,,
,3926921117.10935,13.4986538887024,49.7855949401855,,,6,,,,25.7316547995914,,,1,,,,,,,,,,,,,,,,,,,,,,13.4156293869019,13.5786285400391,49.7855949401855,49.7855949401855,,,4.97620391845703,,1,0,0,0,0,29.3255138397217,6,1,1,13.5816783905029,0,4232058112,13.4951921463013,,,4.84320986756091E-6,2.41823079671569E-7,4.84789954114278E-6,2.4183366988604E-7,0.953134715557098,0.981274724006653,25.5684185028076,0,30,4,200,2.24519990297267E-5,0.260257005691528,0.283281922340393,1,,,,,,,,,,,,,,,,
,3926921138.21339,13.8402552604675,49.7855949401855,,,6,,,,25.7316547995914,,,1,,,,,,,,,,,,,,,,,,,,,,13.7627477645874,13.9164981842041,49.7855949401855,49.7855949401855,,,5.85158348083496,,1,0,0,0,0,28.8367557525635,6,1,1,13.9224252700806,0,4232057760,13.8396297454834,,,4.81134829758985E-6,2.40269471176548E-7,4.81696522887929E-6,2.40282007629638E-7,0.949941754341126,0.983273446559906,25.5525169372559,0,30,4,200,6.17885161773302E-5,0.261515200138092,0.284703820943832,1,,,,,,,,,,,,,,,,
,3926921159.3507,14.1821718215942,49.7855949401855,,,6,,,,25.7316547995914,,,1,,,,,,,,,,,,,,,,,,,,,,14.096905708313,14.2598361968994,49.7855949401855,49.7855949401855,,,5.8879566192627,,1,0,0,0,0,28.8367557525635,6,1,1,14.2674379348755,0,4232058080,14.1793640136719,,,4.78566824803832E-6,2.38996503189479E-7,4.79148728077842E-6,2.39010248991246E-7,0.949164152145386,0.983500361442566,25.5490646362305,5.29055023193359,30,4,200,5.41209847142454E-5,0.262812823057175,0.285738885402679,1,,,,,,,,,,,,,,,,
,3926921180.73981,14.5357413291931,49.7855949401855,,,6,,,,25.7316547995914,,,1,,,,,,,,,,,,,,,,,,,,,,14.4544839859009,14.6117095947266,49.7855949401855,49.7855949401855,,,5.91016912460327,,1,0,0,0,0,28.8367557525635,6,1,1,14.6169986724854,0,4232058176,14.5305769920349,,,4.75830771319308E-6,2.37668893480411E-7,4.7648030071205E-6,2.37683997472355E-7,0.946060717105865,0.982322037220001,25.5382061004639,0,30,4,200,4.28352068411186E-5,0.264356642961502,0.287036508321762,1,,,,,,,,,,,,,,,,
,3926921201.7877,14.8741097450256,49.7855949401855,,,6,,,,25.7316547995914,,,1,,,,,,,,,,,,,,,,,,,,,,14.7879781723022,14.9535493850708,49.7855949401855,49.7855949401855,,,5.92987108230591,,1,0,0,0,0,28.8367557525635,6,1,1,14.960241317749,0,4232058144,14.8713549613953,,,4.74467533674504E-6,2.36990924626993E-7,4.75122102910855E-6,2.3700532995662E-7,0.945826470851898,0.98258364200592,25.5367755889893,0,30,4,200,-5.36921725142747E-5,0.265491813421249,0.287931025028229,1,,,,,,,,,,,,,,,,
,3926921222.57564,15.2432193756104,49.7855949401855,,,6,,,,25.7316547995914,,,1,,,,,,,,,,,,,,,,,,,,,,15.1330623626709,15.3303442001343,49.7855949401855,49.7855949401855,,,5.96548080444336,,1,0,0,0,0,28.8367557525635,6,1,1,15.3533763885498,0,4232058016,15.2206015057034,,,4.71628000139901E-6,2.39188536842922E-7,4.74931077003609E-6,2.39265853434827E-7,0.818745732307434,0.858959376811981,25.2914562225342,0,30,4,200,0.000364739244105294,0.268201768398285,0.292897939682007,1,,,,,,,,,,,,,,,,
,3926921243.50958,15.6163501739502,49.7855949401855,,,6,,,,25.7316547995914,,,1,,,,,,,,,,,,,,,,,,,,,,15.5377292633057,15.6945877075195,49.7855949401855,49.7855949401855,,,5.97093152999878,,1,0,0,0,0,28.8367557525635,2,1,1,15.7002506256104,0,4232058080,15.6220175743103,,,4.68900533198953E-6,2.34254864858403E-7,4.69627989930168E-6,2.34271527805729E-7,0.942421972751617,0.980960190296173,25.5251502990723,5.28834676742554,30,4,200,5.71293785469607E-5,0.267628610134125,0.290555953979492,1,,,,,,,,,,,,,,,,
,3926921264.35641,15.9652080535889,49.7855949401855,,,6,,,,25.7316547995914,,,1,,,,,,,,,,,,,,,,,,,,,,15.8830413818359,16.0396022796631,49.7855949401855,49.7855949401855,,,5.97833013534546,,1,0,0,0,0,28.8367557525635,2,1,1,16.0473747253418,0,4232057888,15.9605648040771,,,4.66000082433325E-6,2.32757073083073E-7,4.66639777406539E-6,2.32771438543125E-7,0.946177065372467,0.983239352703095,25.5373592376709,5.28981399536133,30,4,200,-8.53067285788711E-6,0.268322318792343,0.290375709533691,1,,,,,,,,,,,,,,,,
,3926921285.35014,16.3103466033936,49.7855949401855,,,6,,,,25.7316547995914,,,1,,,,,,,,,,,,,,,,,,,,,,16.234582901001,16.3647537231445,49.7855949401855,49.7855949401855,,,5.98529529571533,,1,0,0,0,0,28.8367557525635,2,1,1,16.3861103057861,0,4232058208,16.2970339457194,,,4.64280330070419E-6,2.31929523403661E-7,4.6498474931572E-6,2.3194449450682E-7,0.943725645542145,0.983607053756714,25.5272102355957,0,30,4,200,4.10944376199041E-5,0.268312633037567,0.290518701076508,1,,,,,,,,,,,,,,,,
,3926921306.36957,16.6490364074707,49.7855949401855,,,6,,,,25.7316547995914,,,1,,,,,,,,,,,,,,,,,,,,,,16.5656929016113,16.7323799133301,49.7855949401855,49.7855949401855,,,5.98684644699097,,1,0,0,0,0,28.8367557525635,2,1,1,16.7323799133301,0,4232058144,16.6504652023315,,,4.63106994197836E-6,2.31330422433446E-7,4.63753135769648E-6,2.3134426075577E-7,0.944723129272461,0.980219960212707,25.5353965759277,0,30,4,200,-1.12601583168725E-5,0.268337160348892,0.29014778137207,1,,,,,,,,,,,,,,,,
,3926921327.9338,17.0093011856079,49.7855949401855,,,6,,,,25.7316547995914,,,1,,,,,,,,,,,,,,,,,,,,,,16.9264030456543,17.0861740112305,49.7855949401855,49.7855949401855,,,6.01308298110962,,1,0,0,0,0,28.8367557525635,2,1,1,17.0921993255615,0,4232058112,17.0023241043091,,,4.59749617849043E-6,2.29689296485409E-7,4.60487984122441E-6,2.29705412079528E-7,0.941971898078918,0.982571482658386,25.5213279724121,0,30,4,200,-3.34654572498039E-7,0.268512427806854,0.290325254201889,1,,,,,,,,,,,,,,,,
,3926921348.94071,17.3534212112427,49.7855949401855,,,6,,,,25.7316547995914,,,1,,,,,,,,,,,,,,,,,,,,,,17.2730350494385,17.4270362854004,49.7855949401855,49.7855949401855,,,6.02074527740478,,1,0,0,0,0,28.8367557525635,2,1,1,17.4338073730469,0,4232057952,17.3501922607422,,,4.58407244430838E-6,2.29055448101792E-7,4.59211886762511E-6,2.2907294397809E-7,0.939274966716766,0.981573820114136,25.5117263793945,5.28758811950684,30,4,200,3.04568984574871E-5,0.268736124038696,0.29042786359787,1,,,,,,,,,,,,,,,,
,3926921370.02683,17.69420337677,49.7855949401855,,,6,,,,25.7316547995914,,,1,,,,,,,,,,,,,,,,,,,,,,17.6077842712402,17.7688770294189,49.7855949401855,49.7855949401855,,,6.04233026504517,,1,0,0,0,0,28.8367557525635,2,1,1,17.7806224822998,0,4232058208,17.6904390335083,,,4.5613787292998E-6,2.27900175125751E-7,4.568987186073E-6,2.27916093313353E-7,0.940828800201416,0.982286632061005,25.5170860290527,0,30,4,200,-1.63100648933323E-5,0.268713295459747,0.29033550620079,1,,,,,,,,,,,,,,,,
,3926921391.06696,18.0417633056641,49.7855949401855,,,6,,,,25.7316547995914,,,1,,,,,,,,,,,,,,,,,,,,,,17.9601421356201,18.1192417144775,49.7855949401855,49.7855949401855,,,6.05363035202026,,1,0,0,0,0,28.8367557525635,2,1,1,18.123384475708,0,4232058080,18.0396030426025,,,4.54363177142024E-6,2.2701176546947E-7,4.55111800724547E-6,2.2702744669462E-7,0.940953016281128,0.981610476970673,25.5183868408203,0,30,4,200,1.13629375846358E-5,0.268524467945099,0.290136963129044,1,,,,,,,,,,,,,,,,
,3926921412.06655,18.389669418335,49.7855949401855,,,6,,,,25.7316547995914,,,1,,,,,,,,,,,,,,,,,,,,,,18.307975769043,18.4648151397705,49.7855949401855,49.7855949401855,,,6.06883955001831,,1,0,0,0,0,28.3479976654053,2,1,1,18.471363067627,0,4232057984,18.3845560073853,,,4.52704804698112E-6,2.26220564539E-7,4.53523276492316E-6,2.26237590732204E-7,0.938234925270081,0.981025815010071,25.5082359313965,0,30,4,200,6.82599647916504E-6,0.268569380044937,0.290157794952393,1,,,,,,,,,,,,,,,,
,3926921432.91925,18.7318782806396,49.7855949401855,,,6,,,,25.7316547995914,,,1,,,,,,,,,,,,,,,,,,,,,,18.6502819061279,18.7945728302002,49.7855949401855,49.7855949401855,,,6.08516502380371,,1,0,0,0,0,28.8367557525635,2,1,1,18.8134746551514,0,4232058240,18.7203229268392,,,4.51433618585619E-6,2.25560327413387E-7,4.52208179247205E-6,2.2557754017674E-7,0.940051794052124,0.981994211673737,25.5143070220947,5.28724145889282,30,4,200,-1.46807706187246E-5,0.268532186746597,0.290003627538681,1,,,,,,,,,,,,,,,,
,3926921453.88897,19.0726938247681,49.7855949401855,,,6,,,,25.7316547995914,,,1,,,,,,,,,,,,,,,,,,,,,,18.9896049499512,19.1487331390381,49.7855949401855,49.7855949401855,,,6.09462690353394,,1,0,0,0,0,29.3255138397217,2,1,1,19.1627960205078,0,4232058208,19.0706541061401,,,4.49656411916197E-6,2.24677925577809E-7,4.50422767341992E-6,2.24693336605491E-7,0.939632713794708,0.980448842048645,25.5144863128662,0,30,4,200,3.85465364161064E-6,0.26859986782074,0.289914608001709,1,,,,,,,,,,,,,,,,
,3926921475.06444,19.4220056533813,49.7855949401855,,,6,,,,25.7316547995914,,,1,,,,,,,,,,,,,,,,,,,,,,19.3363380432129,19.4996471405029,49.7855949401855,49.7855949401855,,,6.11014223098755,,1,0,0,0,0.021820068359375,28.3479976654053,2,1,1,19.5076732635498,0,4232058048,19.4166801452637,,,4.47593555291689E-6,2.23667594181087E-7,4.48418342217828E-6,2.23686251924796E-7,0.938143968582153,0.982160568237305,25.5065536499023,0,30,4,200,1.67531754868833E-6,0.268727540969849,0.290009349584579,1,,,,,,,,,,,,,,,,
,3926921496.20161,19.7680854797363,49.7855949401855,,,6,,,,25.7316547995914,,,1,,,,,,,,,,,,,,,,,,,,,,19.6836566925049,19.8490142822266,49.7855949401855,49.7855949401855,,,6.1167140007019,,1,0,0,0,0,29.3255138397217,2,1,1,19.8525142669678,0,4232058304,19.7634649276733,,,4.46156702491819E-6,2.22957610201668E-7,4.46989949466152E-6,2.22975827923912E-7,0.937576055526733,0.981670200824738,25.5048789978027,0,30,4,200,-3.09015813400038E-5,0.268738001585007,0.289975136518478,1,,,,,,,,,,,,,,,,
,3926921517.28502,20.1198387145996,49.7855949401855,,,6,,,,25.7316547995914,,,1,,,,,,,,,,,,,,,,,,,,,,20.0457916259766,20.1829280853271,49.7855949401855,49.7855949401855,,,6.1346607208252,,1,0,0,0,0.0156402587890625,28.8367557525635,2,1,1,20.2025890350342,0,4232058336,20.1111323038737,,,4.44342190393241E-6,2.22026259543897E-7,4.45112173422096E-6,2.22042457967501E-7,0.939362704753876,0.980848610401154,25.5129833221436,0,30,4,200,2.34506733249873E-5,0.267912894487381,0.2890345454216,1,,,,,,,,,,,,,,,,
,3926921538.23398,20.4623537063599,49.7855949401855,,,6,,,,25.7316547995914,,,1,,,,,,,,,,,,,,,,,,,,,,20.3798751831055,20.5448322296143,49.7855949401855,49.7855949401855,,,6.14772987365723,,1,0,0,0,0.013885498046875,28.8367557525635,2,1,1,20.5477657318115,0,4232058240,20.4622135162354,,,4.43912789921042E-6,2.21838584458862E-7,4.44730953338273E-6,2.21856669367698E-7,0.937407672405243,0.979857981204987,25.5062446594238,5.28656196594238,30,4,200,-2.90685093204956E-5,0.268099784851074,0.289149910211563,1,,,,,,,,,,,,,,,,
,3926921559.1906,20.8042526245117,49.7855949401855,,,6,,,,25.7316547995914,,,1,,,,,,,,,,,,,,,,,,,,,,20.7218627929687,20.877420425415,49.7855949401855,49.7855949401855,,,6.16240644454956,,1,0,0,0,0.013885498046875,28.8367557525635,2,1,1,20.8905830383301,0,4232057888,20.8012756771511,,,4.41793748949817E-6,2.20802236877859E-7,4.42663606099713E-6,2.20821148194887E-7,0.935796916484833,0.980821847915649,25.4986534118652,,30,4,200,1.66852842085063E-5,0.268107891082764,0.289133042097092,1,,,,,,,,,,,,,,,,
,3926921580.16687,21.1477174758911,49.7855949401855,,,6,,,,25.7316547995914,,,1,,,,,,,,,,,,,,,,,,,,,,21.0629081726074,21.2069034576416,49.7855949401855,49.7855949401855,,,6.17089128494263,,1,0,0,0,0,28.8367557525635,2,1,1,21.2325267791748,0,4232058400,21.1361643473307,,,4.41210204715117E-6,2.20522891495964E-7,4.42079869993077E-6,2.20541530515068E-7,0.934939205646515,0.978262543678284,25.4983024597168,0,30,4,200,-2.10951893677702E-5,0.268105566501617,0.289145886898041,1,,,,,,,,,,,,,,,,
,3926921601.13155,21.4935092926025,49.7855949401855,,,6,,,,25.7316547995914,,,1,,,,,,,,,,,,,,,,,,,,,,21.4094753265381,21.5698013305664,49.7855949401855,49.7855949401855,,,6.19497489929199,,1,0,0,0,0,28.8367557525635,2,1,1,21.577543258667,0,4232058208,21.4909021377563,,,4.3963797254033E-6,2.1973913889158E-7,4.40532830578238E-6,2.19759061531918E-7,0.934797763824463,0.980637848377228,25.4948902130127,5.28483819961548,30,4,200,1.36513135657879E-5,0.268212229013443,0.289182186126709,1,,,,,,,,,,,,,,,,
,3926921622.16422,21.8353958129883,49.7855949401855,,,6,,,,25.7316547995914,,,1,,,,,,,,,,,,,,,,,,,,,,21.7531185150146,21.8916416168213,49.7855949401855,49.7855949401855,,,6.20487546920776,,1,0,0,0,0,28.8367557525635,2,1,1,21.9176731109619,0,4232058336,21.8208283318414,,,4.38267991231092E-6,2.19065383903082E-7,4.39169043621179E-6,2.19084344422929E-7,0.934033989906311,0.97935152053833,25.4933013916016,0,30,4,200,-2.00709600903792E-5,0.268365204334259,0.289213508367538,1,,,,,,,,,,,,,,,,
,3926921643.57443,22.1875743865967,49.7855949401855,,,6,,,,25.7316547995914,,,1,,,,,,,,,,,,,,,,,,,,,,22.0980434417725,22.2483806610107,49.7855949401855,49.7855949401855,,,6.21772909164429,,1,0,0,0,0,28.8367557525635,2,1,1,22.2771053314209,0,4232058304,22.1745202806261,,,4.37094201774432E-6,2.18484644879574E-7,4.3802278465531E-6,2.18504748705338E-7,0.933624446392059,0.981157958507538,25.4896335601807,5.28476238250732,30,4,200,1.65393373663392E-6,0.268311828374863,0.289079159498215,1,,,,,,,,,,,,,,,,
,3926921664.43387,22.5303363800049,49.7855949401855,,,6,,,,25.7316547995914,,,1,,,,,,,,,,,,,,,,,,,,,,22.4461002349854,22.6012477874756,49.7855949401855,49.7855949401855,,,6.24753665924072,,1,0,0,0,0,29.3255138397217,2,1,1,22.6145725250244,0,4232058240,22.5147471957737,,,4.3546141736378E-6,2.17652614229435E-7,4.36351019086989E-6,2.17672079415167E-7,0.934720993041992,0.980826497077942,25.4944534301758,0,30,4,200,-1.86977340490557E-5,0.26805305480957,0.288816332817078,1,,,,,,,,,,,,,,,,
,3926921685.52001,22.8694534301758,49.7855949401855,,,6,,,,25.7316547995914,,,1,,,,,,,,,,,,,,,,,,,,,,22.7840938568115,22.9409351348877,49.7855949401855,49.7855949401855,,,6.26255321502686,,1,0,0,0,0,29.3255138397217,2,1,1,22.95481300354,0,4232057920,22.8631683349609,,,4.35002902795075E-6,2.17404568467281E-7,4.35842654607914E-6,2.17422331830865E-7,0.936058282852173,0.979923367500305,25.5008697509766,0,30,4,200,2.00236063392367E-5,0.268192946910858,0.288789540529251,1,,,,,,,,,,,,,,,,
,3926921706.55111,23.2079772949219,49.7855949401855,,,6,,,,25.7316547995914,,,1,,,,,,,,,,,,,,,,,,,,,,23.1209106445313,23.2864570617676,49.7855949401855,49.7855949401855,,,6.28038644790649,,1,0,0,0,0,28.3479976654053,2,1,1,23.2950439453125,0,4232058048,23.2043134689331,,,4.33974645208368E-6,2.16915964557497E-7,4.34834966261338E-6,2.16934306159447E-7,0.934273898601532,0.976819932460785,25.4975070953369,5.2854175567627,30,4,200,0.000676243682391942,0.278405487537384,0.302985727787018,1,,,,,,,,,,,,,,,,
,3926921727.70008,23.5717754364014,49.7855949401855,,,6,,,,25.7316547995914,,,1,,,,,,,,,,,,,,,,,,,,,,23.4872817993164,23.6493663787842,49.7855949401855,49.7855949401855,,,6.29028940200806,,1,0,0,0,0.019989013671875,29.3255138397217,2,1,1,23.6562690734863,0,4232058112,23.566400718689,,,4.3044394243418E-6,2.1524846969901E-7,4.31499346543409E-6,2.1527169005216E-7,0.92774909734726,0.976512551307678,25.4718399047852,0,30,4,200,0.000407231185818091,0.291772842407227,0.314745306968689,1,,,,,,,,,,,,,,,,
,3926921748.86656,23.9195709228516,49.7855949401855,,,6,,,,25.7316547995914,,,1,,,,,,,,,,,,,,,,,,,,,,23.841495513916,23.9724636077881,49.7855949401855,49.7855949401855,,,6.30016040802002,,1,0,0,0,0,28.8367557525635,2,1,1,23.9976463317871,0,4232058144,23.9055014716254,,,4.31422682080216E-6,2.15685914798527E-7,4.32394529311892E-6,2.15706410412258E-7,0.9311483502388,0.978987574577332,25.4822788238525,5.28429889678955,30,4,200,1.35341642817366E-5,0.296076864004135,0.316569000482559,1,,,,,,,,,,,,,,,,
,3926921770.18352,24.2634782791138,49.7855949401855,,,6,,,,25.7316547995914,,,1,,,,,,,,,,,,,,,,,,,,,,24.1790657043457,24.3413009643555,49.7855949401855,49.7855949401855,,,6.31803035736084,,1,0,0,0,0,28.8367557525635,2,1,1,24.3515338897705,0,4232058208,24.2604789733887,,,4.29867370663465E-6,2.14902293711215E-7,4.30819946374777E-6,2.14922881524654E-7,0.931558907032013,0.978561162948608,25.4843711853027,0,30,4,200,-3.10494979203213E-5,0.296395242214203,0.316860437393188,1,,,,,,,,,,,,,,,,
,3926921790.92906,24.6045351028442,49.7855949401855,,,6,,,,25.7316547995914,,,1,,,,,,,,,,,,,,,,,,,,,,24.5229549407959,24.6685352325439,49.7855949401855,49.7855949401855,,,6.32475852966309,,1,0,0,0,0.0203704833984375,28.8367557525635,2,1,1,24.6861152648926,0,4232058144,24.5951069725884,,,4.28743196207351E-6,2.14336070676292E-7,4.29702006822268E-6,2.14356856409561E-7,0.931841671466827,0.980440139770508,25.4834232330322,0,30,4,200,-2.92034314952616E-6,0.29623731970787,0.316592812538147,1,,,,,,,,,,,,,,,,
,3926921812.08438,24.9527111053467,49.7855949401855,,,6,,,,25.7316547995914,,,1,,,,,,,,,,,,,,,,,,,,,,24.8727207183838,25.0274982452393,49.7855949401855,49.7855949401855,,,6.33139038085938,,1,0,0,0,0,29.3255138397217,2,1,1,25.0327014923096,0,4232058368,24.9498743057251,,,4.28830757814374E-6,2.14383521483959E-7,4.29784001054525E-6,2.14404198973269E-7,0.931591689586639,0.978961288928986,25.4840278625488,0,30,4,200,-2.5736198949744E-5,0.296158134937286,0.316722393035889,1,,,,,,,,,,,,,,,,
,3926921833.2498,25.2978429794312,49.7855949401855,,,6,,,,25.7316547995914,,,1,,,,,,,,,,,,,,,,,,,,,,25.2164115905762,25.3584957122803,49.7855949401855,49.7855949401855,,,6.34962272644043,,1,0,0,0,0.013885498046875,28.3479976654053,2,1,1,25.3792743682861,0,4232058208,25.2865695953369,,,4.27563937295712E-6,2.13760856861429E-7,4.2854402732463E-6,2.13782158108571E-7,0.930871725082397,0.979749202728271,25.4802417755127,0,30,4,200,-5.69449548493139E-6,0.296144187450409,0.316519170999527,1,,,,,,,,,,,,,,,,
,3926921854.35016,25.6458473205566,49.7855949401855,,,6,,,,25.7316547995914,,,1,,,,,,,,,,,,,,,,,,,,,,25.5684280395508,25.7189960479736,49.7855949401855,49.7855949401855,,,6.33718061447144,,1,0,0,0,0,28.8367557525635,2,1,1,25.7289714813232,0,4232058144,25.6433681488037,,,4.25788979841159E-6,2.12902071227858E-7,4.26816538581617E-6,2.1292452529553E-7,0.92897093296051,0.978835701942444,25.4737300872803,5.28434038162231,30,4,200,-1.2714023796434E-5,0.29615592956543,0.316495567560196,1,,,,,,,,,,,,,,,,
,3926921875.80206,25.9990501403809,49.7855949401855,,,6,,,,25.7316547995914,,,1,,,,,,,,,,,,,,,,,,,,,,25.9144496917725,26.0752124786377,49.7855949401855,49.7855949401855,,,6.32695817947388,,1,0,0,0,0,28.3479976654053,2,1,1,26.0836505889893,0,4232058080,25.9949779510498,,,4.25930292475659E-6,2.1296579345083E-7,4.26942623891477E-6,2.12988222021853E-7,0.929421305656433,0.978635311126709,25.4757308959961,0,30,4,200,6.98943495081039E-6,0.29616442322731,0.31631126999855,1,,,,,,,,,,,,,,,,
,3926921896.75014,26.3430576324463,49.7855949401855,,,6,,,,25.7316547995914,,,1,,,,,,,,,,,,,,,,,,,,,,26.2586269378662,26.4170570373535,49.7855949401855,49.7855949401855,,,6.35191631317139,,1,0,0,0,0,28.8367557525635,2,1,1,26.4274883270264,0,4232058176,26.338352394104,,,4.243608343777E-6,2.12157859765282E-7,4.25333630930373E-6,2.12179955784531E-7,0.930983006954193,0.979914784431458,25.4805335998535,0,30,4,200,-3.31808678311063E-6,0.29608353972435,0.316309124231338,1,,,,,,,,,,,,,,,,
,3926921917.9417,26.6963729858398,49.7855949401855,,,6,,,,25.7316547995914,,,1,,,,,,,,,,,,,,,,,,,,,,26.6141662597656,26.7654590606689,49.7855949401855,49.7855949401855,,,6.36236095428467,,1,0,0,0,0,28.8367557525635,2,1,1,26.7785797119141,0,4232058144,26.6889974594116,,,4.23405205802316E-6,2.11714691325946E-7,4.24443673145317E-6,2.11738375817632E-7,0.928662419319153,0.979351282119751,25.471866607666,0,30,4,200,-5.04070203533047E-6,0.295945227146149,0.316100299358368,1,,,,,,,,,,,,,,,,
,3926921938.94016,27.031247138977,49.7855949401855,,,6,,,,25.7316547995914,,,1,,,,,,,,,,,,,,,,,,,,,,26.9463024139404,27.1083297729492,49.7855949401855,49.7855949401855,,,6.36862230300903,,1,0,0,0,0,29.3255138397217,2,1,1,27.1161918640137,0,4232058240,27.0290332794189,,,4.23089371341545E-6,2.11526789884834E-7,4.24063325490432E-6,2.11548535104249E-7,0.930666625499725,0.979372560977936,25.4797992706299,0,30,4,200,-3.38044651471137E-6,0.295794993638992,0.315967589616775,1,,,,,,,,,,,,,,,,
,3926921960.12271,27.3817052841187,49.7855949401855,,,6,,,,25.7316547995914,,,1,,,,,,,,,,,,,,,,,,,,,,27.2989158630371,27.4575691223145,49.7855949401855,49.7855949401855,,,6.38039970397949,,1,0,0,0,0,28.8367557525635,2,1,1,27.4644947052002,0,4232058272,27.381583404541,,,4.2200933001869E-6,2.11008704533586E-7,4.23026127613343E-6,2.1103065634149E-7,0.929202795028686,0.979511737823486,25.4738445281982,0,30,4,200,-1.48847266245866E-5,0.295740127563477,0.315693408250809,1,,,,,,,,,,,,,,,,
,3926921981.43333,27.7334766387939,49.7855949401855,,,6,,,,25.7316547995914,,,1,,,,,,,,,,,,,,,,,,,,,,27.6517868041992,27.8054885864258,49.7855949401855,49.7855949401855,,,6.38831424713135,,1,0,0,0,0,28.8367557525635,2,1,1,27.8151664733887,0,4232058176,27.7297281265259,,,4.21053905627826E-6,2.10542328413607E-7,4.22107496173952E-6,2.1056714684336E-7,0.928435623645783,0.980712652206421,25.4696254730225,0,30,4,200,-2.53581183642382E-5,0.295403778553009,0.315464228391647,1,,,,,,,,,,,,,,,,
,3926922002.68643,28.0843687057495,49.7855949401855,,,6,,,,25.7316547995914,,,1,,,,,,,,,,,,,,,,,,,,,,28.0015239715576,28.1634902954102,49.7855949401855,49.7855949401855,,,6.40220069885254,,1,0,0,0,0,28.8367557525635,2,1,1,28.1672134399414,0,4232058368,28.0795429229736,,,4.20092564906994E-6,2.10022698222187E-7,4.21053467190344E-6,2.10044717990985E-7,0.931063413619995,0.979908168315887,25.480863571167,0,30,4,200,-2.42896276176907E-5,0.295041263103485,0.315076917409897,1,,,,,,,,,,,,,,,,
,3926922032.34351,28.5689010620117,49.7855949401855,,,6,,,,25.7367394806628,,,1,,,,,,,,,,,,,,,,,,,,,,28.4856739044189,28.646110534668,49.7855949401855,49.7855949401855,,,6.40722846984863,,1,0,0,0,0,29.3255138397217,2,1,1,28.6521282196045,0,4232058240,28.5648094177246,,,4.1883853470753E-6,2.09443635905704E-7,4.1988682137803E-6,2.09465709321699E-7,0.927840530872345,0.979219257831574,25.4737873077393,0,30,4,200,-4.96864777232986E-6,0.294718265533447,0.314629256725311,1,,,,,,,,,,,,,,,,
,3926922053.27849,28.9121112823486,49.7855949401855,,,6,,,,25.7367394806628,,,1,,,,,,,,,,,,,,,,,,,,,,28.8332977294922,28.9858074188232,49.7855949401855,49.7855949401855,,,6.42299365997314,,1,0,0,0,0,28.3479976654053,2,1,1,28.9909248352051,0,4232057888,28.9084621429443,,,4.18190070911939E-6,2.09146134130304E-7,4.19292217202848E-6,2.0916920494351E-7,0.926098167896271,0.979194581508636,25.4669494628906,0,30,4,200,3.32048585960365E-7,0.294577777385712,0.314523965120316,1,,,,,,,,,,,,,,,,
,3926922074.29682,29.2572317123413,49.7855949401855,,,6,,,,25.7367394806628,,,1,,,,,,,,,,,,,,,,,,,,,,29.1748199462891,29.3290138244629,49.7855949401855,49.7855949401855,,,6.4346079826355,,1,0,0,0,0,28.8367557525635,2,1,1,29.3396434783936,0,4232058368,29.2539888381958,,,4.17457963677128E-6,2.08740315298704E-7,4.18471882734236E-6,2.08763027223586E-7,0.928703010082245,0.978505313396454,25.4780311584473,5.28343486785889,30,4,200,-1.48115723277442E-5,0.294298768043518,0.314085841178894,1,,,,,,,,,,,,,,,,
,3926922095.48593,29.6187353134155,49.7855949401855,,,6,,,,25.7367394806628,,,1,,,,,,,,,,,,,,,,,,,,,,29.5355205535889,29.6936321258545,49.7855949401855,49.7855949401855,,,6.44242811203003,,1,0,0,0,0,28.8367557525635,2,1,1,29.7019500732422,0,4232058176,29.6077304840088,,,4.19355095974729E-6,2.09724850770737E-7,4.20404723582515E-6,2.09747796951608E-7,0.926355421543121,0.974363684654236,25.4737033843994,5.28280401229858,30,4,200,-3.88223706977442E-5,0.293834000825882,0.313850730657578,1,,,,,,,,,,,,,,,,
,3926922116.60826,29.9291181564331,49.7855949401855,,,6,,,,25.7367394806628,,,1,,,,,,,,,,,,,,,,,,,,,,29.8937015533447,29.9586544036865,49.7855949401855,49.7855949401855,,,6.43573474884033,,1,0,0,0,0,28.8367557525635,6,1,1,29.9645347595215,0,4232058240,29.9291460249159,,,4.16789384148114E-6,2.08444152686161E-7,4.17877420136484E-6,2.08467229831706E-7,0.926197946071625,0.978350460529327,25.46826171875,0,30,4,200,4.27404884248972E-5,0.294312953948975,0.314145147800446,1,,,,,,,,,,,,,,,,
,3926922137.47291,29.9936065673828,49.7855949401855,,,6,,,,25.7367394806628,,,1,,,,,,,,,,,,,,,,,,,,,,29.9897480010986,29.9961585998535,49.7855949401855,49.7855949401855,,,6.45483779907227,,1,0,0,0,0.013885498046875,28.8367557525635,5,1,1,29.997465133667,0,4232058080,29.9932905832926,,,4.16543479393902E-6,2.08313065402925E-7,4.17616908244038E-6,2.08336506698171E-7,0.926718533039093,0.978500485420227,25.4702396392822,0,30,4,200,4.25594589614775E-5,0.294932395219803,0.314852267503738,1,,,,,,,,,,,,,,,,
,3926922158.30561,30.0000810623169,49.7855949401855,,,6,,,,25.7367394806628,,,1,,,,,,,,,,,,,,,,,,,,,,29.999568939209,30.0002536773682,49.7855949401855,49.7855949401855,,,6.45392036437988,,1,0,0,0,0,28.8367557525635,5,1,1,30.0004653930664,0,4232058176,29.9998418807983,,,4.16840221842432E-6,2.08420853357826E-7,4.17832911281972E-6,2.08442529628839E-7,0.929415583610535,0.978899300098419,25.4805526733398,0,30,4,200,4.27200066042133E-5,0.295646399259567,0.315434694290161,1,,,,,,,,,,,,,,,,
,3926922179.04675,30.0004053115845,49.7855949401855,,,6,,,,25.7367394806628,,,1,,,,,,,,,,,,,,,,,,,,,,29.9996910095215,30.0006103515625,49.7855949401855,49.7855949401855,,,6.45185375213623,,1,0,0,0,0,29.3255138397217,1,1,1,30.0003871917725,0,4232058144,30.0001816219754,,,4.17063261444775E-6,2.08565629833213E-7,4.18117272044016E-6,2.08588736139115E-7,0.927204251289368,0.977938830852509,25.4727573394775,0,30,4,200,3.13698510581162E-5,0.29646497964859,0.316319584846497,1,,,,,,,,,,,,,,,,