File: Data used in paper/Case study 4/ML_Namond_20240610_1_QHS_0-QHS1011A_SmBaCuBO5_DC-14p2mg_MvT_50oe_20240613 (1).dat
[Header]
; MPMS3 Data File (default extension .dat)
; Copyright (c) 2007, Quantum Design, Inc. All rights reserved.
TITLE,
FILEOPENTIME,3927458359.44614,06/13/2024,4:39 pm
BYAPP,MPMS3 w/ AC,1.0,1.1
INFO,MPMS3 Measurement Release 1.1.16 Build 419, MultiVu Release 2.3.4.15,APPNAME
INFO,Linear Motor Servo Controller,MOTOR_MODULE_NAME
INFO,3101-100 F0,MOTOR_HW_VERSION
INFO,MMC1118,MOTOR_SERIAL_NUMBER
INFO,01.04.28,MOTOR_SOFTWARE_VERSION
INFO,Quantum Design Squid Module,SQUID_MODULE_NAME
INFO,3101-501 B0,SQUID_HW_VERSION
INFO,SQM313,SQUID_SERIAL_NUMBER
INFO,01.03.04,SQUID_SOFTWARE_VERSION
INFO,Quantum Design VSM Oven,OVEN_MODULE_NAME
INFO,3101-201 A3,OVEN_HW_VERSION
INFO,OVB345,OVEN_SERIAL_NUMBER
INFO,01.07.07,OVEN_SOFTWARE_VERSION
INFO,SQUID AC,AC_MODULE_NAME
INFO,3101-401 G0,AC_HW_VERSION
INFO,SAC210,AC_SERIAL_NUMBER
INFO,SQUID AC 00.95.07,AC_SOFTWARE_VERSION
INFO,TCI318,COIL_SERIAL_NUMBER
INFO,0,MOMENT_UNITS
INFO,ML_Namond_20240606_2_QHS_0-QHS1007B_SmBaCuBO5_DC-13p3mg_powder_MvT_50oe_20240613.dat,SAMPLE_MATERIAL
INFO,,SAMPLE_COMMENT
INFO,14.2,SAMPLE_MASS
INFO,,SAMPLE_VOLUME
INFO,,SAMPLE_MOLECULAR_WEIGHT
INFO,,SAMPLE_SIZE
INFO,,SAMPLE_SHAPE
INFO,Straw,SAMPLE_HOLDER
INFO,Standard,SAMPLE_HOLDER_DETAIL
INFO,66.63,SAMPLE_OFFSET
DATATYPE,COMMENT,1
DATATYPE,TIME,2
STARTUPAXIS,X,2
STARTUPAXIS,Y1,5
FIELDGROUP, VSM,2,3,4,5,6,8,9,10,11,14,15
FIELDGROUP, DC, 2,3,4,14,56,57,58,59,60,61,62,63,64,65,66,67,68,69
FIELDGROUP, AC, 2,3,4,11,16,17,18,19,20,21,22,23,24,25,26,27,28,29,30
STARTUPGROUP, All
[Data]
Comment,Time Stamp (sec),Temperature (K),Magnetic Field (Oe),Moment (emu),M. Std. Err. (emu),Transport Action,Averaging Time (sec),Frequency (Hz),Peak Amplitude (mm),Center Position (mm),Lockin Signal' (V),Lockin Signal (V),Range,M. Quad. Signal (emu),AC Moment (emu),AC M. Std Err. (emu),AC Phase (deg),AC Phase Std. Err. (deg),AC Susceptibility (emu/Oe),AC Suscept. Std Err. (emu/Oe),AC X' (emu/Oe),AC X' Std Err. (emu/Oe),AC X'' (emu/Oe),AC X'' Std Err. (emu/Oe),AC Drive (Oe),AC Frequency (Hz),AC Averaging Time (sec),AC Cycles,AC Range,AC Measure Type,AC Signal' (V),AC Signal'' (V),AC Trim Coil Ratio,AC Trim Coil Phase,Min. Temperature (K),Max. Temperature (K),Min. Field (Oe),Max. Field (Oe),Mass (grams),Motor Lag (deg),Pressure (Torr),Measure Count,Measurement Number,SQUID Status (code),Motor Status (code),Measure Status (code),Motor Current (amps),Motor Temp. (C),Temp. Status (code),Field Status (code),Chamber Status (code),Chamber Temp (K),Redirection State,Evercool Status,Average Temp (K),Rotation Angle (deg),Rotator state,DC Moment Fixed Ctr (emu),DC Moment Err Fixed Ctr (emu),DC Moment Free Ctr (emu),DC Moment Err Free Ctr (emu),DC Fixed Fit,DC Free Fit,DC Calculated Center (mm),DC Calculated Center Err (mm),DC Scan Length (mm),DC Scan Time (s),DC Number of Points,DC Squid Drift,DC Min V (V),DC Max V (V),DC Scans per Measure,Map 01,Map 02,Map 03,Map 04,Map 05,Map 06,Map 07,Map 08,Map 09,Map 10,Map 11,Map 12,Map 13,Map 14,Map 15,Map 16
,3927459953.84641,1.79866051673889,50.1284408569336,,,3,,,,28.2260665893555,,,,,,,,,,,,,,,,,,,,,,,,,1.79866051673889,1.79866051673889,50.1284408569336,50.1284408569336,,,2.74733781814575,,0,,,,,,1,1,1,1.79866051673889,0,0,0,,,,,,,,,,,,,,,,,,,,,,,,,,,,,,,,,
,3927460144.29083,4.1080265045166,50.1284408569336,,,6,,,,28.2312397158772,,,1,,,,,,,,,,,,,,,,,,,,,,4.03665924072266,4.16609573364258,50.1284408569336,50.1284408569336,,,3.95317149162292,,1,0,0,0,0.013885498046875,28.8367557525635,6,1,1,4.18837976455688,0,4232058080,4.09832535849677,,,8.17775368753961E-5,4.07882286756385E-6,8.17775485777873E-5,4.07882309878179E-6,0.992067694664001,0.992078602313995,28.2328128814697,3.64591884613037,30,4,200,-0.000194156455108896,-0.499498546123505,-0.11218599230051,1,,,,,,,,,,,,,,,,
,3927460322.49074,6.80170440673828,50.1284408569336,,,6,,,,28.2312397158772,,,1,,,,,,,,,,,,,,,,,,,,,,6.72310638427734,6.85508441925049,50.1284408569336,50.1284408569336,,,4.68924713134766,,1,0,0,0,0.013885498046875,28.3479976654053,6,1,1,6.88030242919922,0,4232058368,6.78550730811225,,,5.32043666874113E-5,2.65368590564419E-6,5.320462481911E-5,2.65368820633493E-6,0.991639912128449,0.992130935192108,28.2419166564941,0.117705501616001,30,4,200,1.51537196870777E-5,-0.401248306035995,-0.149430975317955,1,,,,,,,,,,,,,,,,
,3927460499.46574,9.61338710784912,50.1284408569336,,,6,,,,28.2312397158772,,,1,,,,,,,,,,,,,,,,,,,,,,9.53495502471924,9.67599773406982,50.1284408569336,50.1284408569336,,,5.17004251480103,,1,0,0,0,0,29.3255138397217,6,1,1,9.691819190979,0,4232058336,9.60375213623047,,,3.57613853361233E-5,1.78371641747528E-6,3.57621505362174E-5,1.78372078670093E-6,0.989404261112213,0.991375744342804,28.2545051574707,0,30,4,200,5.01948634337168E-5,-0.317771106958389,-0.148308739066124,1,,,,,,,,,,,,,,,,
,3927460677.83762,12.4911103248596,50.1284408569336,,,6,,,,28.2312397158772,,,1,,,,,,,,,,,,,,,,,,,,,,12.4118156433105,12.5518264770508,50.1284408569336,50.1284408569336,,,5.50284862518311,,1,0,0,0,0,28.8367557525635,6,1,1,12.5704050064087,0,4232058272,12.4807275136312,,,2.31302383129714E-5,1.1537857440537E-6,2.31319065565464E-5,1.15379131516772E-6,0.983649134635925,0.988476514816284,28.2750396728516,0,30,4,200,2.14769147532934E-6,-0.259991526603699,-0.150163277983665,1,,,,,,,,,,,,,,,,
,3927460864.60957,15.5965528488159,50.1284408569336,,,6,,,,28.236242648943,,,1,,,,,,,,,,,,,,,,,,,,,,15.5178318023682,15.6623802185059,50.1284408569336,50.1284408569336,,,5.74387121200562,,1,0,0,0,0.013885498046875,28.8367557525635,2,1,1,15.6752738952637,0,4232058144,15.58753490448,,,1.56951708394834E-5,7.83038367915536E-7,1.56976985149501E-5,7.83045990979815E-7,0.975532829761505,0.982790172100067,28.3018112182617,,30,4,200,-3.80802812287584E-5,-0.227775320410728,-0.153192758560181,1,,,,,,,,,,,,,,,,
,3927461043.55677,18.5332927703857,50.1284408569336,,,6,,,,28.236242648943,,,1,,,,,,,,,,,,,,,,,,,,,,18.451208114624,18.5950717926025,50.1284408569336,50.1284408569336,,,5.86999702453613,,1,0,0,0,0.013885498046875,28.8367557525635,2,1,1,18.6153774261475,0,4232058304,18.5232073465983,,,1.17036445161575E-5,5.83902630244324E-7,1.17067842935368E-5,5.8391289821295E-7,0.975306987762451,0.989577889442444,28.320764541626,7.90319609222934E-6,30,4,200,-4.8775204049889E-5,-0.219536855816841,-0.164152145385742,1,,,,,,,,,,,,,,,,
,3927461221.36925,21.4566049575806,50.1284408569336,,,6,,,,28.236242648943,,,1,,,,,,,,,,,,,,,,,,,,,,21.3771667480469,21.5282955169678,50.1284408569336,50.1284408569336,,,5.99284744262695,,1,0,0,0,0.013885498046875,28.8367557525635,2,1,1,21.5360431671143,0,4232058176,21.4528284072876,,,8.94784654778126E-6,4.46532334570827E-7,8.95249742841065E-6,4.46546048581809E-7,0.966255486011505,0.987292945384979,28.3541812896729,5.32486438751221,30,4,200,3.65869254892459E-6,-0.217659309506416,-0.175236344337463,1,,,,,,,,,,,,,,,,
,3927461400.87362,24.3881177902222,50.1284408569336,,,6,,,,28.236242648943,,,1,,,,,,,,,,,,,,,,,,,,,,24.2956600189209,24.4748001098633,50.1284408569336,50.1284408569336,,,6.09838914871216,,1,0,0,0,0,28.8367557525635,2,1,1,24.4805755615234,0,4232058368,24.3859142303467,,,7.14596655990798E-6,3.56764143871506E-7,7.14973643526346E-6,3.5677525698632E-7,0.955354869365692,0.968343377113342,28.3548831939697,,30,4,200,0.000553401187062263,-0.199195146560669,-0.162062987685204,1,,,,,,,,,,,,,,,,
,3927461578.75555,27.3227920532227,50.1284408569336,,,6,,,,28.236242648943,,,1,,,,,,,,,,,,,,,,,,,,,,27.2417373657227,27.4038238525391,50.1284408569336,50.1284408569336,,,6.19391536712647,,1,0,0,0,0.013885498046875,28.3479976654053,2,1,1,27.4074478149414,0,4232058336,27.3217260360718,,,5.90411878049342E-6,2.94909606744741E-7,5.91218043454105E-6,2.94931494685569E-7,0.945457696914673,0.98003363609314,28.4273719787598,7.55963446863461E-6,30,4,200,-4.88762307213619E-5,-0.193079099059105,-0.164946749806404,1,,,,,,,,,,,,,,,,
,3927461766.2139,29.9969110488892,50.1284408569336,,,6,,,,28.2413463852733,,,1,,,,,,,,,,,,,,,,,,,,,,29.9951038360596,29.9985618591309,50.1284408569336,50.1284408569336,,,6.27233695983887,,1,0,0,0,0.013885498046875,28.3479976654053,5,1,1,29.9987182617188,0,4232058272,29.9968982696533,,,4.77856669057724E-6,2.38885378960866E-7,4.78845086821808E-6,2.38909075189515E-7,0.93205463886261,0.973678946495056,28.4768829345703,0,30,4,200,9.40616610023426E-6,-0.19655354321003,-0.173667594790459,1,,,,,,,,,,,,,,,,
,3927461961.53879,34.0856323242188,50.1284408569336,,,6,,,,28.2413463852733,,,1,,,,,,,,,,,,,,,,,,,,,,33.9346885681152,34.2281188964844,50.1284408569336,50.1284408569336,,,6.3672571182251,,1,0,0,0,0.013885498046875,29.3255138397217,2,1,1,34.2365760803223,0,4232058208,34.0742433336046,,,3.87108693512289E-6,1.93758315108847E-7,3.88370684950151E-6,1.93789194487786E-7,0.915919899940491,0.969943463802338,28.5364017486572,,30,4,200,-8.70368603500538E-5,-0.205649971961975,-0.186582759022713,1,,,,,,,,,,,,,,,,
,3927462149.06323,40.2376403808594,50.1284408569336,,,6,,,,28.2466088153893,,,1,,,,,,,,,,,,,,,,,,,,,,40.0727577209473,40.3811721801758,50.1284408569336,50.1284408569336,,,6.48910760879517,,1,0,0,0,0,28.8367557525635,2,1,1,40.4025230407715,0,4232058240,40.2317878723145,,,3.37373068465657E-6,1.69029134843222E-7,3.38782968108658E-6,1.69063521771822E-7,0.905108749866486,0.966673374176025,28.580249786377,,30,4,200,-3.65311279892921E-5,-0.215499296784401,-0.199110582470894,1,,,,,,,,,,,,,,,,
,3927462336.4641,46.3884944915771,50.1284408569336,,,6,,,,28.2518405152118,,,1,,,,,,,,,,,,,,,,,,,,,,46.2292976379395,46.513313293457,50.1284408569336,50.1284408569336,,,6.62854528427124,,1,0,0,0,0.013885498046875,28.8367557525635,2,1,1,46.5476913452148,0,4232058208,46.3629578484429,,,3.05678606271272E-6,1.53410350550602E-7,3.07438314829354E-6,1.53452502984037E-7,0.888782799243927,0.961086332798004,28.6426963806152,5.35188722610474,30,4,200,-1.12950619950425E-5,-0.220852822065353,-0.205934062600136,1,,,,,,,,,,,,,,,,
,3927462524.4625,52.567626953125,50.1284408569336,,,6,,,,28.2571586066947,,,1,,,,,,,,,,,,,,,,,,,,,,52.4081077575684,52.7137794494629,50.1284408569336,50.1284408569336,,,6.91835260391235,,1,0,0,0,0.013885498046875,28.8367557525635,2,1,1,52.7271461486816,0,4232058112,52.5608215332031,,,2.86931901966422E-6,1.44200843279188E-7,2.88970915435323E-6,1.44250392847429E-7,0.877154231071472,0.958413183689117,28.6907539367676,,30,4,200,-1.62839896802325E-5,-0.224262863397598,-0.210277304053307,1,,,,,,,,,,,,,,,,
,3927462720.05111,59.0013809204102,50.1284408569336,,,6,,,,28.2671949046914,,,1,,,,,,,,,,,,,,,,,,,,,,58.831241607666,59.1614875793457,50.1284408569336,50.1284408569336,,,7.40747737884521,,1,0,0,0,0.013885498046875,28.8367557525635,2,1,1,59.1715202331543,0,4232058208,58.9940376281738,,,2.75362492886566E-6,1.38453610851111E-7,2.77450628228721E-6,1.38504205684761E-7,0.873328268527985,0.957623898983002,28.7149448394775,0,30,4,200,-1.10403216240229E-5,-0.226151794195175,-0.212780326604843,1,,,,,,,,,,,,,,,,
,3927462907.21103,65.165828704834,50.1284408569336,,,6,,,,28.2723484772358,,,1,,,,,,,,,,,,,,,,,,,,,,65.0044937133789,65.3239517211914,50.1284408569336,50.1284408569336,,,8.06610298156738,,1,0,0,0,0.013885498046875,28.8367557525635,2,1,1,65.337646484375,0,4232058240,65.1590850830078,,,2.65766332006681E-6,1.33765288160435E-7,2.68032355821087E-6,1.33817522616366E-7,0.865629196166992,0.955068528652191,28.7471790313721,0,30,4,200,-1.36189528348041E-5,-0.227267429232597,-0.214212417602539,1,,,,,,,,,,,,,,,,
,3927463103.21772,71.6380996704102,50.1284408569336,,,6,,,,28.2826648749208,,,1,,,,,,,,,,,,,,,,,,,,,,71.4629211425781,71.75439453125,50.1284408569336,50.1284408569336,,,8.22910690307617,,1,0,0,0,0.013885498046875,28.3479976654053,2,1,1,71.8132781982422,0,4232058208,71.6092173258464,,,2.57501978362772E-6,1.29777410742226E-7,2.60004047972393E-6,1.29834431427088E-7,0.856289505958557,0.950959026813507,28.788818359375,0,30,4,200,-3.13167743115628E-6,-0.227943658828735,-0.215370744466782,1,,,,,,,,,,,,,,,,
,3927463299.75673,78.1263656616211,50.1284408569336,,,6,,,,28.2931780706221,,,1,,,,,,,,,,,,,,,,,,,,,,77.9540023803711,78.2987289428711,50.1284408569336,50.1284408569336,,,8.30099582672119,,1,0,0,0,0.013885498046875,28.8367557525635,2,1,1,78.2987289428711,0,4232058208,78.1250480651855,,,2.5179415697063E-6,1.27016088933046E-7,2.5446432965298E-6,1.2707784800145E-7,0.850234448909759,0.94943779706955,28.8215885162354,,30,4,200,-4.82013729197206E-6,-0.22846619784832,-0.216065362095833,1,,,,,,,,,,,,,,,,
,3927463496.94577,84.6149291992188,50.1284408569336,,,6,,,,28.3036381766994,,,1,,,,,,,,,,,,,,,,,,,,,,84.4373474121094,84.7790908813477,50.1284408569336,50.1284408569336,,,8.3804988861084,,1,0,0,0,0.013885498046875,28.8367557525635,2,1,1,84.7925109863281,0,4232058432,84.6116081237793,,,2.46735860542309E-6,1.24538722159142E-7,2.49515974017985E-6,1.24603287246697E-7,0.846390902996063,0.949970722198486,28.8480930328369,0.191067203879356,30,4,200,2.21998266169976E-6,-0.228641003370285,-0.216599673032761,1,,,,,,,,,,,,,,,,
,3927463694.12314,91.1696929931641,50.1284408569336,,,6,,,,28.314278569923,,,1,,,,,,,,,,,,,,,,,,,,,,91.006706237793,91.3045349121094,50.1284408569336,50.1284408569336,,,8.4602632522583,,1,0,0,0,0.013885498046875,28.8367557525635,2,1,1,91.3326797485352,0,4232058176,91.1570678710937,,,2.42236280283866E-6,1.22425626268347E-7,2.45266940611485E-6,1.2249486556935E-7,0.838399469852447,0.947829484939575,28.8875885009766,5.68836185266264E-5,30,4,200,2.52107383857947E-6,-0.229050666093826,-0.21708919107914,1,,,,,,,,,,,,,,,,
,3927463891.34455,97.7184944152832,50.1284408569336,,,6,,,,28.3249186534271,,,1,,,,,,,,,,,,,,,,,,,,,,97.5531234741211,97.8335266113281,50.1284408569336,50.1284408569336,,,8.53253173828125,,1,0,0,0,0.013885498046875,28.8367557525635,2,1,1,97.8838653564453,0,4232058144,97.688833448622,,,2.39907929459117E-6,1.21319616352836E-7,2.43088003002281E-6,1.21394428453817E-7,0.83492374420166,0.949785828590393,28.9145946502686,0,30,4,200,4.34508319813176E-6,-0.229298785328865,-0.217441499233246,1,,,,,,,,,,,,,,,,
,3927464097.01505,104.545959472656,50.1284408569336,,,6,,,,28.3411108223677,,,1,,,,,,,,,,,,,,,,,,,,,,104.379814147949,104.672645568848,50.1284408569336,50.1284408569336,,,8.60750484466553,,1,0,0,0,0,29.3255138397217,2,1,1,104.712104797363,0,4232058304,104.527194552951,,,2.36402140106092E-6,1.19583581059337E-7,2.39554893502048E-6,1.19655373113745E-7,0.833119928836823,0.945745229721069,28.9325332641602,0,30,4,200,-9.8969667305937E-6,-0.229464277625084,-0.217753291130066,1,,,,,,,,,,,,,,,,
,3927464295.27323,111.125736236572,50.1284408569336,,,6,,,,28.3519005442444,,,1,,,,,,,,,,,,,,,,,,,,,,110.952842712402,111.265281677246,50.1284408569336,50.1284408569336,,,8.67833042144775,,1,0,0,0,0.013885498046875,28.8367557525635,2,1,1,111.298629760742,0,4232058336,111.103703816732,,,2.34352479456309E-6,1.18655055215015E-7,2.37702420706264E-6,1.18731109871819E-7,0.827885866165161,0.945579946041107,28.9637870788574,5.38180160522461,30,4,200,-9.0074418039876E-6,-0.229380160570145,-0.217901423573494,1,,,,,,,,,,,,,,,,
,3927464500.66461,117.943893432617,50.1284408569336,,,6,,,,28.3682509428659,,,1,,,,,,,,,,,,,,,,,,,,,,117.78458404541,118.090026855469,50.1284408569336,50.1284408569336,,,8.75193691253662,,1,0,0,0,0.013885498046875,29.3255138397217,2,1,1,118.103202819824,0,4232058304,117.936242675781,,,2.30607495324306E-6,1.16864092411611E-7,2.34149044570007E-6,1.16947247773949E-7,0.822888970375061,0.947009384632111,29.0020179748535,0,30,4,200,4.04090360461851E-6,-0.229367226362228,-0.218074530363083,1,,,,,,,,,,,,,,,,
,3927464715.3026,125.053680419922,50.1284408569336,,,6,,,,28.3889299863576,,,1,,,,,,,,,,,,,,,,,,,,,,124.884231567383,125.208038330078,50.1284408569336,50.1284408569336,,,8.82489013671875,,1,0,0,0,0.013885498046875,28.8367557525635,2,1,1,125.223129272461,0,4232058144,125.04935836792,,,2.29340432327933E-6,1.16317400858907E-7,2.32996175616249E-6,1.1640254546549E-7,0.818460524082184,0.942201375961304,29.033842086792,,30,4,200,1.11965246105683E-5,-0.229602441191673,-0.218150973320007,1,,,,,,,,,,,,,,,,
,3927464921.19926,131.900207519531,50.1284408569336,,,6,,,,28.4053230083784,,,1,,,,,,,,,,,,,,,,,,,,,,131.72575378418,132.042922973633,50.1284408569336,50.1284408569336,,,8.8973331451416,,1,0,0,0,0.013885498046875,28.8367557525635,2,1,1,132.074661254883,0,4232058112,131.882841322157,,,2.26641143564782E-6,1.15059130861961E-7,2.30528941462818E-6,1.15149082897001E-7,0.813404381275177,0.945410430431366,29.0746936798096,5.3920955657959,30,4,200,-1.63058866746724E-5,-0.229702264070511,-0.218407183885574,1,,,,,,,,,,,,,,,,
,3927465136.06334,139.056495666504,50.1284408569336,,,6,,,,28.4284457907258,,,1,,,,,,,,,,,,,,,,,,,,,,138.88737487793,139.213012695312,50.1284408569336,50.1284408569336,,,8.96669578552246,,1,0,0,0,0.013885498046875,28.8367557525635,2,1,1,139.225616455078,0,4232058304,139.048376464844,,,2.24786790769164E-6,1.14224020597369E-7,2.28815758496501E-6,1.14317305573323E-7,0.808654069900513,0.941710114479065,29.1120014190674,0,30,4,200,-1.49676367300344E-7,-0.229471623897552,-0.218159049749374,1,,,,,,,,,,,,,,,,
,3927465350.78247,146.182777404785,50.1284408569336,,,6,,,,28.4497467592269,,,1,,,,,,,,,,,,,,,,,,,,,,146.02294921875,146.329559326172,50.1284408569336,50.1284408569336,,,9.04048919677734,,1,0,0,0,0.013885498046875,28.8367557525635,2,1,1,146.356781005859,0,4232058336,146.180833435059,,,2.22534164268664E-6,1.13089088543378E-7,2.26538193606491E-6,1.1318204971767E-7,0.808221220970154,0.941313624382019,29.134485244751,,30,4,200,-2.3888329451438E-5,-0.229514718055725,-0.21827594935894,1,,,,,,,,,,,,,,,,
,3927465566.80129,153.370079040527,50.1284408569336,,,6,,,,28.471116110923,,,1,,,,,,,,,,,,,,,,,,,,,,153.200775146484,153.484039306641,50.1284408569336,50.1284408569336,,,9.11728668212891,,1,0,0,0,0.013885498046875,28.8367557525635,2,1,1,153.53938293457,0,4232058336,153.342112223307,,,2.20058325736107E-6,1.12066094905843E-7,2.24466190938011E-6,1.12166414629666E-7,0.79796427488327,0.938418388366699,29.1925296783447,0,30,4,200,-2.0002646579087E-6,-0.229430958628654,-0.218403354287148,1,,,,,,,,,,,,,,,,
,3927465781.4756,160.491218566895,50.1284408569336,,,6,,,,28.4932964059507,,,1,,,,,,,,,,,,,,,,,,,,,,160.325210571289,160.634429931641,50.1284408569336,50.1284408569336,,,9.18323993682861,,1,0,0,0,0,28.8367557525635,2,1,1,160.6572265625,0,4232058208,160.479103088379,,,2.20430886420938E-6,1.1212960340701E-7,2.24664973899817E-6,1.12227846737138E-7,0.803385078907013,0.944152355194092,29.2012348175049,0,30,4,200,-8.23436948849121E-6,-0.229533150792122,-0.218527466058731,1,,,,,,,,,,,,,,,,
,3927465992.97241,167.528175354004,50.1284408569336,,,6,,,,28.5162828377631,,,1,,,,,,,,,,,,,,,,,,,,,,167.361618041992,167.680755615234,50.1284408569336,50.1284408569336,,,9.23527336120605,,1,0,0,0,0,28.8367557525635,2,1,1,167.694732666016,0,4232058208,167.512620544434,,,2.18485563560928E-6,1.11378020386117E-7,2.23055319384257E-6,1.11483318072733E-7,0.793211758136749,0.935316383838654,29.2525157928467,5.40855932235718,30,4,200,9.90169701253762E-6,-0.229723677039146,-0.21868172287941,1,,,,,,,,,,,,,,,,
,3927466211.69555,174.785339355469,50.1284408569336,,,6,,,,28.5459297739648,,,1,,,,,,,,,,,,,,,,,,,,,,174.605361938477,174.94206237793,50.1284408569336,50.1284408569336,,,9.30381679534912,,1,0,0,0,0.013885498046875,27.8592376708984,2,1,1,174.965316772461,0,4232058272,174.779223632812,,,2.17943302444349E-6,1.11103633986919E-7,2.22571286564943E-6,1.11210638752431E-7,0.793128490447998,0.939731776714325,29.2884387969971,0.024620508775115,30,4,200,3.30677814019964E-8,-0.230325326323509,-0.219229176640511,1,,,,,,,,,,,,,,,,
,3927466421.94532,181.784324645996,50.1284408569336,,,6,,,,28.5694350040465,,,1,,,,,,,,,,,,,,,,,,,,,,181.619567871094,181.9248046875,50.1284408569336,50.1284408569336,,,9.37739372253418,,1,0,0,0,0.013885498046875,28.3479976654053,2,1,1,181.949081420898,0,4232058240,181.77410736084,,,2.16186112758106E-6,1.10345717912225E-7,2.2091652818442E-6,1.1045392411934E-7,0.787428379058838,0.930020332336426,29.3213844299316,0,30,4,200,3.11532812702353E-6,-0.230492532253265,-0.21950064599514,1,,,,,,,,,,,,,,,,
,3927466649.96813,189.359214782715,50.1284408569336,,,6,,,,28.6014141830168,,,1,,,,,,,,,,,,,,,,,,,,,,189.195297241211,189.509826660156,50.1284408569336,50.1284408569336,,,9.45079517364502,,1,0,0,0,0.013885498046875,28.8367557525635,2,1,1,189.523132324219,0,4232058208,189.349290466309,,,2.13642425770268E-6,1.09156009229419E-7,2.18613147564369E-6,1.09267774593347E-7,0.783006846904755,0.934668004512787,29.3778381347656,0,30,4,200,-1.14563990791794E-5,-0.230694457888603,-0.21978172659874,1,,,,,,,,,,,,,,,,
,3927466869.30009,196.65340423584,50.1284408569336,,,6,,,,28.6279585003514,,,1,,,,,,,,,,,,,,,,,,,,,,196.492263793945,196.780349731445,50.1284408569336,50.1284408569336,,,9.51259136199951,,1,0,0,0,0.013885498046875,28.3479976654053,2,1,1,196.814544677734,0,4232058208,196.640580919054,,,2.14051059807696E-6,1.09257865144586E-7,2.18847517724418E-6,1.0936820662074E-7,0.787351429462433,0.937044620513916,29.3900089263916,0,30,4,200,-1.0406200090074E-5,-0.230823650956154,-0.220000222325325,1,,,,,,,,,,,,,,,,
,3927467096.22192,204.198165893555,50.1284408569336,,,6,,,,28.6611138089768,,,1,,,,,,,,,,,,,,,,,,,,,,204.036468505859,204.344619750977,50.1284408569336,50.1284408569336,,,9.57400131225586,,1,0,0,0,0.013885498046875,28.8367557525635,2,1,1,204.35986328125,0,4232058368,204.188780212402,,,2.13425442399434E-6,1.09132315933952E-7,2.1849672177205E-6,1.09247325454863E-7,0.779529094696045,0.929602205753326,29.4444351196289,5.42627286911011,30,4,200,2.68393032456515E-5,-0.231019213795662,-0.219980016350746,1,,,,,,,,,,,,,,,,
,3927467323.97009,211.753601074219,50.1284408569336,,,6,,,,28.6954156792969,,,1,,,,,,,,,,,,,,,,,,,,,,211.593200683594,211.900405883789,50.1284408569336,50.1284408569336,,,9.64980983734131,,1,0,0,0,0.013885498046875,28.8367557525635,2,1,1,211.914001464844,0,4232058176,211.750433349609,,,2.12624175385193E-6,1.08836603502213E-7,2.17927809953249E-6,1.08956569356826E-7,0.775055527687073,0.930420815944672,29.4978160858154,,30,4,200,4.85409236716805E-6,-0.231216609477997,-0.220284909009933,1,,,,,,,,,,,,,,,,
,3927467542.77675,219.019493103027,50.1284408569336,,,6,,,,28.7250577557447,,,1,,,,,,,,,,,,,,,,,,,,,,218.852035522461,219.165115356445,50.1284408569336,50.1284408569336,,,9.72765922546387,,1,0,0,0,0.013885498046875,29.8142719268799,2,1,1,219.186950683594,0,4232058304,219.013725280762,,,2.11552417423054E-6,1.08110045508473E-7,2.16507965536807E-6,1.08223984562516E-7,0.782119989395142,0.933492064476013,29.5035514831543,5.16901826858521,30,4,200,-1.64031807798892E-5,-0.231260672211647,-0.220509812235832,1,,,,,,,,,,,,,,,,
,3927467770.1522,226.576721191406,50.1284408569336,,,6,,,,28.7618941541108,,,1,,,,,,,,,,,,,,,,,,,,,,226.416534423828,226.721572875977,50.1284408569336,50.1284408569336,,,9.79709148406982,,1,0,0,0,0.013885498046875,28.3479976654053,2,1,1,226.736907958984,0,4232058272,226.569384765625,,,2.11476821481262E-6,1.08339122566378E-7,2.17005251041111E-6,1.08463718614183E-7,0.771585643291473,0.934725165367127,29.5840339660645,0,30,4,200,-1.80560909939231E-5,-0.231771111488342,-0.220813095569611,1,,,,,,,,,,,,,,,,
,3927467997.60428,234.146003723145,50.1284408569336,,,6,,,,28.8000393530745,,,1,,,,,,,,,,,,,,,,,,,,,,233.980590820313,234.292007446289,50.1284408569336,50.1284408569336,,,9.88061904907227,,1,0,0,0,0,28.8367557525635,2,1,1,234.311416625977,0,4232058208,234.135411071777,,,2.10739841842878E-6,1.08110848550977E-7,2.16477655407066E-6,1.08241155393972E-7,0.76593005657196,0.929165840148926,29.6374473571777,0.194212630391121,30,4,200,-5.1177162276872E-6,-0.232089757919312,-0.221030473709106,1,,,,,,,,,,,,,,,,
,3927468224.72008,241.686645507813,50.1284408569336,,,6,,,,28.8375736507427,,,1,,,,,,,,,,,,,,,,,,,,,,241.539566040039,241.847640991211,50.1284408569336,50.1284408569336,,,9.96439170837402,,1,0,0,0,0.013885498046875,28.8367557525635,2,1,1,241.847640991211,0,4232058208,241.693885803223,,,2.10165597918179E-6,1.07746222732472E-7,2.15772032767223E-6,1.07874416139362E-7,0.768569707870483,0.930999279022217,29.6670627593994,5.44674777984619,30,4,200,-3.02440148516325E-5,-0.232428446412086,-0.22150830924511,1,,,,,,,,,,,,,,,,
,3927468442.3536,248.908050537109,50.1284408569336,,,6,,,,28.8712329679332,,,1,,,,,,,,,,,,,,,,,,,,,,248.748794555664,249.056442260742,50.1284408569336,50.1284408569336,,,10.0422115325928,,1,0,0,0,0.013885498046875,28.3479976654053,2,1,1,249.074920654297,0,4232058176,248.906221008301,,,2.10976208473622E-6,1.08179989287779E-7,2.16630494810347E-6,1.08306856246149E-7,0.767883360385895,0.930567622184753,29.7025718688965,0,30,4,200,9.35388925427105E-6,-0.232637315988541,-0.221708402037621,1,,,,,,,,,,,,,,,,
,3927468695.3604,257.332305908203,50.1284408569336,,,6,,,,28.9192755945166,,,1,,,,,,,,,,,,,,,,,,,,,,257.174163818359,257.469177246094,50.1284408569336,50.1284408569336,,,10.1551065444946,,1,0,0,0,0.013885498046875,28.8367557525635,2,1,1,257.490447998047,0,4232058208,257.322244262695,,,2.09613462280084E-6,1.07563957583695E-7,2.15444896433225E-6,1.07698752838894E-7,0.764769673347473,0.932638585567474,29.7661304473877,0.0175268482416868,30,4,200,-7.0881665124034E-6,-0.233218193054199,-0.22225783765316,1,,,,,,,,,,,,,,,,
,3927468939.99252,265.470443725586,50.1284408569336,,,6,,,,28.9617331563197,,,1,,,,,,,,,,,,,,,,,,,,,,265.308319091797,265.619689941406,50.1284408569336,50.1284408569336,,,10.2893114089966,,1,0,0,0,0.013885498046875,28.3479976654053,2,1,1,265.632568359375,0,4232058336,265.470388793945,,,2.09717266957189E-6,1.0771536187195E-7,2.15683157454783E-6,1.0785062589868E-7,0.761141657829285,0.928293526172638,29.8180084228516,0,30,4,200,-2.84751258732285E-5,-0.233426496386528,-0.222478568553925,1,,,,,,,,,,,,,,,,
,3927469193.53919,273.858551025391,50.1284408569336,,,6,,,,29.0113088208947,,,1,,,,,,,,,,,,,,,,,,,,,,273.695220947266,274.008728027344,50.1284408569336,50.1284408569336,,,10.3736963272095,,1,0,0,0,0.013885498046875,28.8367557525635,2,1,1,274.021881103516,0,4232058336,273.850497436523,,,2.09463339062547E-6,1.07470804040497E-7,2.15143450344447E-6,1.07597811101589E-7,0.765372157096863,0.926120758056641,29.8473968505859,0,30,4,200,-2.92311087832786E-5,-0.233557045459747,-0.222691461443901,1,,,,,,,,,,,,,,,,
,3927469437.41695,281.988662719727,50.1284408569336,,,6,,,,29.0565015679811,,,1,,,,,,,,,,,,,,,,,,,,,,281.825866699219,282.135559082031,50.1284408569336,50.1284408569336,,,10.4940805435181,,1,0,0,0,0.0128936767578125,28.8367557525635,2,1,1,282.151458740234,0,4232058240,281.987927246094,,,2.08526918041003E-6,1.07371112773889E-7,2.14998214097148E-6,1.07518087715946E-7,0.751524448394775,0.927015662193298,29.9489192962646,0.00032388188992627,30,4,200,-1.4545406884281E-5,-0.233757048845291,-0.222844004631042,1,,,,,,,,,,,,,,,,
,3927469689.78441,290.376846313477,50.1284408569336,,,6,,,,29.1086568654535,,,1,,,,,,,,,,,,,,,,,,,,,,290.217346191406,290.504608154297,50.1284408569336,50.1284408569336,,,10.7264356613159,,1,0,0,0,0.013885498046875,28.8367557525635,2,1,1,290.536346435547,0,4232058336,290.356553819444,,,2.09726538941886E-6,1.082307143195E-7,2.16648997113015E-6,1.08387183874615E-7,0.743232309818268,0.92173159122467,30.0266513824463,5.47965812683105,30,4,200,-2.28117241931614E-5,-0.233857482671738,-0.222809985280037,1,,,,,,,,,,,,,,,,
,3927469934.82521,298.493743896484,50.1284408569336,,,6,,,,29.1568065388632,,,1,,,,,,,,,,,,,,,,,,,,,,298.329406738281,298.649291992188,50.1284408569336,50.1284408569336,,,10.8318777084351,,1,0,0,0,0.013885498046875,28.8367557525635,2,1,1,298.658081054687,0,4232058272,298.496533203125,,,2.08118197478535E-6,1.0761987045556E-7,2.15496130416791E-6,1.07786535705221E-7,0.735937237739563,0.924603641033173,30.1088085174561,5.48714923858643,30,4,200,-1.22427318274276E-5,-0.23402039706707,-0.223045274615288,1,,,,,,,,,,,,,,,,
,3927470137.56913,298.628341674805,50.1284408569336,,,6,,,,29.162845724929,,,1,,,,,,,,,,,,,,,,,,,,,,298.48876953125,298.784149169922,50.1284408569336,50.1284408569336,,,10.8327512741089,,1,0,0,0,0,29.3255138397217,2,1,1,298.472534179687,0,4232058080,298.640063476562,,,2.06285982340321E-6,1.06762460562047E-7,2.13807770973246E-6,1.06931281291969E-7,0.73298305273056,0.925941705703735,30.1282691955566,0,30,4,200,5.88820585107896E-5,-0.233415141701698,-0.222706079483032,1,,,,,,,,,,,,,,,,
,3927470364.34571,290.901824951172,50.1284408569336,,,6,,,,29.1242789718663,,,1,,,,,,,,,,,,,,,,,,,,,,290.754058837891,291.073059082031,50.1284408569336,50.1284408569336,,,10.858024597168,,1,0,0,0,0.013885498046875,29.3255138397217,2,1,1,290.730590820313,0,4232058080,290.913708496094,,,2.12667887745914E-6,1.10167255850124E-7,2.20754925320585E-6,1.10351637098216E-7,0.729787111282349,0.932848155498505,30.1151657104492,INF,30,4,200,-2.97038805001648E-5,-0.230652466416359,-0.219012901186943,1,,,,,,,,,,,,,,,,
,3927470591.82566,283.281875610352,50.1284408569336,,,6,,,,29.0857669648366,,,1,,,,,,,,,,,,,,,,,,,,,,283.110534667969,283.453216552734,50.1284408569336,50.1284408569336,,,10.9132719039917,,1,0,0,0,0.013885498046875,28.8367557525635,2,1,1,283.110534667969,0,4232058272,283.279022216797,,,2.12309054993962E-6,1.10062389431665E-7,2.20497785343739E-6,1.10250403564119E-7,0.727274417877197,0.929271996021271,30.0827083587646,0.0235044192522764,30,4,200,-7.50038961996324E-5,-0.230576440691948,-0.21841236948967,1,,,,,,,,,,,,,,,,
,3927470818.55367,275.729415893555,50.1284408569336,,,6,,,,29.0499349700274,,,1,,,,,,,,,,,,,,,,,,,,,,275.571685791016,275.906646728516,50.1284408569336,50.1284408569336,,,10.9501609802246,,1,0,0,0,0.013885498046875,28.8367557525635,2,1,1,275.552185058594,0,4232057952,275.74645690918,,,2.14826025498518E-6,1.10646763417522E-7,2.21756999239324E-6,1.10806105721359E-7,0.750427842140198,0.939381659030914,29.965389251709,0,30,4,200,-4.12980298278853E-5,-0.230902254581451,-0.219312444329262,1,,,,,,,,,,,,,,,,
,3927471037.46998,268.423217773438,50.1284408569336,,,6,,,,29.0211962834954,,,1,,,,,,,,,,,,,,,,,,,,,,268.273040771484,268.586791992187,50.1284408569336,50.1284408569336,,,10.9940004348755,,1,0,0,0,0.013885498046875,29.3255138397217,2,1,1,268.259643554687,0,4232058560,268.429147338867,,,2.17679462745151E-6,1.1184417204647E-7,2.24167444089076E-6,1.11991985210539E-7,0.759758830070496,0.942164897918701,29.9031410217285,0,30,4,200,-5.36322113475762E-5,-0.230957061052322,-0.218911364674568,1,,,,,,,,,,,,,,,,
,3927471265.63258,260.808471679687,50.1284408569336,,,6,,,,28.9869120788889,,,1,,,,,,,,,,,,,,,,,,,,,,260.656036376953,260.974151611328,50.1284408569336,50.1284408569336,,,11.0594091415405,,1,0,0,0,0.013885498046875,28.8367557525635,2,1,1,260.642791748047,0,4232058144,260.816763305664,,,2.1959113991485E-6,1.12887802806528E-7,2.26183929910469E-6,1.13040804412334E-7,0.757636725902557,0.93617182970047,29.8735618591309,0,30,4,200,-0.000116774492198601,-0.231442764401436,-0.219416752457619,1,,,,,,,,,,,,,,,,
,3927471492.52048,253.23152923584,50.1284408569336,,,6,,,,28.9528292353406,,,1,,,,,,,,,,,,,,,,,,,,,,253.071166992187,253.407638549805,50.1284408569336,50.1284408569336,,,11.1363668441772,,1,0,0,0,0,28.8367557525635,2,1,1,253.055419921875,0,4232058368,253.240104675293,,,2.17459126758017E-6,1.11537006843537E-7,2.23466532068793E-6,1.11672706824595E-7,0.766685903072357,0.93758350610733,29.8017635345459,0,30,4,200,-2.41511315834941E-5,-0.231731936335564,-0.219991445541382,1,,,,,,,,,,,,,,,,
,3927471711.33973,245.947463989258,50.1284408569336,,,6,,,,28.923999227802,,,1,,,,,,,,,,,,,,,,,,,,,,245.786376953125,246.096817016602,50.1284408569336,50.1284408569336,,,11.2183570861816,,1,0,0,0,0.013885498046875,28.8367557525635,2,1,1,245.782363891602,0,4232058112,245.943034362793,,,2.22390674782053E-6,1.13810000156601E-7,2.28063250941606E-6,1.13941660441989E-7,0.77601420879364,0.941659033298492,29.7406520843506,0,30,4,200,-2.98229006148176E-5,-0.23197914659977,-0.219885408878326,1,,,,,,,,,,,,,,,,
,3927471938.6179,238.344932556152,50.1284408569336,,,6,,,,28.8893053140205,,,1,,,,,,,,,,,,,,,,,,,,,,238.195388793945,238.510726928711,50.1284408569336,50.1284408569336,,,11.2994222640991,,1,0,0,0,0,28.8367557525635,2,1,1,238.179138183594,0,4232058112,238.356796264648,,,2.21373207006521E-6,1.13238947443065E-7,2.26985751224922E-6,1.13369726683008E-7,0.777909994125366,0.946972370147705,29.704288482666,0,30,4,200,-3.98478769056965E-5,-0.232232555747032,-0.220566302537918,1,,,,,,,,,,,,,,,,
,3927472165.75727,230.786148071289,50.1284408569336,,,6,,,,28.854413659746,,,1,,,,,,,,,,,,,,,,,,,,,,230.625991821289,230.960418701172,50.1284408569336,50.1284408569336,,,11.3431844711304,,1,0,0,0,0.013885498046875,28.8367557525635,2,1,1,230.611877441406,0,4232058368,230.798823547363,,,2.20950802949619E-6,1.13005707073677E-7,2.26471748081243E-6,1.13132781209175E-7,0.778560996055603,0.943779826164246,29.6630153656006,0,30,4,200,-2.01281382032903E-5,-0.232688546180725,-0.221173658967018,1,,,,,,,,,,,,,,,,
,3927472385.39277,223.459457397461,50.1284408569336,,,6,,,,28.8252358285059,,,1,,,,,,,,,,,,,,,,,,,,,,223.319854736328,223.626403808594,50.1284408569336,50.1284408569336,,,11.4068212509155,,1,0,0,0,0.013885498046875,28.8367557525635,2,1,1,223.292510986328,0,4232058080,223.475234985352,,,2.24685742405796E-6,1.14766308844596E-7,2.30014987483918E-6,1.14887849526138E-7,0.784235537052154,0.946129381656647,29.6141605377197,0,30,4,200,-6.182435026858E-5,-0.232794940471649,-0.221326217055321,1,,,,,,,,,,,,,,,,
,3927472612.63034,215.885498046875,50.1284408569336,,,6,,,,28.7905213344729,,,1,,,,,,,,,,,,,,,,,,,,,,215.734252929687,216.050491333008,50.1284408569336,50.1284408569336,,,11.4535312652588,,1,0,0,0,0.013885498046875,28.8367557525635,2,1,1,215.720504760742,0,4232058176,215.891778564453,,,2.22166152580343E-6,1.13642328169213E-7,2.27711059064166E-6,1.13768871036371E-7,0.777994155883789,0.941191732883453,29.5981197357178,,30,4,200,-4.35028741776478E-5,-0.233076632022858,-0.221501931548119,1,,,,,,,,,,,,,,,,
,3927472840.15882,208.293617248535,50.1284408569336,,,6,,,,28.7560603585057,,,1,,,,,,,,,,,,,,,,,,,,,,208.144393920898,208.457153320313,50.1284408569336,50.1284408569336,,,11.5400218963623,,1,0,0,0,0.013885498046875,28.8367557525635,2,1,1,208.130081176758,0,4232057920,208.30729675293,,,2.24291366998235E-6,1.14403883704586E-7,2.29315370774723E-6,1.14520555964507E-7,0.79055118560791,0.949099481105804,29.5234718322754,0,30,4,200,-3.54390499524015E-6,-0.233453080058098,-0.221920877695084,1,,,,,,,,,,,,,,,,
,3927473059.29744,200.978981018066,50.1284408569336,,,6,,,,28.727725740211,,,1,,,,,,,,,,,,,,,,,,,,,,200.835556030273,201.142929077148,50.1284408569336,50.1284408569336,,,11.6301097869873,,1,0,0,0,0.013885498046875,28.8367557525635,2,1,1,200.815032958984,0,4232058176,200.989807128906,,,2.25448282039209E-6,1.14936896789199E-7,2.30345047449225E-6,1.15049966158657E-7,0.792832136154175,0.946577131748199,29.4831962585449,,30,4,200,7.54563279770082E-6,-0.233301967382431,-0.221679210662842,1,,,,,,,,,,,,,,,,
,3927473287.08377,193.385734558105,50.1284408569336,,,6,,,,28.6943134796818,,,1,,,,,,,,,,,,,,,,,,,,,,193.25325012207,193.553527832031,50.1284408569336,50.1284408569336,,,11.6965208053589,,1,0,0,0,0,28.8367557525635,2,1,1,193.21794128418,0,4232058176,193.410218980577,,,2.25598855479992E-6,1.14810952009649E-7,2.30096112870885E-6,1.14914530727732E-7,0.801162958145142,0.948409080505371,29.4194087982178,0,30,4,200,-1.38431505547487E-5,-0.233809769153595,-0.222158119082451,1,,,,,,,,,,,,,,,,
,3927473518.75043,185.663093566895,50.1284408569336,,,6,,,,28.6611726730653,,,1,,,,,,,,,,,,,,,,,,,,,,185.512893676758,185.834396362305,50.1284408569336,50.1284408569336,,,11.7517127990723,,1,0,0,0,0.013885498046875,28.8367557525635,2,1,1,185.491790771484,0,4232058176,185.674488830566,,,2.27556826256695E-6,1.15853126452707E-7,2.32105273705795E-6,1.1595798829144E-7,0.799266636371613,0.942121684551239,29.386474609375,0,30,4,200,4.05643877456896E-5,-0.233925014734268,-0.22242596745491,1,,,,,,,,,,,,,,,,
,3927473742.11629,178.218078613281,50.1284408569336,,,6,,,,28.6340233309415,,,1,,,,,,,,,,,,,,,,,,,,,,178.095550537109,178.388076782227,50.1284408569336,50.1284408569336,,,11.8103666305542,,1,0,0,0,0.013885498046875,28.3479976654053,2,1,1,178.048080444336,0,4232058496,178.244996812609,,,2.29495643659778E-6,1.16644880093281E-7,2.33790463945547E-6,1.1674445164581E-7,0.807445287704468,0.950975835323334,29.337215423584,0,30,4,200,-5.15913689014269E-6,-0.234155803918838,-0.222728595137596,1,,,,,,,,,,,,,,,,
,3927473974.06728,170.470237731934,50.1284408569336,,,6,,,,28.6023947663775,,,1,,,,,,,,,,,,,,,,,,,,,,170.352020263672,170.634780883789,50.1284408569336,50.1284408569336,,,11.8833322525024,,1,0,0,0,0.013885498046875,28.8367557525635,2,1,1,170.305694580078,0,4232058176,170.498531765408,,,2.31784444359233E-6,1.17917063195516E-7,2.36323443151789E-6,1.18021443396768E-7,0.802884876728058,0.948927462100983,29.319803237915,0,30,4,200,3.86942738259677E-5,-0.234677493572235,-0.222991302609444,1,,,,,,,,,,,,,,,,
,3927474204.84261,162.78182220459,50.1284408569336,,,6,,,,28.5718456173451,,,1,,,,,,,,,,,,,,,,,,,,,,162.657608032227,162.952362060547,50.1284408569336,50.1284408569336,,,11.9581613540649,,1,0,0,0,0.00152587890625,28.8367557525635,2,1,1,162.611282348633,0,4232058144,162.806070963542,,,2.32740423252271E-6,1.18281718419577E-7,2.37003121729839E-6,1.18377664919917E-7,0.807971239089966,0.946236312389374,29.2650108337402,0,30,4,200,8.76989506650716E-5,-0.234489485621452,-0.22284996509552,1,,,,,,,,,,,,,,,,
,3927474419.06558,155.65308380127,50.1284408569336,,,6,,,,28.5470434313676,,,1,,,,,,,,,,,,,,,,,,,,,,155.51252746582,155.815979003906,50.1284408569336,50.1284408569336,,,12.0123119354248,,1,0,0,0,0.013885498046875,28.8367557525635,2,1,1,155.490188598633,0,4232058336,155.665440368652,,,2.34482489234794E-6,1.18999687250836E-7,2.38505669739937E-6,1.1909360224764E-7,0.815162897109985,0.951908707618713,29.2193412780762,0,30,4,200,6.33062518318184E-5,-0.234820514917374,-0.223033934831619,1,,,,,,,,,,,,,,,,
,3927474633.9761,148.488662719727,50.1284408569336,,,6,,,,28.5227513833519,,,1,,,,,,,,,,,,,,,,,,,,,,148.335235595703,148.657928466797,50.1284408569336,50.1284408569336,,,12.0992431640625,,1,0,0,0,0,28.8367557525635,2,1,1,148.319396972656,0,4232058208,148.498692321777,,,2.3604579903706E-6,1.19751632182424E-7,2.40016048542119E-6,1.19840202395342E-7,0.816981732845306,0.953245997428894,29.1891956329346,0,30,4,200,8.37145635159686E-5,-0.234781369566917,-0.222708970308304,1,,,,,,,,,,,,,,,,
,3927474847.45676,141.346221923828,50.1284408569336,,,6,,,,28.4994614782972,,,1,,,,,,,,,,,,,,,,,,,,,,141.194290161133,141.517959594727,50.1284408569336,50.1284408569336,,,12.1172695159912,,1,0,0,0,0.013885498046875,29.3255138397217,2,1,1,141.17448425293,0,4232058144,141.361982727051,,,2.39443951049075E-6,1.21431053586561E-7,2.4339381405221E-6,1.21520607650996E-7,0.818929493427277,0.954332649707794,29.1597061157227,3.83299702662043E-5,30,4,200,7.98694818513468E-5,-0.235192313790321,-0.222973227500916,1,,,,,,,,,,,,,,,,
,3927475069.93338,133.946601867676,50.1284408569336,,,6,,,,28.4714753739374,,,1,,,,,,,,,,,,,,,,,,,,,,133.784271240234,134.125228881836,50.1284408569336,50.1284408569336,,,12.1666526794434,,1,0,0,0,0,28.8367557525635,2,1,1,133.767974853516,0,4232058240,133.950245666504,,,2.40226987756436E-6,1.21692024956293E-7,2.43897896350722E-6,1.21774941805963E-7,0.825009822845459,0.953855097293854,29.1061935424805,0,30,4,200,0.000117821895400994,-0.235051319003105,-0.222782507538795,1,,,,,,,,,,,,,,,,
,3927475283.27018,126.829048156738,50.1284408569336,,,6,,,,28.4500487732178,,,1,,,,,,,,,,,,,,,,,,,,,,126.663749694824,126.994346618652,50.1284408569336,50.1284408569336,,,12.1895742416382,,1,0,0,0,0,28.8367557525635,2,1,1,126.663749694824,0,4232058240,126.834520721436,,,2.42108520296686E-6,1.22638583761466E-7,2.45768742089529E-6,1.22722086887196E-7,0.825305700302124,0.951604664325714,29.0818138122559,3.86471874662675E-5,30,4,200,8.62984015839174E-5,-0.235189884901047,-0.222758248448372,1,,,,,,,,,,,,,,,,
,3927475497.3728,119.685096740723,50.1284408569336,,,6,,,,28.4293982606247,,,1,,,,,,,,,,,,,,,,,,,,,,119.528816223145,119.862525939941,50.1284408569336,50.1284408569336,,,12.2591075897217,,1,0,0,0,0,28.8367557525635,2,1,1,119.507667541504,0,4232058144,119.68736606174,,,2.43596375903397E-6,1.23314283876257E-7,2.47112216875206E-6,1.2339444633689E-7,0.828851163387299,0.951352179050446,29.0460052490234,0,30,4,200,0.000105490413261577,-0.235297828912735,-0.222549051046371,1,,,,,,,,,,,,,,,,
,3927475711.34277,112.552383422852,50.1284408569336,,,6,,,,28.4076158680662,,,1,,,,,,,,,,,,,,,,,,,,,,112.396270751953,112.723434448242,50.1284408569336,50.1284408569336,,,12.2781505584717,,1,0,0,0,0.001983642578125,28.8367557525635,2,1,1,112.381332397461,0,4232058016,112.563228607178,,,2.4670990815974E-6,1.24792212135904E-7,2.50050392464011E-6,1.24869760352306E-7,0.833377301692963,0.950034260749817,29.0041637420654,5.18188062414993E-5,30,4,200,8.35707542137243E-5,-0.235034823417664,-0.222449168562889,1,,,,,,,,,,,,,,,,
,3927475917.03414,105.703987121582,50.1284408569336,,,6,,,,28.3904579578666,,,1,,,,,,,,,,,,,,,,,,,,,,105.575798034668,105.874153137207,50.1284408569336,50.1284408569336,,,12.3092174530029,,1,0,0,0,0.013885498046875,28.8367557525635,2,1,1,105.533821105957,0,4232058208,105.733551873101,,,2.48358710591436E-6,1.25546036434415E-7,2.51540308057949E-6,1.25620611481032E-7,0.837148308753967,0.948963820934296,28.9710502624512,0,30,4,200,4.74274129373953E-5,-0.234406813979149,-0.221860453486443,1,,,,,,,,,,,,,,,,
,3927476131.34391,98.5652198791504,50.1284408569336,,,6,,,,28.3688385389291,,,1,,,,,,,,,,,,,,,,,,,,,,98.4210739135742,98.7304916381836,50.1284408569336,50.1284408569336,,,12.331561088562,,1,0,0,0,0.013885498046875,28.3479976654053,2,1,1,98.3999481201172,0,4232058112,98.5778686523438,,,2.51485129713548E-6,1.26914164559509E-7,2.54210706524988E-6,1.26977993759328E-7,0.847482323646545,0.94542533159256,28.9021778106689,5.25917639606632E-5,30,4,200,4.20488140662201E-5,-0.23347744345665,-0.22071897983551,1,,,,,,,,,,,,,,,,
,3927476336.59257,91.7064361572266,50.1284408569336,,,6,,,,28.3534640203451,,,1,,,,,,,,,,,,,,,,,,,,,,91.5759963989258,91.8678512573242,50.1284408569336,50.1284408569336,,,12.3393516540527,,1,0,0,0,0.013885498046875,29.3255138397217,2,1,1,91.5450210571289,0,4232058112,91.7234013875325,,,2.56779018050855E-6,1.29510091834702E-7,2.59428706463168E-6,1.29571113730914E-7,0.851274013519287,0.947332501411438,28.8744716644287,4.60704759461805E-5,30,4,200,3.63238104910124E-5,-0.232401385903358,-0.219405874609947,1,,,,,,,,,,,,,,,,
,3927476541.62429,84.8897018432617,50.1284408569336,,,6,,,,28.3364517680464,,,1,,,,,,,,,,,,,,,,,,,,,,84.7423706054687,85.0540390014648,50.1284408569336,50.1284408569336,,,12.3430614471436,,1,0,0,0,0.013885498046875,28.8367557525635,2,1,1,84.7253646850586,0,4232058144,84.8991386413574,,,2.60367851477049E-6,1.31169755982953E-7,2.62746008573856E-6,1.31226759954662E-7,0.859019100666046,0.947500348091126,28.8264045715332,0,30,4,200,3.37511264660861E-5,-0.230359569191933,-0.217331752181053,1,,,,,,,,,,,,,,,,
,3927476747.03565,77.9987678527832,50.1284408569336,,,6,,,,28.3204508154776,,,1,,,,,,,,,,,,,,,,,,,,,,77.8474960327148,78.1772994995117,50.1284408569336,50.1284408569336,,,12.3261909484863,,1,0,0,0,0.013885498046875,29.3255138397217,2,1,1,77.8202362060547,0,4232058304,78.0050651550293,,,2.67197207883134E-6,1.34482103311386E-7,2.69411586412701E-6,1.3453494746928E-7,0.865813195705414,0.950539290904999,28.7879524230957,0,30,4,200,7.38462767913006E-6,-0.227727264165878,-0.214400961995125,1,,,,,,,,,,,,,,,,
,3927476942.54218,71.4408416748047,50.1284408569336,,,6,,,,28.309702130662,,,1,,,,,,,,,,,,,,,,,,,,,,71.2989883422852,71.6108703613281,50.1284408569336,50.1284408569336,,,12.3234939575195,,1,0,0,0,0,28.8367557525635,2,1,1,71.2708129882813,0,4232058144,71.4562919616699,,,2.74388027038292E-6,1.38027163009123E-7,2.76509552357082E-6,1.38076886811354E-7,0.869802117347717,0.950907707214355,28.7616653442383,0,30,4,200,1.81235100171762E-5,-0.224781885743141,-0.211102649569511,1,,,,,,,,,,,,,,,,
,3927477147.35225,64.5801467895508,50.1284408569336,,,6,,,,28.2935956555689,,,1,,,,,,,,,,,,,,,,,,,,,,64.4255447387695,64.7547378540039,50.1284408569336,50.1284408569336,,,12.1900110244751,,1,0,0,0,0.013885498046875,29.3255138397217,2,1,1,64.4055557250977,0,4232058176,64.5990456475152,,,2.83998505465002E-6,1.42695364291015E-7,2.85893551593271E-6,1.42741083873774E-7,0.878923714160919,0.95411628484726,28.7136650085449,0,30,4,200,3.23846761602908E-5,-0.220395743846893,-0.206321209669113,1,,,,,,,,,,,,,,,,
,3927477342.94244,58.0319557189941,50.1284408569336,,,6,,,,28.2830906340506,,,1,,,,,,,,,,,,,,,,,,,,,,57.8806190490723,58.2023773193359,50.1284408569336,50.1284408569336,,,11.3984518051147,,1,0,0,0,0.013885498046875,28.3479976654053,2,1,1,57.8615341186523,0,4232057856,58.0483444213867,,,2.9809704414259E-6,1.49598220665633E-7,2.99688331100935E-6,1.49635940999698E-7,0.889210104942322,0.953050673007965,28.6593227386475,1.61210700753145E-5,30,4,200,4.34356661571655E-5,-0.215403094887733,-0.20068271458149,1,,,,,,,,,,,,,,,,
,3927477539.70121,51.4387130737305,50.1284408569336,,,6,,,,28.2726381505711,,,1,,,,,,,,,,,,,,,,,,,,,,51.293643951416,51.6082916259766,50.1284408569336,50.1284408569336,,,10.5921745300293,,1,0,0,0,0.013885498046875,28.3479976654053,2,1,1,51.2691345214844,0,4232058016,51.4530754089355,,,3.20287900199489E-6,1.60167443657067E-7,3.20907759740345E-6,1.60182323177892E-7,0.927424907684326,0.96001660823822,28.5006008148193,5.33859539031982,30,4,200,3.89752749470063E-5,-0.209494143724442,-0.193644002079964,1,,,,,,,,,,,,,,,,
,3927477735.60296,44.888256072998,50.1284408569336,,,6,,,,28.2620668730792,,,1,,,,,,,,,,,,,,,,,,,,,,44.7349319458008,45.0574531555176,50.1284408569336,50.1284408569336,,,9.64376354217529,,1,0,0,0,0.013885498046875,28.8367557525635,2,1,1,44.7190589904785,0,4232058048,44.8968391418457,,,3.47193817463484E-6,1.73526825900523E-7,3.47624592631817E-6,1.73537614484933E-7,0.93541556596756,0.957307815551758,28.4446792602539,0,30,4,200,3.25897672155406E-5,-0.202843338251114,-0.185880288481712,1,,,,,,,,,,,,,,,,
,3927477922.69779,38.6248321533203,50.1284408569336,,,6,,,,28.2565737399949,,,1,,,,,,,,,,,,,,,,,,,,,,38.4734191894531,38.7921867370605,50.1284408569336,50.1284408569336,,,8.97274971008301,,1,0,0,0,0.013885498046875,28.8367557525635,2,1,1,38.4574775695801,0,4232056832,38.6284900665283,,,3.96858809499491E-6,1.98221137671716E-7,3.97228376552109E-6,1.98231484553691E-7,0.946308672428131,0.966398119926453,28.4143981933594,0,30,4,200,4.10367247241084E-5,-0.197995841503143,-0.178757071495056,1,,,,,,,,,,,,,,,,
,3927478117.99047,32.0932474136353,50.1284408569336,,,6,,,,28.2460207655615,,,1,,,,,,,,,,,,,,,,,,,,,,31.9310779571533,32.2554168701172,50.1284408569336,50.1284408569336,,,8.23069477081299,,1,0,0,0,0,28.3479976654053,2,1,1,31.9310779571533,0,4232058016,32.0907257080078,,,5.11429762576163E-6,2.55310974296946E-7,5.11745442473022E-6,2.5532006445584E-7,0.957288086414337,0.974254310131073,28.3746280670166,0,30,4,200,3.77162286895327E-5,-0.195684224367142,-0.171085953712463,1,,,,,,,,,,,,,,,,
,3927478323.63877,29.4538259506226,50.1284408569336,,,6,,,,28.2408118035012,,,1,,,,,,,,,,,,,,,,,,,,,,29.3958759307861,29.5345268249512,50.1284408569336,50.1284408569336,,,7.67740345001221,,1,0,0,0,0,28.8367557525635,2,1,1,29.3694515228271,0,4232058368,29.4666502210829,,,6.16776072789607E-6,3.08568402977796E-7,6.17404627394914E-6,3.08583628872501E-7,0.921651065349579,0.935114562511444,28.405200958252,0,30,4,200,-0.000616128731053322,-0.206770241260529,-0.175933584570885,1,,,,,,,,,,,,,,,,
,3927478501.09337,26.4937286376953,50.1284408569336,,,6,,,,28.2408118035012,,,1,,,,,,,,,,,,,,,,,,,,,,26.4170207977295,26.5815868377686,50.1284408569336,50.1284408569336,,,7.2868332862854,,1,0,0,0,0.013885498046875,28.8367557525635,2,1,1,26.4058704376221,0,4232058240,26.5012903213501,,,9.29076904298696E-6,4.63649484993534E-7,9.29249727165172E-6,4.636548912067E-7,0.966005206108093,0.971586763858795,28.3117866516113,0,30,4,200,-0.000598423765040934,-0.210734680294991,-0.165060058236122,1,,,,,,,,,,,,,,,,
,3927478689.07077,23.3658838272095,50.1284408569336,,,6,,,,28.2357326560963,,,1,,,,,,,,,,,,,,,,,,,,,,23.2956600189209,23.4509353637695,50.1284408569336,50.1284408569336,,,6.82566213607788,,1,0,0,0,0.013885498046875,28.8367557525635,2,1,1,23.2808322906494,0,4232058048,23.3764796786838,,,1.26896808786598E-5,6.32978983465822E-7,1.26900090244608E-5,6.32980339190455E-7,0.984590113162994,0.986214458942413,28.2618217468262,0,30,4,200,0.00020668632350862,-0.216490924358368,-0.155919164419174,1,,,,,,,,,,,,,,,,
,3927478867.47795,20.3939685821533,50.1284408569336,,,6,,,,28.2357326560963,,,1,,,,,,,,,,,,,,,,,,,,,,20.3275814056396,20.470682144165,50.1284408569336,50.1284408569336,,,6.41410064697266,,1,0,0,0,0.013885498046875,28.8367557525635,2,1,1,20.3172550201416,0,4232058400,20.4071632385254,,,1.67857683538927E-5,8.37248429054315E-7,1.67857708209683E-5,8.37248490585986E-7,0.989024221897125,0.98903089761734,28.2371826171875,0,30,4,200,-0.000338216952513903,-0.225749805569649,-0.145714536309242,1,,,,,,,,,,,,,,,,
,3927479046.36754,17.4276351928711,50.1284408569336,,,6,,,,28.2357326560963,,,1,,,,,,,,,,,,,,,,,,,,,,17.3478565216064,17.5074138641357,50.1284408569336,50.1284408569336,,,6.03624057769775,,1,0,0,0,0,28.8367557525635,2,1,1,17.3478565216064,0,4232058144,17.4214557647705,,,2.31774113898187E-5,1.15605257434387E-6,2.31775053501221E-5,1.15605327297267E-6,0.989120006561279,0.989441812038422,28.2456607818604,9.97650658973726E-6,30,4,200,0.00018956686835736,-0.244823455810547,-0.134867683053017,1,,,,,,,,,,,,,,,,
,3927479233.35607,14.3349022865295,50.1284408569336,,,6,,,,28.2307035082423,,,1,,,,,,,,,,,,,,,,,,,,,,14.2570714950562,14.4179811477661,50.1284408569336,50.1284408569336,,,5.64135694503784,,1,0,0,0,0.013885498046875,28.8367557525635,2,1,1,14.251823425293,0,4232058336,14.3320246696472,,,3.37309095675632E-5,1.68249206626511E-6,3.37309718428835E-5,1.68249243398425E-6,0.98679107427597,0.986914873123169,28.2375164031982,0,30,4,200,0.000118511474283878,-0.279532492160797,-0.119617216289043,1,,,,,,,,,,,,,,,,
,3927479412.43761,11.3747410774231,50.1284408569336,,,6,,,,28.2307035082423,,,1,,,,,,,,,,,,,,,,,,,,,,11.291090965271,11.4653787612915,50.1284408569336,50.1284408569336,,,5.23455905914307,,1,0,0,0,0,28.8367557525635,2,1,1,11.2841033935547,0,4232058336,11.3742060661316,,,5.10773148383735E-5,2.54763884178871E-6,5.10773155080608E-5,2.54763886711719E-6,0.989758610725403,0.989758908748627,28.2310047149658,0,30,4,200,0.000144525343785062,-0.338900595903397,-0.097117468714714,1,,,,,,,,,,,,,,,,
,3927479592.22108,8.31980466842651,50.1284408569336,,,6,,,,28.2307035082423,,,1,,,,,,,,,,,,,,,,,,,,,,8.24073791503906,8.40247535705566,50.1284408569336,50.1284408569336,,,4.87820100784302,,1,0,0,0,0.013885498046875,28.3479976654053,6,1,1,8.23713397979736,0,4232058336,8.31577682495117,,,8.12320296314718E-5,4.05161628338424E-6,8.12321114944641E-5,4.05161581185707E-6,0.991933226585388,0.992073774337769,28.2250328063965,0,30,4,200,0.000205573305720463,-0.448441624641418,-0.064342550933361,1,,,,,,,,,,,,,,,,
,3927479773.06439,5.36810421943665,50.1284408569336,,,6,,,,28.2307035082423,,,1,,,,,,,,,,,,,,,,,,,,,,5.29324007034302,5.45017194747925,50.1284408569336,50.1284408569336,,,4.26507997512817,,1,0,0,0,0.013885498046875,28.8367557525635,6,1,1,5.28163242340088,0,4232058336,5.36688284873962,,,0.000131725704961087,6.57007093192352E-6,0.000131726171850233,6.57007032539772E-6,0.992431998252869,0.992928802967071,28.2205009460449,5.29751300811768,30,4,200,0.000402825302444398,-0.621459305286407,0.000853556615766138,1,,,,,,,,,,,,,,,,
,3927479954.04884,2.58929800987244,50.1284408569336,,,6,,,,28.2307035082423,,,1,,,,,,,,,,,,,,,,,,,,,,2.52483224868774,2.6608681678772,50.1284408569336,50.1284408569336,,,3.11929821968079,,1,0,0,0,0,28.8367557525635,6,1,1,2.51772785186768,0,4232058272,2.5924239397049,,,0.000230855676949395,1.15144151050704E-5,0.000230856977532418,1.15144129259298E-5,0.991866528987885,0.992617070674896,28.2177867889404,0,30,4,200,0.000813650258351117,-0.954460620880127,0.137403637170792,1,,,,,,,,,,,,,,,,
,3927480070.75199,1.79918599128723,50.1284408569336,,,6,,,,28.2307035082423,,,1,,,,,,,,,,,,,,,,,,,,,,1.79893064498901,1.80070316791534,50.1284408569336,50.1284408569336,,,2.59274625778198,,1,0,0,0,0.013885498046875,29.3255138397217,1,1,1,1.79944133758545,0,4232058208,1.7997697353363,,,0.000273101979752159,1.36211921005819E-5,0.000273103489631624,1.36211844891274E-5,0.99616414308548,0.998406529426575,28.2174968719482,0,30,4,200,8.78692881087773E-5,-1.08748054504395,0.195588290691376,1,,,,,,,,,,,,,,,,