File: Data used in paper/Case study 4/ML_Poot_20240625_7_QHS_0-QHS1032G_SmBa0p9K0p1CuBO5_DC-12p2mg_MvT_50oe_20240628 (1).dat
[Header]
; MPMS3 Data File (default extension .dat)
; Copyright (c) 2007, Quantum Design, Inc. All rights reserved.
TITLE,
FILEOPENTIME,3928752870.13108,06/28/2024,4:14 pm
BYAPP,MPMS3 w/ AC,1.0,1.1
INFO,MPMS3 Measurement Release 1.1.16 Build 419, MultiVu Release 2.3.4.15,APPNAME
INFO,Linear Motor Servo Controller,MOTOR_MODULE_NAME
INFO,3101-100 F0,MOTOR_HW_VERSION
INFO,MMC1118,MOTOR_SERIAL_NUMBER
INFO,01.04.28,MOTOR_SOFTWARE_VERSION
INFO,Quantum Design Squid Module,SQUID_MODULE_NAME
INFO,3101-501 B0,SQUID_HW_VERSION
INFO,SQM313,SQUID_SERIAL_NUMBER
INFO,01.03.04,SQUID_SOFTWARE_VERSION
INFO,Quantum Design VSM Oven,OVEN_MODULE_NAME
INFO,3101-201 A3,OVEN_HW_VERSION
INFO,OVB345,OVEN_SERIAL_NUMBER
INFO,01.07.07,OVEN_SOFTWARE_VERSION
INFO,SQUID AC,AC_MODULE_NAME
INFO,3101-401 G0,AC_HW_VERSION
INFO,SAC210,AC_SERIAL_NUMBER
INFO,SQUID AC 00.95.07,AC_SOFTWARE_VERSION
INFO,TCI318,COIL_SERIAL_NUMBER
INFO,0,MOMENT_UNITS
INFO,ML_Poot_20240625_7_QHS_0-QHS1032G_SmBa0p9K0p1CuBO5_DC-12p2mg_MvT_50oe_20240628.dat,SAMPLE_MATERIAL
INFO,,SAMPLE_COMMENT
INFO,12.2,SAMPLE_MASS
INFO,,SAMPLE_VOLUME
INFO,,SAMPLE_MOLECULAR_WEIGHT
INFO,,SAMPLE_SIZE
INFO,,SAMPLE_SHAPE
INFO,Straw,SAMPLE_HOLDER
INFO,Standard,SAMPLE_HOLDER_DETAIL
INFO,65.17,SAMPLE_OFFSET
DATATYPE,COMMENT,1
DATATYPE,TIME,2
STARTUPAXIS,X,2
STARTUPAXIS,Y1,5
FIELDGROUP, VSM,2,3,4,5,6,8,9,10,11,14,15
FIELDGROUP, DC, 2,3,4,14,56,57,58,59,60,61,62,63,64,65,66,67,68,69
FIELDGROUP, AC, 2,3,4,11,16,17,18,19,20,21,22,23,24,25,26,27,28,29,30
STARTUPGROUP, All
[Data]
Comment,Time Stamp (sec),Temperature (K),Magnetic Field (Oe),Moment (emu),M. Std. Err. (emu),Transport Action,Averaging Time (sec),Frequency (Hz),Peak Amplitude (mm),Center Position (mm),Lockin Signal' (V),Lockin Signal (V),Range,M. Quad. Signal (emu),AC Moment (emu),AC M. Std Err. (emu),AC Phase (deg),AC Phase Std. Err. (deg),AC Susceptibility (emu/Oe),AC Suscept. Std Err. (emu/Oe),AC X' (emu/Oe),AC X' Std Err. (emu/Oe),AC X'' (emu/Oe),AC X'' Std Err. (emu/Oe),AC Drive (Oe),AC Frequency (Hz),AC Averaging Time (sec),AC Cycles,AC Range,AC Measure Type,AC Signal' (V),AC Signal'' (V),AC Trim Coil Ratio,AC Trim Coil Phase,Min. Temperature (K),Max. Temperature (K),Min. Field (Oe),Max. Field (Oe),Mass (grams),Motor Lag (deg),Pressure (Torr),Measure Count,Measurement Number,SQUID Status (code),Motor Status (code),Measure Status (code),Motor Current (amps),Motor Temp. (C),Temp. Status (code),Field Status (code),Chamber Status (code),Chamber Temp (K),Redirection State,Evercool Status,Average Temp (K),Rotation Angle (deg),Rotator state,DC Moment Fixed Ctr (emu),DC Moment Err Fixed Ctr (emu),DC Moment Free Ctr (emu),DC Moment Err Free Ctr (emu),DC Fixed Fit,DC Free Fit,DC Calculated Center (mm),DC Calculated Center Err (mm),DC Scan Length (mm),DC Scan Time (s),DC Number of Points,DC Squid Drift,DC Min V (V),DC Max V (V),DC Scans per Measure,Map 01,Map 02,Map 03,Map 04,Map 05,Map 06,Map 07,Map 08,Map 09,Map 10,Map 11,Map 12,Map 13,Map 14,Map 15,Map 16
,3928754384.9929,1.79933857917786,50.0059928894043,,,3,,,,26.5936660766602,,,,,,,,,,,,,,,,,,,,,,,,,1.79933857917786,1.79933857917786,50.0059928894043,50.0059928894043,,,2.73870396614075,,0,,,,,,5,1,1,1.79933857917786,0,0,0,,,,,,,,,,,,,,,,,,,,,,,,,,,,,,,,,
,3928754430.68928,1.91693633794785,50.0059928894043,,,6,,,,26.5936660766602,,,1,,,,,,,,,,,,,,,,,,,,,,1.8510320186615,1.97345376014709,50.0059928894043,50.0059928894043,,,2.82706809043884,,1,0,0,0,0.013885498046875,28.3479976654053,6,1,1,1.98284065723419,0,4232057888,1.91120444536209,,,5.63912247718474E-5,2.81289830784576E-6,5.63912284592346E-5,2.81289818484038E-6,0.984029293060303,0.984036087989807,26.5919036865234,0,30,4,200,-0.000240403489442542,-0.355518966913223,-0.0860483050346375,1,,,,,,,,,,,,,,,,
,3928754450.35369,2.1898295879364,50.0059928894043,,,6,,,,26.5936660766602,,,1,,,,,,,,,,,,,,,,,,,,,,2.12266898155212,2.25087380409241,50.0059928894043,50.0059928894043,,,3.01558041572571,,1,0,0,0,0.013885498046875,28.3479976654053,6,1,1,2.25699019432068,0,4232057952,2.18395156860352,,,5.19242987095862E-5,2.59006295930858E-6,5.19243007867146E-5,2.59006300192511E-6,0.984421730041504,0.984423279762268,26.5944843292236,3.41376447677612,30,4,200,-0.000245520874159411,-0.341545909643173,-0.0935132503509522,1,,,,,,,,,,,,,,,,
,3928754469.90963,2.46392405033112,50.0059928894043,,,6,,,,26.5936660766602,,,1,,,,,,,,,,,,,,,,,,,,,,2.39510679244995,2.5294303894043,50.0059928894043,50.0059928894043,,,3.18880367279053,,1,0,0,0,0.013885498046875,28.3479976654053,6,1,1,2.53274130821228,0,4232058176,2.45976502895355,,,4.78020855136629E-5,2.38445689814922E-6,4.78020876916606E-5,2.38445695817764E-6,0.983988225460052,0.983989536762238,26.5944290161133,0,30,4,200,-0.00022375320259016,-0.328676611185074,-0.100066088140011,1,,,,,,,,,,,,,,,,
,3928754498.23632,2.83723986148834,50.0059928894043,,,6,,,,26.5986999214455,,,1,,,,,,,,,,,,,,,,,,,,,,2.77918910980225,2.89331912994385,50.0059928894043,50.0059928894043,,,3.38920617103577,,1,0,0,0,0.013885498046875,29.3255138397217,6,1,1,2.89529061317444,0,4232058208,2.83758854866028,,,4.26909984436136E-5,2.12947591583195E-6,4.26910613266952E-5,2.12947548647363E-6,0.98491632938385,0.985027730464935,26.5917949676514,,30,4,200,-0.000152176799019799,-0.31183847784996,-0.1079186424613,1,,,,,,,,,,,,,,,,
,3928754517.81396,3.1036810874939,50.0059928894043,,,6,,,,26.5986999214455,,,1,,,,,,,,,,,,,,,,,,,,,,3.03251767158508,3.16789746284485,50.0059928894043,50.0059928894043,,,3.52464079856873,,1,0,0,0,0.013885498046875,28.3479976654053,6,1,1,3.17484450340271,0,4232057984,3.09741282463074,,,3.96294283150199E-5,1.97678939027474E-6,3.9629461945203E-5,1.97678914459245E-6,0.983992278575897,0.984053134918213,26.5934371948242,2.06654320322741E-7,30,4,200,-0.000166368423379026,-0.302273571491241,-0.112550392746925,1,,,,,,,,,,,,,,,,
,3928754537.46519,3.38559937477112,50.0059928894043,,,6,,,,26.5986999214455,,,1,,,,,,,,,,,,,,,,,,,,,,3.31750726699829,3.44682884216309,50.0059928894043,50.0059928894043,,,3.65761637687683,,1,0,0,0,0.013885498046875,28.3479976654053,6,1,1,3.45826029777527,0,4232057888,3.38098891576131,,,3.66707718034885E-5,1.82919162432405E-6,3.66707978750927E-5,1.82919131591022E-6,0.98448771238327,0.984544515609741,26.5936965942383,INF,30,4,200,-0.00012364967551548,-0.292291194200516,-0.117092669010162,1,,,,,,,,,,,,,,,,
,3928754557.15548,3.67210948467255,50.0059928894043,,,6,,,,26.5986999214455,,,1,,,,,,,,,,,,,,,,,,,,,,3.60120701789856,3.73334956169128,50.0059928894043,50.0059928894043,,,3.7810652256012,,1,0,0,0,0.013885498046875,27.3704795837402,6,1,1,3.74301195144653,0,4232058208,3.6662828207016,,,3.40631868340538E-5,1.69911661976203E-6,3.40632203642231E-5,1.69911645420822E-6,0.984699010848999,0.984769880771637,26.5931510925293,0,30,4,200,-0.000112594265374355,-0.283437550067902,-0.120639204978943,1,,,,,,,,,,,,,,,,
,3928754576.79404,3.95243215560913,50.0059928894043,,,6,,,,26.5986999214455,,,1,,,,,,,,,,,,,,,,,,,,,,3.88830232620239,4.01327276229858,50.0059928894043,50.0059928894043,,,3.89377570152283,,1,0,0,0,0.013885498046875,28.3479976654053,6,1,1,4.02244853973389,0,4232058240,3.94908367262946,,,3.17501829632781E-5,1.58373111918774E-6,3.17502218799557E-5,1.58373094350018E-6,0.985095739364624,0.985185623168945,26.5925312042236,0,30,4,200,-8.70525109348819E-5,-0.275609403848648,-0.123963236808777,1,,,,,,,,,,,,,,,,
,3928754596.76172,4.24534702301025,50.0059928894043,,,6,,,,26.5986999214455,,,1,,,,,,,,,,,,,,,,,,,,,,4.17172145843506,4.30997705459595,50.0059928894043,50.0059928894043,,,4.00229167938232,,1,0,0,0,0.013885498046875,28.3479976654053,6,1,1,4.31897258758545,0,4232057952,4.2373893737793,,,2.96200188640813E-5,1.47747887025675E-6,2.96200463729842E-5,1.47747860342322E-6,0.984980583190918,0.985054612159729,26.5930805206299,5.15687608718872,30,4,200,-8.49948046379723E-5,-0.268463641405106,-0.127021700143814,1,,,,,,,,,,,,,,,,
,3928754616.63829,4.51544761657715,50.0059928894043,,,6,,,,26.5986999214455,,,1,,,,,,,,,,,,,,,,,,,,,,4.45661687850952,4.57427835464478,50.0059928894043,50.0059928894043,,,4.09377813339233,,1,0,0,0,0.013885498046875,28.3479976654053,6,1,1,4.57427835464478,0,4232057952,4.52105584144592,,,2.78009191806003E-5,1.38672407713932E-6,2.78009593077813E-5,1.38672392451183E-6,0.985774576663971,0.985884189605713,26.5920505523682,0,30,4,200,-6.72107198624872E-5,-0.262015342712402,-0.129552781581879,1,,,,,,,,,,,,,,,,
,3928754636.42619,4.79775524139404,50.0059928894043,,,6,,,,26.5986999214455,,,1,,,,,,,,,,,,,,,,,,,,,,4.72451066970825,4.85518789291382,50.0059928894043,50.0059928894043,,,4.18151187896729,,1,0,0,0,0.013885498046875,28.8367557525635,6,1,1,4.87099981307983,0,4232058016,4.78343641757965,,,2.61749652257312E-5,1.30563508419923E-6,2.61750022235979E-5,1.30563481557303E-6,0.985035717487335,0.985144257545471,26.591911315918,3.41372013092041,30,4,200,-7.97913962742314E-5,-0.256734073162079,-0.13171698153019,1,,,,,,,,,,,,,,,,
,3928754656.20826,5.09950256347656,50.0059928894043,,,6,,,,26.5986999214455,,,1,,,,,,,,,,,,,,,,,,,,,,5.02667999267578,5.16387033462524,50.0059928894043,50.0059928894043,,,4.2715916633606,,1,0,0,0,0.013885498046875,28.3479976654053,6,1,1,5.17232513427734,0,4232058176,5.09434013366699,,,2.45564315338633E-5,1.22489032850625E-6,2.45564603472497E-5,1.22489009989364E-6,0.98559045791626,0.985685169696808,26.5924777984619,0.188744783401489,30,4,200,-8.66563568706624E-5,-0.250881284475327,-0.133622020483017,1,,,,,,,,,,,,,,,,
,3928754675.77349,5.40092587471008,50.0059928894043,,,6,,,,26.5986999214455,,,1,,,,,,,,,,,,,,,,,,,,,,5.32684993743897,5.46846961975098,50.0059928894043,50.0059928894043,,,4.35635089874268,,1,0,0,0,0.013885498046875,28.8367557525635,6,1,1,5.4750018119812,0,4232057952,5.39421010017395,,,2.31100318191834E-5,1.15273791716266E-6,2.3110046394661E-5,1.15273753500186E-6,0.985906541347504,0.985974967479706,26.5934677124023,6.44329595565796,30,4,200,3.40564147336409E-5,-0.245609432458878,-0.135904103517532,1,,,,,,,,,,,,,,,,
,3928754695.54693,5.70950102806091,50.0059928894043,,,6,,,,26.5986999214455,,,1,,,,,,,,,,,,,,,,,,,,,,5.63714790344238,5.7743616104126,50.0059928894043,50.0059928894043,,,4.43780279159546,,1,0,0,0,0.014801025390625,28.8367557525635,6,1,1,5.78185415267944,0,4232058048,5.7030791759491,,,2.175090608601E-5,1.08494799044041E-6,2.17509291374306E-5,1.08494760787153E-6,0.985660016536713,0.985758781433105,26.5923595428467,,30,4,200,-3.79047669412103E-5,-0.24075174331665,-0.137076258659363,1,,,,,,,,,,,,,,,,
,3928754715.1539,6.00869584083557,50.0059928894043,,,6,,,,26.5986999214455,,,1,,,,,,,,,,,,,,,,,,,,,,5.931565284729,6.07568597793579,50.0059928894043,50.0059928894043,,,4.51514101028442,,1,0,0,0,0.013885498046875,28.8367557525635,6,1,1,6.08582639694214,0,4232057952,6.0038595199585,,,2.05326288786109E-5,1.02417830387598E-6,2.05326452251472E-5,1.02417811268578E-6,0.985739231109619,0.985808253288269,26.5934104919434,0,30,4,200,-2.21289756154874E-5,-0.236265629529953,-0.138257279992104,1,,,,,,,,,,,,,,,,
,3928754734.75782,6.31982707977295,50.0059928894043,,,6,,,,26.5986999214455,,,1,,,,,,,,,,,,,,,,,,,,,,6.24382019042969,6.39046001434326,50.0059928894043,50.0059928894043,,,4.58911800384521,,1,0,0,0,0.013885498046875,28.3479976654053,6,1,1,6.39583396911621,0,4232058304,6.31248025894165,,,1.94112748310793E-5,9.6824611364879E-7,1.94112970773944E-5,9.68245772876389E-7,0.985659539699554,0.985764384269714,26.592170715332,3.41374230384827,30,4,200,1.07068899524165E-5,-0.231741189956665,-0.139286950230598,1,,,,,,,,,,,,,,,,
,3928754754.56593,6.62714385986328,50.0059928894043,,,6,,,,26.5986999214455,,,1,,,,,,,,,,,,,,,,,,,,,,6.54940891265869,6.69455432891846,50.0059928894043,50.0059928894043,,,4.66044282913208,,1,0,0,0,0.013885498046875,29.3255138397217,6,1,1,6.70487880706787,0,4232057984,6.62190608978271,,,1.83687564051574E-5,9.16242227115745E-7,1.83687815899213E-5,9.16242030432409E-7,0.985835313796997,0.985947668552399,26.5919818878174,0,30,4,200,4.22373414039612E-5,-0.22703817486763,-0.139380812644958,1,,,,,,,,,,,,,,,,
,3928754774.73791,6.94384360313416,50.0059928894043,,,6,,,,26.5986999214455,,,1,,,,,,,,,,,,,,,,,,,,,,6.86700439453125,7.01315975189209,50.0059928894043,50.0059928894043,,,4.72714757919312,,1,0,0,0,0.013885498046875,28.3479976654053,6,1,1,7.02068281173706,0,4232057920,6.93786787986755,,,1.73974843260845E-5,8.67792641239343E-7,1.7397501171144E-5,8.67792482932375E-7,0.986013650894165,0.986096143722534,26.5929775238037,0,30,4,200,0.000109137268736958,-0.221419587731361,-0.138157531619072,1,,,,,,,,,,,,,,,,
,3928754794.52856,7.25738167762756,50.0059928894043,,,6,,,,26.5986999214455,,,1,,,,,,,,,,,,,,,,,,,,,,7.18184900283814,7.32927942276001,50.0059928894043,50.0059928894043,,,4.79263639450073,,1,0,0,0,0.013885498046875,29.3255138397217,6,1,1,7.33291435241699,0,4232058080,7.25392022132874,,,1.6511200501827E-5,8.23583663773281E-7,1.65112264561026E-5,8.23583395891405E-7,0.986087143421173,0.986224114894867,26.5913524627686,0,30,4,200,4.83378134958912E-5,-0.215315088629723,-0.136617839336395,1,,,,,,,,,,,,,,,,
,3928754814.29373,7.56848287582397,50.0059928894043,,,6,,,,26.5986999214455,,,1,,,,,,,,,,,,,,,,,,,,,,7.49166584014893,7.63665246963501,50.0059928894043,50.0059928894043,,,4.8522515296936,,1,0,0,0,0.013885498046875,28.8367557525635,6,1,1,7.64529991149902,0,4232057952,7.56237001419067,,,1.56942469434579E-5,7.82835504586578E-7,1.56942728933362E-5,7.82835220384653E-7,0.985913336277008,0.986057221889496,26.5911235809326,0,30,4,200,0.000130647793412209,-0.210435792803764,-0.135108709335327,1,,,,,,,,,,,,,,,,
,3928754833.96413,7.88123512268066,50.0059928894043,,,6,,,,26.5986999214455,,,1,,,,,,,,,,,,,,,,,,,,,,7.80559682846069,7.94961500167847,50.0059928894043,50.0059928894043,,,4.91089153289795,,1,0,0,0,0.013885498046875,28.3479976654053,6,1,1,7.95687341690063,0,4232057984,7.87589950561523,,,1.49321027099336E-5,7.44813003149087E-7,1.49321454404492E-5,7.44812697005605E-7,0.98652571439743,0.986770808696747,26.5890483856201,0.0623357109725475,30,4,200,6.62770471535623E-5,-0.204841136932373,-0.133452370762825,1,,,,,,,,,,,,,,,,
,3928754853.82689,8.19823312759399,50.0059928894043,,,6,,,,26.5986999214455,,,1,,,,,,,,,,,,,,,,,,,,,,8.12243270874023,8.26744747161865,50.0059928894043,50.0059928894043,,,4.96522521972656,,1,0,0,0,0.013885498046875,28.3479976654053,6,1,1,8.27403354644775,0,4232058080,8.19172916412354,,,1.42087041986416E-5,7.08734229449598E-7,1.42087145630418E-5,7.08734001853735E-7,0.986118257045746,0.986194133758545,26.5932312011719,3.413743019104,30,4,200,0.000115872906462755,-0.200644478201866,-0.13240222632885,1,,,,,,,,,,,,,,,,
,3928754873.60569,8.5130558013916,50.0059928894043,,,6,,,,26.5986999214455,,,1,,,,,,,,,,,,,,,,,,,,,,8.43561172485352,8.58672046661377,50.0059928894043,50.0059928894043,,,5.01938390731812,,1,0,0,0,0.013885498046875,28.8367557525635,6,1,1,8.59049987792969,0,4232058016,8.50529708862305,,,1.35501320245037E-5,6.75880017915577E-7,1.35501423220988E-5,6.75879766728266E-7,0.986566066741943,0.98665052652359,26.5930252075195,0,30,4,200,0.000133302048197947,-0.195581346750259,-0.130344852805138,1,,,,,,,,,,,,,,,,
,3928754893.69571,8.83210515975952,50.0059928894043,,,6,,,,26.5986999214455,,,1,,,,,,,,,,,,,,,,,,,,,,8.75527954101562,8.90893077850342,50.0059928894043,50.0059928894043,,,5.06887292861938,,1,0,0,0,0.013885498046875,28.3479976654053,6,1,1,8.90893077850342,0,4232057952,8.82922420501709,,,1.29061088380257E-5,6.43759156984589E-7,1.29061236013157E-5,6.43758924773499E-7,0.986221134662628,0.98633074760437,26.5921573638916,3.41374230384827,30,4,200,0.000136459231725894,-0.1899224370718,-0.127918004989624,1,,,,,,,,,,,,,,,,
,3928754913.30565,9.1456151008606,50.0059928894043,,,6,,,,26.5986999214455,,,1,,,,,,,,,,,,,,,,,,,,,,9.06878566741943,9.21411800384521,50.0059928894043,50.0059928894043,,,5.11647987365723,,1,0,0,0,0.013885498046875,28.8367557525635,6,1,1,9.22244453430176,0,4232058080,9.13981428146362,,,1.23052576778003E-5,6.13791095639479E-7,1.23052681112467E-5,6.13790897504749E-7,0.985934793949127,0.986018300056457,26.5929279327393,,30,4,200,9.95913651422598E-5,-0.18518440425396,-0.12606081366539,1,,,,,,,,,,,,,,,,
,3928754933.18491,9.46175813674927,50.0059928894043,,,6,,,,26.5986999214455,,,1,,,,,,,,,,,,,,,,,,,,,,9.37941455841064,9.53365421295166,50.0059928894043,50.0059928894043,,,5.16538524627686,,1,0,0,0,0.013885498046875,27.8592376708984,6,1,1,9.54410171508789,0,4232058016,9.45678453445435,,,1.17253986533966E-5,5.84862667068223E-7,1.17254067176581E-5,5.84862470133298E-7,0.986565053462982,0.986641526222229,26.5932998657227,0,30,4,200,8.21000867290422E-5,-0.180694773793221,-0.124608777463436,1,,,,,,,,,,,,,,,,
,3928754953.01048,9.7778787612915,50.0059928894043,,,6,,,,26.5986999214455,,,1,,,,,,,,,,,,,,,,,,,,,,9.70459270477295,9.85484790802002,50.0059928894043,50.0059928894043,,,5.20881462097168,,1,0,0,0,0.013885498046875,28.8367557525635,6,1,1,9.85484790802002,0,4232058080,9.77849569320679,,,1.11767839430961E-5,5.57504457197482E-7,1.11768025988664E-5,5.57504222890967E-7,0.98568719625473,0.985833883285522,26.5909881591797,0,30,4,200,7.75613880250603E-5,-0.176921635866165,-0.123436465859413,1,,,,,,,,,,,,,,,,
,3928754972.80678,10.0974621772766,50.0059928894043,,,6,,,,26.5986999214455,,,1,,,,,,,,,,,,,,,,,,,,,,10.0197296142578,10.1678867340088,50.0059928894043,50.0059928894043,,,5.25092935562134,,1,0,0,0,0.013885498046875,28.3479976654053,6,1,1,10.1751947402954,0,4232058016,10.0930848121643,,,1.06511538097583E-5,5.31278725839275E-7,1.06511724243324E-5,5.31278529941598E-7,0.986622273921967,0.986781358718872,26.5909385681152,0,30,4,200,6.13452066318132E-5,-0.173218250274658,-0.122220225632191,1,,,,,,,,,,,,,,,,
,3928754992.47817,10.4107136726379,50.0059928894043,,,6,,,,26.5986999214455,,,1,,,,,,,,,,,,,,,,,,,,,,10.332893371582,10.48122215271,50.0059928894043,50.0059928894043,,,5.2917628288269,,1,0,0,0,0.013885498046875,28.8367557525635,6,1,1,10.4885339736938,0,4232058144,10.4075293540955,,,1.0153821582943E-5,5.06476094084699E-7,1.01538481049835E-5,5.0647585559069E-7,0.986003756523132,0.986225724220276,26.5893325805664,0,30,4,200,7.95812229625881E-5,-0.169809952378273,-0.120909482240677,1,,,,,,,,,,,,,,,,
,3928755012.27433,10.7315444946289,50.0059928894043,,,6,,,,26.5986999214455,,,1,,,,,,,,,,,,,,,,,,,,,,10.6540718078613,10.8037824630737,50.0059928894043,50.0059928894043,,,5.33105373382568,,1,0,0,0,0.013885498046875,28.3479976654053,6,1,1,10.8090171813965,0,4232057888,10.7280225753784,,,9.6906047898802E-6,4.83371513936078E-7,9.6906239130022E-6,4.8337131720729E-7,0.985909581184387,0.986079514026642,26.5904693603516,INF,30,4,200,6.64120525470935E-5,-0.166257902979851,-0.119838513433933,1,,,,,,,,,,,,,,,,
,3928755032.04637,11.0483508110046,50.0059928894043,,,6,,,,26.5986999214455,,,1,,,,,,,,,,,,,,,,,,,,,,10.9694967269897,11.1232042312622,50.0059928894043,50.0059928894043,,,5.36820125579834,,1,0,0,0,0.013885498046875,28.3479976654053,6,1,1,11.1272048950195,0,4232057952,11.0468153953552,,,9.23538773709205E-6,4.60667823116917E-7,9.23541639165902E-6,4.60667665000132E-7,0.985481262207031,0.985720574855804,26.5887966156006,0,30,4,200,6.41716469544917E-5,-0.163069263100624,-0.118737198412418,1,,,,,,,,,,,,,,,,
,3928755052.25882,11.3733334541321,50.0059928894043,,,6,,,,26.5986999214455,,,1,,,,,,,,,,,,,,,,,,,,,,11.2995052337646,11.4512062072754,50.0059928894043,50.0059928894043,,,5.40511226654053,,1,0,0,0,0.013885498046875,28.8367557525635,6,1,1,11.4512062072754,0,4232057984,11.3746767997742,,,8.80089145599026E-6,4.38992067270724E-7,8.8009120237303E-6,4.38991887867601E-7,0.98593282699585,0.986129343509674,26.5898590087891,0,30,4,200,5.35525286977645E-5,-0.159888654947281,-0.117787823081017,1,,,,,,,,,,,,,,,,
,3928755071.94533,11.6954870223999,50.0059928894043,,,6,,,,26.5986999214455,,,1,,,,,,,,,,,,,,,,,,,,,,11.6179885864258,11.7661323547363,50.0059928894043,50.0059928894043,,,5.43991136550903,,1,0,0,0,0.013885498046875,28.3479976654053,6,1,1,11.772985458374,0,4232058048,11.6888442993164,,,8.41010117279789E-6,4.19496126120678E-7,8.4101127739816E-6,4.19495968565412E-7,0.986458301544189,0.986588478088379,26.5916309356689,0,30,4,200,4.68278194603045E-5,-0.157275483012199,-0.117125578224659,1,,,,,,,,,,,,,,,,
,3928755091.61354,12.0119714736938,50.0059928894043,,,6,,,,26.5986999214455,,,1,,,,,,,,,,,,,,,,,,,,,,11.9359045028687,12.0808906555176,50.0059928894043,50.0059928894043,,,5.47325229644775,,1,0,0,0,0.013885498046875,27.8592376708984,6,1,1,12.088038444519,0,4232057984,12.0073278427124,,,8.03801256391341E-6,4.00940823688796E-7,8.0380218858668E-6,4.00940646701298E-7,0.985669493675232,0.985781669616699,26.5919494628906,,30,4,200,3.28846363117918E-5,-0.154949426651001,-0.116482928395271,1,,,,,,,,,,,,,,,,
,3928755111.37586,12.3309264183044,50.0059928894043,,,6,,,,26.5986999214455,,,1,,,,,,,,,,,,,,,,,,,,,,12.2533578872681,12.4018392562866,50.0059928894043,50.0059928894043,,,5.50316047668457,,1,0,0,0,0.013885498046875,28.8367557525635,6,1,1,12.4084949493408,0,4232058144,12.3269293785095,,,7.68935088779022E-6,3.83547391256288E-7,7.68938315254145E-6,3.83547236528988E-7,0.986015617847443,0.986348390579224,26.5872592926025,,30,4,200,1.61174539243802E-5,-0.152770340442657,-0.116025261580944,1,,,,,,,,,,,,,,,,
,3928755130.97941,12.6482820510864,50.0059928894043,,,6,,,,26.5986999214455,,,1,,,,,,,,,,,,,,,,,,,,,,12.5690813064575,12.7274827957153,50.0059928894043,50.0059928894043,,,5.5345721244812,,1,0,0,0,0.013885498046875,28.3479976654053,6,1,1,12.7274827957153,0,4232058144,12.6464426040649,,,7.37964777201652E-6,3.68101133353472E-7,7.37968560349141E-6,3.68100916134719E-7,0.985682845115662,0.986087799072266,26.5859432220459,0,30,4,200,2.77548861049581E-5,-0.150751829147339,-0.115650743246078,1,,,,,,,,,,,,,,,,
,3928755150.70505,12.9702920913696,50.0059928894043,,,6,,,,26.5986999214455,,,1,,,,,,,,,,,,,,,,,,,,,,12.8928298950195,13.0293531417847,50.0059928894043,50.0059928894043,,,5.56525087356567,,1,0,0,0,0.013885498046875,28.3479976654053,6,1,1,13.0477542877197,0,4232058144,12.9613386789958,,,7.08915938095724E-6,3.53608747952644E-7,7.08917498947725E-6,3.53608541390011E-7,0.986203491687775,0.986406862735748,26.5897941589355,0.0309819709509611,30,4,200,1.96479268197436E-5,-0.148975923657417,-0.115177787840366,1,,,,,,,,,,,,,,,,
,3928755170.49095,13.2876572608948,50.0059928894043,,,6,,,,26.5986999214455,,,1,,,,,,,,,,,,,,,,,,,,,,13.2103796005249,13.3622627258301,50.0059928894043,50.0059928894043,,,5.59447526931763,,1,0,0,0,0.013885498046875,28.3479976654053,6,1,1,13.3693017959595,0,4232057984,13.285647392273,,,6.80708851751998E-6,3.39539814012948E-7,6.80711299876287E-6,3.39539643057759E-7,0.98605078458786,0.986347794532776,26.5878982543945,0.0303553864359856,30,4,200,1.64455977937905E-5,-0.147364839911461,-0.114902921020985,1,,,,,,,,,,,,,,,,
,3928755198.96349,13.7562403678894,50.0059928894043,,,6,,,,26.6037689005873,,,1,,,,,,,,,,,,,,,,,,,,,,13.67737865448,13.8294916152954,50.0059928894043,50.0059928894043,,,5.63138198852539,,1,0,0,0,0.013885498046875,28.3479976654053,6,1,1,13.8351020812988,0,4232058080,13.7534770011902,,,6.46460401039764E-6,3.2246012681591E-7,6.46466715665054E-6,3.22459997246046E-7,0.985259413719177,0.985966086387634,26.5867557525635,0,30,4,200,1.02578715086565E-5,-0.145478203892708,-0.114635147154331,1,,,,,,,,,,,,,,,,
,3928755219.29042,14.0825185775757,50.0059928894043,,,6,,,,26.6037689005873,,,1,,,,,,,,,,,,,,,,,,,,,,14.0044240951538,14.1486434936523,50.0059928894043,50.0059928894043,,,5.65911293029785,,1,0,0,0,0.013885498046875,29.3255138397217,6,1,1,14.1606130599976,0,4232058208,14.0779653549194,,,6.23868619283992E-6,3.11190411378651E-7,6.23874552298396E-6,3.11190337522411E-7,0.985427796840668,0.986112654209137,26.5871124267578,0.0290418043732643,30,4,200,-6.13568363405648E-6,-0.144214287400246,-0.114370994269848,1,,,,,,,,,,,,,,,,
,3928755238.96924,14.4024019241333,50.0059928894043,,,6,,,,26.6037689005873,,,1,,,,,,,,,,,,,,,,,,,,,,14.3255710601807,14.4604759216309,50.0059928894043,50.0059928894043,,,5.68654680252075,,1,0,0,0,0.014801025390625,28.8367557525635,6,1,1,14.4792327880859,0,4232057920,14.3915395736694,,,6.02783805550769E-6,3.006743958377E-7,6.02788594237556E-6,3.00674245981388E-7,0.985136032104492,0.98571515083313,26.5882663726807,0.0285485293716192,30,4,200,1.14951326395385E-5,-0.143036589026451,-0.114204622805119,1,,,,,,,,,,,,,,,,
,3928755258.66856,14.723705291748,50.0059928894043,,,6,,,,26.6037689005873,,,1,,,,,,,,,,,,,,,,,,,,,,14.6418323516846,14.7956771850586,50.0059928894043,50.0059928894043,,,5.71111869812012,,1,0,0,0,0.013885498046875,28.3479976654053,6,1,1,14.8024568557739,0,4232058080,14.7194418907166,,,5.83069531000288E-6,2.90838646623971E-7,5.83074820315401E-6,2.90838596287038E-7,0.985647559165955,0.986306667327881,26.5875453948975,0,30,4,200,3.40433120982198E-6,-0.14195704460144,-0.114214554429054,1,,,,,,,,,,,,,,,,
,3928755278.44991,15.0449366569519,50.0059928894043,,,6,,,,26.6037689005873,,,1,,,,,,,,,,,,,,,,,,,,,,14.9653968811035,15.1179552078247,50.0059928894043,50.0059928894043,,,5.73555088043213,,1,0,0,0,0.013885498046875,28.3479976654053,6,1,1,15.1244764328003,0,4232058048,15.0409888267517,,,5.63722380257623E-6,2.81195702173492E-7,5.63730624370609E-6,2.81195620674526E-7,0.983880579471588,0.984833776950836,26.5831680297852,,30,4,200,-1.97068789020705E-6,-0.141180694103241,-0.114304326474667,1,,,,,,,,,,,,,,,,
,3928755298.09763,15.4256191253662,50.0059928894043,,,6,,,,26.6037689005873,,,1,,,,,,,,,,,,,,,,,,,,,,15.3460645675659,15.5051040649414,50.0059928894043,50.0059928894043,,,5.75386190414429,,1,0,0,0,0.013885498046875,28.3479976654053,2,1,1,15.5136442184448,0,4232057984,15.4298174858093,,,5.44607280835073E-6,2.71654580045349E-7,5.44617057007728E-6,2.71654541516147E-7,0.985352516174316,0.986644446849823,26.5810642242432,0,30,4,200,-6.93098263582215E-5,-0.138228639960289,-0.112078651785851,1,,,,,,,,,,,,,,,,
,3928755317.97108,15.7609004974365,50.0059928894043,,,6,,,,26.6037689005873,,,1,,,,,,,,,,,,,,,,,,,,,,15.6801300048828,15.83251953125,50.0059928894043,50.0059928894043,,,5.76188182830811,,1,0,0,0,0.013885498046875,28.3479976654053,2,1,1,15.8416709899902,0,4232057952,15.7550305366516,,,5.23787470172347E-6,2.6127756168261E-7,5.23807982033454E-6,2.61277570682877E-7,0.983368039131165,0.985914885997772,26.5704021453857,1,30,4,200,-5.5270291341003E-5,-0.137976169586182,-0.113062024116516,1,,,,,,,,,,,,,,,,
,3928755337.76742,16.0910081863403,50.0059928894043,,,6,,,,26.6037689005873,,,1,,,,,,,,,,,,,,,,,,,,,,16.004150390625,16.1628551483154,50.0059928894043,50.0059928894043,,,5.77487277984619,,1,0,0,0,0.013885498046875,28.3479976654053,2,1,1,16.1711616516113,0,4232057920,16.0847038269043,,,5.0945074903472E-6,2.54119660925658E-7,5.09454200055068E-6,2.54119577894591E-7,0.984960556030273,0.985440254211426,26.5895519256592,5.15650606155396,30,4,200,-3.49855763488449E-5,-0.138464793562889,-0.114019125699997,1,,,,,,,,,,,,,,,,
,3928755357.76697,16.4094829559326,50.0059928894043,,,6,,,,26.6037689005873,,,1,,,,,,,,,,,,,,,,,,,,,,16.3251533508301,16.4847393035889,50.0059928894043,50.0059928894043,,,5.78819179534912,,1,0,0,0,0.013885498046875,28.3479976654053,2,1,1,16.4938125610352,0,4232058240,16.404174041748,,,4.93616125490583E-6,2.4622422776846E-7,4.93624192953122E-6,2.46224229134082E-7,0.984165489673614,0.985233068466186,26.5822048187256,0,30,4,200,-4.44522047473583E-5,-0.138462379574776,-0.1147256270051,1,,,,,,,,,,,,,,,,
,3928755377.79195,16.7434425354004,50.0059928894043,,,6,,,,26.6037689005873,,,1,,,,,,,,,,,,,,,,,,,,,,16.6622257232666,16.8178768157959,50.0059928894043,50.0059928894043,,,5.80190324783325,,1,0,0,0,0.013885498046875,28.3479976654053,2,1,1,16.8246593475342,0,4232057856,16.7388969421387,,,4.78837668918669E-6,2.38850618779478E-7,4.78844021755774E-6,2.38850564490659E-7,0.984656751155853,0.985562801361084,26.5841732025146,0,30,4,200,-3.48816756741144E-5,-0.13867212831974,-0.115676932036877,1,,,,,,,,,,,,,,,,
,3928755397.58658,17.0672664642334,50.0059928894043,,,6,,,,26.6037689005873,,,1,,,,,,,,,,,,,,,,,,,,,,16.9927349090576,17.1351776123047,50.0059928894043,50.0059928894043,,,5.81665706634521,,1,0,0,0,0.013885498046875,28.3479976654053,2,1,1,17.1417980194092,0,4232058080,17.0676898956299,,,4.62070009169105E-6,2.30510238296799E-7,4.62082026197386E-6,2.30510208154952E-7,0.979025900363922,0.980310916900635,26.5765075683594,0,30,4,200,-2.70844084298005E-5,-0.13876211643219,-0.116527020931244,1,,,,,,,,,,,,,,,,
,3928755417.18757,17.3869028091431,50.0059928894043,,,6,,,,26.6037689005873,,,1,,,,,,,,,,,,,,,,,,,,,,17.3053455352783,17.4618282318115,50.0059928894043,50.0059928894043,,,5.8314208984375,,1,0,0,0,0.0147247314453125,28.3479976654053,2,1,1,17.4684600830078,0,4232058208,17.3860429763794,,,4.51575525387224E-6,2.25254312600953E-7,4.51580591024475E-6,2.25254241969917E-7,0.983979105949402,0.984715580940247,26.5856552124023,0,30,4,200,-2.83364133792929E-5,-0.138733714818954,-0.117225095629692,1,,,,,,,,,,,,,,,,
,3928755436.85469,17.7157726287842,50.0059928894043,,,6,,,,26.6037689005873,,,1,,,,,,,,,,,,,,,,,,,,,,17.6369228363037,17.7887668609619,50.0059928894043,50.0059928894043,,,5.84656381607056,,1,0,0,0,0.013885498046875,28.3479976654053,2,1,1,17.7946224212646,0,4232058080,17.7121301651001,,,4.38478407557613E-6,2.18717830748946E-7,4.3848255067239E-6,2.1871776697683E-7,0.984990000724792,0.985653460025787,26.5871162414551,0.024347759783268,30,4,200,-3.55179872713052E-5,-0.138998329639435,-0.117977149784565,1,,,,,,,,,,,,,,,,
,3928755456.62163,18.0336980819702,50.0059928894043,,,6,,,,26.6037689005873,,,1,,,,,,,,,,,,,,,,,,,,,,17.9542198181152,18.1063423156738,50.0059928894043,50.0059928894043,,,5.86268424987793,,1,0,0,0,0.013885498046875,28.3479976654053,2,1,1,18.1131763458252,0,4232058144,18.0319473266602,,,4.26273618945495E-6,2.12637133950279E-7,4.26284250140489E-6,2.1263699237902E-7,0.982862234115601,0.984427392482758,26.5767688751221,0.34799998998642,30,4,200,-4.19745774706826E-5,-0.139099225401878,-0.118522241711617,1,,,,,,,,,,,,,,,,
,3928755476.28195,18.3618116378784,50.0059928894043,,,6,,,,26.6037689005873,,,1,,,,,,,,,,,,,,,,,,,,,,18.2821025848389,18.4321632385254,50.0059928894043,50.0059928894043,,,5.87731075286865,,1,0,0,0,0.013885498046875,28.3479976654053,2,1,1,18.441520690918,0,4232058016,18.3605779647827,,,4.1478896501094E-6,2.06906944525854E-7,4.14794833847908E-6,2.06906883207292E-7,0.983249843120575,0.984135389328003,26.5834884643555,,30,4,200,-3.74399605789222E-5,-0.13949353992939,-0.119536057114601,1,,,,,,,,,,,,,,,,
,3928755496.13818,18.6874103546143,50.0059928894043,,,6,,,,26.6037689005873,,,1,,,,,,,,,,,,,,,,,,,,,,18.6109294891357,18.7611351013184,50.0059928894043,50.0059928894043,,,5.89221286773682,,1,0,0,0,0.013885498046875,28.3479976654053,2,1,1,18.7677059173584,0,4232058336,18.6833145141602,,,4.02713484843622E-6,2.0089324117649E-7,4.02728633137905E-6,2.00893264520267E-7,0.980539262294769,0.982571661472321,26.5711231231689,INF,30,4,200,-2.87930233753286E-5,-0.139901399612427,-0.120410405099392,1,,,,,,,,,,,,,,,,
,3928755515.89737,19.0118322372437,50.0059928894043,,,6,,,,26.6037689005873,,,1,,,,,,,,,,,,,,,,,,,,,,18.9296188354492,19.0831642150879,50.0059928894043,50.0059928894043,,,5.9056339263916,,1,0,0,0,0.013885498046875,27.8592376708984,2,1,1,19.0940456390381,0,4232058016,19.0053197860718,,,3.92655277675624E-6,1.95869048494946E-7,3.92664451304541E-6,1.9586903309894E-7,0.982381045818329,0.983765542507172,26.5779418945313,0,30,4,200,-2.82556684396695E-5,-0.140253409743309,-0.121432676911354,1,,,,,,,,,,,,,,,,
,3928755535.76897,19.3404512405396,50.0059928894043,,,6,,,,26.6037689005873,,,1,,,,,,,,,,,,,,,,,,,,,,19.2602634429932,19.4120063781738,50.0059928894043,50.0059928894043,,,5.92065095901489,,1,0,0,0,0.013885498046875,28.3479976654053,2,1,1,19.4206390380859,0,4232058176,19.33685131073,,,3.83201072343635E-6,1.91155019106269E-7,3.83209708635896E-6,1.91154932458013E-7,0.981804668903351,0.983114957809448,26.5781917572021,0,30,4,200,-4.2711450078059E-5,-0.140650317072868,-0.122159831225872,1,,,,,,,,,,,,,,,,
,3928755555.54161,19.6657657623291,50.0059928894043,,,6,,,,26.6037689005873,,,1,,,,,,,,,,,,,,,,,,,,,,19.5828704833984,19.7428741455078,50.0059928894043,50.0059928894043,,,5.9341025352478,,1,0,0,0,0.013885498046875,28.3479976654053,2,1,1,19.7486610412598,0,4232058080,19.6607133865356,,,3.74015476166506E-6,1.86566743090595E-7,3.74018371425801E-6,1.86566661159126E-7,0.983710169792175,0.984220206737518,26.5885124206543,4.43644694314571E-6,30,4,200,-3.39635371346958E-5,-0.141128569841385,-0.123156145215034,1,,,,,,,,,,,,,,,,
,3928755575.34264,19.984808921814,50.0059928894043,,,6,,,,26.6037689005873,,,1,,,,,,,,,,,,,,,,,,,,,,19.9063205718994,20.0588436126709,50.0059928894043,50.0059928894043,,,5.94753503799438,,1,0,0,0,0.013885498046875,28.8367557525635,2,1,1,20.0632972717285,0,4232058080,19.9817834854126,,,3.65727689602889E-6,1.8243945383086E-7,3.65735384268684E-6,1.82439396734642E-7,0.981561660766602,0.982758104801178,26.5791244506836,6.66062805976253E-6,30,4,200,-4.34078392572701E-5,-0.141407147049904,-0.123671412467957,1,,,,,,,,,,,,,,,,
,3928755595.07558,20.3121328353882,50.0059928894043,,,6,,,,26.6037689005873,,,1,,,,,,,,,,,,,,,,,,,,,,20.2315921783447,20.386344909668,50.0059928894043,50.0059928894043,,,5.96034908294678,,1,0,0,0,0.013885498046875,28.3479976654053,2,1,1,20.3926734924316,0,4232058016,20.3064874649048,,,3.57371598726405E-6,1.78267229116185E-7,3.57379186269685E-6,1.78267123467651E-7,0.982765376567841,0.984081566333771,26.5788440704346,0,30,4,200,-3.0904084269423E-5,-0.141950979828835,-0.124637722969055,1,,,,,,,,,,,,,,,,
,3928755614.87252,20.6366033554077,50.0059928894043,,,6,,,,26.6037689005873,,,1,,,,,,,,,,,,,,,,,,,,,,20.5557556152344,20.7069282531738,50.0059928894043,50.0059928894043,,,5.97532272338867,,1,0,0,0,0.014801025390625,28.3479976654053,2,1,1,20.7174510955811,0,4232058112,20.6325830459595,,,3.50700508706264E-6,1.74942236459124E-7,3.50713886605714E-6,1.7494221543974E-7,0.981869995594025,0.984119594097137,26.5707550048828,1.84375744538556E-6,30,4,200,-3.55212760041468E-5,-0.142211675643921,-0.125378414988518,1,,,,,,,,,,,,,,,,
,3928755635.07137,20.9671535491943,50.0059928894043,,,6,,,,26.6037689005873,,,1,,,,,,,,,,,,,,,,,,,,,,20.8869667053223,21.040922164917,50.0059928894043,50.0059928894043,,,5.98731899261475,,1,0,0,0,0.013885498046875,28.3479976654053,2,1,1,21.0473403930664,0,4232058016,20.9649871826172,,,3.43084853345978E-6,1.71141676197665E-7,3.43095189470831E-6,1.71141624673445E-7,0.982397794723511,0.984220266342163,26.5743312835693,4.76780132885324E-6,30,4,200,-4.47926795459352E-5,-0.142661526799202,-0.126252695918083,1,,,,,,,,,,,,,,,,
,3928755654.79839,21.2922868728638,50.0059928894043,,,6,,,,26.6037689005873,,,1,,,,,,,,,,,,,,,,,,,,,,21.2136325836182,21.3640842437744,50.0059928894043,50.0059928894043,,,6.00023651123047,,1,0,0,0,0.013885498046875,28.3479976654053,2,1,1,21.3709411621094,0,4232058240,21.2879953384399,,,3.36501194973889E-6,1.67860908233682E-7,3.36510223914682E-6,1.67860869950928E-7,0.981299698352814,0.982806980609894,26.5760059356689,0,30,4,200,-4.58395297755487E-5,-0.143322885036469,-0.126905918121338,1,,,,,,,,,,,,,,,,
,3928755674.70955,21.6195840835571,50.0059928894043,,,6,,,,26.6037689005873,,,1,,,,,,,,,,,,,,,,,,,,,,21.5401172637939,21.6919574737549,50.0059928894043,50.0059928894043,,,6.01354932785034,,1,0,0,0,0.013885498046875,28.3479976654053,2,1,1,21.6990509033203,0,4232058336,21.6161066055298,,,3.29486345613034E-6,1.6436874659881E-7,3.29504263951959E-6,1.64368675182398E-7,0.979112267494202,0.981924891471863,26.5642642974854,,30,4,200,-7.74489817558788E-5,-0.143619894981384,-0.12776443362236,1,,,,,,,,,,,,,,,,
,3928755694.66282,21.9476842880249,50.0059928894043,,,6,,,,26.6037689005873,,,1,,,,,,,,,,,,,,,,,,,,,,21.8665733337402,22.0184135437012,50.0059928894043,50.0059928894043,,,6.02543306350708,,1,0,0,0,0.013885498046875,27.8592376708984,2,1,1,22.0287952423096,0,4232058112,21.9398963928223,,,3.2391121781974E-6,1.61584013077772E-7,3.23923548180381E-6,1.61583942770496E-7,0.980166614055634,0.982212722301483,26.5706806182861,0,30,4,200,-8.27611947897822E-5,-0.145043775439262,-0.128985106945038,1,,,,,,,,,,,,,,,,
,3928755714.49839,22.2752628326416,50.0059928894043,,,6,,,,26.6037689005873,,,1,,,,,,,,,,,,,,,,,,,,,,22.1986103057861,22.3433799743652,50.0059928894043,50.0059928894043,,,6.03760623931885,,1,0,0,0,0.013885498046875,28.3479976654053,2,1,1,22.3519153594971,0,4232058048,22.2709335327148,,,3.18570392082421E-6,1.58916141017792E-7,3.18580294800652E-6,1.58916089148277E-7,0.981322646141052,0.983087241649628,26.5738677978516,0.0207734555006027,30,4,200,1.75785989995347E-5,-0.145907640457153,-0.130478128790855,1,,,,,,,,,,,,,,,,
,3928755734.2495,22.6019039154053,50.0059928894043,,,6,,,,26.6037689005873,,,1,,,,,,,,,,,,,,,,,,,,,,22.521167755127,22.6767082214355,50.0059928894043,50.0059928894043,,,6.05044269561768,,1,0,0,0,0.013885498046875,29.3255138397217,2,1,1,22.6826400756836,0,4232058080,22.5952201843262,,,3.13945952095753E-6,1.56612756718408E-7,3.1395418842707E-6,1.56612706543585E-7,0.980191349983215,0.981580078601837,26.5762710571289,0,30,4,200,-4.69588594569359E-5,-0.146323144435883,-0.131179302930832,1,,,,,,,,,,,,,,,,
,3928755754.08147,22.9239797592163,50.0059928894043,,,6,,,,26.6037689005873,,,1,,,,,,,,,,,,,,,,,,,,,,22.8450489044189,22.9902420043945,50.0059928894043,50.0059928894043,,,6.06225395202637,,1,0,0,0,0.013885498046875,28.8367557525635,2,1,1,23.0029106140137,0,4232058048,22.9157712936401,,,3.09097021028729E-6,1.54192860326309E-7,3.09105671548718E-6,1.54192782025829E-7,0.980525255203247,0.982047319412231,26.5752811431885,0,30,4,200,-3.48377689078916E-5,-0.146640405058861,-0.131825834512711,1,,,,,,,,,,,,,,,,
,3928755773.87924,23.2476263046265,50.0059928894043,,,6,,,,26.6037689005873,,,1,,,,,,,,,,,,,,,,,,,,,,23.1691226959229,23.3187065124512,50.0059928894043,50.0059928894043,,,6.07318067550659,,1,0,0,0,0.013885498046875,28.3479976654053,2,1,1,23.3261299133301,0,4232589312,23.2440401077271,,,3.04572815066376E-6,1.53751299220258E-7,3.06265918296711E-6,1.53786783316802E-7,0.8455810546875,0.884165167808533,26.212797164917,0,30,4,200,-0.000358983437763527,-0.147113904356956,-0.127508729696274,1,,,,,,,,,,,,,,,,
,3928755793.67419,23.5683441162109,50.0059928894043,,,6,,,,26.6037689005873,,,1,,,,,,,,,,,,,,,,,,,,,,23.4924621582031,23.6442260742187,50.0059928894043,50.0059928894043,,,6.08553886413574,,1,0,0,0,0.013885498046875,28.8367557525635,2,1,1,23.6442260742187,0,4232056832,23.5656772613525,,,3.00172318158335E-6,1.4974063800671E-7,3.00178838966576E-6,1.49740614946431E-7,0.980568945407867,0.981729030609131,26.578821182251,5.29755163192749,30,4,200,-0.000123749894555658,-0.146013334393501,-0.131165564060211,1,,,,,,,,,,,,,,,,
,3928755813.5059,23.8908996582031,50.0059928894043,,,6,,,,26.6037689005873,,,1,,,,,,,,,,,,,,,,,,,,,,23.811243057251,23.9510879516602,50.0059928894043,50.0059928894043,,,6.09520864486694,,1,0,0,0,0.013885498046875,28.3479976654053,2,1,1,23.9705562591553,0,4232057312,23.8838736216227,,,2.96610163072863E-6,1.47960849175822E-7,2.96615929865177E-6,1.47960826930354E-7,0.981562912464142,0.982657790184021,26.5801544189453,,30,4,200,-8.67115813889541E-5,-0.147762954235077,-0.133200883865356,1,,,,,,,,,,,,,,,,
,3928755833.12864,24.2127065658569,50.0059928894043,,,6,,,,26.6037689005873,,,1,,,,,,,,,,,,,,,,,,,,,,24.1325263977051,24.2883548736572,50.0059928894043,50.0059928894043,,,6.10666275024414,,1,0,0,0,0.013885498046875,28.3479976654053,2,1,1,24.2928867340088,0,4232058336,24.2098634719849,,,2.93627242981849E-6,1.46762787495695E-7,2.93690130195079E-6,1.46763585140022E-7,0.934537291526794,0.937793612480164,26.5263957977295,,30,4,200,4.0978778997669E-5,-0.148356422781944,-0.133823424577713,1,,,,,,,,,,,,,,,,
,3928755852.89444,24.5411252975464,50.0059928894043,,,6,,,,26.6037689005873,,,1,,,,,,,,,,,,,,,,,,,,,,24.463077545166,24.6126384735107,50.0059928894043,50.0059928894043,,,6.11740636825561,,1,0,0,0,0.014801025390625,28.3479976654053,2,1,1,24.6191730499268,0,4232058176,24.5359279632568,,,2.96027134530752E-6,1.48105944750448E-7,2.96052833928653E-6,1.48106860659866E-7,0.921156227588654,0.922179222106934,26.6518936157227,1.25778760775574E-5,30,4,200,0.000304697401588783,-0.148100450634956,-0.132557854056358,1,,,,,,,,,,,,,,,,
,3928755872.55745,24.8526649475098,50.0059928894043,,,6,,,,26.6037689005873,,,1,,,,,,,,,,,,,,,,,,,,,,24.7633190155029,24.9348278045654,50.0059928894043,50.0059928894043,,,6.1275577545166,,1,0,0,0,0.013885498046875,30.3030319213867,2,1,1,24.9420108795166,0,4232058272,24.8473310470581,,,2.8810719145743E-6,1.43784664841023E-7,2.88150145832736E-6,1.43785169568603E-7,0.964646399021149,0.96903133392334,26.5394115447998,5.29526853561401,30,4,200,0.000838268722873181,-0.133649557828903,-0.114800810813904,1,,,,,,,,,,,,,,,,
,3928755892.27458,25.189510345459,50.0059928894043,,,6,,,,26.6037689005873,,,1,,,,,,,,,,,,,,,,,,,,,,25.1080341339111,25.2643527984619,50.0059928894043,50.0059928894043,,,6.13701152801514,,1,0,0,0,0.013885498046875,28.3479976654053,2,1,1,25.2709865570068,0,4232058368,25.1870845794678,,,2.898028963429E-6,1.44565635711126E-7,2.89809570380099E-6,1.44565638516052E-7,0.981363475322723,0.982641518115997,26.5781230926514,0,30,4,200,0.000148313149111345,-0.12361752986908,-0.109021835029125,1,,,,,,,,,,,,,,,,
,3928755912.07679,25.523344039917,50.0059928894043,,,6,,,,26.6037689005873,,,1,,,,,,,,,,,,,,,,,,,,,,25.4390487670898,25.5952453613281,50.0059928894043,50.0059928894043,,,6.14875936508179,,1,0,0,0,0.013885498046875,28.8367557525635,2,1,1,25.6076393127441,0,4232058272,25.5187509536743,,,2.85245326039634E-6,1.42308107595848E-7,2.8524907911492E-6,1.42308051032326E-7,0.976090610027313,0.976664066314697,26.5841197967529,,30,4,200,-3.49808469763957E-5,-0.123289972543716,-0.109502948820591,1,,,,,,,,,,,,,,,,
,3928755931.73827,25.8406829833984,50.0059928894043,,,6,,,,26.6037689005873,,,1,,,,,,,,,,,,,,,,,,,,,,25.7637500762939,25.9138851165771,50.0059928894043,50.0059928894043,,,6.15859699249268,,1,0,0,0,0.013885498046875,28.8367557525635,2,1,1,25.9176158905029,0,4232058016,25.8360380172729,,,2.81495058446026E-6,1.40420702800291E-7,2.81505778049215E-6,1.40420712702107E-7,0.981637835502625,0.983839154243469,26.5708675384521,0,30,4,200,-3.10037976305466E-5,-0.123129934072495,-0.109574533998966,1,,,,,,,,,,,,,,,,
,3928755951.85515,26.1725158691406,50.0059928894043,,,6,,,,26.6037689005873,,,1,,,,,,,,,,,,,,,,,,,,,,26.091007232666,26.2465553283691,50.0059928894043,50.0059928894043,,,6.1706600189209,,1,0,0,0,0.0147247314453125,28.3479976654053,2,1,1,26.2540245056152,0,4232058080,26.1668334960938,,,2.77238893144114E-6,1.38317823231851E-7,2.7724104679743E-6,1.38317754949711E-7,0.974892556667328,0.97522360086441,26.5884609222412,0.188789010047913,30,4,200,-4.12741355830804E-5,-0.124049082398415,-0.11039824783802,1,,,,,,,,,,,,,,,,
,3928755971.58495,26.49742603302,50.0059928894043,,,6,,,,26.6037689005873,,,1,,,,,,,,,,,,,,,,,,,,,,26.4193325042725,26.571834564209,50.0059928894043,50.0059928894043,,,6.1805739402771,,1,0,0,0,0.013885498046875,28.3479976654053,2,1,1,26.5755195617676,0,4232058208,26.4950693130493,,,2.75149332541664E-6,1.37260424454456E-7,2.75154368242958E-6,1.37260371035906E-7,0.979653775691986,0.980593740940094,26.5807037353516,1.00000047683716,30,4,200,-4.06195104005747E-5,-0.12511770427227,-0.111808411777019,1,,,,,,,,,,,,,,,,
,3928755991.27264,26.8182191848755,50.0059928894043,,,6,,,,26.6037689005873,,,1,,,,,,,,,,,,,,,,,,,,,,26.7375087738037,26.8956470489502,50.0059928894043,50.0059928894043,,,6.19055652618408,,1,0,0,0,0.013885498046875,27.8592376708984,2,1,1,26.8989295959473,0,4232057792,26.8163763046265,,,2.71278216851456E-6,1.35333636276221E-7,2.71289029180264E-6,1.35333676184379E-7,0.978129684925079,0.980019450187683,26.5702266693115,6.54859945825592E-7,30,4,200,-2.68978255917318E-5,-0.125577107071877,-0.112602576613426,1,,,,,,,,,,,,,,,,
,3928756011.02545,27.1470203399658,50.0059928894043,,,6,,,,26.6037689005873,,,1,,,,,,,,,,,,,,,,,,,,,,27.0703830718994,27.2132205963135,50.0059928894043,50.0059928894043,,,6.20146942138672,,1,0,0,0,0.014801025390625,28.8367557525635,2,1,1,27.2236576080322,0,4232058112,27.1403741836548,,,2.67281432604339E-6,1.33331927303689E-7,2.67287048798368E-6,1.33331882749043E-7,0.981006801128387,0.982165634632111,26.5790939331055,3.0558709113393E-5,30,4,200,-4.02332152589224E-5,-0.126489400863647,-0.113579422235489,1,,,,,,,,,,,,,,,,
,3928756030.8861,27.4711513519287,50.0059928894043,,,6,,,,26.6037689005873,,,1,,,,,,,,,,,,,,,,,,,,,,27.3938522338867,27.5266761779785,50.0059928894043,50.0059928894043,,,6.21074914932251,,1,0,0,0,0.013885498046875,28.3479976654053,2,1,1,27.5484504699707,0,4232058144,27.4562140570747,,,2.63513986145586E-6,1.31462064575001E-7,2.6352277742108E-6,1.31462042341136E-7,0.977512419223785,0.979055762290955,26.5728702545166,0,30,4,200,-4.99351081089117E-5,-0.127165704965591,-0.114451423287392,1,,,,,,,,,,,,,,,,
,3928756050.65862,27.7958469390869,50.0059928894043,,,6,,,,26.6037689005873,,,1,,,,,,,,,,,,,,,,,,,,,,27.7217216491699,27.8577880859375,50.0059928894043,50.0059928894043,,,6.22115850448608,,1,0,0,0,0.013885498046875,28.3479976654053,2,1,1,27.8778781890869,0,4232058144,27.7890152401394,,,2.61151409449399E-6,1.30283954118457E-7,2.61162577200242E-6,1.30283988444349E-7,0.977333903312683,0.979292631149292,26.5689430236816,0.000152591543155722,30,4,200,-4.62043935840484E-5,-0.128043875098228,-0.115405097603798,1,,,,,,,,,,,,,,,,
,3928756070.46626,28.1197271347046,50.0059928894043,,,6,,,,26.6037689005873,,,1,,,,,,,,,,,,,,,,,,,,,,28.0391273498535,28.181116104126,50.0059928894043,50.0059928894043,,,6.22915649414062,,1,0,0,0,0.013885498046875,29.3255138397217,2,1,1,28.2003269195557,0,4232058080,28.1130620956421,,,2.58148755765126E-6,1.28778384389078E-7,2.58157450638269E-6,1.28778359339046E-7,0.980095446109772,0.981876373291016,26.572696685791,,30,4,200,-3.67130523954984E-5,-0.12850359082222,-0.116006799042225,1,,,,,,,,,,,,,,,,
,3928756090.32051,28.4490842819214,50.0059928894043,,,6,,,,26.6037689005873,,,1,,,,,,,,,,,,,,,,,,,,,,28.3690357208252,28.5061016082764,50.0059928894043,50.0059928894043,,,6.2394528388977,,1,0,0,0,0.013885498046875,28.8367557525635,2,1,1,28.5291328430176,0,4232058080,28.4365446302626,,,2.55037107911158E-6,1.27230557824242E-7,2.55045464744065E-6,1.27230505647096E-7,0.978433847427368,0.980030655860901,26.5730152130127,0,30,4,200,-4.25409634772222E-5,-0.129523560404778,-0.117142483592033,1,,,,,,,,,,,,,,,,
,3928756110.04945,28.7738437652588,50.0059928894043,,,6,,,,26.6037689005873,,,1,,,,,,,,,,,,,,,,,,,,,,28.6944313049316,28.843635559082,50.0059928894043,50.0059928894043,,,6.2494912147522,,1,0,0,0,0.013885498046875,28.8367557525635,2,1,1,28.8532562255859,0,4232058080,28.7706094741821,,,2.50743625794425E-6,1.25090553344529E-7,2.50749539245545E-6,1.25090539286154E-7,0.977738976478577,0.978829681873321,26.5777893066406,5.29756450653076,30,4,200,-3.22768828482367E-5,-0.130244463682175,-0.118229441344738,1,,,,,,,,,,,,,,,,
,3928756129.69765,29.0969352722168,50.0059928894043,,,6,,,,26.6037689005873,,,1,,,,,,,,,,,,,,,,,,,,,,29.0169506072998,29.1686725616455,50.0059928894043,50.0059928894043,,,6.2583212852478,,1,0,0,0,0.013885498046875,28.3479976654053,2,1,1,29.1769199371338,0,4232058080,29.0917980194092,,,2.46928346179878E-6,1.23198793657583E-7,2.46941606598725E-6,1.23198864563234E-7,0.973858952522278,0.975975573062897,26.5648498535156,5.09331148350611E-5,30,4,200,-3.84923332603648E-5,-0.131138101220131,-0.11906910687685,1,,,,,,,,,,,,,,,,
,3928756149.39653,29.4205760955811,50.0059928894043,,,6,,,,26.6037689005873,,,1,,,,,,,,,,,,,,,,,,,,,,29.3403720855713,29.4911727905273,50.0059928894043,50.0059928894043,,,6.26661109924316,,1,0,0,0,0.013885498046875,28.3479976654053,2,1,1,29.5007801055908,0,4232058144,29.4167064666748,,,2.41485245729442E-6,1.20472858837041E-7,2.41488670290303E-6,1.20472802732606E-7,0.97733473777771,0.977990090847015,26.5833511352539,5.29755163192749,30,4,200,-5.15239589731209E-5,-0.131844282150269,-0.120032295584679,1,,,,,,,,,,,,,,,,
,3928756169.30128,29.7672166824341,50.0059928894043,,,6,,,,26.6037689005873,,,1,,,,,,,,,,,,,,,,,,,,,,29.6736793518066,29.8538856506348,50.0059928894043,50.0059928894043,,,6.27591133117676,,1,0,0,0,0.013885498046875,28.3479976654053,6,1,1,29.8607540130615,0,4232058080,29.7676410675049,,,2.37293656152171E-6,1.18382555308099E-7,2.37297279934455E-6,1.18382486099428E-7,0.97702819108963,0.977728724479675,26.5825176239014,0,30,4,200,-1.49996831169119E-5,-0.132653996348381,-0.121227264404297,1,,,,,,,,,,,,,,,,
,3928756189.19284,29.9700794219971,50.0059928894043,,,6,,,,26.6037689005873,,,1,,,,,,,,,,,,,,,,,,,,,,29.9550342559814,29.9822826385498,50.0059928894043,50.0059928894043,,,6.2807297706604,,1,0,0,0,0.013885498046875,28.8367557525635,5,1,1,29.9851245880127,0,4232058112,29.9702637990316,,,2.34677581215061E-6,1.17080771083007E-7,2.3468003243872E-6,1.17080722867322E-7,0.975816428661346,0.976269364356995,26.5861873626709,0.188782125711441,30,4,200,1.42049821079127E-5,-0.132761389017105,-0.121470175683498,1,,,,,,,,,,,,,,,,
,3928756217.98251,29.9993734359741,50.0059928894043,,,6,,,,26.6087814794752,,,1,,,,,,,,,,,,,,,,,,,,,,29.998743057251,29.9999370574951,50.0059928894043,50.0059928894043,,,6.28446292877197,,1,0,0,0,0.013885498046875,28.8367557525635,5,1,1,30.0000038146973,0,4232058176,29.9992156982422,,,2.33986262391159E-6,1.1674077993679E-7,2.34000024789858E-6,1.16740731487012E-7,0.97414368391037,0.976544559001923,26.5677452087402,0,30,4,200,6.3591037360311E-6,-0.132548958063126,-0.12115915119648,1,,,,,,,,,,,,,,,,
,3928756237.73528,30.0003461837769,50.0059928894043,,,6,,,,26.6087814794752,,,1,,,,,,,,,,,,,,,,,,,,,,29.9995899200439,30.0004425048828,50.0059928894043,50.0059928894043,,,6.28725004196167,,1,0,0,0,0.013885498046875,28.3479976654053,5,1,1,30.0003128051758,0,4232058208,30.0000318527222,,,2.34365544687785E-6,1.16920588913232E-7,2.3437035832738E-6,1.16920507679767E-7,0.977463245391846,0.9784255027771,26.5841979980469,,30,4,200,9.12640916794771E-6,-0.132122650742531,-0.12086021900177,1,,,,,,,,,,,,,,,,
,3928756247.65238,30.0004281997681,50.0059928894043,,,6,,,,26.6087814794752,,,1,,,,,,,,,,,,,,,,,,,,,,29.9997367858887,30.0004844665527,50.0059928894043,50.0059928894043,,,6.28807544708252,,1,0,0,0,0.013885498046875,28.3479976654053,1,1,1,30.0004844665527,0,4232058272,30.0001546859741,,,2.34601509379919E-6,1.17045878155033E-7,2.34612459774679E-6,1.1704579075469E-7,0.974762976169586,0.9767165184021,26.5720348358154,,30,4,200,2.25391568164923E-6,-0.132175073027611,-0.120814345777035,1,,,,,,,,,,,,,,,,